Workbook

Sheet Current
B1: Standings as of | C1: 45836
B2: Number of Weeks Played | D2: 24 | AB2: =text(C1,"mm/dd/yy") -> 06/28/25
C3: Beginning of week | F3: Current Week Scores | N3: End of week | Q3: Jan-Jun 2025 | R3: Jul-Dec 2025
A4: Ranking | B4: Name of Player | C4: Games Won | D4: Sets Won | E4: Games Won / Match | F4: Check IN | G4: Court # | H4: Set 0 | I4: Set 1 | J4: Set 2 | K4: Set 3 | L4: Games Won | M4: Sets Won | N4: Games Won | O4: Sets Won | P4: Waiver | Q4: Fee | R4: Fee | S4: Sit outs | T4: No Shows | U4: Absent | V4: Positions Gained/Lost | W4: Ranking
A5: 1 | B5: Pulkit Mathur | C5: 389 | D5: 50 | E5: =if(($D$2-U5-S5)<>0,(C5-(U5*9)-(S5*13))/($D$2-U5-S5),0) -> 16.347826 | F5: =if(isna(VLOOKUP(B5,Checkin!A:B,2,false)),0,VLOOKUP(B5,Checkin!A:B,2,false)) -> 0 | G5: =if(OR($F5=1, $F5=2),VLOOKUP($B5,Courts!$B$2:$K$50,10,false),0) -> 0 | H5: =IF(OR(F5=3,F5=4),9,IF(F5=5,13,0)) -> 0 | I5: =if(OR($F5=1, $F5=2),VLOOKUP($B5,Courts!$B$2:$J$50,5,false),0) -> 0 | J5: =if(OR($F5=1, $F5=2),VLOOKUP($B5,Courts!$B$2:$J$50,6,false),0) -> 0 | K5: =if(OR($F5=1, $F5=2),VLOOKUP($B5,Courts!$B$2:$J$50,7,false),0) -> 0 | L5: =H5+I5+J5+K5 -> 0 | M5: =if(OR($F5=1, $F5=2),VLOOKUP($B5,Courts!$B$2:$J$50,9,false),0) -> 0 | N5: =C5+L5 -> 389 | O5: =D5+M5 -> 50 | P5: X | Q5: X | R5: X | S5: =if(H5=13,1,0)+VLOOKUP(B5,indirect($AB$2&"!B:T"),18,false) -> 1 | U5: =if(H5=9,1,0)+VLOOKUP(B5,indirect($AB$2&"!B:U"),20,false) -> 0 | V5: =VLOOKUP(B5,indirect($AB$2&"!B$5:w$70"),22,false)-A5 -> 0 | W5: 1
A6: =A5+1 -> 2 | B6: Ethan Gu | C6: 321 | D6: 30 | E6: =if(($D$2-U6-S6)<>0,(C6-(U6*9)-(S6*13))/($D$2-U6-S6),0) -> 14.25 | F6: =if(isna(VLOOKUP(B6,Checkin!A:B,2,false)),0,VLOOKUP(B6,Checkin!A:B,2,false)) -> 0 | G6: =if(OR($F6=1, $F6=2),VLOOKUP($B6,Courts!$B$2:$K$50,10,false),0) -> 0 | H6: =IF(OR(F6=3,F6=4),9,IF(F6=5,13,0)) -> 0 | I6: =if(OR($F6=1, $F6=2),VLOOKUP($B6,Courts!$B$2:$J$50,5,false),0) -> 0 | J6: =if(OR($F6=1, $F6=2),VLOOKUP($B6,Courts!$B$2:$J$50,6,false),0) -> 0 | K6: =if(OR($F6=1, $F6=2),VLOOKUP($B6,Courts!$B$2:$J$50,7,false),0) -> 0 | L6: =H6+I6+J6+K6 -> 0 | M6: =if(OR($F6=1, $F6=2),VLOOKUP($B6,Courts!$B$2:$J$50,9,false),0) -> 0 | N6: =C6+L6 -> 321 | O6: =D6+M6 -> 30 | P6: X | Q6: X | R6: X | S6: =if(H6=13,1,0)+VLOOKUP(B6,indirect($AB$2&"!B:T"),18,false) -> 0 | U6: =if(H6=9,1,0)+VLOOKUP(B6,indirect($AB$2&"!B:U"),20,false) -> 4 | V6: =VLOOKUP(B6,indirect($AB$2&"!B$5:w$70"),22,false)-A6 -> 0 | W6: =W5+1 -> 2
A7: =A6+1 -> 3 | B7: Pavan Akkimsetty | C7: 316 | D7: 31 | E7: =if(($D$2-U7-S7)<>0,(C7-(U7*9)-(S7*13))/($D$2-U7-S7),0) -> 14.882353 | F7: =if(isna(VLOOKUP(B7,Checkin!A:B,2,false)),0,VLOOKUP(B7,Checkin!A:B,2,false)) -> 0 | G7: =if(OR($F7=1, $F7=2),VLOOKUP($B7,Courts!$B$2:$K$50,10,false),0) -> 0 | H7: =IF(OR(F7=3,F7=4),9,IF(F7=5,13,0)) -> 0 | I7: =if(OR($F7=1, $F7=2),VLOOKUP($B7,Courts!$B$2:$J$50,5,false),0) -> 0 | J7: =if(OR($F7=1, $F7=2),VLOOKUP($B7,Courts!$B$2:$J$50,6,false),0) -> 0 | K7: =if(OR($F7=1, $F7=2),VLOOKUP($B7,Courts!$B$2:$J$50,7,false),0) -> 0 | L7: =H7+I7+J7+K7 -> 0 | M7: =if(OR($F7=1, $F7=2),VLOOKUP($B7,Courts!$B$2:$J$50,9,false),0) -> 0 | N7: =C7+L7 -> 316 | O7: =D7+M7 -> 31 | P7: X | Q7: X | R7: X | S7: =if(H7=13,1,0)+VLOOKUP(B7,indirect($AB$2&"!B:T"),18,false) -> 0 | U7: =if(H7=9,1,0)+VLOOKUP(B7,indirect($AB$2&"!B:U"),20,false) -> 7 | V7: =VLOOKUP(B7,indirect($AB$2&"!B$5:w$70"),22,false)-A7 -> 0 | W7: =W6+1 -> 3
A8: =A7+1 -> 4 | B8: Sandeep Kamalon | C8: 311 | D8: 30 | E8: =if(($D$2-U8-S8)<>0,(C8-(U8*9)-(S8*13))/($D$2-U8-S8),0) -> 13.136364 | F8: =if(isna(VLOOKUP(B8,Checkin!A:B,2,false)),0,VLOOKUP(B8,Checkin!A:B,2,false)) -> 0 | G8: =if(OR($F8=1, $F8=2),VLOOKUP($B8,Courts!$B$2:$K$50,10,false),0) -> 0 | H8: =IF(OR(F8=3,F8=4),9,IF(F8=5,13,0)) -> 0 | I8: =if(OR($F8=1, $F8=2),VLOOKUP($B8,Courts!$B$2:$J$50,5,false),0) -> 0 | J8: =if(OR($F8=1, $F8=2),VLOOKUP($B8,Courts!$B$2:$J$50,6,false),0) -> 0 | K8: =if(OR($F8=1, $F8=2),VLOOKUP($B8,Courts!$B$2:$J$50,7,false),0) -> 0 | L8: =H8+I8+J8+K8 -> 0 | M8: =if(OR($F8=1, $F8=2),VLOOKUP($B8,Courts!$B$2:$J$50,9,false),0) -> 0 | N8: =C8+L8 -> 311 | O8: =D8+M8 -> 30 | P8: X | Q8: X | R8: X | S8: =if(H8=13,1,0)+VLOOKUP(B8,indirect($AB$2&"!B:T"),18,false) -> 1 | U8: =if(H8=9,1,0)+VLOOKUP(B8,indirect($AB$2&"!B:U"),20,false) -> 1 | V8: =VLOOKUP(B8,indirect($AB$2&"!B$5:w$70"),22,false)-A8 -> 4 | W8: =W7+1 -> 4
A9: =A8+1 -> 5 | B9: Jonathan Phan | C9: 311 | D9: 29 | E9: =if(($D$2-U9-S9)<>0,(C9-(U9*9)-(S9*13))/($D$2-U9-S9),0) -> 14.9375 | F9: =if(isna(VLOOKUP(B9,Checkin!A:B,2,false)),0,VLOOKUP(B9,Checkin!A:B,2,false)) -> 0 | G9: =if(OR($F9=1, $F9=2),VLOOKUP($B9,Courts!$B$2:$K$50,10,false),0) -> 0 | H9: =IF(OR(F9=3,F9=4),9,IF(F9=5,13,0)) -> 0 | I9: =if(OR($F9=1, $F9=2),VLOOKUP($B9,Courts!$B$2:$J$50,5,false),0) -> 0 | J9: =if(OR($F9=1, $F9=2),VLOOKUP($B9,Courts!$B$2:$J$50,6,false),0) -> 0 | K9: =if(OR($F9=1, $F9=2),VLOOKUP($B9,Courts!$B$2:$J$50,7,false),0) -> 0 | L9: =H9+I9+J9+K9 -> 0 | M9: =if(OR($F9=1, $F9=2),VLOOKUP($B9,Courts!$B$2:$J$50,9,false),0) -> 0 | N9: =C9+L9 -> 311 | O9: =D9+M9 -> 29 | P9: X | Q9: X | R9: X | S9: =if(H9=13,1,0)+VLOOKUP(B9,indirect($AB$2&"!B:T"),18,false) -> 0 | U9: =if(H9=9,1,0)+VLOOKUP(B9,indirect($AB$2&"!B:U"),20,false) -> 8 | V9: =VLOOKUP(B9,indirect($AB$2&"!B$5:w$70"),22,false)-A9 -> -1 | W9: =W8+1 -> 5
A10: =A9+1 -> 6 | B10: Basudev Thoppai Vidyasankar | C10: 311 | D10: 27 | E10: =if(($D$2-U10-S10)<>0,(C10-(U10*9)-(S10*13))/($D$2-U10-S10),0) -> 14.588235 | F10: =if(isna(VLOOKUP(B10,Checkin!A:B,2,false)),0,VLOOKUP(B10,Checkin!A:B,2,false)) -> 0 | G10: =if(OR($F10=1, $F10=2),VLOOKUP($B10,Courts!$B$2:$K$50,10,false),0) -> 0 | H10: =IF(OR(F10=3,F10=4),9,IF(F10=5,13,0)) -> 0 | I10: =if(OR($F10=1, $F10=2),VLOOKUP($B10,Courts!$B$2:$J$50,5,false),0) -> 0 | J10: =if(OR($F10=1, $F10=2),VLOOKUP($B10,Courts!$B$2:$J$50,6,false),0) -> 0 | K10: =if(OR($F10=1, $F10=2),VLOOKUP($B10,Courts!$B$2:$J$50,7,false),0) -> 0 | L10: =H10+I10+J10+K10 -> 0 | M10: =if(OR($F10=1, $F10=2),VLOOKUP($B10,Courts!$B$2:$J$50,9,false),0) -> 0 | N10: =C10+L10 -> 311 | O10: =D10+M10 -> 27 | P10: X | Q10: X | R10: X | S10: =if(H10=13,1,0)+VLOOKUP(B10,indirect($AB$2&"!B:T"),18,false) -> 0 | U10: =if(H10=9,1,0)+VLOOKUP(B10,indirect($AB$2&"!B:U"),20,false) -> 7 | V10: =VLOOKUP(B10,indirect($AB$2&"!B$5:w$70"),22,false)-A10 -> 0 | W10: =W9+1 -> 6
A11: =A10+1 -> 7 | B11: Manish Anand | C11: 308 | D11: 22 | E11: =if(($D$2-U11-S11)<>0,(C11-(U11*9)-(S11*13))/($D$2-U11-S11),0) -> 14.5 | F11: =if(isna(VLOOKUP(B11,Checkin!A:B,2,false)),0,VLOOKUP(B11,Checkin!A:B,2,false)) -> 0 | G11: =if(OR($F11=1, $F11=2),VLOOKUP($B11,Courts!$B$2:$K$50,10,false),0) -> 0 | H11: =IF(OR(F11=3,F11=4),9,IF(F11=5,13,0)) -> 0 | I11: =if(OR($F11=1, $F11=2),VLOOKUP($B11,Courts!$B$2:$J$50,5,false),0) -> 0 | J11: =if(OR($F11=1, $F11=2),VLOOKUP($B11,Courts!$B$2:$J$50,6,false),0) -> 0 | K11: =if(OR($F11=1, $F11=2),VLOOKUP($B11,Courts!$B$2:$J$50,7,false),0) -> 0 | L11: =H11+I11+J11+K11 -> 0 | M11: =if(OR($F11=1, $F11=2),VLOOKUP($B11,Courts!$B$2:$J$50,9,false),0) -> 0 | N11: =C11+L11 -> 308 | O11: =D11+M11 -> 22 | P11: X | Q11: X | R11: X | S11: =if(H11=13,1,0)+VLOOKUP(B11,indirect($AB$2&"!B:T"),18,false) -> 1 | U11: =if(H11=9,1,0)+VLOOKUP(B11,indirect($AB$2&"!B:U"),20,false) -> 7 | V11: =VLOOKUP(B11,indirect($AB$2&"!B$5:w$70"),22,false)-A11 -> -2 | W11: =W10+1 -> 7
A12: =A11+1 -> 8 | B12: Joe Luzzi | C12: 305 | D12: 24 | E12: =if(($D$2-U12-S12)<>0,(C12-(U12*9)-(S12*13))/($D$2-U12-S12),0) -> 13.473684 | F12: =if(isna(VLOOKUP(B12,Checkin!A:B,2,false)),0,VLOOKUP(B12,Checkin!A:B,2,false)) -> 0 | G12: =if(OR($F12=1, $F12=2),VLOOKUP($B12,Courts!$B$2:$K$50,10,false),0) -> 0 | H12: =IF(OR(F12=3,F12=4),9,IF(F12=5,13,0)) -> 0 | I12: =if(OR($F12=1, $F12=2),VLOOKUP($B12,Courts!$B$2:$J$50,5,false),0) -> 0 | J12: =if(OR($F12=1, $F12=2),VLOOKUP($B12,Courts!$B$2:$J$50,6,false),0) -> 0 | K12: =if(OR($F12=1, $F12=2),VLOOKUP($B12,Courts!$B$2:$J$50,7,false),0) -> 0 | L12: =H12+I12+J12+K12 -> 0 | M12: =if(OR($F12=1, $F12=2),VLOOKUP($B12,Courts!$B$2:$J$50,9,false),0) -> 0 | N12: =C12+L12 -> 305 | O12: =D12+M12 -> 24 | P12: X | Q12: X | R12: X | S12: =if(H12=13,1,0)+VLOOKUP(B12,indirect($AB$2&"!B:T"),18,false) -> 1 | U12: =if(H12=9,1,0)+VLOOKUP(B12,indirect($AB$2&"!B:U"),20,false) -> 4 | V12: =VLOOKUP(B12,indirect($AB$2&"!B$5:w$70"),22,false)-A12 -> 2 | W12: =W11+1 -> 8
A13: =A12+1 -> 9 | B13: Lloyd Sagar | C13: 303 | D13: 29 | E13: =if(($D$2-U13-S13)<>0,(C13-(U13*9)-(S13*13))/($D$2-U13-S13),0) -> 14.1875 | F13: =if(isna(VLOOKUP(B13,Checkin!A:B,2,false)),0,VLOOKUP(B13,Checkin!A:B,2,false)) -> 0 | G13: =if(OR($F13=1, $F13=2),VLOOKUP($B13,Courts!$B$2:$K$50,10,false),0) -> 0 | H13: =IF(OR(F13=3,F13=4),9,IF(F13=5,13,0)) -> 0 | I13: =if(OR($F13=1, $F13=2),VLOOKUP($B13,Courts!$B$2:$J$50,5,false),0) -> 0 | J13: =if(OR($F13=1, $F13=2),VLOOKUP($B13,Courts!$B$2:$J$50,6,false),0) -> 0 | K13: =if(OR($F13=1, $F13=2),VLOOKUP($B13,Courts!$B$2:$J$50,7,false),0) -> 0 | L13: =H13+I13+J13+K13 -> 0 | M13: =if(OR($F13=1, $F13=2),VLOOKUP($B13,Courts!$B$2:$J$50,9,false),0) -> 0 | N13: =C13+L13 -> 303 | O13: =D13+M13 -> 29 | P13: X | Q13: X | R13: X | S13: =if(H13=13,1,0)+VLOOKUP(B13,indirect($AB$2&"!B:T"),18,false) -> 1 | U13: =if(H13=9,1,0)+VLOOKUP(B13,indirect($AB$2&"!B:U"),20,false) -> 7 | V13: =VLOOKUP(B13,indirect($AB$2&"!B$5:w$70"),22,false)-A13 -> 8 | W13: =W12+1 -> 9
A14: =A13+1 -> 10 | B14: David Shin | C14: 303 | D14: 24 | E14: =if(($D$2-U14-S14)<>0,(C14-(U14*9)-(S14*13))/($D$2-U14-S14),0) -> 13.647059 | F14: =if(isna(VLOOKUP(B14,Checkin!A:B,2,false)),0,VLOOKUP(B14,Checkin!A:B,2,false)) -> 0 | G14: =if(OR($F14=1, $F14=2),VLOOKUP($B14,Courts!$B$2:$K$50,10,false),0) -> 0 | H14: =IF(OR(F14=3,F14=4),9,IF(F14=5,13,0)) -> 0 | I14: =if(OR($F14=1, $F14=2),VLOOKUP($B14,Courts!$B$2:$J$50,5,false),0) -> 0 | J14: =if(OR($F14=1, $F14=2),VLOOKUP($B14,Courts!$B$2:$J$50,6,false),0) -> 0 | K14: =if(OR($F14=1, $F14=2),VLOOKUP($B14,Courts!$B$2:$J$50,7,false),0) -> 0 | L14: =H14+I14+J14+K14 -> 0 | M14: =if(OR($F14=1, $F14=2),VLOOKUP($B14,Courts!$B$2:$J$50,9,false),0) -> 0 | N14: =C14+L14 -> 303 | O14: =D14+M14 -> 24 | P14: X | Q14: X | R14: X | S14: =if(H14=13,1,0)+VLOOKUP(B14,indirect($AB$2&"!B:T"),18,false) -> 2 | U14: =if(H14=9,1,0)+VLOOKUP(B14,indirect($AB$2&"!B:U"),20,false) -> 5 | V14: =VLOOKUP(B14,indirect($AB$2&"!B$5:w$70"),22,false)-A14 -> -3 | W14: =W13+1 -> 10
A15: =A14+1 -> 11 | B15: Herman Au | C15: 303 | D15: 20 | E15: =if(($D$2-U15-S15)<>0,(C15-(U15*9)-(S15*13))/($D$2-U15-S15),0) -> 13.882353 | F15: =if(isna(VLOOKUP(B15,Checkin!A:B,2,false)),0,VLOOKUP(B15,Checkin!A:B,2,false)) -> 0 | G15: =if(OR($F15=1, $F15=2),VLOOKUP($B15,Courts!$B$2:$K$50,10,false),0) -> 0 | H15: =IF(OR(F15=3,F15=4),9,IF(F15=5,13,0)) -> 0 | I15: =if(OR($F15=1, $F15=2),VLOOKUP($B15,Courts!$B$2:$J$50,5,false),0) -> 0 | J15: =if(OR($F15=1, $F15=2),VLOOKUP($B15,Courts!$B$2:$J$50,6,false),0) -> 0 | K15: =if(OR($F15=1, $F15=2),VLOOKUP($B15,Courts!$B$2:$J$50,7,false),0) -> 0 | L15: =H15+I15+J15+K15 -> 0 | M15: =if(OR($F15=1, $F15=2),VLOOKUP($B15,Courts!$B$2:$J$50,9,false),0) -> 0 | N15: =C15+L15 -> 303 | O15: =D15+M15 -> 20 | P15: X | Q15: X | R15: X | S15: =if(H15=13,1,0)+VLOOKUP(B15,indirect($AB$2&"!B:T"),18,false) -> 1 | U15: =if(H15=9,1,0)+VLOOKUP(B15,indirect($AB$2&"!B:U"),20,false) -> 6 | V15: =VLOOKUP(B15,indirect($AB$2&"!B$5:w$70"),22,false)-A15 -> 1 | W15: =W14+1 -> 11
A16: =A15+1 -> 12 | B16: Scott Li | C16: 301 | D16: 24 | E16: =if(($D$2-U16-S16)<>0,(C16-(U16*9)-(S16*13))/($D$2-U16-S16),0) -> 13.764706 | F16: =if(isna(VLOOKUP(B16,Checkin!A:B,2,false)),0,VLOOKUP(B16,Checkin!A:B,2,false)) -> 0 | G16: =if(OR($F16=1, $F16=2),VLOOKUP($B16,Courts!$B$2:$K$50,10,false),0) -> 0 | H16: =IF(OR(F16=3,F16=4),9,IF(F16=5,13,0)) -> 0 | I16: =if(OR($F16=1, $F16=2),VLOOKUP($B16,Courts!$B$2:$J$50,5,false),0) -> 0 | J16: =if(OR($F16=1, $F16=2),VLOOKUP($B16,Courts!$B$2:$J$50,6,false),0) -> 0 | K16: =if(OR($F16=1, $F16=2),VLOOKUP($B16,Courts!$B$2:$J$50,7,false),0) -> 0 | L16: =H16+I16+J16+K16 -> 0 | M16: =if(OR($F16=1, $F16=2),VLOOKUP($B16,Courts!$B$2:$J$50,9,false),0) -> 0 | N16: =C16+L16 -> 301 | O16: =D16+M16 -> 24 | P16: X | Q16: X | R16: X | S16: =if(H16=13,1,0)+VLOOKUP(B16,indirect($AB$2&"!B:T"),18,false) -> 1 | U16: =if(H16=9,1,0)+VLOOKUP(B16,indirect($AB$2&"!B:U"),20,false) -> 6 | V16: =VLOOKUP(B16,indirect($AB$2&"!B$5:w$70"),22,false)-A16 -> -3 | W16: =W15+1 -> 12
A17: =A16+1 -> 13 | B17: Erik Hoeckmann | C17: 299 | D17: 26 | E17: =if(($D$2-U17-S17)<>0,(C17-(U17*9)-(S17*13))/($D$2-U17-S17),0) -> 14.266667 | F17: =if(isna(VLOOKUP(B17,Checkin!A:B,2,false)),0,VLOOKUP(B17,Checkin!A:B,2,false)) -> 0 | G17: =if(OR($F17=1, $F17=2),VLOOKUP($B17,Courts!$B$2:$K$50,10,false),0) -> 0 | H17: =IF(OR(F17=3,F17=4),9,IF(F17=5,13,0)) -> 0 | I17: =if(OR($F17=1, $F17=2),VLOOKUP($B17,Courts!$B$2:$J$50,5,false),0) -> 0 | J17: =if(OR($F17=1, $F17=2),VLOOKUP($B17,Courts!$B$2:$J$50,6,false),0) -> 0 | K17: =if(OR($F17=1, $F17=2),VLOOKUP($B17,Courts!$B$2:$J$50,7,false),0) -> 0 | L17: =H17+I17+J17+K17 -> 0 | M17: =if(OR($F17=1, $F17=2),VLOOKUP($B17,Courts!$B$2:$J$50,9,false),0) -> 0 | N17: =C17+L17 -> 299 | O17: =D17+M17 -> 26 | P17: X | Q17: X | R17: X | S17: =if(H17=13,1,0)+VLOOKUP(B17,indirect($AB$2&"!B:T"),18,false) -> 1 | U17: =if(H17=9,1,0)+VLOOKUP(B17,indirect($AB$2&"!B:U"),20,false) -> 8 | V17: =VLOOKUP(B17,indirect($AB$2&"!B$5:w$70"),22,false)-A17 -> -2 | W17: =W16+1 -> 13
... A69: =A68+1 -> 65 | B69: Barathi Sundaram | C69: 196 | D69: 3 | E69: =if(($D$2-U69-S69)<>0,(C69-(U69*9)-(S69*13))/($D$2-U69-S69),0) -> 6.7777778 | F69: =if(isna(VLOOKUP(B69,Checkin!A:B,2,false)),0,VLOOKUP(B69,Checkin!A:B,2,false)) -> 0 | G69: =if(OR($F69=1, $F69=2),VLOOKUP($B69,Courts!$B$2:$K$50,10,false),0) -> 0 | H69: =IF(OR(F69=3,F69=4),9,IF(F69=5,13,0)) -> 0 | I69: =if(OR($F69=1, $F69=2),VLOOKUP($B69,Courts!$B$2:$J$50,5,false),0) -> 0 | J69: =if(OR($F69=1, $F69=2),VLOOKUP($B69,Courts!$B$2:$J$50,6,false),0) -> 0 | K69: =if(OR($F69=1, $F69=2),VLOOKUP($B69,Courts!$B$2:$J$50,7,false),0) -> 0 | L69: =H69+I69+J69+K69 -> 0 | M69: =if(OR($F69=1, $F69=2),VLOOKUP($B69,Courts!$B$2:$J$50,9,false),0) -> 0 | N69: =C69+L69 -> 196 | O69: =D69+M69 -> 3 | P69: X | Q69: X | R69: X | S69: =if(H69=13,1,0)+VLOOKUP(B69,indirect($AB$2&"!B:T"),18,false) -> 0 | U69: =if(H69=9,1,0)+VLOOKUP(B69,indirect($AB$2&"!B:U"),20,false) -> 15 | V69: =VLOOKUP(B69,indirect($AB$2&"!B$5:w$70"),22,false)-A69 -> 0 | W69: =W68+1 -> 65
P74: Renewed | R74: =COUNTIF(R5:R69,"X") -> 64 | S74: =R74/R78 -> 0.98461538
P75: Not Renewing | R75: =countif(R5:R69,"N") -> 1
B76: Top Scores | C76: Games | D76: Sets | E76: Court # | P76: New Members | R76: 1
B77: =IFERROR(__xludf.DUMMYFUNCTION("QUERY(B5:M69,""Select B, L, M, G where L >= 18 order by L desc,M desc"",0)"),"#N/A") -> #N/A | P77: To Renew | R77: =countif(R5:R69,"") -> 0
P78: Total | R78: =sum(R74:R77)-R76 -> 65
B90: Top 10 Movements (UP) | C90: Positions Moved | D90: Position Last week | E90: Position This week | F90: Points this week | G90: Court | L90: Cross Check
B91: =IFERROR(__xludf.DUMMYFUNCTION("query(B5:V69,""select B, V order by V Desc Limit 10"")"),"Lam Bui") -> Lam Bui | C91: =IFERROR(__xludf.DUMMYFUNCTION("""COMPUTED_VALUE"""),13.0) -> 13 | D91: =VLOOKUP(B91,indirect($AB$2&"!B$5:w$70"),22, false) -> 27 | E91: =VLOOKUP(B91,B$5:W$69,22, false) -> 14 | F91: =VLOOKUP(B91,indirect($AB$2&"!B$5:U$70"),11, false) -> 18 | G91: =VLOOKUP(B91,indirect($AB$2&"!B$5:U$70"),6, false) -> 4 | L91: =if(D91-E91=C91,"ok","Error") -> ok
B92: =IFERROR(__xludf.DUMMYFUNCTION("""COMPUTED_VALUE"""),"Lloyd Sagar") -> Lloyd Sagar | C92: =IFERROR(__xludf.DUMMYFUNCTION("""COMPUTED_VALUE"""),8.0) -> 8 | D92: =VLOOKUP(B92,indirect($AB$2&"!B$5:w$70"),22, false) -> 17 | E92: =VLOOKUP(B92,B$5:W$69,22, false) -> 9 | F92: =VLOOKUP(B92,indirect($AB$2&"!B$5:U$70"),11, false) -> 18 | G92: =VLOOKUP(B92,indirect($AB$2&"!B$5:U$70"),6, false) -> 3 | L92: =if(D92-E92=C92,"ok","Error") -> ok
B93: =IFERROR(__xludf.DUMMYFUNCTION("""COMPUTED_VALUE"""),"Jimmy Awolesi") -> Jimmy Awolesi | C93: =IFERROR(__xludf.DUMMYFUNCTION("""COMPUTED_VALUE"""),8.0) -> 8 | D93: =VLOOKUP(B93,indirect($AB$2&"!B$5:w$70"),22, false) -> 34 | E93: =VLOOKUP(B93,B$5:W$69,22, false) -> 26 | F93: =VLOOKUP(B93,indirect($AB$2&"!B$5:U$70"),11, false) -> 19 | G93: =VLOOKUP(B93,indirect($AB$2&"!B$5:U$70"),6, false) -> 5 | L93: =if(D93-E93=C93,"ok","Error") -> ok
B94: =IFERROR(__xludf.DUMMYFUNCTION("""COMPUTED_VALUE"""),"Ted Shen") -> Ted Shen | C94: =IFERROR(__xludf.DUMMYFUNCTION("""COMPUTED_VALUE"""),6.0) -> 6 | D94: =VLOOKUP(B94,indirect($AB$2&"!B$5:w$70"),22, false) -> 21 | E94: =VLOOKUP(B94,B$5:W$69,22, false) -> 15 | F94: =VLOOKUP(B94,indirect($AB$2&"!B$5:U$70"),11, false) -> 14 | G94: =VLOOKUP(B94,indirect($AB$2&"!B$5:U$70"),6, false) -> 3 | L94: =if(D94-E94=C94,"ok","Error") -> ok
B95: =IFERROR(__xludf.DUMMYFUNCTION("""COMPUTED_VALUE"""),"Matthew Huang") -> Matthew Huang | C95: =IFERROR(__xludf.DUMMYFUNCTION("""COMPUTED_VALUE"""),5.0) -> 5 | D95: =VLOOKUP(B95,indirect($AB$2&"!B$5:w$70"),22, false) -> 43 | E95: =VLOOKUP(B95,B$5:W$69,22, false) -> 38 | F95: =VLOOKUP(B95,indirect($AB$2&"!B$5:U$70"),11, false) -> 18 | G95: =VLOOKUP(B95,indirect($AB$2&"!B$5:U$70"),6, false) -> 7 | L95: =if(D95-E95=C95,"ok","Error") -> ok
B96: =IFERROR(__xludf.DUMMYFUNCTION("""COMPUTED_VALUE"""),"Sandeep Kamalon") -> Sandeep Kamalon | C96: =IFERROR(__xludf.DUMMYFUNCTION("""COMPUTED_VALUE"""),4.0) -> 4 | D96: =VLOOKUP(B96,indirect($AB$2&"!B$5:w$70"),22, false) -> 8 | E96: =VLOOKUP(B96,B$5:W$69,22, false) -> 4 | F96: =VLOOKUP(B96,indirect($AB$2&"!B$5:U$70"),11, false) -> 18 | G96: =VLOOKUP(B96,indirect($AB$2&"!B$5:U$70"),6, false) -> 2 | L96: =if(D96-E96=C96,"ok","Error") -> ok
B97: =IFERROR(__xludf.DUMMYFUNCTION("""COMPUTED_VALUE"""),"Wayne Liu") -> Wayne Liu | C97: =IFERROR(__xludf.DUMMYFUNCTION("""COMPUTED_VALUE"""),4.0) -> 4 | D97: =VLOOKUP(B97,indirect($AB$2&"!B$5:w$70"),22, false) -> 31 | E97: =VLOOKUP(B97,B$5:W$69,22, false) -> 27 | F97: =VLOOKUP(B97,indirect($AB$2&"!B$5:U$70"),11, false) -> 14 | G97: =VLOOKUP(B97,indirect($AB$2&"!B$5:U$70"),6, false) -> 5 | L97: =if(D97-E97=C97,"ok","Error") -> ok
B98: =IFERROR(__xludf.DUMMYFUNCTION("""COMPUTED_VALUE"""),"Balaji Alahari") -> Balaji Alahari | C98: =IFERROR(__xludf.DUMMYFUNCTION("""COMPUTED_VALUE"""),3.0) -> 3 | D98: =VLOOKUP(B98,indirect($AB$2&"!B$5:w$70"),22, false) -> 62 | E98: =VLOOKUP(B98,B$5:W$69,22, false) -> 59 | F98: =VLOOKUP(B98,indirect($AB$2&"!B$5:U$70"),11, false) -> 15 | G98: =VLOOKUP(B98,indirect($AB$2&"!B$5:U$70"),6, false) -> 8 | L98: =if(D98-E98=C98,"ok","Error") -> ok
B99: =IFERROR(__xludf.DUMMYFUNCTION("""COMPUTED_VALUE"""),"Joe Luzzi") -> Joe Luzzi | C99: =IFERROR(__xludf.DUMMYFUNCTION("""COMPUTED_VALUE"""),2.0) -> 2 | D99: =VLOOKUP(B99,indirect($AB$2&"!B$5:w$70"),22, false) -> 10 | E99: =VLOOKUP(B99,B$5:W$69,22, false) -> 8 | F99: =VLOOKUP(B99,indirect($AB$2&"!B$5:U$70"),11, false) -> 14 | G99: =VLOOKUP(B99,indirect($AB$2&"!B$5:U$70"),6, false) -> 2 | L99: =if(D99-E99=C99,"ok","Error") -> ok
B100: =IFERROR(__xludf.DUMMYFUNCTION("""COMPUTED_VALUE"""),"Tina Hanson") -> Tina Hanson | C100: =IFERROR(__xludf.DUMMYFUNCTION("""COMPUTED_VALUE"""),2.0) -> 2 | D100: =VLOOKUP(B100,indirect($AB$2&"!B$5:w$70"),22, false) -> 22 | E100: =VLOOKUP(B100,B$5:W$69,22, false) -> 20 | F100: =VLOOKUP(B100,indirect($AB$2&"!B$5:U$70"),11, false) -> 12 | G100: =VLOOKUP(B100,indirect($AB$2&"!B$5:U$70"),6, false) -> 3 | L100: =if(D100-E100=C100,"ok","Error") -> ok
B103: Top 10 Movements (Down) | C103: Positions | D103: Position Last week | E103: Position This week | F103: Points this week | G103: Court | L103: Cross Check
B104: =IFERROR(__xludf.DUMMYFUNCTION("query(B5:V69,""select B, V order by V asc Limit 10"")"),"Troy Wong") -> Troy Wong | C104: =IFERROR(__xludf.DUMMYFUNCTION("""COMPUTED_VALUE"""),-6.0) -> -6 | D104: =VLOOKUP(B104,indirect($AB$2&"!B$5:w$70"),22, false) -> 19 | E104: =VLOOKUP(B104,B$5:W$69,22, false) -> 25 | F104: =VLOOKUP(B104,indirect($AB$2&"!B$5:U$70"),11, false) -> 9 | G104: =VLOOKUP(B104,indirect($AB$2&"!B$5:U$70"),6, false) -> 0 | L104: =if(D104-E104=C104,"ok","Error") -> ok
B105: =IFERROR(__xludf.DUMMYFUNCTION("""COMPUTED_VALUE"""),"Robert Chang") -> Robert Chang | C105: =IFERROR(__xludf.DUMMYFUNCTION("""COMPUTED_VALUE"""),-5.0) -> -5 | D105: =VLOOKUP(B105,indirect($AB$2&"!B$5:w$70"),22, false) -> 16 | E105: =VLOOKUP(B105,B$5:W$69,22, false) -> 21 | F105: =VLOOKUP(B105,indirect($AB$2&"!B$5:U$70"),11, false) -> 9 | G105: =VLOOKUP(B105,indirect($AB$2&"!B$5:U$70"),6, false) -> 0 | L105: =if(D105-E105=C105,"ok","Error") -> ok
B106: =IFERROR(__xludf.DUMMYFUNCTION("""COMPUTED_VALUE"""),"Tom Le") -> Tom Le | C106: =IFERROR(__xludf.DUMMYFUNCTION("""COMPUTED_VALUE"""),-5.0) -> -5 | D106: =VLOOKUP(B106,indirect($AB$2&"!B$5:w$70"),22, false) -> 24 | E106: =VLOOKUP(B106,B$5:W$69,22, false) -> 29 | F106: =VLOOKUP(B106,indirect($AB$2&"!B$5:U$70"),11, false) -> 9 | G106: =VLOOKUP(B106,indirect($AB$2&"!B$5:U$70"),6, false) -> 0 | L106: =if(D106-E106=C106,"ok","Error") -> ok
B107: =IFERROR(__xludf.DUMMYFUNCTION("""COMPUTED_VALUE"""),"Oscar Bonilla") -> Oscar Bonilla | C107: =IFERROR(__xludf.DUMMYFUNCTION("""COMPUTED_VALUE"""),-4.0) -> -4 | D107: =VLOOKUP(B107,indirect($AB$2&"!B$5:w$70"),22, false) -> 18 | E107: =VLOOKUP(B107,B$5:W$69,22, false) -> 22 | F107: =VLOOKUP(B107,indirect($AB$2&"!B$5:U$70"),11, false) -> 9 | G107: =VLOOKUP(B107,indirect($AB$2&"!B$5:U$70"),6, false) -> 0 | L107: =if(D107-E107=C107,"ok","Error") -> ok
B108: =IFERROR(__xludf.DUMMYFUNCTION("""COMPUTED_VALUE"""),"David Shin") -> David Shin | C108: =IFERROR(__xludf.DUMMYFUNCTION("""COMPUTED_VALUE"""),-3.0) -> -3 | D108: =VLOOKUP(B108,indirect($AB$2&"!B$5:w$70"),22, false) -> 7 | E108: =VLOOKUP(B108,B$5:W$69,22, false) -> 10 | F108: =VLOOKUP(B108,indirect($AB$2&"!B$5:U$70"),11, false) -> 9 | G108: =VLOOKUP(B108,indirect($AB$2&"!B$5:U$70"),6, false) -> 0 | L108: =if(D108-E108=C108,"ok","Error") -> ok
...

Sheet Courts
A1: Court # | B1: Name of the Player | C1: Games Won | D1: Sets Won | E1: Check In | F1: Set 1 | G1: Set 2 | H1: Set 3 | I1: Total Games won | J1: Sets Won | K1: Court # | L1: Scores Entered by | M1: Mark 'X', if the court needs to be played at WHS | O1: Set 1 | P1: Set 2 | Q1: Set 2 | S1: Sets Validations | V1: Set 1 | W1: Set 2 | X1: Set 2
A2: 1 | B2: =IFERROR(__xludf.DUMMYFUNCTION("QUERY(indirect(""'"" & ""Current"" & ""'!B5:F69""),""Select B, C, D, F where F = 1 or F = 2 "",0)"),"#N/A") -> #N/A | I2: =sum(F2:H2) -> 0 | K2: =A2 -> 1 | O2: =if(COUNTIF(V2:V4,"Good")=2,"Good","Error") -> Error | P2: =if(COUNTIF(W2:W4,"Good")=2,"Good","Error") -> Error | Q2: =if(COUNTIF(X2:X4,"Good")=2,"Good","Error") -> Error | S2: =sum(J2:J5) -> 0 | T2: =if(S2=0,"",if(S2=6,"Good","ERROR")) | V2: =if(isna(VLOOKUP(F2,F3:F5,1,false)),"Error","Good") -> Error | W2: =if(isna(VLOOKUP(G2,G3:G5,1,false)),"Error","Good") -> Error | X2: =if(isna(VLOOKUP(H2,H3:H5,1,false)),"Error","Good") -> Error
A3: 1 | I3: =sum(F3:H3) -> 0 | K3: =A3 -> 1 | V3: =if(isna(VLOOKUP(F3,F4:F5,1,false)),"Error","Good") -> Error | W3: =if(isna(VLOOKUP(G3,G4:G5,1,false)),"Error","Good") -> Error | X3: =if(isna(VLOOKUP(H3,H4:H5,1,false)),"Error","Good") -> Error | AD3: Alejandro Mejia
A4: 1 | I4: =sum(F4:H4) -> 0 | K4: =A4 -> 1 | V4: =if(F4=F5,"Good") -> Good | W4: =if(G4=G5,"Good") -> Good | X4: =if(H4=H5,"Good") -> Good | Y4: N | Z4: Skip Court 3 | AD4: Jimmy Awolesi
A5: 1 | I5: =sum(F5:H5) -> 0 | K5: =A5 -> 1 | Y5: N | Z5: Skip Court 4 | AD5: Tony Wong
A6: 2 | I6: =sum(F6:H6) -> 0 | K6: =A6 -> 2 | O6: =if(COUNTIF(V6:V8,"Good")=2,"Good","Error") -> Error | P6: =if(COUNTIF(W6:W8,"Good")=2,"Good","Error") -> Error | Q6: =if(COUNTIF(X6:X8,"Good")=2,"Good","Error") -> Error | S6: =sum(J6:J9) -> 0 | T6: =if(S6=0,"",if(S6=6,"Good","ERROR")) | V6: =if(isna(VLOOKUP(F6,F7:F9,1,false)),"Error","Good") -> Error | W6: =if(isna(VLOOKUP(G6,G7:G9,1,false)),"Error","Good") -> Error | X6: =if(isna(VLOOKUP(H6,H7:H9,1,false)),"Error","Good") -> Error | AD6: Vinaya Kajla
A7: 2 | I7: =sum(F7:H7) -> 0 | K7: =A7 -> 2 | V7: =if(isna(VLOOKUP(F7,F8:F9,1,false)),"Error","Good") -> Error | W7: =if(isna(VLOOKUP(G7,G8:G9,1,false)),"Error","Good") -> Error | X7: =if(isna(VLOOKUP(H7,H8:H9,1,false)),"Error","Good") -> Error
A8: 2 | I8: =sum(F8:H8) -> 0 | K8: =A8 -> 2 | V8: =if(F8=F9,"Good") -> Good | W8: =if(G8=G9,"Good") -> Good | X8: =if(H8=H9,"Good") -> Good
A9: 2 | I9: =sum(F9:H9) -> 0 | K9: =A9 -> 2
A10: 3 | I10: =sum(F10:H10) -> 0 | K10: =A10 -> 3 | O10: =if(COUNTIF(V10:V12,"Good")=2,"Good","Error") -> Error | P10: =if(COUNTIF(W10:W12,"Good")=2,"Good","Error") -> Error | Q10: =if(COUNTIF(X10:X12,"Good")=2,"Good","Error") -> Error | S10: =sum(J10:J13) -> 0 | T10: =if(S10=0,"",if(S10=6,"Good","ERROR")) | V10: =if(isna(VLOOKUP(F10,F11:F13,1,false)),"Error","Good") -> Error | W10: =if(isna(VLOOKUP(G10,G11:G13,1,false)),"Error","Good") -> Error | X10: =if(isna(VLOOKUP(H10,H11:H13,1,false)),"Error","Good") -> Error
A11: 3 | I11: =sum(F11:H11) -> 0 | K11: =A11 -> 3 | V11: =if(isna(VLOOKUP(F11,F12:F13,1,false)),"Error","Good") -> Error | W11: =if(isna(VLOOKUP(G11,G12:G13,1,false)),"Error","Good") -> Error | X11: =if(isna(VLOOKUP(H11,H12:H13,1,false)),"Error","Good") -> Error | AD11: Suleman Alidina
A12: 3 | I12: =sum(F12:H12) -> 0 | K12: =A12 -> 3 | V12: =if(F12=F13,"Good") -> Good | W12: =if(G12=G13,"Good") -> Good | X12: =if(H12=H13,"Good") -> Good | AD12: Ash Nikravan
A13: 3 | I13: =sum(F13:H13) -> 0 | K13: =A13 -> 3 | AD13: Susanta Mishra
A14: 4 | I14: =sum(F14:H14) -> 0 | K14: =A14 -> 4 | O14: =if(COUNTIF(V14:V16,"Good")=2,"Good","Error") -> Error | P14: =if(COUNTIF(W14:W16,"Good")=2,"Good","Error") -> Error | Q14: =if(COUNTIF(X14:X16,"Good")=2,"Good","Error") -> Error | S14: =sum(J14:J17) -> 0 | T14: =if(S14=0,"",if(S14=6,"Good","ERROR")) | V14: =if(isna(VLOOKUP(F14,F15:F17,1,false)),"Error","Good") -> Error | W14: =if(isna(VLOOKUP(G14,G15:G17,1,false)),"Error","Good") -> Error | X14: =if(isna(VLOOKUP(H14,H15:H17,1,false)),"Error","Good") -> Error | AD14: David Tam
A15: 4 | I15: =sum(F15:H15) -> 0 | K15: =A15 -> 4 | V15: =if(isna(VLOOKUP(F15,F16:F17,1,false)),"Error","Good") -> Error | W15: =if(isna(VLOOKUP(G15,G16:G17,1,false)),"Error","Good") -> Error | X15: =if(isna(VLOOKUP(H15,H16:H17,1,false)),"Error","Good") -> Error
A16: 4 | I16: =sum(F16:H16) -> 0 | K16: =A16 -> 4 | V16: =if(F16=F17,"Good") -> Good | W16: =if(G16=G17,"Good") -> Good | X16: =if(H16=H17,"Good") -> Good
A17: 4 | I17: =sum(F17:H17) -> 0 | K17: =A17 -> 4
A18: 5 | I18: =sum(F18:H18) -> 0 | K18: =A18 -> 5 | O18: =if(COUNTIF(V18:V20,"Good")=2,"Good","Error") -> Error | P18: =if(COUNTIF(W18:W20,"Good")=2,"Good","Error") -> Error | Q18: =if(COUNTIF(X18:X20,"Good")=2,"Good","Error") -> Error | S18: =sum(J18:J21) -> 0 | T18: =if(S18=0,"",if(S18=6,"Good","ERROR")) | V18: =if(isna(VLOOKUP(F18,F19:F21,1,false)),"Error","Good") -> Error | W18: =if(isna(VLOOKUP(G18,G19:G21,1,false)),"Error","Good") -> Error | X18: =if(isna(VLOOKUP(H18,H19:H21,1,false)),"Error","Good") -> Error | AD18: Pulkit Mathur
A19: 5 | I19: =sum(F19:H19) -> 0 | K19: =A19 -> 5 | V19: =if(isna(VLOOKUP(F19,F20:F21,1,false)),"Error","Good") -> Error | W19: =if(isna(VLOOKUP(G19,G20:G21,1,false)),"Error","Good") -> Error | X19: =if(isna(VLOOKUP(H19,H20:H21,1,false)),"Error","Good") -> Error | AD19: Kingsley Kuo
A20: 5 | I20: =sum(F20:H20) -> 0 | K20: =A20 -> 5 | V20: =if(F20=F21,"Good") -> Good | W20: =if(G20=G21,"Good") -> Good | X20: =if(H20=H21,"Good") -> Good | AD20: Scott Li
A21: 5 | I21: =sum(F21:H21) -> 0 | K21: =A21 -> 5 | AD21: Vamsi Lolla
A22: 6 | I22: =sum(F22:H22) -> 0 | K22: =A22 -> 6 | O22: =if(COUNTIF(V22:V24,"Good")=2,"Good","Error") -> Error | P22: =if(COUNTIF(W22:W24,"Good")=2,"Good","Error") -> Error | Q22: =if(COUNTIF(X22:X24,"Good")=2,"Good","Error") -> Error | S22: =sum(J22:J25) -> 0 | T22: =if(S22=0,"",if(S22=6,"Good","ERROR")) | V22: =if(isna(VLOOKUP(F22,F23:F25,1,false)),"Error","Good") -> Error | W22: =if(isna(VLOOKUP(G22,G23:G25,1,false)),"Error","Good") -> Error | X22: =if(isna(VLOOKUP(H22,H23:H25,1,false)),"Error","Good") -> Error
A23: 6 | I23: =sum(F23:H23) -> 0 | K23: =A23 -> 6 | V23: =if(isna(VLOOKUP(F23,F24:F25,1,false)),"Error","Good") -> Error | W23: =if(isna(VLOOKUP(G23,G24:G25,1,false)),"Error","Good") -> Error | X23: =if(isna(VLOOKUP(H23,H24:H25,1,false)),"Error","Good") -> Error
A24: 6 | I24: =sum(F24:H24) -> 0 | K24: =A24 -> 6 | V24: =if(F24=F25,"Good") -> Good | W24: =if(G24=G25,"Good") -> Good | X24: =if(H24=H25,"Good") -> Good | AD24: Rajasekar Ramasamy
A25: 6 | I25: =sum(F25:H25) -> 0 | K25: =A25 -> 6 | AD25: Anish Kumar
A26: 7 | I26: =sum(F26:H26) -> 0 | K26: =A26 -> 7 | O26: =if(COUNTIF(V26:V28,"Good")=2,"Good","Error") -> Error | P26: =if(COUNTIF(W26:W28,"Good")=2,"Good","Error") -> Error | Q26: =if(COUNTIF(X26:X28,"Good")=2,"Good","Error") -> Error | S26: =sum(J26:J29) -> 0 | T26: =if(S26=0,"",if(S26=6,"Good","ERROR")) | V26: =if(isna(VLOOKUP(F26,F27:F29,1,false)),"Error","Good") -> Error | W26: =if(isna(VLOOKUP(G26,G27:G29,1,false)),"Error","Good") -> Error | X26: =if(isna(VLOOKUP(H26,H27:H29,1,false)),"Error","Good") -> Error | AD26: Manuel Rivera
A27: 7 | I27: =sum(F27:H27) -> 0 | K27: =A27 -> 7 | V27: =if(isna(VLOOKUP(F27,F28:F29,1,false)),"Error","Good") -> Error | W27: =if(isna(VLOOKUP(G27,G28:G29,1,false)),"Error","Good") -> Error | X27: =if(isna(VLOOKUP(H27,H28:H29,1,false)),"Error","Good") -> Error | AD27: Ted Shen
A28: 7 | I28: =sum(F28:H28) -> 0 | K28: =A28 -> 7 | V28: =if(F28=F29,"Good") -> Good | W28: =if(G28=G29,"Good") -> Good | X28: =if(H28=H29,"Good") -> Good
A29: 7 | I29: =sum(F29:H29) -> 0 | K29: =A29 -> 7
A30: 8 | I30: =sum(F30:H30) -> 0 | K30: =A30 -> 8 | O30: =if(COUNTIF(V30:V32,"Good")=2,"Good","Error") -> Error | P30: =if(COUNTIF(W30:W32,"Good")=2,"Good","Error") -> Error | Q30: =if(COUNTIF(X30:X32,"Good")=2,"Good","Error") -> Error | S30: =sum(J30:J33) -> 0 | T30: =if(S30=0,"",if(S30=6,"Good","ERROR")) | V30: =if(isna(VLOOKUP(F30,F31:F33,1,false)),"Error","Good") -> Error | W30: =if(isna(VLOOKUP(G30,G31:G33,1,false)),"Error","Good") -> Error | X30: =if(isna(VLOOKUP(H30,H31:H33,1,false)),"Error","Good") -> Error
A31: 8 | I31: =sum(F31:H31) -> 0 | K31: =A31 -> 8 | V31: =if(isna(VLOOKUP(F31,F32:F33,1,false)),"Error","Good") -> Error | W31: =if(isna(VLOOKUP(G31,G32:G33,1,false)),"Error","Good") -> Error | X31: =if(isna(VLOOKUP(H31,H32:H33,1,false)),"Error","Good") -> Error
A32: 8 | I32: =sum(F32:H32) -> 0 | K32: =A32 -> 8 | V32: =if(F32=F33,"Good") -> Good | W32: =if(G32=G33,"Good") -> Good | X32: =if(H32=H33,"Good") -> Good
A33: 8 | I33: =sum(F33:H33) -> 0 | K33: =A33 -> 8 | AD33: Chinna Ponnaganti
A34: 9 | I34: =sum(F34:H34) -> 0 | K34: =A34 -> 9 | O34: =if(COUNTIF(V34:V36,"Good")=2,"Good","Error") -> Error | P34: =if(COUNTIF(W34:W36,"Good")=2,"Good","Error") -> Error | Q34: =if(COUNTIF(X34:X36,"Good")=2,"Good","Error") -> Error | S34: =sum(J34:J37) -> 0 | T34: =if(S34=0,"",if(S34=6,"Good","ERROR")) | V34: =if(isna(VLOOKUP(F34,F35:F37,1,false)),"Error","Good") -> Error | W34: =if(isna(VLOOKUP(G34,G35:G37,1,false)),"Error","Good") -> Error | X34: =if(isna(VLOOKUP(H34,H35:H37,1,false)),"Error","Good") -> Error | AD34: Mauricio Palacios
A35: 9 | I35: =sum(F35:H35) -> 0 | K35: =A35 -> 9 | V35: =if(isna(VLOOKUP(F35,F36:F37,1,false)),"Error","Good") -> Error | W35: =if(isna(VLOOKUP(G35,G36:G37,1,false)),"Error","Good") -> Error | X35: =if(isna(VLOOKUP(H35,H36:H37,1,false)),"Error","Good") -> Error | AD35: Joyce Zhu
A36: 9 | I36: =sum(F36:H36) -> 0 | K36: =A36 -> 9 | V36: =if(F36=F37,"Good") -> Good | W36: =if(G36=G37,"Good") -> Good | X36: =if(H36=H37,"Good") -> Good | AD36: Balaji Alahari
A37: 9 | I37: =sum(F37:H37) -> 0 | K37: =A37 -> 9
A38: 10 | I38: =sum(F38:H38) -> 0 | K38: =A38 -> 10 | O38: =if(COUNTIF(V38:V40,"Good")=2,"Good","Error") -> Error | P38: =if(COUNTIF(W38:W40,"Good")=2,"Good","Error") -> Error | Q38: =if(COUNTIF(X38:X40,"Good")=2,"Good","Error") -> Error | S38: =sum(J38:J41) -> 0 | T38: =if(S38=0,"",if(S38=6,"Good","ERROR")) | V38: =if(isna(VLOOKUP(F38,F39:F41,1,false)),"Error","Good") -> Error | W38: =if(isna(VLOOKUP(G38,G39:G41,1,false)),"Error","Good") -> Error | X38: =if(isna(VLOOKUP(H38,H39:H41,1,false)),"Error","Good") -> Error
A39: 10 | I39: =sum(F39:H39) -> 0 | K39: =A39 -> 10 | V39: =if(isna(VLOOKUP(F39,F40:F41,1,false)),"Error","Good") -> Error | W39: =if(isna(VLOOKUP(G39,G40:G41,1,false)),"Error","Good") -> Error | X39: =if(isna(VLOOKUP(H39,H40:H41,1,false)),"Error","Good") -> Error
A40: 10 | I40: =sum(F40:H40) -> 0 | K40: =A40 -> 10 | V40: =if(F40=F41,"Good") -> Good | W40: =if(G40=G41,"Good") -> Good | X40: =if(H40=H41,"Good") -> Good
...

Sheet Checkin
A1: Name | B1: Check in | C1: Previous sitouts | E1: Sl.No | F1: Playing(1) | G1: Out(3) | H1: Out-Can Play(4) | I1: To Respond | J1: Sitouts(5) | K1: Playing-Can Sit(2) | L1: Previous sitouts | M1: Sit Outs Needed
A2: =IFERROR(__xludf.DUMMYFUNCTION("IMPORTRANGE(""1uZFF2o7rrfB0YZtASdZnP52Ef50ZinvtOPb1Tbuq8J4"",""CheckIn!C1:D99"")"),"#REF!") -> #REF! | C2: =iferror(VLOOKUP(A2,indirect("'" & "Current" & "'!$B:$S"),18,false),"") | E2: 1 | F2: =IFERROR(__xludf.DUMMYFUNCTION("QUERY(A2:B98, ""Select A where B = 1 order by A"")"),"#N/A") -> #N/A | G2: =IFERROR(__xludf.DUMMYFUNCTION("QUERY($A2:$B98, ""Select A where B = 3 order by A"")"),"#N/A") -> #N/A | H2: =IFERROR(__xludf.DUMMYFUNCTION("QUERY($A2:$B98, ""Select A where B = 4"")"),"#N/A") -> #N/A | I2: =IFERROR(__xludf.DUMMYFUNCTION("QUERY(Current!B5:F69, ""Select B where F = 0 order by B"")"),"Adrian Tay") -> Adrian Tay | J2: =IFERROR(__xludf.DUMMYFUNCTION("QUERY($A2:$C98, ""Select A where B = 5 order by C"")"),"#N/A") -> #N/A | K2: =IFERROR(__xludf.DUMMYFUNCTION("QUERY($A2:$C98, ""Select A,C where B = 2 order by C"")"),"#N/A") -> #N/A | M2: =if(P21>0,1,"")
C3: =iferror(VLOOKUP(A3,indirect("'" & "Current" & "'!$B:$S"),18,false),"") | E3: =E2+1 -> 2 | I3: =IFERROR(__xludf.DUMMYFUNCTION("""COMPUTED_VALUE"""),"Alejandro Mejia") -> Alejandro Mejia | M3: =if(AND(M2>0, counta($K$2:K3)<=$P$21),M2+1,"")
C4: =iferror(VLOOKUP(A4,indirect("'" & "Current" & "'!$B:$S"),18,false),"") | E4: =E3+1 -> 3 | I4: =IFERROR(__xludf.DUMMYFUNCTION("""COMPUTED_VALUE"""),"Alex Hou") -> Alex Hou | M4: =if(AND(M3>0, counta($K$2:K4)<=$P$21),M3+1,"") | O4: Last update | P4: =now() -> 46311.564 | R4: Whatsapp Message
C5: =iferror(VLOOKUP(A5,indirect("'" & "Current" & "'!$B:$S"),18,false),"") | E5: =E4+1 -> 4 | I5: =IFERROR(__xludf.DUMMYFUNCTION("""COMPUTED_VALUE"""),"Allen Zhang") -> Allen Zhang | M5: =if(AND(M4>0, counta($K$2:K5)<=$P$21),M4+1,"")
C6: =iferror(VLOOKUP(A6,indirect("'" & "Current" & "'!$B:$S"),18,false),"") | E6: =E5+1 -> 5 | I6: =IFERROR(__xludf.DUMMYFUNCTION("""COMPUTED_VALUE"""),"Andrew Wen") -> Andrew Wen | M6: =if(AND(M5>0, counta($K$2:K6)<=$P$21),M5+1,"") | O6: Playing | P6: =if(isna(F2),0,COUNTA(F$2:F$58)) -> 0 | R6: =CONCATENATE( " *",P$15," Courts Full*") -> *0 Courts Full*
C7: =iferror(VLOOKUP(A7,indirect("'" & "Current" & "'!$B:$S"),18,false),"") | E7: =E6+1 -> 6 | I7: =IFERROR(__xludf.DUMMYFUNCTION("""COMPUTED_VALUE"""),"Balaji Alahari") -> Balaji Alahari | M7: =if(AND(M6>0, counta($K$2:K7)<=$P$21),M6+1,"") | O7: Playing-Can Sit | P7: =if(isna(K2),0,COUNTA(K2:K98)) -> 0
C8: =iferror(VLOOKUP(A8,indirect("'" & "Current" & "'!$B:$S"),18,false),"") | E8: =E7+1 -> 7 | I8: =IFERROR(__xludf.DUMMYFUNCTION("""COMPUTED_VALUE"""),"Barathi Sundaram") -> Barathi Sundaram | M8: =if(AND(M7>0, counta($K$2:K8)<=$P$21),M7+1,"") | O8: Out/Can Play | P8: =if(isna(H2),0,COUNTA(H$2:H$58)) -> 0 | R8: =CONCATENATE(O$16," -- *",P$16,"*") -> Playing -- *0*
C9: =iferror(VLOOKUP(A9,indirect("'" & "Current" & "'!$B:$S"),18,false),"") | E9: =E8+1 -> 8 | I9: =IFERROR(__xludf.DUMMYFUNCTION("""COMPUTED_VALUE"""),"Basudev Thoppai Vidyasankar") -> Basudev Thoppai Vidyasankar | M9: =if(AND(M8>0, counta($K$2:K9)<=$P$21),M8+1,"") | O9: Out | P9: =if(isna(G2),0,COUNTA(G$2:G$58)) -> 0 | R9: =CONCATENATE(O$17," ------ ",P$17) -> Out ------ 0
C10: =iferror(VLOOKUP(A10,indirect("'" & "Current" & "'!$B:$S"),18,false),"") | E10: =E9+1 -> 9 | I10: =IFERROR(__xludf.DUMMYFUNCTION("""COMPUTED_VALUE"""),"Chinna Ponnaganti") -> Chinna Ponnaganti | M10: =if(AND(M9>0, counta($K$2:K10)<=$P$21),M9+1,"") | O10: Sitouts | P10: =if(isna(J2),0,COUNTA(J$2:J$29)) -> 0 | R10: =CONCATENATE(O$18," ------ ",P$18) -> TBD ------ 65
C11: =iferror(VLOOKUP(A11,indirect("'" & "Current" & "'!$B:$S"),18,false),"") | E11: =E10+1 -> 10 | I11: =IFERROR(__xludf.DUMMYFUNCTION("""COMPUTED_VALUE"""),"Cid Macaraeg") -> Cid Macaraeg | M11: =if(AND(M10>0, counta($K$2:K11)<=$P$21),M10+1,"") | O11: TBD | P11: =if(isna(I2),0,COUNTA(I$2:I$98)) -> 65
C12: =iferror(VLOOKUP(A12,indirect("'" & "Current" & "'!$B:$S"),18,false),"") | E12: =E11+1 -> 11 | I12: =IFERROR(__xludf.DUMMYFUNCTION("""COMPUTED_VALUE"""),"Coco Yan") -> Coco Yan | M12: =if(AND(M11>0, counta($K$2:K12)<=$P$21),M11+1,"") | O12: Total | P12: =sum(P6:P11) -> 65 | R12: *Sent Reminders*
C13: =iferror(VLOOKUP(A13,indirect("'" & "Current" & "'!$B:$S"),18,false),"") | E13: =E12+1 -> 12 | I13: =IFERROR(__xludf.DUMMYFUNCTION("""COMPUTED_VALUE"""),"David Shin") -> David Shin | M13: =if(AND(M12>0, counta($K$2:K13)<=$P$21),M12+1,"")
C14: =iferror(VLOOKUP(A14,indirect("'" & "Current" & "'!$B:$S"),18,false),"") | E14: =E13+1 -> 13 | I14: =IFERROR(__xludf.DUMMYFUNCTION("""COMPUTED_VALUE"""),"Elayaraja Thangaraj ") -> Elayaraja Thangaraj | M14: =if(AND(M13>0, counta($K$2:K14)<=$P$21),M13+1,"")
C15: =iferror(VLOOKUP(A15,indirect("'" & "Current" & "'!$B:$S"),18,false),"") | E15: =E14+1 -> 14 | I15: =IFERROR(__xludf.DUMMYFUNCTION("""COMPUTED_VALUE"""),"Eric Pan") -> Eric Pan | M15: =if(AND(M14>0, counta($K$2:K15)<=$P$21),M14+1,"") | O15: Courts Full | P15: =rounddown(P16/4,0) -> 0
C16: =iferror(VLOOKUP(A16,indirect("'" & "Current" & "'!$B:$S"),18,false),"") | E16: =E15+1 -> 15 | I16: =IFERROR(__xludf.DUMMYFUNCTION("""COMPUTED_VALUE"""),"Eric Tan") -> Eric Tan | M16: =if(AND(M15>0, counta($K$2:K16)<=$P$21),M15+1,"") | O16: Playing | P16: =sum(P6:P7) -> 0
C17: =iferror(VLOOKUP(A17,indirect("'" & "Current" & "'!$B:$S"),18,false),"") | E17: =E16+1 -> 16 | I17: =IFERROR(__xludf.DUMMYFUNCTION("""COMPUTED_VALUE"""),"Erik Hoeckmann") -> Erik Hoeckmann | M17: =if(AND(M16>0, counta($K$2:K17)<=$P$21),M16+1,"") | O17: Out | P17: =P9+P8 -> 0
C18: =iferror(VLOOKUP(A18,indirect("'" & "Current" & "'!$B:$S"),18,false),"") | E18: =E17+1 -> 17 | I18: =IFERROR(__xludf.DUMMYFUNCTION("""COMPUTED_VALUE"""),"Ethan Gu") -> Ethan Gu | M18: =if(AND(M17>0, counta($K$2:K18)<=$P$21),M17+1,"") | O18: TBD | P18: =P11 -> 65
C19: =iferror(VLOOKUP(A19,indirect("'" & "Current" & "'!$B:$S"),18,false),"") | E19: =E18+1 -> 18 | I19: =IFERROR(__xludf.DUMMYFUNCTION("""COMPUTED_VALUE"""),"Frank Moon") -> Frank Moon | M19: =if(AND(M18>0, counta($K$2:K19)<=$P$21),M18+1,"") | O19: Total | P19: =sum(P16:P18) -> 65 | Q19: =if(P19>65,"Check duplicates","")
C20: =iferror(VLOOKUP(A20,indirect("'" & "Current" & "'!$B:$S"),18,false),"") | E20: =E19+1 -> 19 | I20: =IFERROR(__xludf.DUMMYFUNCTION("""COMPUTED_VALUE"""),"Herman Au") -> Herman Au | M20: =if(AND(M19>0, counta($K$2:K20)<=$P$21),M19+1,"")
C21: =iferror(VLOOKUP(A21,indirect("'" & "Current" & "'!$B:$S"),18,false),"") | E21: =E20+1 -> 20 | I21: =IFERROR(__xludf.DUMMYFUNCTION("""COMPUTED_VALUE"""),"Hongyuan Wen") -> Hongyuan Wen | M21: =if(AND(M20>0, counta($K$2:K21)<=$P$21),M20+1,"") | O21: Sitouts Needed | P21: =max(mod(P16,4),P16-44) -> 0
C22: =iferror(VLOOKUP(A22,indirect("'" & "Current" & "'!$B:$S"),18,false),"") | E22: =E21+1 -> 21 | I22: =IFERROR(__xludf.DUMMYFUNCTION("""COMPUTED_VALUE"""),"Hubert J Sung") -> Hubert J Sung | M22: =if(AND(M21>0, counta($K$2:K22)<=$P$21),M21+1,"")
C23: =iferror(VLOOKUP(A23,indirect("'" & "Current" & "'!$B:$S"),18,false),"") | E23: =E22+1 -> 22 | I23: =IFERROR(__xludf.DUMMYFUNCTION("""COMPUTED_VALUE"""),"James Phan") -> James Phan | M23: =if(AND(M22>0, counta($K$2:K23)<=$P$21),M22+1,"") | O23: Vacations/Injuries
C24: =iferror(VLOOKUP(A24,indirect("'" & "Current" & "'!$B:$S"),18,false),"") | E24: =E23+1 -> 23 | I24: =IFERROR(__xludf.DUMMYFUNCTION("""COMPUTED_VALUE"""),"Jim Miao") -> Jim Miao | M24: =if(AND(M23>0, counta($K$2:K24)<=$P$21),M23+1,"") | O24: Frank Moon | P24: 9098000351 | Q24: Until end of season
C25: =iferror(VLOOKUP(A25,indirect("'" & "Current" & "'!$B:$S"),18,false),"") | E25: =E24+1 -> 24 | I25: =IFERROR(__xludf.DUMMYFUNCTION("""COMPUTED_VALUE"""),"Jimmy Awolesi") -> Jimmy Awolesi | M25: =if(AND(M24>0, counta($K$2:K25)<=$P$21),M24+1,"") | O25: Leigh-Anh Nguyen | P25: 6266794225 | Q25: Until end of season
C26: =iferror(VLOOKUP(A26,indirect("'" & "Current" & "'!$B:$S"),18,false),"") | E26: =E25+1 -> 25 | I26: =IFERROR(__xludf.DUMMYFUNCTION("""COMPUTED_VALUE"""),"Joe Luzzi") -> Joe Luzzi | M26: =if(AND(M25>0, counta($K$2:K26)<=$P$21),M25+1,"") | O26: Trinath Goteti | P26: 7142673763 | Q26: Left UTC
C27: =iferror(VLOOKUP(A27,indirect("'" & "Current" & "'!$B:$S"),18,false),"") | E27: =E26+1 -> 26 | I27: =IFERROR(__xludf.DUMMYFUNCTION("""COMPUTED_VALUE"""),"Jonathan Phan") -> Jonathan Phan | O27: Scott Li | P27: 6503070756 | Q27: Until end of season
C28: =iferror(VLOOKUP(A28,indirect("'" & "Current" & "'!$B:$S"),18,false),"") | E28: =E27+1 -> 27 | I28: =IFERROR(__xludf.DUMMYFUNCTION("""COMPUTED_VALUE"""),"Joyce Zhu") -> Joyce Zhu | O28: Naveen Raj | P28: 9493096136 | Q28: Until 7/8
C29: =iferror(VLOOKUP(A29,indirect("'" & "Current" & "'!$B:$S"),18,false),"") | E29: =E28+1 -> 28 | I29: =IFERROR(__xludf.DUMMYFUNCTION("""COMPUTED_VALUE"""),"Kumar Palakeel") -> Kumar Palakeel
C30: =iferror(VLOOKUP(A30,indirect("'" & "Current" & "'!$B:$S"),18,false),"") | E30: =E29+1 -> 29 | I30: =IFERROR(__xludf.DUMMYFUNCTION("""COMPUTED_VALUE"""),"Lam Bui") -> Lam Bui
C31: =iferror(VLOOKUP(A31,indirect("'" & "Current" & "'!$B:$S"),18,false),"") | E31: =E30+1 -> 30 | I31: =IFERROR(__xludf.DUMMYFUNCTION("""COMPUTED_VALUE"""),"Leigh-Anh Nguyen") -> Leigh-Anh Nguyen
C32: =iferror(VLOOKUP(A32,indirect("'" & "Current" & "'!$B:$S"),18,false),"") | E32: =E31+1 -> 31 | I32: =IFERROR(__xludf.DUMMYFUNCTION("""COMPUTED_VALUE"""),"Lloyd Sagar") -> Lloyd Sagar
C33: =iferror(VLOOKUP(A33,indirect("'" & "Current" & "'!$B:$S"),18,false),"") | E33: =E32+1 -> 32 | I33: =IFERROR(__xludf.DUMMYFUNCTION("""COMPUTED_VALUE"""),"Luis Hsu") -> Luis Hsu
C34: =iferror(VLOOKUP(A34,indirect("'" & "Current" & "'!$B:$S"),18,false),"") | E34: =E33+1 -> 33 | I34: =IFERROR(__xludf.DUMMYFUNCTION("""COMPUTED_VALUE"""),"Manish Anand") -> Manish Anand
C35: =iferror(VLOOKUP(A35,indirect("'" & "Current" & "'!$B:$S"),18,false),"") | E35: =E34+1 -> 34 | I35: =IFERROR(__xludf.DUMMYFUNCTION("""COMPUTED_VALUE"""),"Manuel Rivera") -> Manuel Rivera
C36: =iferror(VLOOKUP(A36,indirect("'" & "Current" & "'!$B:$S"),18,false),"") | E36: =E35+1 -> 35 | I36: =IFERROR(__xludf.DUMMYFUNCTION("""COMPUTED_VALUE"""),"Matthew Huang") -> Matthew Huang
C37: =iferror(VLOOKUP(A37,indirect("'" & "Current" & "'!$B:$S"),18,false),"") | E37: =E36+1 -> 36 | I37: =IFERROR(__xludf.DUMMYFUNCTION("""COMPUTED_VALUE"""),"Mauricio Palacios") -> Mauricio Palacios
C38: =iferror(VLOOKUP(A38,indirect("'" & "Current" & "'!$B:$S"),18,false),"") | E38: =E37+1 -> 37 | I38: =IFERROR(__xludf.DUMMYFUNCTION("""COMPUTED_VALUE"""),"Naveen Raj") -> Naveen Raj
C39: =iferror(VLOOKUP(A39,indirect("'" & "Current" & "'!$B:$S"),18,false),"") | E39: =E38+1 -> 38 | I39: =IFERROR(__xludf.DUMMYFUNCTION("""COMPUTED_VALUE"""),"Nicole Ni") -> Nicole Ni
C40: =iferror(VLOOKUP(A40,indirect("'" & "Current" & "'!$B:$S"),18,false),"") | E40: =E39+1 -> 39 | I40: =IFERROR(__xludf.DUMMYFUNCTION("""COMPUTED_VALUE"""),"Oscar Bonilla") -> Oscar Bonilla
...

Sheet Data
A1: No | B1: Name of Player | C1: 45661 | D1: =C1+7 -> 45668 | E1: =D1+7 -> 45675 | F1: =E1+7 -> 45682 | G1: =F1+7 -> 45689 | H1: =G1+7 -> 45696 | I1: =H1+7 -> 45703 | J1: =I1+7 -> 45710 | K1: =J1+7 -> 45717 | ... AB1: =AA1+7 -> 45836
A2: 1 | B2: Adrian Tay | C2: =IFERROR(VLOOKUP($B2,indirect(text(C$1,"mm/dd/yy")&"!B:L"),11,false),"Not played") -> 18 | D2: =IFERROR(VLOOKUP($B2,indirect(text(D$1,"mm/dd/yy")&"!B:L"),11,false),"Not played") -> 9 | E2: =IFERROR(VLOOKUP($B2,indirect(text(E$1,"mm/dd/yy")&"!B:L"),11,false),"Not played") -> 9 | F2: =IFERROR(VLOOKUP($B2,indirect(text(F$1,"mm/dd/yy")&"!B:L"),11,false),"Not played") -> 18 | G2: =IFERROR(VLOOKUP($B2,indirect(text(G$1,"mm/dd/yy")&"!B:L"),11,false),"Not played") -> 9 | H2: =IFERROR(VLOOKUP($B2,indirect(text(H$1,"mm/dd/yy")&"!B:L"),11,false),"Not played") -> 9 | I2: =IFERROR(VLOOKUP($B2,indirect(text(I$1,"mm/dd/yy")&"!B:L"),11,false),"Not played") -> 18 | J2: =IFERROR(VLOOKUP($B2,indirect(text(J$1,"mm/dd/yy")&"!B:L"),11,false),"Not played") -> 9 | ... AB2: =IFERROR(VLOOKUP($B2,indirect(text(AB$1,"mm/dd/yy")&"!B:L"),11,false),"Not played") -> 9
A3: =A2+1 -> 2 | B3: Alejandro Mejia | C3: =IFERROR(VLOOKUP($B3,indirect(text(C$1,"mm/dd/yy")&"!B:L"),11,false),"Not played") -> 19 | D3: =IFERROR(VLOOKUP($B3,indirect(text(D$1,"mm/dd/yy")&"!B:L"),11,false),"Not played") -> 19 | E3: =IFERROR(VLOOKUP($B3,indirect(text(E$1,"mm/dd/yy")&"!B:L"),11,false),"Not played") -> 9 | F3: =IFERROR(VLOOKUP($B3,indirect(text(F$1,"mm/dd/yy")&"!B:L"),11,false),"Not played") -> 9 | G3: =IFERROR(VLOOKUP($B3,indirect(text(G$1,"mm/dd/yy")&"!B:L"),11,false),"Not played") -> 18 | H3: =IFERROR(VLOOKUP($B3,indirect(text(H$1,"mm/dd/yy")&"!B:L"),11,false),"Not played") -> 18 | I3: =IFERROR(VLOOKUP($B3,indirect(text(I$1,"mm/dd/yy")&"!B:L"),11,false),"Not played") -> 12 | J3: =IFERROR(VLOOKUP($B3,indirect(text(J$1,"mm/dd/yy")&"!B:L"),11,false),"Not played") -> 9 | ... AB3: =IFERROR(VLOOKUP($B3,indirect(text(AB$1,"mm/dd/yy")&"!B:L"),11,false),"Not played") -> 9
A4: =A3+1 -> 3 | B4: Alex Hou | C4: =IFERROR(VLOOKUP($B4,indirect(text(C$1,"mm/dd/yy")&"!B:L"),11,false),"Not played") -> 12 | D4: =IFERROR(VLOOKUP($B4,indirect(text(D$1,"mm/dd/yy")&"!B:L"),11,false),"Not played") -> 15 | E4: =IFERROR(VLOOKUP($B4,indirect(text(E$1,"mm/dd/yy")&"!B:L"),11,false),"Not played") -> 14 | F4: =IFERROR(VLOOKUP($B4,indirect(text(F$1,"mm/dd/yy")&"!B:L"),11,false),"Not played") -> 12 | G4: =IFERROR(VLOOKUP($B4,indirect(text(G$1,"mm/dd/yy")&"!B:L"),11,false),"Not played") -> 15 | H4: =IFERROR(VLOOKUP($B4,indirect(text(H$1,"mm/dd/yy")&"!B:L"),11,false),"Not played") -> 10 | I4: =IFERROR(VLOOKUP($B4,indirect(text(I$1,"mm/dd/yy")&"!B:L"),11,false),"Not played") -> 15 | J4: =IFERROR(VLOOKUP($B4,indirect(text(J$1,"mm/dd/yy")&"!B:L"),11,false),"Not played") -> 16 | ... AB4: =IFERROR(VLOOKUP($B4,indirect(text(AB$1,"mm/dd/yy")&"!B:L"),11,false),"Not played") -> 12
A5: =A4+1 -> 4 | B5: Allen Zhang | C5: =IFERROR(VLOOKUP($B5,indirect(text(C$1,"mm/dd/yy")&"!B:L"),11,false),"Not played") -> 12 | D5: =IFERROR(VLOOKUP($B5,indirect(text(D$1,"mm/dd/yy")&"!B:L"),11,false),"Not played") -> 8 | E5: =IFERROR(VLOOKUP($B5,indirect(text(E$1,"mm/dd/yy")&"!B:L"),11,false),"Not played") -> 8 | F5: =IFERROR(VLOOKUP($B5,indirect(text(F$1,"mm/dd/yy")&"!B:L"),11,false),"Not played") -> 13 | G5: =IFERROR(VLOOKUP($B5,indirect(text(G$1,"mm/dd/yy")&"!B:L"),11,false),"Not played") -> 10 | H5: =IFERROR(VLOOKUP($B5,indirect(text(H$1,"mm/dd/yy")&"!B:L"),11,false),"Not played") -> 18 | I5: =IFERROR(VLOOKUP($B5,indirect(text(I$1,"mm/dd/yy")&"!B:L"),11,false),"Not played") -> 10 | J5: =IFERROR(VLOOKUP($B5,indirect(text(J$1,"mm/dd/yy")&"!B:L"),11,false),"Not played") -> 14 | ... AB5: =IFERROR(VLOOKUP($B5,indirect(text(AB$1,"mm/dd/yy")&"!B:L"),11,false),"Not played") -> 10
A6: =A5+1 -> 5 | B6: Andrew Wen | C6: =IFERROR(VLOOKUP($B6,indirect(text(C$1,"mm/dd/yy")&"!B:L"),11,false),"Not played") -> 13 | D6: =IFERROR(VLOOKUP($B6,indirect(text(D$1,"mm/dd/yy")&"!B:L"),11,false),"Not played") -> 13 | E6: =IFERROR(VLOOKUP($B6,indirect(text(E$1,"mm/dd/yy")&"!B:L"),11,false),"Not played") -> 13 | F6: =IFERROR(VLOOKUP($B6,indirect(text(F$1,"mm/dd/yy")&"!B:L"),11,false),"Not played") -> 12 | G6: =IFERROR(VLOOKUP($B6,indirect(text(G$1,"mm/dd/yy")&"!B:L"),11,false),"Not played") -> 9 | H6: =IFERROR(VLOOKUP($B6,indirect(text(H$1,"mm/dd/yy")&"!B:L"),11,false),"Not played") -> 8 | I6: =IFERROR(VLOOKUP($B6,indirect(text(I$1,"mm/dd/yy")&"!B:L"),11,false),"Not played") -> 11 | J6: =IFERROR(VLOOKUP($B6,indirect(text(J$1,"mm/dd/yy")&"!B:L"),11,false),"Not played") -> 8 | ... AB6: =IFERROR(VLOOKUP($B6,indirect(text(AB$1,"mm/dd/yy")&"!B:L"),11,false),"Not played") -> 12
A7: =A6+1 -> 6 | B7: Balaji Alahari | C7: =IFERROR(VLOOKUP($B7,indirect(text(C$1,"mm/dd/yy")&"!B:L"),11,false),"Not played") -> 13 | D7: =IFERROR(VLOOKUP($B7,indirect(text(D$1,"mm/dd/yy")&"!B:L"),11,false),"Not played") -> 9 | E7: =IFERROR(VLOOKUP($B7,indirect(text(E$1,"mm/dd/yy")&"!B:L"),11,false),"Not played") -> 9 | F7: =IFERROR(VLOOKUP($B7,indirect(text(F$1,"mm/dd/yy")&"!B:L"),11,false),"Not played") -> 9 | G7: =IFERROR(VLOOKUP($B7,indirect(text(G$1,"mm/dd/yy")&"!B:L"),11,false),"Not played") -> 9 | H7: =IFERROR(VLOOKUP($B7,indirect(text(H$1,"mm/dd/yy")&"!B:L"),11,false),"Not played") -> 9 | I7: =IFERROR(VLOOKUP($B7,indirect(text(I$1,"mm/dd/yy")&"!B:L"),11,false),"Not played") -> 9 | J7: =IFERROR(VLOOKUP($B7,indirect(text(J$1,"mm/dd/yy")&"!B:L"),11,false),"Not played") -> 9 | ... AB7: =IFERROR(VLOOKUP($B7,indirect(text(AB$1,"mm/dd/yy")&"!B:L"),11,false),"Not played") -> 15
A8: =A7+1 -> 7 | B8: Barathi Sundaram | C8: =IFERROR(VLOOKUP($B8,indirect(text(C$1,"mm/dd/yy")&"!B:L"),11,false),"Not played") -> 9 | D8: =IFERROR(VLOOKUP($B8,indirect(text(D$1,"mm/dd/yy")&"!B:L"),11,false),"Not played") -> 7 | E8: =IFERROR(VLOOKUP($B8,indirect(text(E$1,"mm/dd/yy")&"!B:L"),11,false),"Not played") -> 10 | F8: =IFERROR(VLOOKUP($B8,indirect(text(F$1,"mm/dd/yy")&"!B:L"),11,false),"Not played") -> 9 | G8: =IFERROR(VLOOKUP($B8,indirect(text(G$1,"mm/dd/yy")&"!B:L"),11,false),"Not played") -> 2 | H8: =IFERROR(VLOOKUP($B8,indirect(text(H$1,"mm/dd/yy")&"!B:L"),11,false),"Not played") -> 9 | I8: =IFERROR(VLOOKUP($B8,indirect(text(I$1,"mm/dd/yy")&"!B:L"),11,false),"Not played") -> 11 | J8: =IFERROR(VLOOKUP($B8,indirect(text(J$1,"mm/dd/yy")&"!B:L"),11,false),"Not played") -> 9 | ... AB8: =IFERROR(VLOOKUP($B8,indirect(text(AB$1,"mm/dd/yy")&"!B:L"),11,false),"Not played") -> 9
A9: =A8+1 -> 8 | B9: Basudev Thoppai Vidyasankar | C9: =IFERROR(VLOOKUP($B9,indirect(text(C$1,"mm/dd/yy")&"!B:L"),11,false),"Not played") -> 16 | D9: =IFERROR(VLOOKUP($B9,indirect(text(D$1,"mm/dd/yy")&"!B:L"),11,false),"Not played") -> 19 | E9: =IFERROR(VLOOKUP($B9,indirect(text(E$1,"mm/dd/yy")&"!B:L"),11,false),"Not played") -> 15 | F9: =IFERROR(VLOOKUP($B9,indirect(text(F$1,"mm/dd/yy")&"!B:L"),11,false),"Not played") -> 8 | G9: =IFERROR(VLOOKUP($B9,indirect(text(G$1,"mm/dd/yy")&"!B:L"),11,false),"Not played") -> 9 | H9: =IFERROR(VLOOKUP($B9,indirect(text(H$1,"mm/dd/yy")&"!B:L"),11,false),"Not played") -> 14 | I9: =IFERROR(VLOOKUP($B9,indirect(text(I$1,"mm/dd/yy")&"!B:L"),11,false),"Not played") -> 19 | J9: =IFERROR(VLOOKUP($B9,indirect(text(J$1,"mm/dd/yy")&"!B:L"),11,false),"Not played") -> 9 | ... AB9: =IFERROR(VLOOKUP($B9,indirect(text(AB$1,"mm/dd/yy")&"!B:L"),11,false),"Not played") -> 14
A10: =A9+1 -> 9 | B10: Chinna Ponnaganti | C10: =IFERROR(VLOOKUP($B10,indirect(text(C$1,"mm/dd/yy")&"!B:L"),11,false),"Not played") -> 13 | D10: =IFERROR(VLOOKUP($B10,indirect(text(D$1,"mm/dd/yy")&"!B:L"),11,false),"Not played") -> 13 | E10: =IFERROR(VLOOKUP($B10,indirect(text(E$1,"mm/dd/yy")&"!B:L"),11,false),"Not played") -> 18 | F10: =IFERROR(VLOOKUP($B10,indirect(text(F$1,"mm/dd/yy")&"!B:L"),11,false),"Not played") -> 10 | G10: =IFERROR(VLOOKUP($B10,indirect(text(G$1,"mm/dd/yy")&"!B:L"),11,false),"Not played") -> 9 | H10: =IFERROR(VLOOKUP($B10,indirect(text(H$1,"mm/dd/yy")&"!B:L"),11,false),"Not played") -> 13 | I10: =IFERROR(VLOOKUP($B10,indirect(text(I$1,"mm/dd/yy")&"!B:L"),11,false),"Not played") -> 9 | J10: =IFERROR(VLOOKUP($B10,indirect(text(J$1,"mm/dd/yy")&"!B:L"),11,false),"Not played") -> 7 | ... AB10: =IFERROR(VLOOKUP($B10,indirect(text(AB$1,"mm/dd/yy")&"!B:L"),11,false),"Not played") -> 10
A11: =A10+1 -> 10 | B11: Cid Macaraeg | C11: =IFERROR(VLOOKUP($B11,indirect(text(C$1,"mm/dd/yy")&"!B:L"),11,false),"Not played") -> 19 | D11: =IFERROR(VLOOKUP($B11,indirect(text(D$1,"mm/dd/yy")&"!B:L"),11,false),"Not played") -> 13 | E11: =IFERROR(VLOOKUP($B11,indirect(text(E$1,"mm/dd/yy")&"!B:L"),11,false),"Not played") -> 9 | F11: =IFERROR(VLOOKUP($B11,indirect(text(F$1,"mm/dd/yy")&"!B:L"),11,false),"Not played") -> 12 | G11: =IFERROR(VLOOKUP($B11,indirect(text(G$1,"mm/dd/yy")&"!B:L"),11,false),"Not played") -> 9 | H11: =IFERROR(VLOOKUP($B11,indirect(text(H$1,"mm/dd/yy")&"!B:L"),11,false),"Not played") -> 18 | I11: =IFERROR(VLOOKUP($B11,indirect(text(I$1,"mm/dd/yy")&"!B:L"),11,false),"Not played") -> 15 | J11: =IFERROR(VLOOKUP($B11,indirect(text(J$1,"mm/dd/yy")&"!B:L"),11,false),"Not played") -> 16 | ... AB11: =IFERROR(VLOOKUP($B11,indirect(text(AB$1,"mm/dd/yy")&"!B:L"),11,false),"Not played") -> 9
A12: =A11+1 -> 11 | B12: Coco Yan | C12: =IFERROR(VLOOKUP($B12,indirect(text(C$1,"mm/dd/yy")&"!B:L"),11,false),"Not played") -> 13 | D12: =IFERROR(VLOOKUP($B12,indirect(text(D$1,"mm/dd/yy")&"!B:L"),11,false),"Not played") -> 9 | E12: =IFERROR(VLOOKUP($B12,indirect(text(E$1,"mm/dd/yy")&"!B:L"),11,false),"Not played") -> 11 | F12: =IFERROR(VLOOKUP($B12,indirect(text(F$1,"mm/dd/yy")&"!B:L"),11,false),"Not played") -> 13 | G12: =IFERROR(VLOOKUP($B12,indirect(text(G$1,"mm/dd/yy")&"!B:L"),11,false),"Not played") -> 11 | H12: =IFERROR(VLOOKUP($B12,indirect(text(H$1,"mm/dd/yy")&"!B:L"),11,false),"Not played") -> 13 | I12: =IFERROR(VLOOKUP($B12,indirect(text(I$1,"mm/dd/yy")&"!B:L"),11,false),"Not played") -> 12 | J12: =IFERROR(VLOOKUP($B12,indirect(text(J$1,"mm/dd/yy")&"!B:L"),11,false),"Not played") -> 9 | ... AB12: =IFERROR(VLOOKUP($B12,indirect(text(AB$1,"mm/dd/yy")&"!B:L"),11,false),"Not played") -> 10
A13: =A12+1 -> 12 | B13: David Shin | C13: =IFERROR(VLOOKUP($B13,indirect(text(C$1,"mm/dd/yy")&"!B:L"),11,false),"Not played") -> 13 | D13: =IFERROR(VLOOKUP($B13,indirect(text(D$1,"mm/dd/yy")&"!B:L"),11,false),"Not played") -> 9 | E13: =IFERROR(VLOOKUP($B13,indirect(text(E$1,"mm/dd/yy")&"!B:L"),11,false),"Not played") -> 18 | F13: =IFERROR(VLOOKUP($B13,indirect(text(F$1,"mm/dd/yy")&"!B:L"),11,false),"Not played") -> 12 | G13: =IFERROR(VLOOKUP($B13,indirect(text(G$1,"mm/dd/yy")&"!B:L"),11,false),"Not played") -> 13 | H13: =IFERROR(VLOOKUP($B13,indirect(text(H$1,"mm/dd/yy")&"!B:L"),11,false),"Not played") -> 13 | I13: =IFERROR(VLOOKUP($B13,indirect(text(I$1,"mm/dd/yy")&"!B:L"),11,false),"Not played") -> 19 | J13: =IFERROR(VLOOKUP($B13,indirect(text(J$1,"mm/dd/yy")&"!B:L"),11,false),"Not played") -> 16 | ... AB13: =IFERROR(VLOOKUP($B13,indirect(text(AB$1,"mm/dd/yy")&"!B:L"),11,false),"Not played") -> 9
A14: =A13+1 -> 13 | B14: Elayaraja Thangaraj | C14: =IFERROR(VLOOKUP($B14,indirect(text(C$1,"mm/dd/yy")&"!B:L"),11,false),"Not played") -> 11 | D14: =IFERROR(VLOOKUP($B14,indirect(text(D$1,"mm/dd/yy")&"!B:L"),11,false),"Not played") -> 14 | E14: =IFERROR(VLOOKUP($B14,indirect(text(E$1,"mm/dd/yy")&"!B:L"),11,false),"Not played") -> 9 | F14: =IFERROR(VLOOKUP($B14,indirect(text(F$1,"mm/dd/yy")&"!B:L"),11,false),"Not played") -> 9 | G14: =IFERROR(VLOOKUP($B14,indirect(text(G$1,"mm/dd/yy")&"!B:L"),11,false),"Not played") -> 16 | H14: =IFERROR(VLOOKUP($B14,indirect(text(H$1,"mm/dd/yy")&"!B:L"),11,false),"Not played") -> 9 | I14: =IFERROR(VLOOKUP($B14,indirect(text(I$1,"mm/dd/yy")&"!B:L"),11,false),"Not played") -> 9 | J14: =IFERROR(VLOOKUP($B14,indirect(text(J$1,"mm/dd/yy")&"!B:L"),11,false),"Not played") -> 9 | ... AB14: =IFERROR(VLOOKUP($B14,indirect(text(AB$1,"mm/dd/yy")&"!B:L"),11,false),"Not played") -> 13
... A66: =A65+1 -> 65 | B66: Wayne Liu | C66: =IFERROR(VLOOKUP($B66,indirect(text(C$1,"mm/dd/yy")&"!B:L"),11,false),"Not played") -> 19 | D66: =IFERROR(VLOOKUP($B66,indirect(text(D$1,"mm/dd/yy")&"!B:L"),11,false),"Not played") -> 12 | E66: =IFERROR(VLOOKUP($B66,indirect(text(E$1,"mm/dd/yy")&"!B:L"),11,false),"Not played") -> 13 | F66: =IFERROR(VLOOKUP($B66,indirect(text(F$1,"mm/dd/yy")&"!B:L"),11,false),"Not played") -> 8 | G66: =IFERROR(VLOOKUP($B66,indirect(text(G$1,"mm/dd/yy")&"!B:L"),11,false),"Not played") -> 14 | H66: =IFERROR(VLOOKUP($B66,indirect(text(H$1,"mm/dd/yy")&"!B:L"),11,false),"Not played") -> 4 | I66: =IFERROR(VLOOKUP($B66,indirect(text(I$1,"mm/dd/yy")&"!B:L"),11,false),"Not played") -> 13 | J66: =IFERROR(VLOOKUP($B66,indirect(text(J$1,"mm/dd/yy")&"!B:L"),11,false),"Not played") -> 7 | ... AB66: =IFERROR(VLOOKUP($B66,indirect(text(AB$1,"mm/dd/yy")&"!B:L"),11,false),"Not played") -> 14
B72: Color Coding | C72: 0-8
C73: 9-17
C74: 18-20
C75: 21

Sheet Waitlist
A1: =IFERROR(__xludf.DUMMYFUNCTION("IMPORTRANGE(""1vk67ABbS4TvdE0gnpv39mwReeTC8qhP2vyc266Yeuy8"",""Waitlist!A1:D199"")"),"#REF!") -> #REF!
G4: Here is the link to add new players to the waitlist.
G5: tinyurl.com/UTCWaitList

Sheet 062825
B1: Standings as of | C1: 45836
B2: Number of Weeks Played | D2: 24 | AB2: =text(C1-7,"mm/dd/yy") -> 06/21/25
C3: Beginning of week | F3: Current Week Scores | N3: End of week | Q3: Jan-Jun 2025 | R3: Jul-Dec 2025
A4: Ranking | B4: Name of Player | C4: Games Won | D4: Sets Won | E4: Games Won / Match | F4: Check IN | G4: Court # | H4: Set 0 | I4: Set 1 | J4: Set 2 | K4: Set 3 | L4: Games Won | M4: Sets Won | N4: Games Won | O4: Sets Won | P4: Waiver | Q4: Fee | R4: Fee | S4: Sit outs | T4: No Shows | U4: Absent | V4: Positions Gained/Lost | W4: Ranking
A5: 1 | B5: Pulkit Mathur | C5: 371 | D5: 47 | E5: =if(($D$2-U5-S5)<>0,(C5-(U5*9)-(S5*13))/($D$2-U5-S5),0) -> 15.565217 | F5: 1 | G5: 1 | H5: 0 | I5: 6 | J5: 6 | K5: 6 | L5: 18 | M5: 3 | N5: =C5+L5 -> 389 | O5: =D5+M5 -> 50 | P5: X | Q5: X | R5: X | S5: =if(H5=13,1,0)+VLOOKUP(B5,indirect($AB$2&"!B:T"),18,false) -> 1 | U5: =if(H5=9,1,0)+VLOOKUP(B5,indirect($AB$2&"!B:U"),20,false) -> 0 | V5: =VLOOKUP(B5,indirect($AB$2&"!B$5:w$70"),22,false)-A5 -> 0 | W5: 1
A6: =A5+1 -> 2 | B6: Ethan Gu | C6: 310 | D6: 29 | E6: =if(($D$2-U6-S6)<>0,(C6-(U6*9)-(S6*13))/($D$2-U6-S6),0) -> 13.7 | F6: 1 | G6: 1 | H6: 0 | I6: 1 | J6: 4 | K6: 6 | L6: 11 | M6: 1 | N6: =C6+L6 -> 321 | O6: =D6+M6 -> 30 | P6: X | Q6: X | R6: X | S6: =if(H6=13,1,0)+VLOOKUP(B6,indirect($AB$2&"!B:T"),18,false) -> 0 | U6: =if(H6=9,1,0)+VLOOKUP(B6,indirect($AB$2&"!B:U"),20,false) -> 4 | V6: =VLOOKUP(B6,indirect($AB$2&"!B$5:w$70"),22,false)-A6 -> 0 | W6: =W5+1 -> 2
A7: =A6+1 -> 3 | B7: Pavan Akkimsetty | C7: 303 | D7: 30 | E7: =if(($D$2-U7-S7)<>0,(C7-(U7*9)-(S7*13))/($D$2-U7-S7),0) -> 14.117647 | F7: 1 | G7: 1 | H7: 0 | I7: 6 | J7: 4 | K7: 3 | L7: 13 | M7: 1 | N7: =C7+L7 -> 316 | O7: =D7+M7 -> 31 | P7: X | Q7: X | R7: X | S7: =if(H7=13,1,0)+VLOOKUP(B7,indirect($AB$2&"!B:T"),18,false) -> 0 | U7: =if(H7=9,1,0)+VLOOKUP(B7,indirect($AB$2&"!B:U"),20,false) -> 7 | V7: =VLOOKUP(B7,indirect($AB$2&"!B$5:w$70"),22,false)-A7 -> 1 | W7: =W6+1 -> 3
A8: =A7+1 -> 4 | B8: Jonathan Phan | C8: 301 | D8: 28 | E8: =if(($D$2-U8-S8)<>0,(C8-(U8*9)-(S8*13))/($D$2-U8-S8),0) -> 14.3125 | F8: 1 | G8: 1 | H8: 0 | I8: 1 | J8: 6 | K8: 3 | L8: 10 | M8: 1 | N8: =C8+L8 -> 311 | O8: =D8+M8 -> 29 | P8: X | Q8: X | R8: X | S8: =if(H8=13,1,0)+VLOOKUP(B8,indirect($AB$2&"!B:T"),18,false) -> 0 | U8: =if(H8=9,1,0)+VLOOKUP(B8,indirect($AB$2&"!B:U"),20,false) -> 8 | V8: =VLOOKUP(B8,indirect($AB$2&"!B$5:w$70"),22,false)-A8 -> 4 | W8: =W7+1 -> 4
A9: =A8+1 -> 5 | B9: Manish Anand | C9: 299 | D9: 22 | E9: =if(($D$2-U9-S9)<>0,(C9-(U9*9)-(S9*13))/($D$2-U9-S9),0) -> 13.9375 | F9: 3 | G9: 0 | H9: 9 | I9: 0 | J9: 0 | K9: 0 | L9: 9 | M9: 0 | N9: =C9+L9 -> 308 | O9: =D9+M9 -> 22 | P9: X | Q9: X | R9: X | S9: =if(H9=13,1,0)+VLOOKUP(B9,indirect($AB$2&"!B:T"),18,false) -> 1 | U9: =if(H9=9,1,0)+VLOOKUP(B9,indirect($AB$2&"!B:U"),20,false) -> 7 | V9: =VLOOKUP(B9,indirect($AB$2&"!B$5:w$70"),22,false)-A9 -> 0 | W9: =W8+1 -> 5
