Workbook

Sheet Current
B1: Standings as of | C1: 45472
B2: Number of Weeks Played | D2: 0
C3: Beginning of week | E3: Current Week Scores | M3: End of week | P3: Jan-Jul 2024 | Q3: Jul-Dec 2024
A4: Ranking | B4: Name of Player | C4: Games Won | D4: Sets Won | E4: Check IN | F4: Court # | G4: Set 0 | H4: Set 1 | I4: Set 2 | J4: Set 3 | K4: Games Won | L4: Sets Won | M4: Games Won | N4: Sets Won | O4: Waiver | P4: Fee | Q4: Fee | R4: Sit outs | S4: No Shows | T4: Absent
A5: 1 | B5: Adrian Tay | C5: 300 | D5: 34 | E5: =if(isna(VLOOKUP(B5,Checkin!A:B,2,false)),0,VLOOKUP(B5,Checkin!A:B,2,false)) -> 0 | F5: =if(OR($E5=1, $E5=2),VLOOKUP($B5,Courts!$B$2:$K$50,10,false),0) -> 0 | G5: =IF(OR(E5=3,E5=4),9,IF(E5=5,13,0)) -> 0 | H5: =if(OR($E5=1, $E5=2),VLOOKUP($B5,Courts!$B$2:$J$50,5,false),0) -> 0 | I5: =if(OR($E5=1, $E5=2),VLOOKUP($B5,Courts!$B$2:$J$50,6,false),0) -> 0 | J5: =if(OR($E5=1, $E5=2),VLOOKUP($B5,Courts!$B$2:$J$50,7,false),0) -> 0 | K5: =G5+H5+I5+J5 -> 0 | L5: =if(OR($E5=1, $E5=2),VLOOKUP($B5,Courts!$B$2:$J$50,9,false),0) -> 0 | M5: =C5+K5 -> 300 | N5: =D5+L5 -> 34 | O5: X | P5: X | Q5: X | R5: =if(G5=13,1,0)+VLOOKUP(B5,'062224'!B:T,17,false) -> 1 | T5: =if(G5=9,1,0)+VLOOKUP(B5,'062224'!B:T,19,false) -> 7
A6: =A5+1 -> 2 | B6: Peter Cheng | C6: 278 | D6: 27 | E6: =if(isna(VLOOKUP(B6,Checkin!A:B,2,false)),0,VLOOKUP(B6,Checkin!A:B,2,false)) -> 0 | F6: =if(OR($E6=1, $E6=2),VLOOKUP($B6,Courts!$B$2:$K$50,10,false),0) -> 0 | G6: =IF(OR(E6=3,E6=4),9,IF(E6=5,13,0)) -> 0 | H6: =if(OR($E6=1, $E6=2),VLOOKUP($B6,Courts!$B$2:$J$50,5,false),0) -> 0 | I6: =if(OR($E6=1, $E6=2),VLOOKUP($B6,Courts!$B$2:$J$50,6,false),0) -> 0 | J6: =if(OR($E6=1, $E6=2),VLOOKUP($B6,Courts!$B$2:$J$50,7,false),0) -> 0 | K6: =G6+H6+I6+J6 -> 0 | L6: =if(OR($E6=1, $E6=2),VLOOKUP($B6,Courts!$B$2:$J$50,9,false),0) -> 0 | M6: =C6+K6 -> 278 | N6: =D6+L6 -> 27 | O6: X | P6: X | Q6: X | R6: =if(G6=13,1,0)+VLOOKUP(B6,'062224'!B:T,17,false) -> 2 | T6: =if(G6=9,1,0)+VLOOKUP(B6,'062224'!B:T,19,false) -> 7
A7: =A6+1 -> 3 | B7: Suleman Alidina | C7: 271 | D7: 30 | E7: =if(isna(VLOOKUP(B7,Checkin!A:B,2,false)),0,VLOOKUP(B7,Checkin!A:B,2,false)) -> 0 | F7: =if(OR($E7=1, $E7=2),VLOOKUP($B7,Courts!$B$2:$K$50,10,false),0) -> 0 | G7: =IF(OR(E7=3,E7=4),9,IF(E7=5,13,0)) -> 0 | H7: =if(OR($E7=1, $E7=2),VLOOKUP($B7,Courts!$B$2:$J$50,5,false),0) -> 0 | I7: =if(OR($E7=1, $E7=2),VLOOKUP($B7,Courts!$B$2:$J$50,6,false),0) -> 0 | J7: =if(OR($E7=1, $E7=2),VLOOKUP($B7,Courts!$B$2:$J$50,7,false),0) -> 0 | K7: =G7+H7+I7+J7 -> 0 | L7: =if(OR($E7=1, $E7=2),VLOOKUP($B7,Courts!$B$2:$J$50,9,false),0) -> 0 | M7: =C7+K7 -> 271 | N7: =D7+L7 -> 30 | O7: X | P7: X | Q7: X | R7: =if(G7=13,1,0)+VLOOKUP(B7,'062224'!B:T,17,false) -> 0 | T7: =if(G7=9,1,0)+VLOOKUP(B7,'062224'!B:T,19,false) -> 4
A8: =A7+1 -> 4 | B8: Christopher Li | C8: 271 | D8: 27 | E8: =if(isna(VLOOKUP(B8,Checkin!A:B,2,false)),0,VLOOKUP(B8,Checkin!A:B,2,false)) -> 0 | F8: =if(OR($E8=1, $E8=2),VLOOKUP($B8,Courts!$B$2:$K$50,10,false),0) -> 0 | G8: =IF(OR(E8=3,E8=4),9,IF(E8=5,13,0)) -> 0 | H8: =if(OR($E8=1, $E8=2),VLOOKUP($B8,Courts!$B$2:$J$50,5,false),0) -> 0 | I8: =if(OR($E8=1, $E8=2),VLOOKUP($B8,Courts!$B$2:$J$50,6,false),0) -> 0 | J8: =if(OR($E8=1, $E8=2),VLOOKUP($B8,Courts!$B$2:$J$50,7,false),0) -> 0 | K8: =G8+H8+I8+J8 -> 0 | L8: =if(OR($E8=1, $E8=2),VLOOKUP($B8,Courts!$B$2:$J$50,9,false),0) -> 0 | M8: =C8+K8 -> 271 | N8: =D8+L8 -> 27 | O8: X | P8: X | Q8: X | R8: =if(G8=13,1,0)+VLOOKUP(B8,'062224'!B:T,17,false) -> 0 | T8: =if(G8=9,1,0)+VLOOKUP(B8,'062224'!B:T,19,false) -> 10
A9: =A8+1 -> 5 | B9: Peter Homsey | C9: 263 | D9: 23 | E9: =if(isna(VLOOKUP(B9,Checkin!A:B,2,false)),0,VLOOKUP(B9,Checkin!A:B,2,false)) -> 0 | F9: =if(OR($E9=1, $E9=2),VLOOKUP($B9,Courts!$B$2:$K$50,10,false),0) -> 0 | G9: =IF(OR(E9=3,E9=4),9,IF(E9=5,13,0)) -> 0 | H9: =if(OR($E9=1, $E9=2),VLOOKUP($B9,Courts!$B$2:$J$50,5,false),0) -> 0 | I9: =if(OR($E9=1, $E9=2),VLOOKUP($B9,Courts!$B$2:$J$50,6,false),0) -> 0 | J9: =if(OR($E9=1, $E9=2),VLOOKUP($B9,Courts!$B$2:$J$50,7,false),0) -> 0 | K9: =G9+H9+I9+J9 -> 0 | L9: =if(OR($E9=1, $E9=2),VLOOKUP($B9,Courts!$B$2:$J$50,9,false),0) -> 0 | M9: =C9+K9 -> 263 | N9: =D9+L9 -> 23 | O9: X | P9: X | Q9: X | R9: =if(G9=13,1,0)+VLOOKUP(B9,'062224'!B:T,17,false) -> 0 | T9: =if(G9=9,1,0)+VLOOKUP(B9,'062224'!B:T,19,false) -> 7
A10: =A9+1 -> 6 | B10: Lam Bui | C10: 263 | D10: 18 | E10: =if(isna(VLOOKUP(B10,Checkin!A:B,2,false)),0,VLOOKUP(B10,Checkin!A:B,2,false)) -> 0 | F10: =if(OR($E10=1, $E10=2),VLOOKUP($B10,Courts!$B$2:$K$50,10,false),0) -> 0 | G10: =IF(OR(E10=3,E10=4),9,IF(E10=5,13,0)) -> 0 | H10: =if(OR($E10=1, $E10=2),VLOOKUP($B10,Courts!$B$2:$J$50,5,false),0) -> 0 | I10: =if(OR($E10=1, $E10=2),VLOOKUP($B10,Courts!$B$2:$J$50,6,false),0) -> 0 | J10: =if(OR($E10=1, $E10=2),VLOOKUP($B10,Courts!$B$2:$J$50,7,false),0) -> 0 | K10: =G10+H10+I10+J10 -> 0 | L10: =if(OR($E10=1, $E10=2),VLOOKUP($B10,Courts!$B$2:$J$50,9,false),0) -> 0 | M10: =C10+K10 -> 263 | N10: =D10+L10 -> 18 | O10: X | P10: X | Q10: X | R10: =if(G10=13,1,0)+VLOOKUP(B10,'062224'!B:T,17,false) -> 2 | T10: =if(G10=9,1,0)+VLOOKUP(B10,'062224'!B:T,19,false) -> 11
A11: =A10+1 -> 7 | B11: Jonathan Phan | C11: 261 | D11: 22 | E11: =if(isna(VLOOKUP(B11,Checkin!A:B,2,false)),0,VLOOKUP(B11,Checkin!A:B,2,false)) -> 0 | F11: =if(OR($E11=1, $E11=2),VLOOKUP($B11,Courts!$B$2:$K$50,10,false),0) -> 0 | G11: =IF(OR(E11=3,E11=4),9,IF(E11=5,13,0)) -> 0 | H11: =if(OR($E11=1, $E11=2),VLOOKUP($B11,Courts!$B$2:$J$50,5,false),0) -> 0 | I11: =if(OR($E11=1, $E11=2),VLOOKUP($B11,Courts!$B$2:$J$50,6,false),0) -> 0 | J11: =if(OR($E11=1, $E11=2),VLOOKUP($B11,Courts!$B$2:$J$50,7,false),0) -> 0 | K11: =G11+H11+I11+J11 -> 0 | L11: =if(OR($E11=1, $E11=2),VLOOKUP($B11,Courts!$B$2:$J$50,9,false),0) -> 0 | M11: =C11+K11 -> 261 | N11: =D11+L11 -> 22 | O11: X | P11: X | Q11: X | R11: =if(G11=13,1,0)+VLOOKUP(B11,'062224'!B:T,17,false) -> 1 | T11: =if(G11=9,1,0)+VLOOKUP(B11,'062224'!B:T,19,false) -> 4
A12: =A11+1 -> 8 | B12: David Shin | C12: 259 | D12: 23 | E12: =if(isna(VLOOKUP(B12,Checkin!A:B,2,false)),0,VLOOKUP(B12,Checkin!A:B,2,false)) -> 0 | F12: =if(OR($E12=1, $E12=2),VLOOKUP($B12,Courts!$B$2:$K$50,10,false),0) -> 0 | G12: =IF(OR(E12=3,E12=4),9,IF(E12=5,13,0)) -> 0 | H12: =if(OR($E12=1, $E12=2),VLOOKUP($B12,Courts!$B$2:$J$50,5,false),0) -> 0 | I12: =if(OR($E12=1, $E12=2),VLOOKUP($B12,Courts!$B$2:$J$50,6,false),0) -> 0 | J12: =if(OR($E12=1, $E12=2),VLOOKUP($B12,Courts!$B$2:$J$50,7,false),0) -> 0 | K12: =G12+H12+I12+J12 -> 0 | L12: =if(OR($E12=1, $E12=2),VLOOKUP($B12,Courts!$B$2:$J$50,9,false),0) -> 0 | M12: =C12+K12 -> 259 | N12: =D12+L12 -> 23 | O12: X | P12: X | Q12: X | R12: =if(G12=13,1,0)+VLOOKUP(B12,'062224'!B:T,17,false) -> 2 | T12: =if(G12=9,1,0)+VLOOKUP(B12,'062224'!B:T,19,false) -> 4
A13: =A12+1 -> 9 | B13: Luis Hsu | C13: 259 | D13: 23 | E13: =if(isna(VLOOKUP(B13,Checkin!A:B,2,false)),0,VLOOKUP(B13,Checkin!A:B,2,false)) -> 0 | F13: =if(OR($E13=1, $E13=2),VLOOKUP($B13,Courts!$B$2:$K$50,10,false),0) -> 0 | G13: =IF(OR(E13=3,E13=4),9,IF(E13=5,13,0)) -> 0 | H13: =if(OR($E13=1, $E13=2),VLOOKUP($B13,Courts!$B$2:$J$50,5,false),0) -> 0 | I13: =if(OR($E13=1, $E13=2),VLOOKUP($B13,Courts!$B$2:$J$50,6,false),0) -> 0 | J13: =if(OR($E13=1, $E13=2),VLOOKUP($B13,Courts!$B$2:$J$50,7,false),0) -> 0 | K13: =G13+H13+I13+J13 -> 0 | L13: =if(OR($E13=1, $E13=2),VLOOKUP($B13,Courts!$B$2:$J$50,9,false),0) -> 0 | M13: =C13+K13 -> 259 | N13: =D13+L13 -> 23 | O13: X | P13: X | Q13: X | R13: =if(G13=13,1,0)+VLOOKUP(B13,'062224'!B:T,17,false) -> 1 | T13: =if(G13=9,1,0)+VLOOKUP(B13,'062224'!B:T,19,false) -> 10
A14: =A13+1 -> 10 | B14: Ted Shen | C14: 254 | D14: 20 | E14: =if(isna(VLOOKUP(B14,Checkin!A:B,2,false)),0,VLOOKUP(B14,Checkin!A:B,2,false)) -> 0 | F14: =if(OR($E14=1, $E14=2),VLOOKUP($B14,Courts!$B$2:$K$50,10,false),0) -> 0 | G14: =IF(OR(E14=3,E14=4),9,IF(E14=5,13,0)) -> 0 | H14: =if(OR($E14=1, $E14=2),VLOOKUP($B14,Courts!$B$2:$J$50,5,false),0) -> 0 | I14: =if(OR($E14=1, $E14=2),VLOOKUP($B14,Courts!$B$2:$J$50,6,false),0) -> 0 | J14: =if(OR($E14=1, $E14=2),VLOOKUP($B14,Courts!$B$2:$J$50,7,false),0) -> 0 | K14: =G14+H14+I14+J14 -> 0 | L14: =if(OR($E14=1, $E14=2),VLOOKUP($B14,Courts!$B$2:$J$50,9,false),0) -> 0 | M14: =C14+K14 -> 254 | N14: =D14+L14 -> 20 | O14: X | P14: X | Q14: X | R14: =if(G14=13,1,0)+VLOOKUP(B14,'062224'!B:T,17,false) -> 2 | T14: =if(G14=9,1,0)+VLOOKUP(B14,'062224'!B:T,19,false) -> 2
A15: =A14+1 -> 11 | B15: Eric Pan | C15: 254 | D15: 19 | E15: =if(isna(VLOOKUP(B15,Checkin!A:B,2,false)),0,VLOOKUP(B15,Checkin!A:B,2,false)) -> 0 | F15: =if(OR($E15=1, $E15=2),VLOOKUP($B15,Courts!$B$2:$K$50,10,false),0) -> 0 | G15: =IF(OR(E15=3,E15=4),9,IF(E15=5,13,0)) -> 0 | H15: =if(OR($E15=1, $E15=2),VLOOKUP($B15,Courts!$B$2:$J$50,5,false),0) -> 0 | I15: =if(OR($E15=1, $E15=2),VLOOKUP($B15,Courts!$B$2:$J$50,6,false),0) -> 0 | J15: =if(OR($E15=1, $E15=2),VLOOKUP($B15,Courts!$B$2:$J$50,7,false),0) -> 0 | K15: =G15+H15+I15+J15 -> 0 | L15: =if(OR($E15=1, $E15=2),VLOOKUP($B15,Courts!$B$2:$J$50,9,false),0) -> 0 | M15: =C15+K15 -> 254 | N15: =D15+L15 -> 19 | O15: X | P15: X | Q15: X | R15: =if(G15=13,1,0)+VLOOKUP(B15,'062224'!B:T,17,false) -> 1 | T15: =if(G15=9,1,0)+VLOOKUP(B15,'062224'!B:T,19,false) -> 12
A16: =A15+1 -> 12 | B16: Sean Chang | C16: 253 | D16: 15 | E16: =if(isna(VLOOKUP(B16,Checkin!A:B,2,false)),0,VLOOKUP(B16,Checkin!A:B,2,false)) -> 0 | F16: =if(OR($E16=1, $E16=2),VLOOKUP($B16,Courts!$B$2:$K$50,10,false),0) -> 0 | G16: =IF(OR(E16=3,E16=4),9,IF(E16=5,13,0)) -> 0 | H16: =if(OR($E16=1, $E16=2),VLOOKUP($B16,Courts!$B$2:$J$50,5,false),0) -> 0 | I16: =if(OR($E16=1, $E16=2),VLOOKUP($B16,Courts!$B$2:$J$50,6,false),0) -> 0 | J16: =if(OR($E16=1, $E16=2),VLOOKUP($B16,Courts!$B$2:$J$50,7,false),0) -> 0 | K16: =G16+H16+I16+J16 -> 0 | L16: =if(OR($E16=1, $E16=2),VLOOKUP($B16,Courts!$B$2:$J$50,9,false),0) -> 0 | M16: =C16+K16 -> 253 | N16: =D16+L16 -> 15 | O16: X | P16: X | Q16: X | R16: =if(G16=13,1,0)+VLOOKUP(B16,'062224'!B:T,17,false) -> 2 | T16: =if(G16=9,1,0)+VLOOKUP(B16,'062224'!B:T,19,false) -> 6
A17: =A16+1 -> 13 | B17: Pavan Akkimsetty | C17: 252 | D17: 22 | E17: =if(isna(VLOOKUP(B17,Checkin!A:B,2,false)),0,VLOOKUP(B17,Checkin!A:B,2,false)) -> 0 | F17: =if(OR($E17=1, $E17=2),VLOOKUP($B17,Courts!$B$2:$K$50,10,false),0) -> 0 | G17: =IF(OR(E17=3,E17=4),9,IF(E17=5,13,0)) -> 0 | H17: =if(OR($E17=1, $E17=2),VLOOKUP($B17,Courts!$B$2:$J$50,5,false),0) -> 0 | I17: =if(OR($E17=1, $E17=2),VLOOKUP($B17,Courts!$B$2:$J$50,6,false),0) -> 0 | J17: =if(OR($E17=1, $E17=2),VLOOKUP($B17,Courts!$B$2:$J$50,7,false),0) -> 0 | K17: =G17+H17+I17+J17 -> 0 | L17: =if(OR($E17=1, $E17=2),VLOOKUP($B17,Courts!$B$2:$J$50,9,false),0) -> 0 | M17: =C17+K17 -> 252 | N17: =D17+L17 -> 22 | O17: X | P17: X | Q17: X | R17: =if(G17=13,1,0)+VLOOKUP(B17,'062224'!B:T,17,false) -> 0 | T17: =if(G17=9,1,0)+VLOOKUP(B17,'062224'!B:T,19,false) -> 7
... A69: =A68+1 -> 65 | B69: Jose Ortiz | C69: 179 | D69: 2 | E69: =if(isna(VLOOKUP(B69,Checkin!A:B,2,false)),0,VLOOKUP(B69,Checkin!A:B,2,false)) -> 0 | F69: =if(OR($E69=1, $E69=2),VLOOKUP($B69,Courts!$B$2:$K$50,10,false),0) -> 0 | G69: =IF(OR(E69=3,E69=4),9,IF(E69=5,13,0)) -> 0 | H69: =if(OR($E69=1, $E69=2),VLOOKUP($B69,Courts!$B$2:$J$50,5,false),0) -> 0 | I69: =if(OR($E69=1, $E69=2),VLOOKUP($B69,Courts!$B$2:$J$50,6,false),0) -> 0 | J69: =if(OR($E69=1, $E69=2),VLOOKUP($B69,Courts!$B$2:$J$50,7,false),0) -> 0 | K69: =G69+H69+I69+J69 -> 0 | L69: =if(OR($E69=1, $E69=2),VLOOKUP($B69,Courts!$B$2:$J$50,9,false),0) -> 0 | M69: =C69+K69 -> 179 | N69: =D69+L69 -> 2 | O69: X | P69: X | Q69: X | R69: =if(G69=13,1,0)+VLOOKUP(B69,'062224'!B:T,17,false) -> 0 | T69: =if(G69=9,1,0)+VLOOKUP(B69,'062224'!B:T,19,false) -> 19
B72: =COUNTA(B5:B69) -> 65 | O72: Paid | P72: =COUNTA(P5:P69) -> 65 | Q72: =COUNTA(Q5:Q69) -> 65
O73: To Pay | P73: =P74-P72 -> 0 | Q73: =Q74-Q72 -> 0
O74: Total | P74: =B72 -> 65 | Q74: =P74 -> 65
O77: Paid | Q77: =COUNTIF(Q5:Q69,"X") -> 52
B78: Top Scores | C78: Games | D78: Sets | O78: Not Renewing | Q78: =countif(Q5:Q69,"N") -> 13
B79: =IFERROR(__xludf.DUMMYFUNCTION("QUERY(B5:L69,""Select B, K, L where K >= 18 order by K desc, L desc"",0)"),"#N/A") -> #N/A | O79: To Pay | Q79: =countif(Q5:Q69,"") -> 0
O80: Total | Q80: =sum(Q77:Q79) -> 65
B90: Scores for this week
B91: Name of Player | C91: Games Won | D91: Sets Won | E91: Check IN | F91: Court # | G91: Set 0 | H91: Set 1 | I91: Set 2 | J91: Set 3 | K91: Games Won | L91: Sets Won | M91: Games Won | N91: Sets Won
B92: =IFERROR(__xludf.DUMMYFUNCTION("QUERY(B5:N69, ""Select B, C, D, E, F, G, H, I, J, K, L, M, N where F >= 1"")"),"#N/A") -> #N/A
B134: Absentees
B135: Name of Player | C135: Games Won | D135: Sets Won | E135: Check IN | F135: Court # | G135: Set 0 | H135: Set 1 | I135: Set 2 | J135: Set 3 | K135: Games Won | L135: Sets Won | M135: Games Won | N135: Sets Won
B136: =IFERROR(__xludf.DUMMYFUNCTION("QUERY(B5:N69, ""Select B, C, D, E, F, G, H, I, J, K, L, M, N where F = 0"")"),"Adrian Tay") -> Adrian Tay | C136: =IFERROR(__xludf.DUMMYFUNCTION("""COMPUTED_VALUE"""),300.0) -> 300 | D136: =IFERROR(__xludf.DUMMYFUNCTION("""COMPUTED_VALUE"""),34.0) -> 34 | E136: =IFERROR(__xludf.DUMMYFUNCTION("""COMPUTED_VALUE"""),0.0) -> 0 | F136: =IFERROR(__xludf.DUMMYFUNCTION("""COMPUTED_VALUE"""),0.0) -> 0 | G136: =IFERROR(__xludf.DUMMYFUNCTION("""COMPUTED_VALUE"""),0.0) -> 0 | H136: =IFERROR(__xludf.DUMMYFUNCTION("""COMPUTED_VALUE"""),0.0) -> 0 | I136: =IFERROR(__xludf.DUMMYFUNCTION("""COMPUTED_VALUE"""),0.0) -> 0 | J136: =IFERROR(__xludf.DUMMYFUNCTION("""COMPUTED_VALUE"""),0.0) -> 0 | K136: =IFERROR(__xludf.DUMMYFUNCTION("""COMPUTED_VALUE"""),0.0) -> 0 | L136: =IFERROR(__xludf.DUMMYFUNCTION("""COMPUTED_VALUE"""),0.0) -> 0 | M136: =IFERROR(__xludf.DUMMYFUNCTION("""COMPUTED_VALUE"""),300.0) -> 300 | N136: =IFERROR(__xludf.DUMMYFUNCTION("""COMPUTED_VALUE"""),34.0) -> 34
B137: =IFERROR(__xludf.DUMMYFUNCTION("""COMPUTED_VALUE"""),"Peter Cheng") -> Peter Cheng | C137: =IFERROR(__xludf.DUMMYFUNCTION("""COMPUTED_VALUE"""),278.0) -> 278 | D137: =IFERROR(__xludf.DUMMYFUNCTION("""COMPUTED_VALUE"""),27.0) -> 27 | E137: =IFERROR(__xludf.DUMMYFUNCTION("""COMPUTED_VALUE"""),0.0) -> 0 | F137: =IFERROR(__xludf.DUMMYFUNCTION("""COMPUTED_VALUE"""),0.0) -> 0 | G137: =IFERROR(__xludf.DUMMYFUNCTION("""COMPUTED_VALUE"""),0.0) -> 0 | H137: =IFERROR(__xludf.DUMMYFUNCTION("""COMPUTED_VALUE"""),0.0) -> 0 | I137: =IFERROR(__xludf.DUMMYFUNCTION("""COMPUTED_VALUE"""),0.0) -> 0 | J137: =IFERROR(__xludf.DUMMYFUNCTION("""COMPUTED_VALUE"""),0.0) -> 0 | K137: =IFERROR(__xludf.DUMMYFUNCTION("""COMPUTED_VALUE"""),0.0) -> 0 | L137: =IFERROR(__xludf.DUMMYFUNCTION("""COMPUTED_VALUE"""),0.0) -> 0 | M137: =IFERROR(__xludf.DUMMYFUNCTION("""COMPUTED_VALUE"""),278.0) -> 278 | N137: =IFERROR(__xludf.DUMMYFUNCTION("""COMPUTED_VALUE"""),27.0) -> 27
B138: =IFERROR(__xludf.DUMMYFUNCTION("""COMPUTED_VALUE"""),"Suleman Alidina") -> Suleman Alidina | C138: =IFERROR(__xludf.DUMMYFUNCTION("""COMPUTED_VALUE"""),271.0) -> 271 | D138: =IFERROR(__xludf.DUMMYFUNCTION("""COMPUTED_VALUE"""),30.0) -> 30 | E138: =IFERROR(__xludf.DUMMYFUNCTION("""COMPUTED_VALUE"""),0.0) -> 0 | F138: =IFERROR(__xludf.DUMMYFUNCTION("""COMPUTED_VALUE"""),0.0) -> 0 | G138: =IFERROR(__xludf.DUMMYFUNCTION("""COMPUTED_VALUE"""),0.0) -> 0 | H138: =IFERROR(__xludf.DUMMYFUNCTION("""COMPUTED_VALUE"""),0.0) -> 0 | I138: =IFERROR(__xludf.DUMMYFUNCTION("""COMPUTED_VALUE"""),0.0) -> 0 | J138: =IFERROR(__xludf.DUMMYFUNCTION("""COMPUTED_VALUE"""),0.0) -> 0 | K138: =IFERROR(__xludf.DUMMYFUNCTION("""COMPUTED_VALUE"""),0.0) -> 0 | L138: =IFERROR(__xludf.DUMMYFUNCTION("""COMPUTED_VALUE"""),0.0) -> 0 | M138: =IFERROR(__xludf.DUMMYFUNCTION("""COMPUTED_VALUE"""),271.0) -> 271 | N138: =IFERROR(__xludf.DUMMYFUNCTION("""COMPUTED_VALUE"""),30.0) -> 30
B139: =IFERROR(__xludf.DUMMYFUNCTION("""COMPUTED_VALUE"""),"Christopher Li") -> Christopher Li | C139: =IFERROR(__xludf.DUMMYFUNCTION("""COMPUTED_VALUE"""),271.0) -> 271 | D139: =IFERROR(__xludf.DUMMYFUNCTION("""COMPUTED_VALUE"""),27.0) -> 27 | E139: =IFERROR(__xludf.DUMMYFUNCTION("""COMPUTED_VALUE"""),0.0) -> 0 | F139: =IFERROR(__xludf.DUMMYFUNCTION("""COMPUTED_VALUE"""),0.0) -> 0 | G139: =IFERROR(__xludf.DUMMYFUNCTION("""COMPUTED_VALUE"""),0.0) -> 0 | H139: =IFERROR(__xludf.DUMMYFUNCTION("""COMPUTED_VALUE"""),0.0) -> 0 | I139: =IFERROR(__xludf.DUMMYFUNCTION("""COMPUTED_VALUE"""),0.0) -> 0 | J139: =IFERROR(__xludf.DUMMYFUNCTION("""COMPUTED_VALUE"""),0.0) -> 0 | K139: =IFERROR(__xludf.DUMMYFUNCTION("""COMPUTED_VALUE"""),0.0) -> 0 | L139: =IFERROR(__xludf.DUMMYFUNCTION("""COMPUTED_VALUE"""),0.0) -> 0 | M139: =IFERROR(__xludf.DUMMYFUNCTION("""COMPUTED_VALUE"""),271.0) -> 271 | N139: =IFERROR(__xludf.DUMMYFUNCTION("""COMPUTED_VALUE"""),27.0) -> 27
B140: =IFERROR(__xludf.DUMMYFUNCTION("""COMPUTED_VALUE"""),"Peter Homsey") -> Peter Homsey | C140: =IFERROR(__xludf.DUMMYFUNCTION("""COMPUTED_VALUE"""),263.0) -> 263 | D140: =IFERROR(__xludf.DUMMYFUNCTION("""COMPUTED_VALUE"""),23.0) -> 23 | E140: =IFERROR(__xludf.DUMMYFUNCTION("""COMPUTED_VALUE"""),0.0) -> 0 | F140: =IFERROR(__xludf.DUMMYFUNCTION("""COMPUTED_VALUE"""),0.0) -> 0 | G140: =IFERROR(__xludf.DUMMYFUNCTION("""COMPUTED_VALUE"""),0.0) -> 0 | H140: =IFERROR(__xludf.DUMMYFUNCTION("""COMPUTED_VALUE"""),0.0) -> 0 | I140: =IFERROR(__xludf.DUMMYFUNCTION("""COMPUTED_VALUE"""),0.0) -> 0 | J140: =IFERROR(__xludf.DUMMYFUNCTION("""COMPUTED_VALUE"""),0.0) -> 0 | K140: =IFERROR(__xludf.DUMMYFUNCTION("""COMPUTED_VALUE"""),0.0) -> 0 | L140: =IFERROR(__xludf.DUMMYFUNCTION("""COMPUTED_VALUE"""),0.0) -> 0 | M140: =IFERROR(__xludf.DUMMYFUNCTION("""COMPUTED_VALUE"""),263.0) -> 263 | N140: =IFERROR(__xludf.DUMMYFUNCTION("""COMPUTED_VALUE"""),23.0) -> 23
B141: =IFERROR(__xludf.DUMMYFUNCTION("""COMPUTED_VALUE"""),"Lam Bui") -> Lam Bui | C141: =IFERROR(__xludf.DUMMYFUNCTION("""COMPUTED_VALUE"""),263.0) -> 263 | D141: =IFERROR(__xludf.DUMMYFUNCTION("""COMPUTED_VALUE"""),18.0) -> 18 | E141: =IFERROR(__xludf.DUMMYFUNCTION("""COMPUTED_VALUE"""),0.0) -> 0 | F141: =IFERROR(__xludf.DUMMYFUNCTION("""COMPUTED_VALUE"""),0.0) -> 0 | G141: =IFERROR(__xludf.DUMMYFUNCTION("""COMPUTED_VALUE"""),0.0) -> 0 | H141: =IFERROR(__xludf.DUMMYFUNCTION("""COMPUTED_VALUE"""),0.0) -> 0 | I141: =IFERROR(__xludf.DUMMYFUNCTION("""COMPUTED_VALUE"""),0.0) -> 0 | J141: =IFERROR(__xludf.DUMMYFUNCTION("""COMPUTED_VALUE"""),0.0) -> 0 | K141: =IFERROR(__xludf.DUMMYFUNCTION("""COMPUTED_VALUE"""),0.0) -> 0 | L141: =IFERROR(__xludf.DUMMYFUNCTION("""COMPUTED_VALUE"""),0.0) -> 0 | M141: =IFERROR(__xludf.DUMMYFUNCTION("""COMPUTED_VALUE"""),263.0) -> 263 | N141: =IFERROR(__xludf.DUMMYFUNCTION("""COMPUTED_VALUE"""),18.0) -> 18
B142: =IFERROR(__xludf.DUMMYFUNCTION("""COMPUTED_VALUE"""),"Jonathan Phan") -> Jonathan Phan | C142: =IFERROR(__xludf.DUMMYFUNCTION("""COMPUTED_VALUE"""),261.0) -> 261 | D142: =IFERROR(__xludf.DUMMYFUNCTION("""COMPUTED_VALUE"""),22.0) -> 22 | E142: =IFERROR(__xludf.DUMMYFUNCTION("""COMPUTED_VALUE"""),0.0) -> 0 | F142: =IFERROR(__xludf.DUMMYFUNCTION("""COMPUTED_VALUE"""),0.0) -> 0 | G142: =IFERROR(__xludf.DUMMYFUNCTION("""COMPUTED_VALUE"""),0.0) -> 0 | H142: =IFERROR(__xludf.DUMMYFUNCTION("""COMPUTED_VALUE"""),0.0) -> 0 | I142: =IFERROR(__xludf.DUMMYFUNCTION("""COMPUTED_VALUE"""),0.0) -> 0 | J142: =IFERROR(__xludf.DUMMYFUNCTION("""COMPUTED_VALUE"""),0.0) -> 0 | K142: =IFERROR(__xludf.DUMMYFUNCTION("""COMPUTED_VALUE"""),0.0) -> 0 | L142: =IFERROR(__xludf.DUMMYFUNCTION("""COMPUTED_VALUE"""),0.0) -> 0 | M142: =IFERROR(__xludf.DUMMYFUNCTION("""COMPUTED_VALUE"""),261.0) -> 261 | N142: =IFERROR(__xludf.DUMMYFUNCTION("""COMPUTED_VALUE"""),22.0) -> 22
B143: =IFERROR(__xludf.DUMMYFUNCTION("""COMPUTED_VALUE"""),"David Shin") -> David Shin | C143: =IFERROR(__xludf.DUMMYFUNCTION("""COMPUTED_VALUE"""),259.0) -> 259 | D143: =IFERROR(__xludf.DUMMYFUNCTION("""COMPUTED_VALUE"""),23.0) -> 23 | E143: =IFERROR(__xludf.DUMMYFUNCTION("""COMPUTED_VALUE"""),0.0) -> 0 | F143: =IFERROR(__xludf.DUMMYFUNCTION("""COMPUTED_VALUE"""),0.0) -> 0 | G143: =IFERROR(__xludf.DUMMYFUNCTION("""COMPUTED_VALUE"""),0.0) -> 0 | H143: =IFERROR(__xludf.DUMMYFUNCTION("""COMPUTED_VALUE"""),0.0) -> 0 | I143: =IFERROR(__xludf.DUMMYFUNCTION("""COMPUTED_VALUE"""),0.0) -> 0 | J143: =IFERROR(__xludf.DUMMYFUNCTION("""COMPUTED_VALUE"""),0.0) -> 0 | K143: =IFERROR(__xludf.DUMMYFUNCTION("""COMPUTED_VALUE"""),0.0) -> 0 | L143: =IFERROR(__xludf.DUMMYFUNCTION("""COMPUTED_VALUE"""),0.0) -> 0 | M143: =IFERROR(__xludf.DUMMYFUNCTION("""COMPUTED_VALUE"""),259.0) -> 259 | N143: =IFERROR(__xludf.DUMMYFUNCTION("""COMPUTED_VALUE"""),23.0) -> 23
B144: =IFERROR(__xludf.DUMMYFUNCTION("""COMPUTED_VALUE"""),"Luis Hsu") -> Luis Hsu | C144: =IFERROR(__xludf.DUMMYFUNCTION("""COMPUTED_VALUE"""),259.0) -> 259 | D144: =IFERROR(__xludf.DUMMYFUNCTION("""COMPUTED_VALUE"""),23.0) -> 23 | E144: =IFERROR(__xludf.DUMMYFUNCTION("""COMPUTED_VALUE"""),0.0) -> 0 | F144: =IFERROR(__xludf.DUMMYFUNCTION("""COMPUTED_VALUE"""),0.0) -> 0 | G144: =IFERROR(__xludf.DUMMYFUNCTION("""COMPUTED_VALUE"""),0.0) -> 0 | H144: =IFERROR(__xludf.DUMMYFUNCTION("""COMPUTED_VALUE"""),0.0) -> 0 | I144: =IFERROR(__xludf.DUMMYFUNCTION("""COMPUTED_VALUE"""),0.0) -> 0 | J144: =IFERROR(__xludf.DUMMYFUNCTION("""COMPUTED_VALUE"""),0.0) -> 0 | K144: =IFERROR(__xludf.DUMMYFUNCTION("""COMPUTED_VALUE"""),0.0) -> 0 | L144: =IFERROR(__xludf.DUMMYFUNCTION("""COMPUTED_VALUE"""),0.0) -> 0 | M144: =IFERROR(__xludf.DUMMYFUNCTION("""COMPUTED_VALUE"""),259.0) -> 259 | N144: =IFERROR(__xludf.DUMMYFUNCTION("""COMPUTED_VALUE"""),23.0) -> 23
B145: =IFERROR(__xludf.DUMMYFUNCTION("""COMPUTED_VALUE"""),"Ted Shen") -> Ted Shen | C145: =IFERROR(__xludf.DUMMYFUNCTION("""COMPUTED_VALUE"""),254.0) -> 254 | D145: =IFERROR(__xludf.DUMMYFUNCTION("""COMPUTED_VALUE"""),20.0) -> 20 | E145: =IFERROR(__xludf.DUMMYFUNCTION("""COMPUTED_VALUE"""),0.0) -> 0 | F145: =IFERROR(__xludf.DUMMYFUNCTION("""COMPUTED_VALUE"""),0.0) -> 0 | G145: =IFERROR(__xludf.DUMMYFUNCTION("""COMPUTED_VALUE"""),0.0) -> 0 | H145: =IFERROR(__xludf.DUMMYFUNCTION("""COMPUTED_VALUE"""),0.0) -> 0 | I145: =IFERROR(__xludf.DUMMYFUNCTION("""COMPUTED_VALUE"""),0.0) -> 0 | J145: =IFERROR(__xludf.DUMMYFUNCTION("""COMPUTED_VALUE"""),0.0) -> 0 | K145: =IFERROR(__xludf.DUMMYFUNCTION("""COMPUTED_VALUE"""),0.0) -> 0 | L145: =IFERROR(__xludf.DUMMYFUNCTION("""COMPUTED_VALUE"""),0.0) -> 0 | M145: =IFERROR(__xludf.DUMMYFUNCTION("""COMPUTED_VALUE"""),254.0) -> 254 | N145: =IFERROR(__xludf.DUMMYFUNCTION("""COMPUTED_VALUE"""),20.0) -> 20
...

Sheet Courts
A1: Court # | B1: Name of the Player | C1: Games Won | D1: Sets Won | E1: Check In | F1: Set 1 | G1: Set 2 | H1: Set 3 | I1: Total Games won | J1: Sets Won | K1: Court # | M1: Set 1 | N1: Set 2 | O1: Set 2 | Q1: Sets Validations | T1: Set 1 | U1: Set 2 | V1: Set 2
A2: 1 | B2: =IFERROR(__xludf.DUMMYFUNCTION("QUERY(Current!B5:E69,""Select B, C, D, E where E = 1 or E = 2 "",0)"),"#N/A") -> #N/A | F2: 7 | G2: 2 | H2: 6 | I2: =sum(F2:H2) -> 15 | J2: 2 | K2: =A2 -> 1 | M2: =if(COUNTIF(T2:T4,"Good")=2,"Good","Error") -> Good | N2: =if(COUNTIF(U2:U4,"Good")=2,"Good","Error") -> Good | O2: =if(COUNTIF(V2:V4,"Good")=2,"Good","Error") -> Good | Q2: =sum(J2:J5) -> 6 | R2: =if(Q2=0,"",if(Q2=6,"Good","ERROR")) -> Good | T2: =if(isna(VLOOKUP(F2,F3:F5,1,false)),"Error","Good") -> Good | U2: =if(isna(VLOOKUP(G2,G3:G5,1,false)),"Error","Good") -> Good | V2: =if(isna(VLOOKUP(H2,H3:H5,1,false)),"Error","Good") -> Good
A3: 1 | F3: 5 | G3: 6 | H3: 6 | I3: =sum(F3:H3) -> 17 | J3: 2 | K3: =A3 -> 1 | T3: =if(isna(VLOOKUP(F3,F4:F5,1,false)),"Error","Good") -> Good | U3: =if(isna(VLOOKUP(G3,G4:G5,1,false)),"Error","Good") -> Good | V3: =if(isna(VLOOKUP(H3,H4:H5,1,false)),"Error","Good") -> Error | AB3: Alejandro Mejia
A4: 1 | F4: 5 | G4: 2 | H4: 4 | I4: =sum(F4:H4) -> 11 | J4: 0 | K4: =A4 -> 1 | T4: =if(F4=F5,"Good") -> FALSE | U4: =if(G4=G5,"Good") -> FALSE | V4: =if(H4=H5,"Good") -> Good | X4: Skip Court 3 | AB4: Jimmy Awolesi
A5: 1 | F5: 7 | G5: 6 | H5: 4 | I5: =sum(F5:H5) -> 17 | J5: 2 | K5: =A5 -> 1 | W5: Y | X5: Skip Court 4 | AB5: Tony Wong
A6: 2 | F6: 6 | G6: 6 | H6: 4 | I6: =sum(F6:H6) -> 16 | J6: 2 | K6: =A6 -> 2 | M6: =if(COUNTIF(T6:T8,"Good")=2,"Good","Error") -> Good | N6: =if(COUNTIF(U6:U8,"Good")=2,"Good","Error") -> Good | O6: =if(COUNTIF(V6:V8,"Good")=2,"Good","Error") -> Good | Q6: =sum(J6:J9) -> 6 | R6: =if(Q6=0,"",if(Q6=6,"Good","ERROR")) -> Good | T6: =if(isna(VLOOKUP(F6,F7:F9,1,false)),"Error","Good") -> Good | U6: =if(isna(VLOOKUP(G6,G7:G9,1,false)),"Error","Good") -> Good | V6: =if(isna(VLOOKUP(H6,H7:H9,1,false)),"Error","Good") -> Good | AB6: Vinaya Kajla
A7: 2 | F7: 4 | G7: 6 | H7: 6 | I7: =sum(F7:H7) -> 16 | J7: 0 | K7: =A7 -> 2 | T7: =if(isna(VLOOKUP(F7,F8:F9,1,false)),"Error","Good") -> Good | U7: =if(isna(VLOOKUP(G7,G8:G9,1,false)),"Error","Good") -> Error | V7: =if(isna(VLOOKUP(H7,H8:H9,1,false)),"Error","Good") -> Good
A8: 2 | F8: 4 | G8: 3 | H8: 4 | I8: =sum(F8:H8) -> 11 | J8: 2 | K8: =A8 -> 2 | T8: =if(F8=F9,"Good") -> FALSE | U8: =if(G8=G9,"Good") -> Good | V8: =if(H8=H9,"Good") -> FALSE
A9: 2 | F9: 6 | G9: 3 | H9: 6 | I9: =sum(F9:H9) -> 15 | J9: 2 | K9: =A9 -> 2
A10: =if(W4="Y",A9+3,A9+1) -> 3 | F10: 3 | G10: 4 | H10: 2 | I10: =sum(F10:H10) -> 9 | J10: 0 | K10: =A10 -> 3 | M10: =if(COUNTIF(T10:T12,"Good")=2,"Good","Error") -> Good | N10: =if(COUNTIF(U10:U12,"Good")=2,"Good","Error") -> Good | O10: =if(COUNTIF(V10:V12,"Good")=2,"Good","Error") -> Good | Q10: =sum(J10:J13) -> 6 | R10: =if(Q10=0,"",if(Q10=6,"Good","ERROR")) -> Good | T10: =if(isna(VLOOKUP(F10,F11:F13,1,false)),"Error","Good") -> Good | U10: =if(isna(VLOOKUP(G10,G11:G13,1,false)),"Error","Good") -> Good | V10: =if(isna(VLOOKUP(H10,H11:H13,1,false)),"Error","Good") -> Good
A11: =A10 -> 3 | F11: 6 | G11: 4 | H11: 6 | I11: =sum(F11:H11) -> 16 | J11: 2 | K11: =A11 -> 3 | T11: =if(isna(VLOOKUP(F11,F12:F13,1,false)),"Error","Good") -> Good | U11: =if(isna(VLOOKUP(G11,G12:G13,1,false)),"Error","Good") -> Error | V11: =if(isna(VLOOKUP(H11,H12:H13,1,false)),"Error","Good") -> Good | AB11: Suleman Alidina
A12: =A11 -> 3 | F12: 3 | G12: 6 | H12: 6 | I12: =sum(F12:H12) -> 15 | J12: 2 | K12: =A12 -> 3 | T12: =if(F12=F13,"Good") -> FALSE | U12: =if(G12=G13,"Good") -> Good | V12: =if(H12=H13,"Good") -> FALSE | AB12: Ash Nikravan
A13: =A12 -> 3 | F13: 6 | G13: 6 | H13: 2 | I13: =sum(F13:H13) -> 14 | J13: 2 | K13: =A13 -> 3 | AB13: Susanta Mishra
A14: =if(W5="Y",A13+2,A13+1) -> 5 | F14: 6 | G14: 6 | H14: 6 | I14: =sum(F14:H14) -> 18 | J14: 3 | K14: =A14 -> 5 | M14: =if(COUNTIF(T14:T16,"Good")=2,"Good","Error") -> Good | N14: =if(COUNTIF(U14:U16,"Good")=2,"Good","Error") -> Good | O14: =if(COUNTIF(V14:V16,"Good")=2,"Good","Error") -> Good | Q14: =sum(J14:J17) -> 6 | R14: =if(Q14=0,"",if(Q14=6,"Good","ERROR")) -> Good | T14: =if(isna(VLOOKUP(F14,F15:F17,1,false)),"Error","Good") -> Good | U14: =if(isna(VLOOKUP(G14,G15:G17,1,false)),"Error","Good") -> Good | V14: =if(isna(VLOOKUP(H14,H15:H17,1,false)),"Error","Good") -> Good | AB14: David Tam
A15: =A14 -> 5 | F15: 0 | G15: 6 | H15: 3 | I15: =sum(F15:H15) -> 9 | J15: 1 | K15: =A15 -> 5 | T15: =if(isna(VLOOKUP(F15,F16:F17,1,false)),"Error","Good") -> Good | U15: =if(isna(VLOOKUP(G15,G16:G17,1,false)),"Error","Good") -> Error | V15: =if(isna(VLOOKUP(H15,H16:H17,1,false)),"Error","Good") -> Good
A16: =A15 -> 5 | F16: 0 | G16: 3 | H16: 6 | I16: =sum(F16:H16) -> 9 | J16: 1 | K16: =A16 -> 5 | T16: =if(F16=F17,"Good") -> FALSE | U16: =if(G16=G17,"Good") -> Good | V16: =if(H16=H17,"Good") -> FALSE
A17: =A16 -> 5 | F17: 6 | G17: 3 | H17: 3 | I17: =sum(F17:H17) -> 12 | J17: 1 | K17: =A17 -> 5
A18: =A17+1 -> 6 | F18: 5 | G18: 5 | H18: 6 | I18: =sum(F18:H18) -> 16 | J18: 1 | K18: =A18 -> 6 | M18: =if(COUNTIF(T18:T20,"Good")=2,"Good","Error") -> Good | N18: =if(COUNTIF(U18:U20,"Good")=2,"Good","Error") -> Good | O18: =if(COUNTIF(V18:V20,"Good")=2,"Good","Error") -> Good | Q18: =sum(J18:J21) -> 6 | R18: =if(Q18=0,"",if(Q18=6,"Good","ERROR")) -> Good | T18: =if(isna(VLOOKUP(F18,F19:F21,1,false)),"Error","Good") -> Good | U18: =if(isna(VLOOKUP(G18,G19:G21,1,false)),"Error","Good") -> Good | V18: =if(isna(VLOOKUP(H18,H19:H21,1,false)),"Error","Good") -> Good | AB18: Pulkit Mathur
A19: =A18 -> 6 | F19: 7 | G19: 7 | H19: 6 | I19: =sum(F19:H19) -> 20 | J19: 3 | K19: =A19 -> 6 | T19: =if(isna(VLOOKUP(F19,F20:F21,1,false)),"Error","Good") -> Good | U19: =if(isna(VLOOKUP(G19,G20:G21,1,false)),"Error","Good") -> Good | V19: =if(isna(VLOOKUP(H19,H20:H21,1,false)),"Error","Good") -> Error | AB19: Kingsley Kuo
A20: =A19 -> 6 | F20: 5 | G20: 7 | H20: 3 | I20: =sum(F20:H20) -> 15 | J20: 1 | K20: =A20 -> 6 | T20: =if(F20=F21,"Good") -> FALSE | U20: =if(G20=G21,"Good") -> FALSE | V20: =if(H20=H21,"Good") -> Good | AB20: Scott Li
A21: =A20 -> 6 | F21: 7 | G21: 5 | H21: 3 | I21: =sum(F21:H21) -> 15 | J21: 1 | K21: =A21 -> 6 | AB21: Vamsi Lolla
A22: =A21+1 -> 7 | I22: =sum(F22:H22) -> 0 | K22: =A22 -> 7 | M22: =if(COUNTIF(T22:T24,"Good")=2,"Good","Error") -> Error | N22: =if(COUNTIF(U22:U24,"Good")=2,"Good","Error") -> Error | O22: =if(COUNTIF(V22:V24,"Good")=2,"Good","Error") -> Error | Q22: =sum(J22:J25) -> 0 | R22: =if(Q22=0,"",if(Q22=6,"Good","ERROR")) | T22: =if(isna(VLOOKUP(F22,F23:F25,1,false)),"Error","Good") -> Error | U22: =if(isna(VLOOKUP(G22,G23:G25,1,false)),"Error","Good") -> Error | V22: =if(isna(VLOOKUP(H22,H23:H25,1,false)),"Error","Good") -> Error
A23: =A22 -> 7 | I23: =sum(F23:H23) -> 0 | K23: =A23 -> 7 | T23: =if(isna(VLOOKUP(F23,F24:F25,1,false)),"Error","Good") -> Error | U23: =if(isna(VLOOKUP(G23,G24:G25,1,false)),"Error","Good") -> Error | V23: =if(isna(VLOOKUP(H23,H24:H25,1,false)),"Error","Good") -> Error
A24: =A23 -> 7 | I24: =sum(F24:H24) -> 0 | K24: =A24 -> 7 | T24: =if(F24=F25,"Good") -> Good | U24: =if(G24=G25,"Good") -> Good | V24: =if(H24=H25,"Good") -> Good | AB24: Rajasekar Ramasamy
A25: =A24 -> 7 | I25: =sum(F25:H25) -> 0 | K25: =A25 -> 7 | AB25: Anish Kumar
A26: =A25+1 -> 8 | I26: =sum(F26:H26) -> 0 | K26: =A26 -> 8 | M26: =if(COUNTIF(T26:T28,"Good")=2,"Good","Error") -> Error | N26: =if(COUNTIF(U26:U28,"Good")=2,"Good","Error") -> Error | O26: =if(COUNTIF(V26:V28,"Good")=2,"Good","Error") -> Error | Q26: =sum(J26:J29) -> 0 | R26: =if(Q26=0,"",if(Q26=6,"Good","ERROR")) | T26: =if(isna(VLOOKUP(F26,F27:F29,1,false)),"Error","Good") -> Error | U26: =if(isna(VLOOKUP(G26,G27:G29,1,false)),"Error","Good") -> Error | V26: =if(isna(VLOOKUP(H26,H27:H29,1,false)),"Error","Good") -> Error | AB26: Manuel Rivera
A27: =A26 -> 8 | I27: =sum(F27:H27) -> 0 | K27: =A27 -> 8 | T27: =if(isna(VLOOKUP(F27,F28:F29,1,false)),"Error","Good") -> Error | U27: =if(isna(VLOOKUP(G27,G28:G29,1,false)),"Error","Good") -> Error | V27: =if(isna(VLOOKUP(H27,H28:H29,1,false)),"Error","Good") -> Error | AB27: Ted Shen
A28: =A27 -> 8 | I28: =sum(F28:H28) -> 0 | K28: =A28 -> 8 | T28: =if(F28=F29,"Good") -> Good | U28: =if(G28=G29,"Good") -> Good | V28: =if(H28=H29,"Good") -> Good
A29: =A28 -> 8 | I29: =sum(F29:H29) -> 0 | K29: =A29 -> 8
A30: =A29+1 -> 9 | I30: =sum(F30:H30) -> 0 | K30: =A30 -> 9 | M30: =if(COUNTIF(T30:T32,"Good")=2,"Good","Error") -> Error | N30: =if(COUNTIF(U30:U32,"Good")=2,"Good","Error") -> Error | O30: =if(COUNTIF(V30:V32,"Good")=2,"Good","Error") -> Error | Q30: =sum(J30:J33) -> 0 | R30: =if(Q30=0,"",if(Q30=6,"Good","ERROR")) | T30: =if(isna(VLOOKUP(F30,F31:F33,1,false)),"Error","Good") -> Error | U30: =if(isna(VLOOKUP(G30,G31:G33,1,false)),"Error","Good") -> Error | V30: =if(isna(VLOOKUP(H30,H31:H33,1,false)),"Error","Good") -> Error
A31: =A30 -> 9 | I31: =sum(F31:H31) -> 0 | K31: =A31 -> 9 | T31: =if(isna(VLOOKUP(F31,F32:F33,1,false)),"Error","Good") -> Error | U31: =if(isna(VLOOKUP(G31,G32:G33,1,false)),"Error","Good") -> Error | V31: =if(isna(VLOOKUP(H31,H32:H33,1,false)),"Error","Good") -> Error
A32: =A31 -> 9 | I32: =sum(F32:H32) -> 0 | K32: =A32 -> 9 | T32: =if(F32=F33,"Good") -> Good | U32: =if(G32=G33,"Good") -> Good | V32: =if(H32=H33,"Good") -> Good
A33: =A32 -> 9 | I33: =sum(F33:H33) -> 0 | K33: =A33 -> 9 | AB33: Chinna Ponnaganti
A34: 99 | I34: =sum(F34:H34) -> 0 | K34: 99 | AB34: Mauricio Palacios
A35: 99 | I35: =sum(F35:H35) -> 0 | K35: 99 | AB35: Joyce Zhu
A36: 99 | I36: =sum(F36:H36) -> 0 | K36: 99 | AB36: Balaji Alahari
A37: 99 | I37: =sum(F37:H37) -> 0 | K37: 99
A38: 99 | I38: =sum(F38:H38) -> 0 | K38: 99
A39: 99 | I39: =sum(F39:H39) -> 0 | K39: 99
A40: 99 | I40: =sum(F40:H40) -> 0 | K40: 99
...

Sheet Checkin
A1: f | B1: Check in | D1: Sl.No | E1: Playing | F1: Playing-Can Sit | G1: Out | H1: Out-Can Play | I1: To Respond | J1: Sitouts | K1: Previous sitouts | L1: Eligible sitouts
A2: =IFERROR(__xludf.DUMMYFUNCTION("IMPORTRANGE(""1uZFF2o7rrfB0YZtASdZnP52Ef50ZinvtOPb1Tbuq8J4"",""CheckIn!C1:D99"")"),"#REF!") -> #REF! | D2: 1 | E2: =IFERROR(__xludf.DUMMYFUNCTION("QUERY(A2:B70, ""Select A where B = 1 order by A"")"),"#N/A") -> #N/A | F2: =IFERROR(__xludf.DUMMYFUNCTION("QUERY($A2:$B65, ""Select A where B = 2"")"),"#N/A") -> #N/A | G2: =IFERROR(__xludf.DUMMYFUNCTION("QUERY($A2:$B99, ""Select A where B = 3 order by A"")"),"#N/A") -> #N/A | H2: =IFERROR(__xludf.DUMMYFUNCTION("QUERY($A2:$B65, ""Select A where B = 4 order by A"")"),"#N/A") -> #N/A | I2: =IFERROR(__xludf.DUMMYFUNCTION("QUERY(Current!B5:E72, ""Select B where E = 0 order by B"")"),"Adrian Tay") -> Adrian Tay | J2: =IFERROR(__xludf.DUMMYFUNCTION("QUERY(Current!B5:E100, ""Select B where E = 5 order by B"")"),"#N/A") -> #N/A | K2: =VLOOKUP(F2,Current!B:R,17,false) -> #N/A | L2: =if(isna(if(K2=0,1,0)),0,IF(K2=0,1,0)) -> 0
D3: =D2+1 -> 2 | I3: =IFERROR(__xludf.DUMMYFUNCTION("""COMPUTED_VALUE"""),"Alejandro Mejia") -> Alejandro Mejia | K3: =VLOOKUP(F3,Current!B:R,17,false) -> #N/A | L3: =if(isna(if(K3=0,1,0)),0,IF(K3=0,1,0)) -> 0
D4: =D3+1 -> 3 | I4: =IFERROR(__xludf.DUMMYFUNCTION("""COMPUTED_VALUE"""),"Amit Patel") -> Amit Patel | K4: =VLOOKUP(F4,Current!B:R,17,false) -> #N/A | L4: =if(isna(if(K4=0,1,0)),0,IF(K4=0,1,0)) -> 0 | N4: Last update | O4: =now() -> 46311.565
D5: =D4+1 -> 4 | I5: =IFERROR(__xludf.DUMMYFUNCTION("""COMPUTED_VALUE"""),"Andrew Chin") -> Andrew Chin | K5: =VLOOKUP(F5,Current!B:R,17,false) -> #N/A | L5: =if(isna(if(K5=0,1,0)),0,IF(K5=0,1,0)) -> 0
D6: =D5+1 -> 5 | I6: =IFERROR(__xludf.DUMMYFUNCTION("""COMPUTED_VALUE"""),"Andrew Wen") -> Andrew Wen | K6: =VLOOKUP(F6,Current!B:R,17,false) -> #N/A | L6: =if(isna(if(K6=0,1,0)),0,IF(K6=0,1,0)) -> 0
D7: =D6+1 -> 6 | I7: =IFERROR(__xludf.DUMMYFUNCTION("""COMPUTED_VALUE"""),"Ash Nikravan") -> Ash Nikravan | K7: =VLOOKUP(F7,Current!B:R,17,false) -> #N/A | L7: =if(isna(if(K7=0,1,0)),0,IF(K7=0,1,0)) -> 0
D8: =D7+1 -> 7 | I8: =IFERROR(__xludf.DUMMYFUNCTION("""COMPUTED_VALUE"""),"Balaji Alahari") -> Balaji Alahari | K8: =VLOOKUP(F8,Current!B:R,17,false) -> #N/A | L8: =if(isna(if(K8=0,1,0)),0,IF(K8=0,1,0)) -> 0
D9: =D8+1 -> 8 | I9: =IFERROR(__xludf.DUMMYFUNCTION("""COMPUTED_VALUE"""),"Chandrasekar Chinnathambi") -> Chandrasekar Chinnathambi | K9: =VLOOKUP(F9,Current!B:R,17,false) -> #N/A | L9: =if(isna(if(K9=0,1,0)),0,IF(K9=0,1,0)) -> 0 | N9: Playing | O9: =if(isna(E2),0,COUNTA(E$2:E$58)) -> 0
D10: =D9+1 -> 9 | I10: =IFERROR(__xludf.DUMMYFUNCTION("""COMPUTED_VALUE"""),"Chinna Ponnaganti") -> Chinna Ponnaganti | K10: =VLOOKUP(F10,Current!B:R,17,false) -> #N/A | L10: =if(isna(if(K10=0,1,0)),0,IF(K10=0,1,0)) -> 0 | N10: Playing-Can Sit | O10: =if(isna(F2),0,COUNTA(F$2:F$58)) -> 0
D11: =D10+1 -> 10 | I11: =IFERROR(__xludf.DUMMYFUNCTION("""COMPUTED_VALUE"""),"Christopher Li") -> Christopher Li | K11: =VLOOKUP(F11,Current!B:R,17,false) -> #N/A | L11: =if(isna(if(K11=0,1,0)),0,IF(K11=0,1,0)) -> 0 | N11: Out/Can Play | O11: =if(isna(H2),0,COUNTA(H$2:H$58)) -> 0
D12: =D11+1 -> 11 | I12: =IFERROR(__xludf.DUMMYFUNCTION("""COMPUTED_VALUE"""),"Coco Yan") -> Coco Yan | K12: =VLOOKUP(F12,Current!B:R,17,false) -> #N/A | L12: =if(isna(if(K12=0,1,0)),0,IF(K12=0,1,0)) -> 0 | N12: Out | O12: =if(isna(G2),0,COUNTA(G$2:G$58)) -> 0
D13: =D12+1 -> 12 | I13: =IFERROR(__xludf.DUMMYFUNCTION("""COMPUTED_VALUE"""),"David Shin") -> David Shin | K13: =VLOOKUP(F13,Current!B:R,17,false) -> #N/A | L13: =if(isna(if(K13=0,1,0)),0,IF(K13=0,1,0)) -> 0 | N13: TBD | O13: =if(isna(I2),0,COUNTA(I$2:I$99)) -> 65
D14: =D13+1 -> 13 | I14: =IFERROR(__xludf.DUMMYFUNCTION("""COMPUTED_VALUE"""),"David Tam") -> David Tam | K14: =VLOOKUP(F14,Current!B:R,17,false) -> #N/A | L14: =if(isna(if(K14=0,1,0)),0,IF(K14=0,1,0)) -> 0 | N14: Total | O14: =sum(O9:O13) -> 65
D15: =D14+1 -> 14 | I15: =IFERROR(__xludf.DUMMYFUNCTION("""COMPUTED_VALUE"""),"Elayaraja Thangaraj ") -> Elayaraja Thangaraj | K15: =VLOOKUP(F15,Current!B:R,17,false) -> #N/A | L15: =if(isna(if(K15=0,1,0)),0,IF(K15=0,1,0)) -> 0
D16: =D15+1 -> 15 | I16: =IFERROR(__xludf.DUMMYFUNCTION("""COMPUTED_VALUE"""),"Eric Pan") -> Eric Pan | K16: =VLOOKUP(F16,Current!B:R,17,false) -> #N/A | L16: =if(isna(if(K16=0,1,0)),0,IF(K16=0,1,0)) -> 0
D17: =D16+1 -> 16 | I17: =IFERROR(__xludf.DUMMYFUNCTION("""COMPUTED_VALUE"""),"Eric Tan") -> Eric Tan | K17: =VLOOKUP(F17,Current!B:R,17,false) -> #N/A | L17: =if(isna(if(K17=0,1,0)),0,IF(K17=0,1,0)) -> 0 | N17: Playing | O17: =sum(O9:O11) -> 0 | P17: Check out-can play
D18: =D17+1 -> 17 | I18: =IFERROR(__xludf.DUMMYFUNCTION("""COMPUTED_VALUE"""),"Erik Hoeckmann") -> Erik Hoeckmann | K18: =VLOOKUP(F18,Current!B:R,17,false) -> #N/A | L18: =if(isna(if(K18=0,1,0)),0,IF(K18=0,1,0)) -> 0 | N18: Out | O18: =if(isna(G2),0,COUNTA(G$2:G$58)) -> 0
D19: =D18+1 -> 18 | I19: =IFERROR(__xludf.DUMMYFUNCTION("""COMPUTED_VALUE"""),"Jimmy Awolesi") -> Jimmy Awolesi | K19: =VLOOKUP(F19,Current!B:R,17,false) -> #N/A | L19: =if(isna(if(K19=0,1,0)),0,IF(K19=0,1,0)) -> 0 | N19: TBD | O19: =O13 -> 65
D20: =D19+1 -> 19 | I20: =IFERROR(__xludf.DUMMYFUNCTION("""COMPUTED_VALUE"""),"Joe Luzzi") -> Joe Luzzi | K20: =VLOOKUP(F20,Current!B:R,17,false) -> #N/A | L20: =if(isna(if(K20=0,1,0)),0,IF(K20=0,1,0)) -> 0 | N20: Total | O20: =sum(O17:O19) -> 65
D21: =D20+1 -> 20 | I21: =IFERROR(__xludf.DUMMYFUNCTION("""COMPUTED_VALUE"""),"Jonathan Phan") -> Jonathan Phan | K21: =VLOOKUP(F21,Current!B:R,17,false) -> #N/A | L21: =if(isna(if(K21=0,1,0)),0,IF(K21=0,1,0)) -> 0
D22: =D21+1 -> 21 | I22: =IFERROR(__xludf.DUMMYFUNCTION("""COMPUTED_VALUE"""),"Jose Ortiz") -> Jose Ortiz | K22: =VLOOKUP(F22,Current!B:R,17,false) -> #N/A | L22: =if(isna(if(K22=0,1,0)),0,IF(K22=0,1,0)) -> 0
D23: =D22+1 -> 22 | I23: =IFERROR(__xludf.DUMMYFUNCTION("""COMPUTED_VALUE"""),"Joyce Zhu") -> Joyce Zhu | K23: =VLOOKUP(F23,Current!B:R,17,false) -> #N/A | L23: =if(isna(if(K23=0,1,0)),0,IF(K23=0,1,0)) -> 0
D24: =D23+1 -> 23 | I24: =IFERROR(__xludf.DUMMYFUNCTION("""COMPUTED_VALUE"""),"Kingsley Kuo") -> Kingsley Kuo | K24: Total | L24: =sum(L2:L23) -> 0 | N24: Vacations
D25: =D24+1 -> 24 | I25: =IFERROR(__xludf.DUMMYFUNCTION("""COMPUTED_VALUE"""),"Kumar Palakeel") -> Kumar Palakeel | N25: Naveen Raj | O25: Until 7/18
D26: =D25+1 -> 25 | I26: =IFERROR(__xludf.DUMMYFUNCTION("""COMPUTED_VALUE"""),"Lam Bui") -> Lam Bui | N26: Trinath Goteti | O26: ?
D27: =D26+1 -> 26 | I27: =IFERROR(__xludf.DUMMYFUNCTION("""COMPUTED_VALUE"""),"Lloyd Sagar") -> Lloyd Sagar | N27: Pavan | O27: 45464
D28: =D27+1 -> 27 | I28: =IFERROR(__xludf.DUMMYFUNCTION("""COMPUTED_VALUE"""),"Luis Hsu") -> Luis Hsu
D29: =D28+1 -> 28 | I29: =IFERROR(__xludf.DUMMYFUNCTION("""COMPUTED_VALUE"""),"Manish Anand") -> Manish Anand
D30: =D29+1 -> 29 | I30: =IFERROR(__xludf.DUMMYFUNCTION("""COMPUTED_VALUE"""),"Manuel Rivera") -> Manuel Rivera | N30: Injured/Recovering
D31: =D30+1 -> 30 | I31: =IFERROR(__xludf.DUMMYFUNCTION("""COMPUTED_VALUE"""),"Marcus Yovas") -> Marcus Yovas | N31: Sai Dilip Ponnaganti
D32: =D31+1 -> 31 | I32: =IFERROR(__xludf.DUMMYFUNCTION("""COMPUTED_VALUE"""),"Matthew Huang") -> Matthew Huang
D33: =D32+1 -> 32 | I33: =IFERROR(__xludf.DUMMYFUNCTION("""COMPUTED_VALUE"""),"Mauricio Palacios") -> Mauricio Palacios
D34: =D33+1 -> 33 | I34: =IFERROR(__xludf.DUMMYFUNCTION("""COMPUTED_VALUE"""),"Naveen Raj") -> Naveen Raj
D35: =D34+1 -> 34 | I35: =IFERROR(__xludf.DUMMYFUNCTION("""COMPUTED_VALUE"""),"Nohely Mejia") -> Nohely Mejia
D36: =D35+1 -> 35 | I36: =IFERROR(__xludf.DUMMYFUNCTION("""COMPUTED_VALUE"""),"Oscar Bonilla") -> Oscar Bonilla
D37: =D36+1 -> 36 | I37: =IFERROR(__xludf.DUMMYFUNCTION("""COMPUTED_VALUE"""),"Pavan Akkimsetty") -> Pavan Akkimsetty
D38: =D37+1 -> 37 | I38: =IFERROR(__xludf.DUMMYFUNCTION("""COMPUTED_VALUE"""),"Peter Cheng") -> Peter Cheng
D39: =D38+1 -> 38 | I39: =IFERROR(__xludf.DUMMYFUNCTION("""COMPUTED_VALUE"""),"Peter Homsey") -> Peter Homsey
D40: =D39+1 -> 39 | I40: =IFERROR(__xludf.DUMMYFUNCTION("""COMPUTED_VALUE"""),"Pulkit Mathur") -> Pulkit Mathur
...

Sheet 062924
B1: Standings as of | C1: 45472
B2: Number of Weeks Played | D2: 0
C3: Beginning of week | E3: Current Week Scores | M3: End of week | P3: Jan-Jul 2024 | Q3: Jul-Dec 2024
A4: Ranking | B4: Name of Player | C4: Games Won | D4: Sets Won | E4: Check IN | F4: Court # | G4: Set 0 | H4: Set 1 | I4: Set 2 | J4: Set 3 | K4: Games Won | L4: Sets Won | M4: Games Won | N4: Sets Won | O4: Waiver | P4: Fee | Q4: Fee | R4: Sit outs | S4: No Shows | T4: Absent
A5: 1 | B5: Adrian Tay | C5: 300 | D5: 34 | E5: 3 | F5: 0 | G5: 9 | H5: 0 | I5: 0 | J5: 0 | K5: 9 | L5: 0 | M5: =C5+K5 -> 309 | N5: =D5+L5 -> 34 | O5: X | P5: X | Q5: X | R5: =if(G5=13,1,0)+VLOOKUP(B5,'062224'!B:T,17,false) -> 1 | T5: =if(G5=9,1,0)+VLOOKUP(B5,'062224'!B:T,19,false) -> 8
A6: =A5+1 -> 2 | B6: Peter Cheng | C6: 278 | D6: 27 | E6: 1 | F6: 1 | G6: 0 | H6: 7 | I6: 2 | J6: 6 | K6: 15 | L6: 2 | M6: =C6+K6 -> 293 | N6: =D6+L6 -> 29 | O6: X | P6: X | Q6: X | R6: =if(G6=13,1,0)+VLOOKUP(B6,'062224'!B:T,17,false) -> 2 | T6: =if(G6=9,1,0)+VLOOKUP(B6,'062224'!B:T,19,false) -> 7
A7: =A6+1 -> 3 | B7: Christopher Li | C7: 271 | D7: 27 | E7: 1 | F7: 1 | G7: 0 | H7: 5 | I7: 6 | J7: 6 | K7: 17 | L7: 2 | M7: =C7+K7 -> 288 | N7: =D7+L7 -> 29 | O7: X | P7: X | Q7: X | R7: =if(G7=13,1,0)+VLOOKUP(B7,'062224'!B:T,17,false) -> 0 | T7: =if(G7=9,1,0)+VLOOKUP(B7,'062224'!B:T,19,false) -> 10
A8: =A7+1 -> 4 | B8: Suleman Alidina | C8: 271 | D8: 30 | E8: 5 | F8: 0 | G8: 13 | H8: 0 | I8: 0 | J8: 0 | K8: 13 | L8: 0 | M8: =C8+K8 -> 284 | N8: =D8+L8 -> 30 | O8: X | P8: X | Q8: X | R8: =if(G8=13,1,0)+VLOOKUP(B8,'062224'!B:T,17,false) -> 1 | T8: =if(G8=9,1,0)+VLOOKUP(B8,'062224'!B:T,19,false) -> 4
A9: =A8+1 -> 5 | B9: Luis Hsu | C9: 259 | D9: 23 | E9: 2 | F9: 1 | G9: 0 | H9: 7 | I9: 6 | J9: 4 | K9: 17 | L9: 2 | M9: =C9+K9 -> 276 | N9: =D9+L9 -> 25 | O9: X | P9: X | Q9: X | R9: =if(G9=13,1,0)+VLOOKUP(B9,'062224'!B:T,17,false) -> 1 | T9: =if(G9=9,1,0)+VLOOKUP(B9,'062224'!B:T,19,false) -> 10
A10: =A9+1 -> 6 | B10: Peter Homsey | C10: 263 | D10: 23 | E10: 3 | F10: 0 | G10: 9 | H10: 0 | I10: 0 | J10: 0 | K10: 9 | L10: 0 | M10: =C10+K10 -> 272 | N10: =D10+L10 -> 23 | O10: X | P10: X | Q10: X | R10: =if(G10=13,1,0)+VLOOKUP(B10,'062224'!B:T,17,false) -> 0 | T10: =if(G10=9,1,0)+VLOOKUP(B10,'062224'!B:T,19,false) -> 8
A11: =A10+1 -> 7 | B11: Lam Bui | C11: 263 | D11: 18 | E11: 3 | F11: 0 | G11: 9 | H11: 0 | I11: 0 | J11: 0 | K11: 9 | L11: 0 | M11: =C11+K11 -> 272 | N11: =D11+L11 -> 18 | O11: X | P11: X | Q11: X | R11: =if(G11=13,1,0)+VLOOKUP(B11,'062224'!B:T,17,false) -> 2 | T11: =if(G11=9,1,0)+VLOOKUP(B11,'062224'!B:T,19,false) -> 12
A12: =A11+1 -> 8 | B12: David Shin | C12: 259 | D12: 23 | E12: 2 | F12: 1 | G12: 0 | H12: 5 | I12: 2 | J12: 4 | K12: 11 | L12: 0 | M12: =C12+K12 -> 270 | N12: =D12+L12 -> 23 | O12: X | P12: X | Q12: X | R12: =if(G12=13,1,0)+VLOOKUP(B12,'062224'!B:T,17,false) -> 2 | T12: =if(G12=9,1,0)+VLOOKUP(B12,'062224'!B:T,19,false) -> 4
A13: =A12+1 -> 9 | B13: Ted Shen | C13: 254 | D13: 20 | E13: 1 | F13: 2 | G13: 0 | H13: 6 | I13: 6 | J13: 4 | K13: 16 | L13: 2 | M13: =C13+K13 -> 270 | N13: =D13+L13 -> 22 | O13: X | P13: X | Q13: X | R13: =if(G13=13,1,0)+VLOOKUP(B13,'062224'!B:T,17,false) -> 2 | T13: =if(G13=9,1,0)+VLOOKUP(B13,'062224'!B:T,19,false) -> 2
A14: =A13+1 -> 10 | B14: Jonathan Phan | C14: 261 | D14: 22 | E14: 3 | F14: 0 | G14: 9 | H14: 0 | I14: 0 | J14: 0 | K14: 9 | L14: 0 | M14: =C14+K14 -> 270 | N14: =D14+L14 -> 22 | O14: X | P14: X | Q14: X | R14: =if(G14=13,1,0)+VLOOKUP(B14,'062224'!B:T,17,false) -> 1 | T14: =if(G14=9,1,0)+VLOOKUP(B14,'062224'!B:T,19,false) -> 5
A15: =A14+1 -> 11 | B15: Sean Chang | C15: 253 | D15: 15 | E15: 1 | F15: 2 | G15: 0 | H15: 4 | I15: 6 | J15: 6 | K15: 16 | L15: 0 | M15: =C15+K15 -> 269 | N15: =D15+L15 -> 15 | O15: X | P15: X | Q15: X | R15: =if(G15=13,1,0)+VLOOKUP(B15,'062224'!B:T,17,false) -> 2 | T15: =if(G15=9,1,0)+VLOOKUP(B15,'062224'!B:T,19,false) -> 6
A16: =A15+1 -> 12 | B16: Erik Hoeckmann | C16: 248 | D16: 24 | E16: 1 | F16: 2 | G16: 0 | H16: 6 | I16: 3 | J16: 6 | K16: 15 | L16: 2 | M16: =C16+K16 -> 263 | N16: =D16+L16 -> 26 | O16: X | P16: X | Q16: X | R16: =if(G16=13,1,0)+VLOOKUP(B16,'062224'!B:T,17,false) -> 0 | T16: =if(G16=9,1,0)+VLOOKUP(B16,'062224'!B:T,19,false) -> 6
A17: =A16+1 -> 13 | B17: Pavan Akkimsetty | C17: 252 | D17: 22 | E17: 1 | F17: 2 | G17: 0 | H17: 4 | I17: 3 | J17: 4 | K17: 11 | L17: 2 | M17: =C17+K17 -> 263 | N17: =D17+L17 -> 24 | O17: X | P17: X | Q17: X | R17: =if(G17=13,1,0)+VLOOKUP(B17,'062224'!B:T,17,false) -> 0 | T17: =if(G17=9,1,0)+VLOOKUP(B17,'062224'!B:T,19,false) -> 7
... A69: =A68+1 -> 65 | B69: Jose Ortiz | C69: 179 | D69: 2 | E69: 3 | F69: 0 | G69: 9 | H69: 0 | I69: 0 | J69: 0 | K69: 9 | L69: 0 | M69: =C69+K69 -> 188 | N69: =D69+L69 -> 2 | O69: X | P69: X | Q69: X | R69: =if(G69=13,1,0)+VLOOKUP(B69,'062224'!B:T,17,false) -> 0 | T69: =if(G69=9,1,0)+VLOOKUP(B69,'062224'!B:T,19,false) -> 20
B72: =COUNTA(B5:B69) -> 65 | O72: Paid | P72: =COUNTA(P5:P69) -> 65 | Q72: =COUNTA(Q5:Q69) -> 65
O73: To Pay | P73: =P74-P72 -> 0 | Q73: =Q74-Q72 -> 0
O74: Total | P74: =B72 -> 65 | Q74: =P74 -> 65
O77: Paid | Q77: =COUNTIF(Q5:Q69,"X") -> 52
B78: Top Scores | C78: Games | D78: Sets | O78: Not Renewing | Q78: =countif(Q5:Q69,"N") -> 13
B79: =IFERROR(__xludf.DUMMYFUNCTION("QUERY(B5:L69,""Select B, K, L where K >= 18 order by K desc, L desc"",0)"),"Elayaraja Thangaraj ") -> Elayaraja Thangaraj | C79: =IFERROR(__xludf.DUMMYFUNCTION("""COMPUTED_VALUE"""),20.0) -> 20 | D79: =IFERROR(__xludf.DUMMYFUNCTION("""COMPUTED_VALUE"""),3.0) -> 3 | O79: To Pay | Q79: =countif(Q5:Q69,"") -> 0
B80: =IFERROR(__xludf.DUMMYFUNCTION("""COMPUTED_VALUE"""),"Vishnu Amarnath") -> Vishnu Amarnath | C80: =IFERROR(__xludf.DUMMYFUNCTION("""COMPUTED_VALUE"""),18.0) -> 18 | D80: =IFERROR(__xludf.DUMMYFUNCTION("""COMPUTED_VALUE"""),3.0) -> 3 | O80: Total | Q80: =sum(Q77:Q79) -> 65
B90: Scores for this week
B91: Name of Player | C91: Games Won | D91: Sets Won | E91: Check IN | F91: Court # | G91: Set 0 | H91: Set 1 | I91: Set 2 | J91: Set 3 | K91: Games Won | L91: Sets Won | M91: Games Won | N91: Sets Won
B92: =IFERROR(__xludf.DUMMYFUNCTION("QUERY(B5:N69, ""Select B, C, D, E, F, G, H, I, J, K, L, M, N where F >= 1"")"),"Peter Cheng") -> Peter Cheng | C92: =IFERROR(__xludf.DUMMYFUNCTION("""COMPUTED_VALUE"""),278.0) -> 278 | D92: =IFERROR(__xludf.DUMMYFUNCTION("""COMPUTED_VALUE"""),27.0) -> 27 | E92: =IFERROR(__xludf.DUMMYFUNCTION("""COMPUTED_VALUE"""),1.0) -> 1 | F92: =IFERROR(__xludf.DUMMYFUNCTION("""COMPUTED_VALUE"""),1.0) -> 1 | G92: =IFERROR(__xludf.DUMMYFUNCTION("""COMPUTED_VALUE"""),0.0) -> 0 | H92: =IFERROR(__xludf.DUMMYFUNCTION("""COMPUTED_VALUE"""),7.0) -> 7 | I92: =IFERROR(__xludf.DUMMYFUNCTION("""COMPUTED_VALUE"""),2.0) -> 2 | J92: =IFERROR(__xludf.DUMMYFUNCTION("""COMPUTED_VALUE"""),6.0) -> 6 | K92: =IFERROR(__xludf.DUMMYFUNCTION("""COMPUTED_VALUE"""),15.0) -> 15 | L92: =IFERROR(__xludf.DUMMYFUNCTION("""COMPUTED_VALUE"""),2.0) -> 2 | M92: =IFERROR(__xludf.DUMMYFUNCTION("""COMPUTED_VALUE"""),293.0) -> 293 | N92: =IFERROR(__xludf.DUMMYFUNCTION("""COMPUTED_VALUE"""),29.0) -> 29
B93: =IFERROR(__xludf.DUMMYFUNCTION("""COMPUTED_VALUE"""),"Christopher Li") -> Christopher Li | C93: =IFERROR(__xludf.DUMMYFUNCTION("""COMPUTED_VALUE"""),271.0) -> 271 | D93: =IFERROR(__xludf.DUMMYFUNCTION("""COMPUTED_VALUE"""),27.0) -> 27 | E93: =IFERROR(__xludf.DUMMYFUNCTION("""COMPUTED_VALUE"""),1.0) -> 1 | F93: =IFERROR(__xludf.DUMMYFUNCTION("""COMPUTED_VALUE"""),1.0) -> 1 | G93: =IFERROR(__xludf.DUMMYFUNCTION("""COMPUTED_VALUE"""),0.0) -> 0 | H93: =IFERROR(__xludf.DUMMYFUNCTION("""COMPUTED_VALUE"""),5.0) -> 5 | I93: =IFERROR(__xludf.DUMMYFUNCTION("""COMPUTED_VALUE"""),6.0) -> 6 | J93: =IFERROR(__xludf.DUMMYFUNCTION("""COMPUTED_VALUE"""),6.0) -> 6 | K93: =IFERROR(__xludf.DUMMYFUNCTION("""COMPUTED_VALUE"""),17.0) -> 17 | L93: =IFERROR(__xludf.DUMMYFUNCTION("""COMPUTED_VALUE"""),2.0) -> 2 | M93: =IFERROR(__xludf.DUMMYFUNCTION("""COMPUTED_VALUE"""),288.0) -> 288 | N93: =IFERROR(__xludf.DUMMYFUNCTION("""COMPUTED_VALUE"""),29.0) -> 29
B94: =IFERROR(__xludf.DUMMYFUNCTION("""COMPUTED_VALUE"""),"Luis Hsu") -> Luis Hsu | C94: =IFERROR(__xludf.DUMMYFUNCTION("""COMPUTED_VALUE"""),259.0) -> 259 | D94: =IFERROR(__xludf.DUMMYFUNCTION("""COMPUTED_VALUE"""),23.0) -> 23 | E94: =IFERROR(__xludf.DUMMYFUNCTION("""COMPUTED_VALUE"""),2.0) -> 2 | F94: =IFERROR(__xludf.DUMMYFUNCTION("""COMPUTED_VALUE"""),1.0) -> 1 | G94: =IFERROR(__xludf.DUMMYFUNCTION("""COMPUTED_VALUE"""),0.0) -> 0 | H94: =IFERROR(__xludf.DUMMYFUNCTION("""COMPUTED_VALUE"""),7.0) -> 7 | I94: =IFERROR(__xludf.DUMMYFUNCTION("""COMPUTED_VALUE"""),6.0) -> 6 | J94: =IFERROR(__xludf.DUMMYFUNCTION("""COMPUTED_VALUE"""),4.0) -> 4 | K94: =IFERROR(__xludf.DUMMYFUNCTION("""COMPUTED_VALUE"""),17.0) -> 17 | L94: =IFERROR(__xludf.DUMMYFUNCTION("""COMPUTED_VALUE"""),2.0) -> 2 | M94: =IFERROR(__xludf.DUMMYFUNCTION("""COMPUTED_VALUE"""),276.0) -> 276 | N94: =IFERROR(__xludf.DUMMYFUNCTION("""COMPUTED_VALUE"""),25.0) -> 25
B95: =IFERROR(__xludf.DUMMYFUNCTION("""COMPUTED_VALUE"""),"David Shin") -> David Shin | C95: =IFERROR(__xludf.DUMMYFUNCTION("""COMPUTED_VALUE"""),259.0) -> 259 | D95: =IFERROR(__xludf.DUMMYFUNCTION("""COMPUTED_VALUE"""),23.0) -> 23 | E95: =IFERROR(__xludf.DUMMYFUNCTION("""COMPUTED_VALUE"""),2.0) -> 2 | F95: =IFERROR(__xludf.DUMMYFUNCTION("""COMPUTED_VALUE"""),1.0) -> 1 | G95: =IFERROR(__xludf.DUMMYFUNCTION("""COMPUTED_VALUE"""),0.0) -> 0 | H95: =IFERROR(__xludf.DUMMYFUNCTION("""COMPUTED_VALUE"""),5.0) -> 5 | I95: =IFERROR(__xludf.DUMMYFUNCTION("""COMPUTED_VALUE"""),2.0) -> 2 | J95: =IFERROR(__xludf.DUMMYFUNCTION("""COMPUTED_VALUE"""),4.0) -> 4 | K95: =IFERROR(__xludf.DUMMYFUNCTION("""COMPUTED_VALUE"""),11.0) -> 11 | L95: =IFERROR(__xludf.DUMMYFUNCTION("""COMPUTED_VALUE"""),0.0) -> 0 | M95: =IFERROR(__xludf.DUMMYFUNCTION("""COMPUTED_VALUE"""),270.0) -> 270 | N95: =IFERROR(__xludf.DUMMYFUNCTION("""COMPUTED_VALUE"""),23.0) -> 23
B96: =IFERROR(__xludf.DUMMYFUNCTION("""COMPUTED_VALUE"""),"Ted Shen") -> Ted Shen | C96: =IFERROR(__xludf.DUMMYFUNCTION("""COMPUTED_VALUE"""),254.0) -> 254 | D96: =IFERROR(__xludf.DUMMYFUNCTION("""COMPUTED_VALUE"""),20.0) -> 20 | E96: =IFERROR(__xludf.DUMMYFUNCTION("""COMPUTED_VALUE"""),1.0) -> 1 | F96: =IFERROR(__xludf.DUMMYFUNCTION("""COMPUTED_VALUE"""),2.0) -> 2 | G96: =IFERROR(__xludf.DUMMYFUNCTION("""COMPUTED_VALUE"""),0.0) -> 0 | H96: =IFERROR(__xludf.DUMMYFUNCTION("""COMPUTED_VALUE"""),6.0) -> 6 | I96: =IFERROR(__xludf.DUMMYFUNCTION("""COMPUTED_VALUE"""),6.0) -> 6 | J96: =IFERROR(__xludf.DUMMYFUNCTION("""COMPUTED_VALUE"""),4.0) -> 4 | K96: =IFERROR(__xludf.DUMMYFUNCTION("""COMPUTED_VALUE"""),16.0) -> 16 | L96: =IFERROR(__xludf.DUMMYFUNCTION("""COMPUTED_VALUE"""),2.0) -> 2 | M96: =IFERROR(__xludf.DUMMYFUNCTION("""COMPUTED_VALUE"""),270.0) -> 270 | N96: =IFERROR(__xludf.DUMMYFUNCTION("""COMPUTED_VALUE"""),22.0) -> 22
B97: =IFERROR(__xludf.DUMMYFUNCTION("""COMPUTED_VALUE"""),"Sean Chang") -> Sean Chang | C97: =IFERROR(__xludf.DUMMYFUNCTION("""COMPUTED_VALUE"""),253.0) -> 253 | D97: =IFERROR(__xludf.DUMMYFUNCTION("""COMPUTED_VALUE"""),15.0) -> 15 | E97: =IFERROR(__xludf.DUMMYFUNCTION("""COMPUTED_VALUE"""),1.0) -> 1 | F97: =IFERROR(__xludf.DUMMYFUNCTION("""COMPUTED_VALUE"""),2.0) -> 2 | G97: =IFERROR(__xludf.DUMMYFUNCTION("""COMPUTED_VALUE"""),0.0) -> 0 | H97: =IFERROR(__xludf.DUMMYFUNCTION("""COMPUTED_VALUE"""),4.0) -> 4 | I97: =IFERROR(__xludf.DUMMYFUNCTION("""COMPUTED_VALUE"""),6.0) -> 6 | J97: =IFERROR(__xludf.DUMMYFUNCTION("""COMPUTED_VALUE"""),6.0) -> 6 | K97: =IFERROR(__xludf.DUMMYFUNCTION("""COMPUTED_VALUE"""),16.0) -> 16 | L97: =IFERROR(__xludf.DUMMYFUNCTION("""COMPUTED_VALUE"""),0.0) -> 0 | M97: =IFERROR(__xludf.DUMMYFUNCTION("""COMPUTED_VALUE"""),269.0) -> 269 | N97: =IFERROR(__xludf.DUMMYFUNCTION("""COMPUTED_VALUE"""),15.0) -> 15
B98: =IFERROR(__xludf.DUMMYFUNCTION("""COMPUTED_VALUE"""),"Erik Hoeckmann") -> Erik Hoeckmann | C98: =IFERROR(__xludf.DUMMYFUNCTION("""COMPUTED_VALUE"""),248.0) -> 248 | D98: =IFERROR(__xludf.DUMMYFUNCTION("""COMPUTED_VALUE"""),24.0) -> 24 | E98: =IFERROR(__xludf.DUMMYFUNCTION("""COMPUTED_VALUE"""),1.0) -> 1 | F98: =IFERROR(__xludf.DUMMYFUNCTION("""COMPUTED_VALUE"""),2.0) -> 2 | G98: =IFERROR(__xludf.DUMMYFUNCTION("""COMPUTED_VALUE"""),0.0) -> 0 | H98: =IFERROR(__xludf.DUMMYFUNCTION("""COMPUTED_VALUE"""),6.0) -> 6 | I98: =IFERROR(__xludf.DUMMYFUNCTION("""COMPUTED_VALUE"""),3.0) -> 3 | J98: =IFERROR(__xludf.DUMMYFUNCTION("""COMPUTED_VALUE"""),6.0) -> 6 | K98: =IFERROR(__xludf.DUMMYFUNCTION("""COMPUTED_VALUE"""),15.0) -> 15 | L98: =IFERROR(__xludf.DUMMYFUNCTION("""COMPUTED_VALUE"""),2.0) -> 2 | M98: =IFERROR(__xludf.DUMMYFUNCTION("""COMPUTED_VALUE"""),263.0) -> 263 | N98: =IFERROR(__xludf.DUMMYFUNCTION("""COMPUTED_VALUE"""),26.0) -> 26
B99: =IFERROR(__xludf.DUMMYFUNCTION("""COMPUTED_VALUE"""),"Pavan Akkimsetty") -> Pavan Akkimsetty | C99: =IFERROR(__xludf.DUMMYFUNCTION("""COMPUTED_VALUE"""),252.0) -> 252 | D99: =IFERROR(__xludf.DUMMYFUNCTION("""COMPUTED_VALUE"""),22.0) -> 22 | E99: =IFERROR(__xludf.DUMMYFUNCTION("""COMPUTED_VALUE"""),1.0) -> 1 | F99: =IFERROR(__xludf.DUMMYFUNCTION("""COMPUTED_VALUE"""),2.0) -> 2 | G99: =IFERROR(__xludf.DUMMYFUNCTION("""COMPUTED_VALUE"""),0.0) -> 0 | H99: =IFERROR(__xludf.DUMMYFUNCTION("""COMPUTED_VALUE"""),4.0) -> 4 | I99: =IFERROR(__xludf.DUMMYFUNCTION("""COMPUTED_VALUE"""),3.0) -> 3 | J99: =IFERROR(__xludf.DUMMYFUNCTION("""COMPUTED_VALUE"""),4.0) -> 4 | K99: =IFERROR(__xludf.DUMMYFUNCTION("""COMPUTED_VALUE"""),11.0) -> 11 | L99: =IFERROR(__xludf.DUMMYFUNCTION("""COMPUTED_VALUE"""),2.0) -> 2 | M99: =IFERROR(__xludf.DUMMYFUNCTION("""COMPUTED_VALUE"""),263.0) -> 263 | N99: =IFERROR(__xludf.DUMMYFUNCTION("""COMPUTED_VALUE"""),24.0) -> 24
B100: =IFERROR(__xludf.DUMMYFUNCTION("""COMPUTED_VALUE"""),"Chinna Ponnaganti") -> Chinna Ponnaganti | C100: =IFERROR(__xludf.DUMMYFUNCTION("""COMPUTED_VALUE"""),243.0) -> 243 | D100: =IFERROR(__xludf.DUMMYFUNCTION("""COMPUTED_VALUE"""),21.0) -> 21 | E100: =IFERROR(__xludf.DUMMYFUNCTION("""COMPUTED_VALUE"""),2.0) -> 2 | F100: =IFERROR(__xludf.DUMMYFUNCTION("""COMPUTED_VALUE"""),3.0) -> 3 | G100: =IFERROR(__xludf.DUMMYFUNCTION("""COMPUTED_VALUE"""),0.0) -> 0 | H100: =IFERROR(__xludf.DUMMYFUNCTION("""COMPUTED_VALUE"""),6.0) -> 6 | I100: =IFERROR(__xludf.DUMMYFUNCTION("""COMPUTED_VALUE"""),4.0) -> 4 | J100: =IFERROR(__xludf.DUMMYFUNCTION("""COMPUTED_VALUE"""),6.0) -> 6 | K100: =IFERROR(__xludf.DUMMYFUNCTION("""COMPUTED_VALUE"""),16.0) -> 16 | L100: =IFERROR(__xludf.DUMMYFUNCTION("""COMPUTED_VALUE"""),2.0) -> 2 | M100: =IFERROR(__xludf.DUMMYFUNCTION("""COMPUTED_VALUE"""),259.0) -> 259 | N100: =IFERROR(__xludf.DUMMYFUNCTION("""COMPUTED_VALUE"""),23.0) -> 23
B101: =IFERROR(__xludf.DUMMYFUNCTION("""COMPUTED_VALUE"""),"Tom Le") -> Tom Le | C101: =IFERROR(__xludf.DUMMYFUNCTION("""COMPUTED_VALUE"""),246.0) -> 246 | D101: =IFERROR(__xludf.DUMMYFUNCTION("""COMPUTED_VALUE"""),19.0) -> 19 | E101: =IFERROR(__xludf.DUMMYFUNCTION("""COMPUTED_VALUE"""),1.0) -> 1 | F101: =IFERROR(__xludf.DUMMYFUNCTION("""COMPUTED_VALUE"""),3.0) -> 3 | G101: =IFERROR(__xludf.DUMMYFUNCTION("""COMPUTED_VALUE"""),0.0) -> 0 | H101: =IFERROR(__xludf.DUMMYFUNCTION("""COMPUTED_VALUE"""),3.0) -> 3 | I101: =IFERROR(__xludf.DUMMYFUNCTION("""COMPUTED_VALUE"""),4.0) -> 4 | J101: =IFERROR(__xludf.DUMMYFUNCTION("""COMPUTED_VALUE"""),2.0) -> 2 | K101: =IFERROR(__xludf.DUMMYFUNCTION("""COMPUTED_VALUE"""),9.0) -> 9 | L101: =IFERROR(__xludf.DUMMYFUNCTION("""COMPUTED_VALUE"""),0.0) -> 0 | M101: =IFERROR(__xludf.DUMMYFUNCTION("""COMPUTED_VALUE"""),255.0) -> 255 | N101: =IFERROR(__xludf.DUMMYFUNCTION("""COMPUTED_VALUE"""),19.0) -> 19
B102: =IFERROR(__xludf.DUMMYFUNCTION("""COMPUTED_VALUE"""),"Oscar Bonilla") -> Oscar Bonilla | C102: =IFERROR(__xludf.DUMMYFUNCTION("""COMPUTED_VALUE"""),240.0) -> 240 | D102: =IFERROR(__xludf.DUMMYFUNCTION("""COMPUTED_VALUE"""),15.0) -> 15 | E102: =IFERROR(__xludf.DUMMYFUNCTION("""COMPUTED_VALUE"""),1.0) -> 1 | F102: =IFERROR(__xludf.DUMMYFUNCTION("""COMPUTED_VALUE"""),3.0) -> 3 | G102: =IFERROR(__xludf.DUMMYFUNCTION("""COMPUTED_VALUE"""),0.0) -> 0 | H102: =IFERROR(__xludf.DUMMYFUNCTION("""COMPUTED_VALUE"""),3.0) -> 3 | I102: =IFERROR(__xludf.DUMMYFUNCTION("""COMPUTED_VALUE"""),6.0) -> 6 | J102: =IFERROR(__xludf.DUMMYFUNCTION("""COMPUTED_VALUE"""),6.0) -> 6 | K102: =IFERROR(__xludf.DUMMYFUNCTION("""COMPUTED_VALUE"""),15.0) -> 15 | L102: =IFERROR(__xludf.DUMMYFUNCTION("""COMPUTED_VALUE"""),2.0) -> 2 | M102: =IFERROR(__xludf.DUMMYFUNCTION("""COMPUTED_VALUE"""),255.0) -> 255 | N102: =IFERROR(__xludf.DUMMYFUNCTION("""COMPUTED_VALUE"""),17.0) -> 17
B103: =IFERROR(__xludf.DUMMYFUNCTION("""COMPUTED_VALUE"""),"Mauricio Palacios") -> Mauricio Palacios | C103: =IFERROR(__xludf.DUMMYFUNCTION("""COMPUTED_VALUE"""),239.0) -> 239 | D103: =IFERROR(__xludf.DUMMYFUNCTION("""COMPUTED_VALUE"""),16.0) -> 16 | E103: =IFERROR(__xludf.DUMMYFUNCTION("""COMPUTED_VALUE"""),2.0) -> 2 | F103: =IFERROR(__xludf.DUMMYFUNCTION("""COMPUTED_VALUE"""),3.0) -> 3 | G103: =IFERROR(__xludf.DUMMYFUNCTION("""COMPUTED_VALUE"""),0.0) -> 0 | H103: =IFERROR(__xludf.DUMMYFUNCTION("""COMPUTED_VALUE"""),6.0) -> 6 | I103: =IFERROR(__xludf.DUMMYFUNCTION("""COMPUTED_VALUE"""),6.0) -> 6 | J103: =IFERROR(__xludf.DUMMYFUNCTION("""COMPUTED_VALUE"""),2.0) -> 2 | K103: =IFERROR(__xludf.DUMMYFUNCTION("""COMPUTED_VALUE"""),14.0) -> 14 | L103: =IFERROR(__xludf.DUMMYFUNCTION("""COMPUTED_VALUE"""),2.0) -> 2 | M103: =IFERROR(__xludf.DUMMYFUNCTION("""COMPUTED_VALUE"""),253.0) -> 253 | N103: =IFERROR(__xludf.DUMMYFUNCTION("""COMPUTED_VALUE"""),18.0) -> 18
B104: =IFERROR(__xludf.DUMMYFUNCTION("""COMPUTED_VALUE"""),"Vishnu Amarnath") -> Vishnu Amarnath | C104: =IFERROR(__xludf.DUMMYFUNCTION("""COMPUTED_VALUE"""),234.0) -> 234 | D104: =IFERROR(__xludf.DUMMYFUNCTION("""COMPUTED_VALUE"""),20.0) -> 20 | E104: =IFERROR(__xludf.DUMMYFUNCTION("""COMPUTED_VALUE"""),1.0) -> 1 | F104: =IFERROR(__xludf.DUMMYFUNCTION("""COMPUTED_VALUE"""),5.0) -> 5 | G104: =IFERROR(__xludf.DUMMYFUNCTION("""COMPUTED_VALUE"""),0.0) -> 0 | H104: =IFERROR(__xludf.DUMMYFUNCTION("""COMPUTED_VALUE"""),6.0) -> 6 | I104: =IFERROR(__xludf.DUMMYFUNCTION("""COMPUTED_VALUE"""),6.0) -> 6 | J104: =IFERROR(__xludf.DUMMYFUNCTION("""COMPUTED_VALUE"""),6.0) -> 6 | K104: =IFERROR(__xludf.DUMMYFUNCTION("""COMPUTED_VALUE"""),18.0) -> 18 | L104: =IFERROR(__xludf.DUMMYFUNCTION("""COMPUTED_VALUE"""),3.0) -> 3 | M104: =IFERROR(__xludf.DUMMYFUNCTION("""COMPUTED_VALUE"""),252.0) -> 252 | N104: =IFERROR(__xludf.DUMMYFUNCTION("""COMPUTED_VALUE"""),23.0) -> 23
...

Sheet 062224
B1: Standings as of | C1: 45465
B2: Number of Weeks Played | D2: 21
C3: Beginning of week | E3: Current Week Scores | M3: End of week | P3: Jan-Jul 2024 | Q3: Jul-Dec 2024
A4: Ranking | B4: Name of Player | C4: Games Won | D4: Sets Won | E4: Check IN | F4: Court # | G4: Set 0 | H4: Set 1 | I4: Set 2 | J4: Set 3 | K4: Games Won | L4: Sets Won | M4: Games Won | N4: Sets Won | O4: Waiver | P4: Fee | Q4: Fee | R4: Sit outs | S4: No Shows | T4: Absent
A5: 1 | B5: Adrian Tay | C5: 281 | D5: 31 | E5: 1 | F5: 1 | G5: 0 | H5: 6 | I5: 6 | J5: 7 | K5: 19 | L5: 3 | M5: =C5+K5 -> 300 | N5: =D5+L5 -> 34 | O5: X | P5: X | R5: =if(G5=13,1,0)+VLOOKUP(B5,'061524'!B:T,17,false) -> 1 | T5: =if(G5=9,1,0)+VLOOKUP(B5,'061524'!B:T,19,false) -> 7
A6: =A5+1 -> 2 | B6: Peter Cheng | C6: 269 | D6: 27 | E6: 3 | F6: 0 | G6: 9 | H6: 0 | I6: 0 | J6: 0 | K6: 9 | L6: 0 | M6: =C6+K6 -> 278 | N6: =D6+L6 -> 27 | O6: X | P6: X | Q6: X | R6: =if(G6=13,1,0)+VLOOKUP(B6,'061524'!B:T,17,false) -> 2 | T6: =if(G6=9,1,0)+VLOOKUP(B6,'061524'!B:T,19,false) -> 7
