Workbook

Sheet Current
B1: Standings as of | C1: 46004
B2: Number of Weeks Played | D2: 24 | AC2: =text(C1,"mm/dd/yy") -> 12/13/25
C3: Beginning of week | F3: Current Week Scores | N3: End of week | Q3: Jul-Dec 2025 | R3: Jan-Jun 2026
A4: Ranking | B4: Name of Player | C4: Games Won | D4: Sets Won | E4: Games Won / Match | F4: Check IN | G4: Court # | H4: Set 0 | I4: Set 1 | J4: Set 2 | K4: Set 3 | L4: Games Won | M4: Sets Won | N4: Games Won | O4: Sets Won | P4: Waiver | Q4: Fee | R4: Fee | S4: Games Played | T4: Sit outs | U4: No Shows | V4: Absent | W4: Positions Gained/Lost | X4: Ranking | Y4: Perfect attendence | Z4: Check
A5: 1 | B5: Adrian Tay | C5: 326 | D5: 38 | E5: =if(S5>0,(C5-(V5*9)-(T5*13))/S5,0) -> 15.470588 | F5: =if(isna(VLOOKUP(B5,Checkin!A:B,2,false)),0,VLOOKUP(B5,Checkin!A:B,2,false)) -> 3 | G5: =if(OR($F5=1, $F5=2),VLOOKUP($B5,Courts!$B$2:$K$50,10,false),0) -> 0 | H5: =IF(OR(F5=3,F5=4),9,IF(F5=5,13,0)) -> 9 | I5: =if(OR($F5=1, $F5=2),VLOOKUP($B5,Courts!$B$2:$J$50,5,false),0) -> 0 | J5: =if(OR($F5=1, $F5=2),VLOOKUP($B5,Courts!$B$2:$J$50,6,false),0) -> 0 | K5: =if(OR($F5=1, $F5=2),VLOOKUP($B5,Courts!$B$2:$J$50,7,false),0) -> 0 | L5: =H5+I5+J5+K5 -> 9 | M5: =if(OR($F5=1, $F5=2),VLOOKUP($B5,Courts!$B$2:$J$50,9,false),0) -> 0 | N5: =C5+L5 -> 335 | O5: =D5+M5 -> 38 | P5: X | Q5: X | R5: X | S5: =vlookup(B5,indirect("'" & AC$2 & "'!B5:W69"),18,false)++if(text(C$1,"mm/dd/yy")=$AC$2,0,if(H5>0,0,1)) -> 17 | T5: =if(H5=13,1,0)+vlookup(B5,indirect("'" & AC$2 & "'!B5:W69"),19,false) -> 0 | V5: =vlookup(B5,indirect("'" & AC$2 & "'!B5:W69"),21,false)+if(text(C$1,"mm/dd/yy")=$AC$2,0,if(H5=9,1,0)) -> 7 | W5: =vlookup(B5,indirect("'" & AC$2 & "'!B5:x69"),23,false)-X5 -> 0 | X5: 1 | Y5: =if(S5=D$2,"Y","N") -> N | Z5: =if($D$2=sum(S5:V5),"","Error")
A6: =A5+1 -> 2 | B6: Darren Wong | C6: 323 | D6: 36 | E6: =if(S6>0,(C6-(V6*9)-(T6*13))/S6,0) -> 15.058824 | F6: =if(isna(VLOOKUP(B6,Checkin!A:B,2,false)),0,VLOOKUP(B6,Checkin!A:B,2,false)) -> 3 | G6: =if(OR($F6=1, $F6=2),VLOOKUP($B6,Courts!$B$2:$K$50,10,false),0) -> 0 | H6: =IF(OR(F6=3,F6=4),9,IF(F6=5,13,0)) -> 9 | I6: =if(OR($F6=1, $F6=2),VLOOKUP($B6,Courts!$B$2:$J$50,5,false),0) -> 0 | J6: =if(OR($F6=1, $F6=2),VLOOKUP($B6,Courts!$B$2:$J$50,6,false),0) -> 0 | K6: =if(OR($F6=1, $F6=2),VLOOKUP($B6,Courts!$B$2:$J$50,7,false),0) -> 0 | L6: =H6+I6+J6+K6 -> 9 | M6: =if(OR($F6=1, $F6=2),VLOOKUP($B6,Courts!$B$2:$J$50,9,false),0) -> 0 | N6: =C6+L6 -> 332 | O6: =D6+M6 -> 36 | P6: X | Q6: X | R6: X | S6: =vlookup(B6,indirect("'" & AC$2 & "'!B5:W69"),18,false)++if(text(C$1,"mm/dd/yy")=$AC$2,0,if(H6>0,0,1)) -> 17 | T6: =if(H6=13,1,0)+vlookup(B6,indirect("'" & AC$2 & "'!B5:W69"),19,false) -> 1 | V6: =vlookup(B6,indirect("'" & AC$2 & "'!B5:W69"),21,false)+if(text(C$1,"mm/dd/yy")=$AC$2,0,if(H6=9,1,0)) -> 6 | W6: =vlookup(B6,indirect("'" & AC$2 & "'!B5:x69"),23,false)-X6 -> 0 | X6: =X5+1 -> 2 | Y6: =if(S6=D$2,"Y","N") -> N | Z6: =if($D$2=sum(S6:V6),"","Error")
A7: =A6+1 -> 3 | B7: Lam Bui | C7: 322 | D7: 33 | E7: =if(S7>0,(C7-(V7*9)-(T7*13))/S7,0) -> 14.3 | F7: =if(isna(VLOOKUP(B7,Checkin!A:B,2,false)),0,VLOOKUP(B7,Checkin!A:B,2,false)) -> 3 | G7: =if(OR($F7=1, $F7=2),VLOOKUP($B7,Courts!$B$2:$K$50,10,false),0) -> 0 | H7: =IF(OR(F7=3,F7=4),9,IF(F7=5,13,0)) -> 9 | I7: =if(OR($F7=1, $F7=2),VLOOKUP($B7,Courts!$B$2:$J$50,5,false),0) -> 0 | J7: =if(OR($F7=1, $F7=2),VLOOKUP($B7,Courts!$B$2:$J$50,6,false),0) -> 0 | K7: =if(OR($F7=1, $F7=2),VLOOKUP($B7,Courts!$B$2:$J$50,7,false),0) -> 0 | L7: =H7+I7+J7+K7 -> 9 | M7: =if(OR($F7=1, $F7=2),VLOOKUP($B7,Courts!$B$2:$J$50,9,false),0) -> 0 | N7: =C7+L7 -> 331 | O7: =D7+M7 -> 33 | P7: X | Q7: X | R7: X | S7: =vlookup(B7,indirect("'" & AC$2 & "'!B5:W69"),18,false)++if(text(C$1,"mm/dd/yy")=$AC$2,0,if(H7>0,0,1)) -> 20 | T7: =if(H7=13,1,0)+vlookup(B7,indirect("'" & AC$2 & "'!B5:W69"),19,false) -> 0 | V7: =vlookup(B7,indirect("'" & AC$2 & "'!B5:W69"),21,false)+if(text(C$1,"mm/dd/yy")=$AC$2,0,if(H7=9,1,0)) -> 4 | W7: =vlookup(B7,indirect("'" & AC$2 & "'!B5:x69"),23,false)-X7 -> 0 | X7: =X6+1 -> 3 | Y7: =if(S7=D$2,"Y","N") -> N | Z7: =if($D$2=sum(S7:V7),"","Error")
A8: =A7+1 -> 4 | B8: Eric Pan | C8: 315 | D8: 32 | E8: =if(S8>0,(C8-(V8*9)-(T8*13))/S8,0) -> 15.785714 | F8: =if(isna(VLOOKUP(B8,Checkin!A:B,2,false)),0,VLOOKUP(B8,Checkin!A:B,2,false)) -> 3 | G8: =if(OR($F8=1, $F8=2),VLOOKUP($B8,Courts!$B$2:$K$50,10,false),0) -> 0 | H8: =IF(OR(F8=3,F8=4),9,IF(F8=5,13,0)) -> 9 | I8: =if(OR($F8=1, $F8=2),VLOOKUP($B8,Courts!$B$2:$J$50,5,false),0) -> 0 | J8: =if(OR($F8=1, $F8=2),VLOOKUP($B8,Courts!$B$2:$J$50,6,false),0) -> 0 | K8: =if(OR($F8=1, $F8=2),VLOOKUP($B8,Courts!$B$2:$J$50,7,false),0) -> 0 | L8: =H8+I8+J8+K8 -> 9 | M8: =if(OR($F8=1, $F8=2),VLOOKUP($B8,Courts!$B$2:$J$50,9,false),0) -> 0 | N8: =C8+L8 -> 324 | O8: =D8+M8 -> 32 | P8: X | Q8: X | R8: X | S8: =vlookup(B8,indirect("'" & AC$2 & "'!B5:W69"),18,false)++if(text(C$1,"mm/dd/yy")=$AC$2,0,if(H8>0,0,1)) -> 14 | T8: =if(H8=13,1,0)+vlookup(B8,indirect("'" & AC$2 & "'!B5:W69"),19,false) -> 1 | V8: =vlookup(B8,indirect("'" & AC$2 & "'!B5:W69"),21,false)+if(text(C$1,"mm/dd/yy")=$AC$2,0,if(H8=9,1,0)) -> 9 | W8: =vlookup(B8,indirect("'" & AC$2 & "'!B5:x69"),23,false)-X8 -> 2 | X8: =X7+1 -> 4 | Y8: =if(S8=D$2,"Y","N") -> N | Z8: =if($D$2=sum(S8:V8),"","Error")
A9: =A8+1 -> 5 | B9: Pulkit Mathur | C9: 311 | D9: 31 | E9: =if(S9>0,(C9-(V9*9)-(T9*13))/S9,0) -> 14.277778 | F9: =if(isna(VLOOKUP(B9,Checkin!A:B,2,false)),0,VLOOKUP(B9,Checkin!A:B,2,false)) -> 1 | G9: =if(OR($F9=1, $F9=2),VLOOKUP($B9,Courts!$B$2:$K$50,10,false),0) -> 1 | H9: =IF(OR(F9=3,F9=4),9,IF(F9=5,13,0)) -> 0 | I9: =if(OR($F9=1, $F9=2),VLOOKUP($B9,Courts!$B$2:$J$50,5,false),0) -> 6 | J9: =if(OR($F9=1, $F9=2),VLOOKUP($B9,Courts!$B$2:$J$50,6,false),0) -> 6 | K9: =if(OR($F9=1, $F9=2),VLOOKUP($B9,Courts!$B$2:$J$50,7,false),0) -> 5 | L9: =H9+I9+J9+K9 -> 17 | M9: =if(OR($F9=1, $F9=2),VLOOKUP($B9,Courts!$B$2:$J$50,9,false),0) -> 1 | N9: =C9+L9 -> 328 | O9: =D9+M9 -> 32 | P9: X | Q9: X | R9: X | S9: =vlookup(B9,indirect("'" & AC$2 & "'!B5:W69"),18,false)++if(text(C$1,"mm/dd/yy")=$AC$2,0,if(H9>0,0,1)) -> 18 | T9: =if(H9=13,1,0)+vlookup(B9,indirect("'" & AC$2 & "'!B5:W69"),19,false) -> 0 | V9: =vlookup(B9,indirect("'" & AC$2 & "'!B5:W69"),21,false)+if(text(C$1,"mm/dd/yy")=$AC$2,0,if(H9=9,1,0)) -> 6 | W9: =vlookup(B9,indirect("'" & AC$2 & "'!B5:x69"),23,false)-X9 -> 0 | X9: =X8+1 -> 5 | Y9: =if(S9=D$2,"Y","N") -> N | Z9: =if($D$2=sum(S9:V9),"","Error")
A10: =A9+1 -> 6 | B10: Sandeep Kamalon | C10: 310 | D10: 36 | E10: =if(S10>0,(C10-(V10*9)-(T10*13))/S10,0) -> 13.090909 | F10: =if(isna(VLOOKUP(B10,Checkin!A:B,2,false)),0,VLOOKUP(B10,Checkin!A:B,2,false)) -> 3 | G10: =if(OR($F10=1, $F10=2),VLOOKUP($B10,Courts!$B$2:$K$50,10,false),0) -> 0 | H10: =IF(OR(F10=3,F10=4),9,IF(F10=5,13,0)) -> 9 | I10: =if(OR($F10=1, $F10=2),VLOOKUP($B10,Courts!$B$2:$J$50,5,false),0) -> 0 | J10: =if(OR($F10=1, $F10=2),VLOOKUP($B10,Courts!$B$2:$J$50,6,false),0) -> 0 | K10: =if(OR($F10=1, $F10=2),VLOOKUP($B10,Courts!$B$2:$J$50,7,false),0) -> 0 | L10: =H10+I10+J10+K10 -> 9 | M10: =if(OR($F10=1, $F10=2),VLOOKUP($B10,Courts!$B$2:$J$50,9,false),0) -> 0 | N10: =C10+L10 -> 319 | O10: =D10+M10 -> 36 | P10: X | Q10: X | R10: X | S10: =vlookup(B10,indirect("'" & AC$2 & "'!B5:W69"),18,false)++if(text(C$1,"mm/dd/yy")=$AC$2,0,if(H10>0,0,1)) -> 22 | T10: =if(H10=13,1,0)+vlookup(B10,indirect("'" & AC$2 & "'!B5:W69"),19,false) -> 1 | V10: =vlookup(B10,indirect("'" & AC$2 & "'!B5:W69"),21,false)+if(text(C$1,"mm/dd/yy")=$AC$2,0,if(H10=9,1,0)) -> 1 | W10: =vlookup(B10,indirect("'" & AC$2 & "'!B5:x69"),23,false)-X10 -> -2 | X10: =X9+1 -> 6 | Y10: =if(S10=D$2,"Y","N") -> N | Z10: =if($D$2=sum(S10:V10),"","Error")
A11: =A10+1 -> 7 | B11: David Shin | C11: 303 | D11: 27 | E11: =if(S11>0,(C11-(V11*9)-(T11*13))/S11,0) -> 13.142857 | F11: =if(isna(VLOOKUP(B11,Checkin!A:B,2,false)),0,VLOOKUP(B11,Checkin!A:B,2,false)) -> 1 | G11: =if(OR($F11=1, $F11=2),VLOOKUP($B11,Courts!$B$2:$K$50,10,false),0) -> 1 | H11: =IF(OR(F11=3,F11=4),9,IF(F11=5,13,0)) -> 0 | I11: =if(OR($F11=1, $F11=2),VLOOKUP($B11,Courts!$B$2:$J$50,5,false),0) -> 3 | J11: =if(OR($F11=1, $F11=2),VLOOKUP($B11,Courts!$B$2:$J$50,6,false),0) -> 6 | K11: =if(OR($F11=1, $F11=2),VLOOKUP($B11,Courts!$B$2:$J$50,7,false),0) -> 7 | L11: =H11+I11+J11+K11 -> 16 | M11: =if(OR($F11=1, $F11=2),VLOOKUP($B11,Courts!$B$2:$J$50,9,false),0) -> 1 | N11: =C11+L11 -> 319 | O11: =D11+M11 -> 28 | P11: X | Q11: X | R11: X | S11: =vlookup(B11,indirect("'" & AC$2 & "'!B5:W69"),18,false)++if(text(C$1,"mm/dd/yy")=$AC$2,0,if(H11>0,0,1)) -> 21 | T11: =if(H11=13,1,0)+vlookup(B11,indirect("'" & AC$2 & "'!B5:W69"),19,false) -> 0 | V11: =vlookup(B11,indirect("'" & AC$2 & "'!B5:W69"),21,false)+if(text(C$1,"mm/dd/yy")=$AC$2,0,if(H11=9,1,0)) -> 3 | W11: =vlookup(B11,indirect("'" & AC$2 & "'!B5:x69"),23,false)-X11 -> 2 | X11: =X10+1 -> 7 | Y11: =if(S11=D$2,"Y","N") -> N | Z11: =if($D$2=sum(S11:V11),"","Error")
A12: =A11+1 -> 8 | B12: Ethan Gu | C12: 301 | D12: 31 | E12: =if(S12>0,(C12-(V12*9)-(T12*13))/S12,0) -> 13.047619 | F12: =if(isna(VLOOKUP(B12,Checkin!A:B,2,false)),0,VLOOKUP(B12,Checkin!A:B,2,false)) -> 1 | G12: =if(OR($F12=1, $F12=2),VLOOKUP($B12,Courts!$B$2:$K$50,10,false),0) -> 1 | H12: =IF(OR(F12=3,F12=4),9,IF(F12=5,13,0)) -> 0 | I12: =if(OR($F12=1, $F12=2),VLOOKUP($B12,Courts!$B$2:$J$50,5,false),0) -> 3 | J12: =if(OR($F12=1, $F12=2),VLOOKUP($B12,Courts!$B$2:$J$50,6,false),0) -> 7 | K12: =if(OR($F12=1, $F12=2),VLOOKUP($B12,Courts!$B$2:$J$50,7,false),0) -> 5 | L12: =H12+I12+J12+K12 -> 15 | M12: =if(OR($F12=1, $F12=2),VLOOKUP($B12,Courts!$B$2:$J$50,9,false),0) -> 1 | N12: =C12+L12 -> 316 | O12: =D12+M12 -> 32 | P12: X | Q12: X | R12: X | S12: =vlookup(B12,indirect("'" & AC$2 & "'!B5:W69"),18,false)++if(text(C$1,"mm/dd/yy")=$AC$2,0,if(H12>0,0,1)) -> 21 | T12: =if(H12=13,1,0)+vlookup(B12,indirect("'" & AC$2 & "'!B5:W69"),19,false) -> 0 | V12: =vlookup(B12,indirect("'" & AC$2 & "'!B5:W69"),21,false)+if(text(C$1,"mm/dd/yy")=$AC$2,0,if(H12=9,1,0)) -> 3 | W12: =vlookup(B12,indirect("'" & AC$2 & "'!B5:x69"),23,false)-X12 -> -1 | X12: =X11+1 -> 8 | Y12: =if(S12=D$2,"Y","N") -> N | Z12: =if($D$2=sum(S12:V12),"","Error")
A13: =A12+1 -> 9 | B13: Rajasekar Ramasamy | C13: 301 | D13: 31 | E13: =if(S13>0,(C13-(V13*9)-(T13*13))/S13,0) -> 12.681818 | F13: =if(isna(VLOOKUP(B13,Checkin!A:B,2,false)),0,VLOOKUP(B13,Checkin!A:B,2,false)) -> 3 | G13: =if(OR($F13=1, $F13=2),VLOOKUP($B13,Courts!$B$2:$K$50,10,false),0) -> 0 | H13: =IF(OR(F13=3,F13=4),9,IF(F13=5,13,0)) -> 9 | I13: =if(OR($F13=1, $F13=2),VLOOKUP($B13,Courts!$B$2:$J$50,5,false),0) -> 0 | J13: =if(OR($F13=1, $F13=2),VLOOKUP($B13,Courts!$B$2:$J$50,6,false),0) -> 0 | K13: =if(OR($F13=1, $F13=2),VLOOKUP($B13,Courts!$B$2:$J$50,7,false),0) -> 0 | L13: =H13+I13+J13+K13 -> 9 | M13: =if(OR($F13=1, $F13=2),VLOOKUP($B13,Courts!$B$2:$J$50,9,false),0) -> 0 | N13: =C13+L13 -> 310 | O13: =D13+M13 -> 31 | P13: X | Q13: X | R13: X | S13: =vlookup(B13,indirect("'" & AC$2 & "'!B5:W69"),18,false)++if(text(C$1,"mm/dd/yy")=$AC$2,0,if(H13>0,0,1)) -> 22 | T13: =if(H13=13,1,0)+vlookup(B13,indirect("'" & AC$2 & "'!B5:W69"),19,false) -> 1 | V13: =vlookup(B13,indirect("'" & AC$2 & "'!B5:W69"),21,false)+if(text(C$1,"mm/dd/yy")=$AC$2,0,if(H13=9,1,0)) -> 1 | W13: =vlookup(B13,indirect("'" & AC$2 & "'!B5:x69"),23,false)-X13 -> 1 | X13: =X12+1 -> 9 | Y13: =if(S13=D$2,"Y","N") -> N | Z13: =if($D$2=sum(S13:V13),"","Error")
A14: =A13+1 -> 10 | B14: Pavan Akkimsetty | C14: 301 | D14: 25 | E14: =if(S14>0,(C14-(V14*9)-(T14*13))/S14,0) -> 14 | F14: =if(isna(VLOOKUP(B14,Checkin!A:B,2,false)),0,VLOOKUP(B14,Checkin!A:B,2,false)) -> 3 | G14: =if(OR($F14=1, $F14=2),VLOOKUP($B14,Courts!$B$2:$K$50,10,false),0) -> 0 | H14: =IF(OR(F14=3,F14=4),9,IF(F14=5,13,0)) -> 9 | I14: =if(OR($F14=1, $F14=2),VLOOKUP($B14,Courts!$B$2:$J$50,5,false),0) -> 0 | J14: =if(OR($F14=1, $F14=2),VLOOKUP($B14,Courts!$B$2:$J$50,6,false),0) -> 0 | K14: =if(OR($F14=1, $F14=2),VLOOKUP($B14,Courts!$B$2:$J$50,7,false),0) -> 0 | L14: =H14+I14+J14+K14 -> 9 | M14: =if(OR($F14=1, $F14=2),VLOOKUP($B14,Courts!$B$2:$J$50,9,false),0) -> 0 | N14: =C14+L14 -> 310 | O14: =D14+M14 -> 25 | P14: X | Q14: X | R14: X | S14: =vlookup(B14,indirect("'" & AC$2 & "'!B5:W69"),18,false)++if(text(C$1,"mm/dd/yy")=$AC$2,0,if(H14>0,0,1)) -> 17 | T14: =if(H14=13,1,0)+vlookup(B14,indirect("'" & AC$2 & "'!B5:W69"),19,false) -> 0 | V14: =vlookup(B14,indirect("'" & AC$2 & "'!B5:W69"),21,false)+if(text(C$1,"mm/dd/yy")=$AC$2,0,if(H14=9,1,0)) -> 7 | W14: =vlookup(B14,indirect("'" & AC$2 & "'!B5:x69"),23,false)-X14 -> -2 | X14: =X13+1 -> 10 | Y14: =if(S14=D$2,"Y","N") -> N | Z14: =if($D$2=sum(S14:V14),"","Error")
A15: =A14+1 -> 11 | B15: Oscar Bonilla | C15: 300 | D15: 26 | E15: =if(S15>0,(C15-(V15*9)-(T15*13))/S15,0) -> 13.666667 | F15: =if(isna(VLOOKUP(B15,Checkin!A:B,2,false)),0,VLOOKUP(B15,Checkin!A:B,2,false)) -> 3 | G15: =if(OR($F15=1, $F15=2),VLOOKUP($B15,Courts!$B$2:$K$50,10,false),0) -> 0 | H15: =IF(OR(F15=3,F15=4),9,IF(F15=5,13,0)) -> 9 | I15: =if(OR($F15=1, $F15=2),VLOOKUP($B15,Courts!$B$2:$J$50,5,false),0) -> 0 | J15: =if(OR($F15=1, $F15=2),VLOOKUP($B15,Courts!$B$2:$J$50,6,false),0) -> 0 | K15: =if(OR($F15=1, $F15=2),VLOOKUP($B15,Courts!$B$2:$J$50,7,false),0) -> 0 | L15: =H15+I15+J15+K15 -> 9 | M15: =if(OR($F15=1, $F15=2),VLOOKUP($B15,Courts!$B$2:$J$50,9,false),0) -> 0 | N15: =C15+L15 -> 309 | O15: =D15+M15 -> 26 | P15: X | Q15: X | R15: X | S15: =vlookup(B15,indirect("'" & AC$2 & "'!B5:W69"),18,false)++if(text(C$1,"mm/dd/yy")=$AC$2,0,if(H15>0,0,1)) -> 18 | T15: =if(H15=13,1,0)+vlookup(B15,indirect("'" & AC$2 & "'!B5:W69"),19,false) -> 0 | V15: =vlookup(B15,indirect("'" & AC$2 & "'!B5:W69"),21,false)+if(text(C$1,"mm/dd/yy")=$AC$2,0,if(H15=9,1,0)) -> 6 | W15: =vlookup(B15,indirect("'" & AC$2 & "'!B5:x69"),23,false)-X15 -> 0 | X15: =X14+1 -> 11 | Y15: =if(S15=D$2,"Y","N") -> N | Z15: =if($D$2=sum(S15:V15),"","Error")
A16: =A15+1 -> 12 | B16: Joe Luzzi | C16: 300 | D16: 21 | E16: =if(S16>0,(C16-(V16*9)-(T16*13))/S16,0) -> 13.444444 | F16: =if(isna(VLOOKUP(B16,Checkin!A:B,2,false)),0,VLOOKUP(B16,Checkin!A:B,2,false)) -> 1 | G16: =if(OR($F16=1, $F16=2),VLOOKUP($B16,Courts!$B$2:$K$50,10,false),0) -> 1 | H16: =IF(OR(F16=3,F16=4),9,IF(F16=5,13,0)) -> 0 | I16: =if(OR($F16=1, $F16=2),VLOOKUP($B16,Courts!$B$2:$J$50,5,false),0) -> 6 | J16: =if(OR($F16=1, $F16=2),VLOOKUP($B16,Courts!$B$2:$J$50,6,false),0) -> 7 | K16: =if(OR($F16=1, $F16=2),VLOOKUP($B16,Courts!$B$2:$J$50,7,false),0) -> 7 | L16: =H16+I16+J16+K16 -> 20 | M16: =if(OR($F16=1, $F16=2),VLOOKUP($B16,Courts!$B$2:$J$50,9,false),0) -> 3 | N16: =C16+L16 -> 320 | O16: =D16+M16 -> 24 | P16: X | Q16: X | R16: X | S16: =vlookup(B16,indirect("'" & AC$2 & "'!B5:W69"),18,false)++if(text(C$1,"mm/dd/yy")=$AC$2,0,if(H16>0,0,1)) -> 18 | T16: =if(H16=13,1,0)+vlookup(B16,indirect("'" & AC$2 & "'!B5:W69"),19,false) -> 1 | V16: =vlookup(B16,indirect("'" & AC$2 & "'!B5:W69"),21,false)+if(text(C$1,"mm/dd/yy")=$AC$2,0,if(H16=9,1,0)) -> 5 | W16: =vlookup(B16,indirect("'" & AC$2 & "'!B5:x69"),23,false)-X16 -> 0 | X16: =X15+1 -> 12 | Y16: =if(S16=D$2,"Y","N") -> N | Z16: =if($D$2=sum(S16:V16),"","Error")
A17: =A16+1 -> 13 | B17: Herman Au | C17: 298 | D17: 28 | E17: =if(S17>0,(C17-(V17*9)-(T17*13))/S17,0) -> 12.421053 | F17: =if(isna(VLOOKUP(B17,Checkin!A:B,2,false)),0,VLOOKUP(B17,Checkin!A:B,2,false)) -> 5 | G17: =if(OR($F17=1, $F17=2),VLOOKUP($B17,Courts!$B$2:$K$50,10,false),0) -> 0 | H17: =IF(OR(F17=3,F17=4),9,IF(F17=5,13,0)) -> 13 | I17: =if(OR($F17=1, $F17=2),VLOOKUP($B17,Courts!$B$2:$J$50,5,false),0) -> 0 | J17: =if(OR($F17=1, $F17=2),VLOOKUP($B17,Courts!$B$2:$J$50,6,false),0) -> 0 | K17: =if(OR($F17=1, $F17=2),VLOOKUP($B17,Courts!$B$2:$J$50,7,false),0) -> 0 | L17: =H17+I17+J17+K17 -> 13 | M17: =if(OR($F17=1, $F17=2),VLOOKUP($B17,Courts!$B$2:$J$50,9,false),0) -> 0 | N17: =C17+L17 -> 311 | O17: =D17+M17 -> 28 | P17: X | Q17: X | R17: X | S17: =vlookup(B17,indirect("'" & AC$2 & "'!B5:W69"),18,false)++if(text(C$1,"mm/dd/yy")=$AC$2,0,if(H17>0,0,1)) -> 19 | T17: =if(H17=13,1,0)+vlookup(B17,indirect("'" & AC$2 & "'!B5:W69"),19,false) -> 2 | V17: =vlookup(B17,indirect("'" & AC$2 & "'!B5:W69"),21,false)+if(text(C$1,"mm/dd/yy")=$AC$2,0,if(H17=9,1,0)) -> 4 | W17: =vlookup(B17,indirect("'" & AC$2 & "'!B5:x69"),23,false)-X17 -> 3 | X17: =X16+1 -> 13 | Y17: =if(S17=D$2,"Y","N") -> N | Z17: =if($D$2=sum(S17:V17),"","Error") -> Error
... A69: =A68+1 -> 65 | B69: Barathi Sundaram | C69: 192 | D69: 2 | E69: =if(S69>0,(C69-(V69*9)-(T69*13))/S69,0) -> 5.5714286 | F69: =if(isna(VLOOKUP(B69,Checkin!A:B,2,false)),0,VLOOKUP(B69,Checkin!A:B,2,false)) -> 0 | G69: =if(OR($F69=1, $F69=2),VLOOKUP($B69,Courts!$B$2:$K$50,10,false),0) -> 0 | H69: =IF(OR(F69=3,F69=4),9,IF(F69=5,13,0)) -> 0 | I69: =if(OR($F69=1, $F69=2),VLOOKUP($B69,Courts!$B$2:$J$50,5,false),0) -> 0 | J69: =if(OR($F69=1, $F69=2),VLOOKUP($B69,Courts!$B$2:$J$50,6,false),0) -> 0 | K69: =if(OR($F69=1, $F69=2),VLOOKUP($B69,Courts!$B$2:$J$50,7,false),0) -> 0 | L69: =H69+I69+J69+K69 -> 0 | M69: =if(OR($F69=1, $F69=2),VLOOKUP($B69,Courts!$B$2:$J$50,9,false),0) -> 0 | N69: =C69+L69 -> 192 | O69: =D69+M69 -> 2 | P69: X | Q69: X | R69: X | S69: =vlookup(B69,indirect("'" & AC$2 & "'!B5:W69"),18,false)++if(text(C$1,"mm/dd/yy")=$AC$2,0,if(H69>0,0,1)) -> 7 | T69: =if(H69=13,1,0)+vlookup(B69,indirect("'" & AC$2 & "'!B5:W69"),19,false) -> 0 | V69: =vlookup(B69,indirect("'" & AC$2 & "'!B5:W69"),21,false)+if(text(C$1,"mm/dd/yy")=$AC$2,0,if(H69=9,1,0)) -> 17 | W69: =vlookup(B69,indirect("'" & AC$2 & "'!B5:x69"),23,false)-X69 -> 0 | X69: =X68+1 -> 65 | Y69: =if(S69=D$2,"Y","N") -> N | Z69: =if($D$2=sum(S69:V69),"","Error")
P73: Membership Renewals
P74: Renewed | R74: =countif(R5:R69,"X") -> 64 | S74: =R74/R77 -> 0.98461538
B75: For Publishing in the WhatsApp Group for the score updates on saturday | P75: Not Renewing | R75: =countif(R5:R69,"N") -> 1
P76: To Renew | R76: =countif(R5:R69,"") -> 0
P77: Total | R77: =sum(R74:R76) -> 65
B78: =concatenate("Top Scores : " &AC2) -> Top Scores : 12/13/25
B80: Name of Player | C80: Games | D80: Sets | E80: Court #
B81: =IFERROR(__xludf.DUMMYFUNCTION("QUERY(indirect(AC2 & ""!B5:M69""),""Select B, L, M, G where L >= 18 order by L desc,M desc"",0)"),"Herman Au") -> Herman Au | C81: =IFERROR(__xludf.DUMMYFUNCTION("""COMPUTED_VALUE"""),19.0) -> 19 | D81: =IFERROR(__xludf.DUMMYFUNCTION("""COMPUTED_VALUE"""),3.0) -> 3 | E81: =IFERROR(__xludf.DUMMYFUNCTION("""COMPUTED_VALUE"""),2.0) -> 2
B82: =IFERROR(__xludf.DUMMYFUNCTION("""COMPUTED_VALUE"""),"Naveen Raj") -> Naveen Raj | C82: =IFERROR(__xludf.DUMMYFUNCTION("""COMPUTED_VALUE"""),19.0) -> 19 | D82: =IFERROR(__xludf.DUMMYFUNCTION("""COMPUTED_VALUE"""),3.0) -> 3 | E82: =IFERROR(__xludf.DUMMYFUNCTION("""COMPUTED_VALUE"""),4.0) -> 4
B83: =IFERROR(__xludf.DUMMYFUNCTION("""COMPUTED_VALUE"""),"Jim Miao") -> Jim Miao | C83: =IFERROR(__xludf.DUMMYFUNCTION("""COMPUTED_VALUE"""),19.0) -> 19 | D83: =IFERROR(__xludf.DUMMYFUNCTION("""COMPUTED_VALUE"""),3.0) -> 3 | E83: =IFERROR(__xludf.DUMMYFUNCTION("""COMPUTED_VALUE"""),6.0) -> 6
B84: =IFERROR(__xludf.DUMMYFUNCTION("""COMPUTED_VALUE"""),"Eric Pan") -> Eric Pan | C84: =IFERROR(__xludf.DUMMYFUNCTION("""COMPUTED_VALUE"""),18.0) -> 18 | D84: =IFERROR(__xludf.DUMMYFUNCTION("""COMPUTED_VALUE"""),3.0) -> 3 | E84: =IFERROR(__xludf.DUMMYFUNCTION("""COMPUTED_VALUE"""),1.0) -> 1
B85: =IFERROR(__xludf.DUMMYFUNCTION("""COMPUTED_VALUE"""),"Vishnu Amarnath") -> Vishnu Amarnath | C85: =IFERROR(__xludf.DUMMYFUNCTION("""COMPUTED_VALUE"""),18.0) -> 18 | D85: =IFERROR(__xludf.DUMMYFUNCTION("""COMPUTED_VALUE"""),3.0) -> 3 | E85: =IFERROR(__xludf.DUMMYFUNCTION("""COMPUTED_VALUE"""),7.0) -> 7
B86: =IFERROR(__xludf.DUMMYFUNCTION("""COMPUTED_VALUE"""),"Jimmy Awolesi") -> Jimmy Awolesi | C86: =IFERROR(__xludf.DUMMYFUNCTION("""COMPUTED_VALUE"""),18.0) -> 18 | D86: =IFERROR(__xludf.DUMMYFUNCTION("""COMPUTED_VALUE"""),2.0) -> 2 | E86: =IFERROR(__xludf.DUMMYFUNCTION("""COMPUTED_VALUE"""),5.0) -> 5
B87: =IFERROR(__xludf.DUMMYFUNCTION("""COMPUTED_VALUE"""),"Manuel Rivera") -> Manuel Rivera | C87: =IFERROR(__xludf.DUMMYFUNCTION("""COMPUTED_VALUE"""),18.0) -> 18 | D87: =IFERROR(__xludf.DUMMYFUNCTION("""COMPUTED_VALUE"""),2.0) -> 2 | E87: =IFERROR(__xludf.DUMMYFUNCTION("""COMPUTED_VALUE"""),8.0) -> 8
B97: Top 10 Movements (UP)
B99: Name of Player | C99: Positions Moved | D99: Position Last week | E99: Position This week | F99: Points this week | G99: Court | L99: Cross Check
B100: =IFERROR(__xludf.DUMMYFUNCTION("query(B5:W69,""select B, W order by W Desc Limit 10"")"),"Naveen Raj") -> Naveen Raj | C100: =IFERROR(__xludf.DUMMYFUNCTION("""COMPUTED_VALUE"""),8.0) -> 8 | D100: =VLOOKUP(B100,indirect($AC$2&"!B$5:X$69"),23, false) -> 27 | E100: =VLOOKUP(B100,B$5:X$69,23, false) -> 19 | F100: =VLOOKUP(B100,indirect($AC$2&"!B$5:U$70"),11, false) -> 19 | G100: =VLOOKUP(B100,indirect($AC$2&"!B$5:U$70"),6, false) -> 4 | L100: =if(D100-E100=C100,"ok","Error") -> ok
B101: =IFERROR(__xludf.DUMMYFUNCTION("""COMPUTED_VALUE"""),"Jimmy Awolesi") -> Jimmy Awolesi | C101: =IFERROR(__xludf.DUMMYFUNCTION("""COMPUTED_VALUE"""),7.0) -> 7 | D101: =VLOOKUP(B101,indirect($AC$2&"!B$5:X$69"),23, false) -> 33 | E101: =VLOOKUP(B101,B$5:X$69,23, false) -> 26 | F101: =VLOOKUP(B101,indirect($AC$2&"!B$5:U$70"),11, false) -> 18 | G101: =VLOOKUP(B101,indirect($AC$2&"!B$5:U$70"),6, false) -> 5 | L101: =if(D101-E101=C101,"ok","Error") -> ok
B102: =IFERROR(__xludf.DUMMYFUNCTION("""COMPUTED_VALUE"""),"Ted Shen") -> Ted Shen | C102: =IFERROR(__xludf.DUMMYFUNCTION("""COMPUTED_VALUE"""),4.0) -> 4 | D102: =VLOOKUP(B102,indirect($AC$2&"!B$5:X$69"),23, false) -> 24 | E102: =VLOOKUP(B102,B$5:X$69,23, false) -> 20 | F102: =VLOOKUP(B102,indirect($AC$2&"!B$5:U$70"),11, false) -> 15 | G102: =VLOOKUP(B102,indirect($AC$2&"!B$5:U$70"),6, false) -> 3 | L102: =if(D102-E102=C102,"ok","Error") -> ok
B103: =IFERROR(__xludf.DUMMYFUNCTION("""COMPUTED_VALUE"""),"Mauricio Palacios") -> Mauricio Palacios | C103: =IFERROR(__xludf.DUMMYFUNCTION("""COMPUTED_VALUE"""),4.0) -> 4 | D103: =VLOOKUP(B103,indirect($AC$2&"!B$5:X$69"),23, false) -> 25 | E103: =VLOOKUP(B103,B$5:X$69,23, false) -> 21 | F103: =VLOOKUP(B103,indirect($AC$2&"!B$5:U$70"),11, false) -> 15 | G103: =VLOOKUP(B103,indirect($AC$2&"!B$5:U$70"),6, false) -> 4 | L103: =if(D103-E103=C103,"ok","Error") -> ok
B104: =IFERROR(__xludf.DUMMYFUNCTION("""COMPUTED_VALUE"""),"Vishnu Amarnath") -> Vishnu Amarnath | C104: =IFERROR(__xludf.DUMMYFUNCTION("""COMPUTED_VALUE"""),4.0) -> 4 | D104: =VLOOKUP(B104,indirect($AC$2&"!B$5:X$69"),23, false) -> 50 | E104: =VLOOKUP(B104,B$5:X$69,23, false) -> 46 | F104: =VLOOKUP(B104,indirect($AC$2&"!B$5:U$70"),11, false) -> 18 | G104: =VLOOKUP(B104,indirect($AC$2&"!B$5:U$70"),6, false) -> 7 | L104: =if(D104-E104=C104,"ok","Error") -> ok
B105: =IFERROR(__xludf.DUMMYFUNCTION("""COMPUTED_VALUE"""),"Manuel Rivera") -> Manuel Rivera | C105: =IFERROR(__xludf.DUMMYFUNCTION("""COMPUTED_VALUE"""),4.0) -> 4 | D105: =VLOOKUP(B105,indirect($AC$2&"!B$5:X$69"),23, false) -> 53 | E105: =VLOOKUP(B105,B$5:X$69,23, false) -> 49 | F105: =VLOOKUP(B105,indirect($AC$2&"!B$5:U$70"),11, false) -> 18 | G105: =VLOOKUP(B105,indirect($AC$2&"!B$5:U$70"),6, false) -> 8 | L105: =if(D105-E105=C105,"ok","Error") -> ok
...

Sheet Courts
A1: Court # | B1: Name of the Player | C1: Games Won | D1: Sets Won | E1: Check In | F1: Set 1 | G1: Set 2 | H1: Set 3 | I1: Total Games won | J1: Sets Won | K1: Court # | L1: Scores Entered by | M1: Mark 'X', if the court needs to be played at WHS | O1: Set 1 | P1: Set 2 | Q1: Set 3 | R1: Sets Won | U1: Set 1 | V1: Set 2 | W1: Set 2 | Y1: Sets Validations | AB1: Set 1 | AC1: Set 2 | AD1: Set 2
A2: 1 | B2: =IFERROR(__xludf.DUMMYFUNCTION("QUERY(indirect(""'"" & ""Current"" & ""'!B5:F69""),""Select B, C, D, F where F = 1 or F = 2 "",0)"),"Pulkit Mathur") -> Pulkit Mathur | C2: =IFERROR(__xludf.DUMMYFUNCTION("""COMPUTED_VALUE"""),311.0) -> 311 | D2: =IFERROR(__xludf.DUMMYFUNCTION("""COMPUTED_VALUE"""),31.0) -> 31 | E2: =IFERROR(__xludf.DUMMYFUNCTION("""COMPUTED_VALUE"""),1.0) -> 1 | F2: 6 | G2: 6 | H2: 5 | I2: =sum(F2:H2) -> 17 | J2: 1 | K2: =A2 -> 1 | O2: =if(F2=max(F$2:F$5),1,0) -> 1 | P2: =if(G2=max(G$2:G$5),1,0) -> 0 | Q2: =if(H2=max(H$2:H$5),1,0) -> 0 | R2: =sum(O2:Q2) -> 1 | U2: =if(COUNTIF(AB2:AB4,"Good")=2,"Good","Error") -> Good | V2: =if(COUNTIF(AC2:AC4,"Good")=2,"Good","Error") -> Good | W2: =if(COUNTIF(AD2:AD4,"Good")=2,"Good","Error") -> Good | Y2: =sum(J2:J5) -> 6 | Z2: =if(Y2=0,"",if(Y2=6,"Good","ERROR")) -> Good | AB2: =if(isna(VLOOKUP(F2,F3:F5,1,false)),"Error","Good") -> Good | AC2: =if(isna(VLOOKUP(G2,G3:G5,1,false)),"Error","Good") -> Good | AD2: =if(isna(VLOOKUP(H2,H3:H5,1,false)),"Error","Good") -> Good
A3: 1 | B3: =IFERROR(__xludf.DUMMYFUNCTION("""COMPUTED_VALUE"""),"David Shin") -> David Shin | C3: =IFERROR(__xludf.DUMMYFUNCTION("""COMPUTED_VALUE"""),303.0) -> 303 | D3: =IFERROR(__xludf.DUMMYFUNCTION("""COMPUTED_VALUE"""),27.0) -> 27 | E3: =IFERROR(__xludf.DUMMYFUNCTION("""COMPUTED_VALUE"""),1.0) -> 1 | F3: 3 | G3: 6 | H3: 7 | I3: =sum(F3:H3) -> 16 | J3: 1 | K3: =A3 -> 1 | O3: =if(F3=max(F$2:F$5),1,0) -> 0 | P3: =if(G3=max(G$2:G$5),1,0) -> 0 | Q3: =if(H3=max(H$2:H$5),1,0) -> 1 | R3: =sum(O3:Q3) -> 1 | AB3: =if(isna(VLOOKUP(F3,F4:F5,1,false)),"Error","Good") -> Good | AC3: =if(isna(VLOOKUP(G3,G4:G5,1,false)),"Error","Good") -> Error | AD3: =if(isna(VLOOKUP(H3,H4:H5,1,false)),"Error","Good") -> Good | AJ3: Alejandro Mejia
A4: 1 | B4: =IFERROR(__xludf.DUMMYFUNCTION("""COMPUTED_VALUE"""),"Ethan Gu") -> Ethan Gu | C4: =IFERROR(__xludf.DUMMYFUNCTION("""COMPUTED_VALUE"""),301.0) -> 301 | D4: =IFERROR(__xludf.DUMMYFUNCTION("""COMPUTED_VALUE"""),31.0) -> 31 | E4: =IFERROR(__xludf.DUMMYFUNCTION("""COMPUTED_VALUE"""),1.0) -> 1 | F4: 3 | G4: 7 | H4: 5 | I4: =sum(F4:H4) -> 15 | J4: 1 | K4: =A4 -> 1 | O4: =if(F4=max(F$2:F$5),1,0) -> 0 | P4: =if(G4=max(G$2:G$5),1,0) -> 1 | Q4: =if(H4=max(H$2:H$5),1,0) -> 0 | R4: =sum(O4:Q4) -> 1 | AB4: =if(F4=F5,"Good") -> FALSE | AC4: =if(G4=G5,"Good") -> Good | AD4: =if(H4=H5,"Good") -> FALSE | AJ4: Jimmy Awolesi
A5: 1 | B5: =IFERROR(__xludf.DUMMYFUNCTION("""COMPUTED_VALUE"""),"Joe Luzzi") -> Joe Luzzi | C5: =IFERROR(__xludf.DUMMYFUNCTION("""COMPUTED_VALUE"""),300.0) -> 300 | D5: =IFERROR(__xludf.DUMMYFUNCTION("""COMPUTED_VALUE"""),21.0) -> 21 | E5: =IFERROR(__xludf.DUMMYFUNCTION("""COMPUTED_VALUE"""),1.0) -> 1 | F5: 6 | G5: 7 | H5: 7 | I5: =sum(F5:H5) -> 20 | J5: 3 | K5: =A5 -> 1 | L5: Chinna Ponnaganti | O5: =if(F5=max(F$2:F$5),1,0) -> 1 | P5: =if(G5=max(G$2:G$5),1,0) -> 1 | Q5: =if(H5=max(H$2:H$5),1,0) -> 1 | R5: =sum(O5:Q5) -> 3 | AJ5: Tony Wong
A6: 2 | B6: =IFERROR(__xludf.DUMMYFUNCTION("""COMPUTED_VALUE"""),"Suleman Alidina") -> Suleman Alidina | C6: =IFERROR(__xludf.DUMMYFUNCTION("""COMPUTED_VALUE"""),293.0) -> 293 | D6: =IFERROR(__xludf.DUMMYFUNCTION("""COMPUTED_VALUE"""),29.0) -> 29 | E6: =IFERROR(__xludf.DUMMYFUNCTION("""COMPUTED_VALUE"""),2.0) -> 2 | I6: =sum(F6:H6) -> 0 | K6: =A6 -> 2 | O6: =if(F6=max(F$6:F$9),1,0) -> 1 | P6: =if(G6=max(G$6:G$9),1,0) -> 1 | Q6: =if(H6=max(H$6:H$9),1,0) -> 1 | R6: =sum(O6:Q6) -> 3 | U6: =if(COUNTIF(AB6:AB8,"Good")=2,"Good","Error") -> Error | V6: =if(COUNTIF(AC6:AC8,"Good")=2,"Good","Error") -> Error | W6: =if(COUNTIF(AD6:AD8,"Good")=2,"Good","Error") -> Error | Y6: =sum(J6:J9) -> 0 | Z6: =if(Y6=0,"",if(Y6=6,"Good","ERROR")) | AB6: =if(isna(VLOOKUP(F6,F7:F9,1,false)),"Error","Good") -> Error | AC6: =if(isna(VLOOKUP(G6,G7:G9,1,false)),"Error","Good") -> Error | AD6: =if(isna(VLOOKUP(H6,H7:H9,1,false)),"Error","Good") -> Error | AJ6: Vinaya Kajla
A7: 2 | B7: =IFERROR(__xludf.DUMMYFUNCTION("""COMPUTED_VALUE"""),"Tina Hanson") -> Tina Hanson | C7: =IFERROR(__xludf.DUMMYFUNCTION("""COMPUTED_VALUE"""),292.0) -> 292 | D7: =IFERROR(__xludf.DUMMYFUNCTION("""COMPUTED_VALUE"""),29.0) -> 29 | E7: =IFERROR(__xludf.DUMMYFUNCTION("""COMPUTED_VALUE"""),1.0) -> 1 | I7: =sum(F7:H7) -> 0 | K7: =A7 -> 2 | O7: =if(F7=max(F$6:F$9),1,0) -> 1 | P7: =if(G7=max(G$6:G$9),1,0) -> 1 | Q7: =if(H7=max(H$6:H$9),1,0) -> 1 | R7: =sum(O7:Q7) -> 3 | AB7: =if(isna(VLOOKUP(F7,F8:F9,1,false)),"Error","Good") -> Error | AC7: =if(isna(VLOOKUP(G7,G8:G9,1,false)),"Error","Good") -> Error | AD7: =if(isna(VLOOKUP(H7,H8:H9,1,false)),"Error","Good") -> Error
A8: 2 | B8: =IFERROR(__xludf.DUMMYFUNCTION("""COMPUTED_VALUE"""),"Naveen Raj") -> Naveen Raj | C8: =IFERROR(__xludf.DUMMYFUNCTION("""COMPUTED_VALUE"""),288.0) -> 288 | D8: =IFERROR(__xludf.DUMMYFUNCTION("""COMPUTED_VALUE"""),29.0) -> 29 | E8: =IFERROR(__xludf.DUMMYFUNCTION("""COMPUTED_VALUE"""),1.0) -> 1 | I8: =sum(F8:H8) -> 0 | K8: =A8 -> 2 | O8: =if(F8=max(F$6:F$9),1,0) -> 1 | P8: =if(G8=max(G$6:G$9),1,0) -> 1 | Q8: =if(H8=max(H$6:H$9),1,0) -> 1 | R8: =sum(O8:Q8) -> 3 | AB8: =if(F8=F9,"Good") -> Good | AC8: =if(G8=G9,"Good") -> Good | AD8: =if(H8=H9,"Good") -> Good
A9: 2 | B9: =IFERROR(__xludf.DUMMYFUNCTION("""COMPUTED_VALUE"""),"Ted Shen") -> Ted Shen | C9: =IFERROR(__xludf.DUMMYFUNCTION("""COMPUTED_VALUE"""),286.0) -> 286 | D9: =IFERROR(__xludf.DUMMYFUNCTION("""COMPUTED_VALUE"""),27.0) -> 27 | E9: =IFERROR(__xludf.DUMMYFUNCTION("""COMPUTED_VALUE"""),1.0) -> 1 | I9: =sum(F9:H9) -> 0 | K9: =A9 -> 2 | O9: =if(F9=max(F$6:F$9),1,0) -> 1 | P9: =if(G9=max(G$6:G$9),1,0) -> 1 | Q9: =if(H9=max(H$6:H$9),1,0) -> 1 | R9: =sum(O9:Q9) -> 3
A10: 3 | B10: =IFERROR(__xludf.DUMMYFUNCTION("""COMPUTED_VALUE"""),"Mauricio Palacios") -> Mauricio Palacios | C10: =IFERROR(__xludf.DUMMYFUNCTION("""COMPUTED_VALUE"""),286.0) -> 286 | D10: =IFERROR(__xludf.DUMMYFUNCTION("""COMPUTED_VALUE"""),22.0) -> 22 | E10: =IFERROR(__xludf.DUMMYFUNCTION("""COMPUTED_VALUE"""),1.0) -> 1 | I10: =sum(F10:H10) -> 0 | K10: =A10 -> 3 | O10: =if(F10=max(F$10:F$13),1,0) -> 1 | P10: =if(G10=max(G$10:G$13),1,0) -> 1 | Q10: =if(H10=max(H$10:H$13),1,0) -> 1 | R10: =sum(O10:Q10) -> 3 | U10: =if(COUNTIF(AB10:AB12,"Good")=2,"Good","Error") -> Error | V10: =if(COUNTIF(AC10:AC12,"Good")=2,"Good","Error") -> Error | W10: =if(COUNTIF(AD10:AD12,"Good")=2,"Good","Error") -> Error | Y10: =sum(J10:J13) -> 0 | Z10: =if(Y10=0,"",if(Y10=6,"Good","ERROR")) | AB10: =if(isna(VLOOKUP(F10,F11:F13,1,false)),"Error","Good") -> Error | AC10: =if(isna(VLOOKUP(G10,G11:G13,1,false)),"Error","Good") -> Error | AD10: =if(isna(VLOOKUP(H10,H11:H13,1,false)),"Error","Good") -> Error
A11: 3 | B11: =IFERROR(__xludf.DUMMYFUNCTION("""COMPUTED_VALUE"""),"Elayaraja Thangaraj") -> Elayaraja Thangaraj | C11: =IFERROR(__xludf.DUMMYFUNCTION("""COMPUTED_VALUE"""),286.0) -> 286 | D11: =IFERROR(__xludf.DUMMYFUNCTION("""COMPUTED_VALUE"""),21.0) -> 21 | E11: =IFERROR(__xludf.DUMMYFUNCTION("""COMPUTED_VALUE"""),1.0) -> 1 | I11: =sum(F11:H11) -> 0 | K11: =A11 -> 3 | O11: =if(F11=max(F$10:F$13),1,0) -> 1 | P11: =if(G11=max(G$10:G$13),1,0) -> 1 | Q11: =if(H11=max(H$10:H$13),1,0) -> 1 | R11: =sum(O11:Q11) -> 3 | AB11: =if(isna(VLOOKUP(F11,F12:F13,1,false)),"Error","Good") -> Error | AC11: =if(isna(VLOOKUP(G11,G12:G13,1,false)),"Error","Good") -> Error | AD11: =if(isna(VLOOKUP(H11,H12:H13,1,false)),"Error","Good") -> Error | AJ11: Suleman Alidina
A12: 3 | B12: =IFERROR(__xludf.DUMMYFUNCTION("""COMPUTED_VALUE"""),"Coco Yan") -> Coco Yan | C12: =IFERROR(__xludf.DUMMYFUNCTION("""COMPUTED_VALUE"""),285.0) -> 285 | D12: =IFERROR(__xludf.DUMMYFUNCTION("""COMPUTED_VALUE"""),22.0) -> 22 | E12: =IFERROR(__xludf.DUMMYFUNCTION("""COMPUTED_VALUE"""),1.0) -> 1 | I12: =sum(F12:H12) -> 0 | K12: =A12 -> 3 | O12: =if(F12=max(F$10:F$13),1,0) -> 1 | P12: =if(G12=max(G$10:G$13),1,0) -> 1 | Q12: =if(H12=max(H$10:H$13),1,0) -> 1 | R12: =sum(O12:Q12) -> 3 | AB12: =if(F12=F13,"Good") -> Good | AC12: =if(G12=G13,"Good") -> Good | AD12: =if(H12=H13,"Good") -> Good | AJ12: Ash Nikravan
A13: 3 | B13: =IFERROR(__xludf.DUMMYFUNCTION("""COMPUTED_VALUE"""),"Allen Zhang") -> Allen Zhang | C13: =IFERROR(__xludf.DUMMYFUNCTION("""COMPUTED_VALUE"""),284.0) -> 284 | D13: =IFERROR(__xludf.DUMMYFUNCTION("""COMPUTED_VALUE"""),24.0) -> 24 | E13: =IFERROR(__xludf.DUMMYFUNCTION("""COMPUTED_VALUE"""),1.0) -> 1 | I13: =sum(F13:H13) -> 0 | K13: =A13 -> 3 | O13: =if(F13=max(F$10:F$13),1,0) -> 1 | P13: =if(G13=max(G$10:G$13),1,0) -> 1 | Q13: =if(H13=max(H$10:H$13),1,0) -> 1 | R13: =sum(O13:Q13) -> 3 | AJ13: Susanta Mishra
A14: 4 | B14: =IFERROR(__xludf.DUMMYFUNCTION("""COMPUTED_VALUE"""),"Jimmy Awolesi") -> Jimmy Awolesi | C14: =IFERROR(__xludf.DUMMYFUNCTION("""COMPUTED_VALUE"""),283.0) -> 283 | D14: =IFERROR(__xludf.DUMMYFUNCTION("""COMPUTED_VALUE"""),25.0) -> 25 | E14: =IFERROR(__xludf.DUMMYFUNCTION("""COMPUTED_VALUE"""),1.0) -> 1 | I14: =sum(F14:H14) -> 0 | K14: =A14 -> 4 | O14: =if(F14=max(F$14:F$17),1,0) -> 1 | P14: =if(G14=max(G$14:G$17),1,0) -> 1 | Q14: =if(H14=max(H$14:H$17),1,0) -> 1 | R14: =sum(O14:Q14) -> 3 | U14: =if(COUNTIF(AB14:AB16,"Good")=2,"Good","Error") -> Error | V14: =if(COUNTIF(AC14:AC16,"Good")=2,"Good","Error") -> Error | W14: =if(COUNTIF(AD14:AD16,"Good")=2,"Good","Error") -> Error | Y14: =sum(J14:J17) -> 0 | Z14: =if(Y14=0,"",if(Y14=6,"Good","ERROR")) | AB14: =if(isna(VLOOKUP(F14,F15:F17,1,false)),"Error","Good") -> Error | AC14: =if(isna(VLOOKUP(G14,G15:G17,1,false)),"Error","Good") -> Error | AD14: =if(isna(VLOOKUP(H14,H15:H17,1,false)),"Error","Good") -> Error | AJ14: David Tam
A15: 4 | B15: =IFERROR(__xludf.DUMMYFUNCTION("""COMPUTED_VALUE"""),"Nicole Ni") -> Nicole Ni | C15: =IFERROR(__xludf.DUMMYFUNCTION("""COMPUTED_VALUE"""),283.0) -> 283 | D15: =IFERROR(__xludf.DUMMYFUNCTION("""COMPUTED_VALUE"""),23.0) -> 23 | E15: =IFERROR(__xludf.DUMMYFUNCTION("""COMPUTED_VALUE"""),1.0) -> 1 | I15: =sum(F15:H15) -> 0 | K15: =A15 -> 4 | O15: =if(F15=max(F$14:F$17),1,0) -> 1 | P15: =if(G15=max(G$14:G$17),1,0) -> 1 | Q15: =if(H15=max(H$14:H$17),1,0) -> 1 | R15: =sum(O15:Q15) -> 3 | AB15: =if(isna(VLOOKUP(F15,F16:F17,1,false)),"Error","Good") -> Error | AC15: =if(isna(VLOOKUP(G15,G16:G17,1,false)),"Error","Good") -> Error | AD15: =if(isna(VLOOKUP(H15,H16:H17,1,false)),"Error","Good") -> Error
A16: 4 | B16: =IFERROR(__xludf.DUMMYFUNCTION("""COMPUTED_VALUE"""),"Erik Hoeckmann") -> Erik Hoeckmann | C16: =IFERROR(__xludf.DUMMYFUNCTION("""COMPUTED_VALUE"""),281.0) -> 281 | D16: =IFERROR(__xludf.DUMMYFUNCTION("""COMPUTED_VALUE"""),22.0) -> 22 | E16: =IFERROR(__xludf.DUMMYFUNCTION("""COMPUTED_VALUE"""),1.0) -> 1 | I16: =sum(F16:H16) -> 0 | K16: =A16 -> 4 | O16: =if(F16=max(F$14:F$17),1,0) -> 1 | P16: =if(G16=max(G$14:G$17),1,0) -> 1 | Q16: =if(H16=max(H$14:H$17),1,0) -> 1 | R16: =sum(O16:Q16) -> 3 | AB16: =if(F16=F17,"Good") -> Good | AC16: =if(G16=G17,"Good") -> Good | AD16: =if(H16=H17,"Good") -> Good
A17: 4 | B17: =IFERROR(__xludf.DUMMYFUNCTION("""COMPUTED_VALUE"""),"Hongyuan Wen") -> Hongyuan Wen | C17: =IFERROR(__xludf.DUMMYFUNCTION("""COMPUTED_VALUE"""),278.0) -> 278 | D17: =IFERROR(__xludf.DUMMYFUNCTION("""COMPUTED_VALUE"""),19.0) -> 19 | E17: =IFERROR(__xludf.DUMMYFUNCTION("""COMPUTED_VALUE"""),1.0) -> 1 | I17: =sum(F17:H17) -> 0 | K17: =A17 -> 4 | O17: =if(F17=max(F$14:F$17),1,0) -> 1 | P17: =if(G17=max(G$14:G$17),1,0) -> 1 | Q17: =if(H17=max(H$14:H$17),1,0) -> 1 | R17: =sum(O17:Q17) -> 3
A18: 5 | B18: =IFERROR(__xludf.DUMMYFUNCTION("""COMPUTED_VALUE"""),"Jim Miao") -> Jim Miao | C18: =IFERROR(__xludf.DUMMYFUNCTION("""COMPUTED_VALUE"""),275.0) -> 275 | D18: =IFERROR(__xludf.DUMMYFUNCTION("""COMPUTED_VALUE"""),22.0) -> 22 | E18: =IFERROR(__xludf.DUMMYFUNCTION("""COMPUTED_VALUE"""),1.0) -> 1 | I18: =sum(F18:H18) -> 0 | K18: =A18 -> 5 | O18: =if(F18=max(F$18:F$21),1,0) -> 1 | P18: =if(G18=max(G$18:G$21),1,0) -> 1 | Q18: =if(H18=max(H$18:H$21),1,0) -> 1 | R18: =sum(O18:Q18) -> 3 | U18: =if(COUNTIF(AB18:AB20,"Good")=2,"Good","Error") -> Error | V18: =if(COUNTIF(AC18:AC20,"Good")=2,"Good","Error") -> Error | W18: =if(COUNTIF(AD18:AD20,"Good")=2,"Good","Error") -> Error | Y18: =sum(J18:J21) -> 0 | Z18: =if(Y18=0,"",if(Y18=6,"Good","ERROR")) | AB18: =if(isna(VLOOKUP(F18,F19:F21,1,false)),"Error","Good") -> Error | AC18: =if(isna(VLOOKUP(G18,G19:G21,1,false)),"Error","Good") -> Error | AD18: =if(isna(VLOOKUP(H18,H19:H21,1,false)),"Error","Good") -> Error | AJ18: Pulkit Mathur
A19: 5 | B19: =IFERROR(__xludf.DUMMYFUNCTION("""COMPUTED_VALUE"""),"Sean Chang") -> Sean Chang | C19: =IFERROR(__xludf.DUMMYFUNCTION("""COMPUTED_VALUE"""),271.0) -> 271 | D19: =IFERROR(__xludf.DUMMYFUNCTION("""COMPUTED_VALUE"""),22.0) -> 22 | E19: =IFERROR(__xludf.DUMMYFUNCTION("""COMPUTED_VALUE"""),1.0) -> 1 | I19: =sum(F19:H19) -> 0 | K19: =A19 -> 5 | O19: =if(F19=max(F$18:F$21),1,0) -> 1 | P19: =if(G19=max(G$18:G$21),1,0) -> 1 | Q19: =if(H19=max(H$18:H$21),1,0) -> 1 | R19: =sum(O19:Q19) -> 3 | AB19: =if(isna(VLOOKUP(F19,F20:F21,1,false)),"Error","Good") -> Error | AC19: =if(isna(VLOOKUP(G19,G20:G21,1,false)),"Error","Good") -> Error | AD19: =if(isna(VLOOKUP(H19,H20:H21,1,false)),"Error","Good") -> Error | AJ19: Kingsley Kuo
A20: 5 | B20: =IFERROR(__xludf.DUMMYFUNCTION("""COMPUTED_VALUE"""),"Manish Anand") -> Manish Anand | C20: =IFERROR(__xludf.DUMMYFUNCTION("""COMPUTED_VALUE"""),247.0) -> 247 | D20: =IFERROR(__xludf.DUMMYFUNCTION("""COMPUTED_VALUE"""),12.0) -> 12 | E20: =IFERROR(__xludf.DUMMYFUNCTION("""COMPUTED_VALUE"""),1.0) -> 1 | I20: =sum(F20:H20) -> 0 | K20: =A20 -> 5 | O20: =if(F20=max(F$18:F$21),1,0) -> 1 | P20: =if(G20=max(G$18:G$21),1,0) -> 1 | Q20: =if(H20=max(H$18:H$21),1,0) -> 1 | R20: =sum(O20:Q20) -> 3 | AB20: =if(F20=F21,"Good") -> Good | AC20: =if(G20=G21,"Good") -> Good | AD20: =if(H20=H21,"Good") -> Good | AJ20: Scott Li
A21: 5 | B21: =IFERROR(__xludf.DUMMYFUNCTION("""COMPUTED_VALUE"""),"Susanta Mishra") -> Susanta Mishra | C21: =IFERROR(__xludf.DUMMYFUNCTION("""COMPUTED_VALUE"""),224.0) -> 224 | D21: =IFERROR(__xludf.DUMMYFUNCTION("""COMPUTED_VALUE"""),7.0) -> 7 | E21: =IFERROR(__xludf.DUMMYFUNCTION("""COMPUTED_VALUE"""),1.0) -> 1 | I21: =sum(F21:H21) -> 0 | K21: =A21 -> 5 | O21: =if(F21=max(F$18:F$21),1,0) -> 1 | P21: =if(G21=max(G$18:G$21),1,0) -> 1 | Q21: =if(H21=max(H$18:H$21),1,0) -> 1 | R21: =sum(O21:Q21) -> 3 | AJ21: Vamsi Lolla
A22: 6 | B22: =IFERROR(__xludf.DUMMYFUNCTION("""COMPUTED_VALUE"""),"Luis Hsu") -> Luis Hsu | C22: =IFERROR(__xludf.DUMMYFUNCTION("""COMPUTED_VALUE"""),216.0) -> 216 | D22: =IFERROR(__xludf.DUMMYFUNCTION("""COMPUTED_VALUE"""),3.0) -> 3 | E22: =IFERROR(__xludf.DUMMYFUNCTION("""COMPUTED_VALUE"""),1.0) -> 1 | I22: =sum(F22:H22) -> 0 | K22: =A22 -> 6 | O22: =if(F22=max(F$22:F$25),1,0) -> 1 | P22: =if(G22=max(G$22:G$25),1,0) -> 1 | Q22: =if(H22=max(H$22:H$25),1,0) -> 1 | R22: =sum(O22:Q22) -> 3 | U22: =if(COUNTIF(AB22:AB24,"Good")=2,"Good","Error") -> Error | V22: =if(COUNTIF(AC22:AC24,"Good")=2,"Good","Error") -> Error | W22: =if(COUNTIF(AD22:AD24,"Good")=2,"Good","Error") -> Error | Y22: =sum(J22:J25) -> 0 | Z22: =if(Y22=0,"",if(Y22=6,"Good","ERROR")) | AB22: =if(isna(VLOOKUP(F22,F23:F25,1,false)),"Error","Good") -> Error | AC22: =if(isna(VLOOKUP(G22,G23:G25,1,false)),"Error","Good") -> Error | AD22: =if(isna(VLOOKUP(H22,H23:H25,1,false)),"Error","Good") -> Error
A23: 6 | B23: =IFERROR(__xludf.DUMMYFUNCTION("""COMPUTED_VALUE"""),"Lloyd Sagar") -> Lloyd Sagar | C23: =IFERROR(__xludf.DUMMYFUNCTION("""COMPUTED_VALUE"""),207.0) -> 207 | D23: =IFERROR(__xludf.DUMMYFUNCTION("""COMPUTED_VALUE"""),0.0) -> 0 | E23: =IFERROR(__xludf.DUMMYFUNCTION("""COMPUTED_VALUE"""),1.0) -> 1 | I23: =sum(F23:H23) -> 0 | K23: =A23 -> 6 | O23: =if(F23=max(F$22:F$25),1,0) -> 1 | P23: =if(G23=max(G$22:G$25),1,0) -> 1 | Q23: =if(H23=max(H$22:H$25),1,0) -> 1 | R23: =sum(O23:Q23) -> 3 | AB23: =if(isna(VLOOKUP(F23,F24:F25,1,false)),"Error","Good") -> Error | AC23: =if(isna(VLOOKUP(G23,G24:G25,1,false)),"Error","Good") -> Error | AD23: =if(isna(VLOOKUP(H23,H24:H25,1,false)),"Error","Good") -> Error
A24: 6 | I24: =sum(F24:H24) -> 0 | K24: =A24 -> 6 | O24: =if(F24=max(F$22:F$25),1,0) -> 1 | P24: =if(G24=max(G$22:G$25),1,0) -> 1 | Q24: =if(H24=max(H$22:H$25),1,0) -> 1 | R24: =sum(O24:Q24) -> 3 | AB24: =if(F24=F25,"Good") -> Good | AC24: =if(G24=G25,"Good") -> Good | AD24: =if(H24=H25,"Good") -> Good | AJ24: Rajasekar Ramasamy
A25: 6 | I25: =sum(F25:H25) -> 0 | K25: =A25 -> 6 | O25: =if(F25=max(F$22:F$25),1,0) -> 1 | P25: =if(G25=max(G$22:G$25),1,0) -> 1 | Q25: =if(H25=max(H$22:H$25),1,0) -> 1 | R25: =sum(O25:Q25) -> 3 | AJ25: Anish Kumar
A26: 7 | I26: =sum(F26:H26) -> 0 | K26: =A26 -> 7 | O26: =if(F26=max(F$26:F$29),1,0) -> 1 | P26: =if(G26=max(G$26:G$29),1,0) -> 1 | Q26: =if(H26=max(H$26:H$29),1,0) -> 1 | R26: =sum(O26:Q26) -> 3 | U26: =if(COUNTIF(AB26:AB28,"Good")=2,"Good","Error") -> Error | V26: =if(COUNTIF(AC26:AC28,"Good")=2,"Good","Error") -> Error | W26: =if(COUNTIF(AD26:AD28,"Good")=2,"Good","Error") -> Error | Y26: =sum(J26:J29) -> 0 | Z26: =if(Y26=0,"",if(Y26=6,"Good","ERROR")) | AB26: =if(isna(VLOOKUP(F26,F27:F29,1,false)),"Error","Good") -> Error | AC26: =if(isna(VLOOKUP(G26,G27:G29,1,false)),"Error","Good") -> Error | AD26: =if(isna(VLOOKUP(H26,H27:H29,1,false)),"Error","Good") -> Error | AJ26: Manuel Rivera
A27: 7 | I27: =sum(F27:H27) -> 0 | K27: =A27 -> 7 | O27: =if(F27=max(F$26:F$29),1,0) -> 1 | P27: =if(G27=max(G$26:G$29),1,0) -> 1 | Q27: =if(H27=max(H$26:H$29),1,0) -> 1 | R27: =sum(O27:Q27) -> 3 | AB27: =if(isna(VLOOKUP(F27,F28:F29,1,false)),"Error","Good") -> Error | AC27: =if(isna(VLOOKUP(G27,G28:G29,1,false)),"Error","Good") -> Error | AD27: =if(isna(VLOOKUP(H27,H28:H29,1,false)),"Error","Good") -> Error | AJ27: Ted Shen
A28: 7 | I28: =sum(F28:H28) -> 0 | K28: =A28 -> 7 | O28: =if(F28=max(F$26:F$29),1,0) -> 1 | P28: =if(G28=max(G$26:G$29),1,0) -> 1 | Q28: =if(H28=max(H$26:H$29),1,0) -> 1 | R28: =sum(O28:Q28) -> 3 | AB28: =if(F28=F29,"Good") -> Good | AC28: =if(G28=G29,"Good") -> Good | AD28: =if(H28=H29,"Good") -> Good
A29: 7 | I29: =sum(F29:H29) -> 0 | K29: =A29 -> 7 | O29: =if(F29=max(F$26:F$29),1,0) -> 1 | P29: =if(G29=max(G$26:G$29),1,0) -> 1 | Q29: =if(H29=max(H$26:H$29),1,0) -> 1 | R29: =sum(O29:Q29) -> 3
A30: 8 | I30: =sum(F30:H30) -> 0 | K30: =A30 -> 8 | O30: =if(F30=max(F$30:F$33),1,0) -> 1 | P30: =if(G30=max(G$30:G$33),1,0) -> 1 | Q30: =if(H30=max(H$30:H$33),1,0) -> 1 | R30: =sum(O30:Q30) -> 3 | U30: =if(COUNTIF(AB30:AB32,"Good")=2,"Good","Error") -> Error | V30: =if(COUNTIF(AC30:AC32,"Good")=2,"Good","Error") -> Error | W30: =if(COUNTIF(AD30:AD32,"Good")=2,"Good","Error") -> Error | Y30: =sum(J30:J33) -> 0 | Z30: =if(Y30=0,"",if(Y30=6,"Good","ERROR")) | AB30: =if(isna(VLOOKUP(F30,F31:F33,1,false)),"Error","Good") -> Error | AC30: =if(isna(VLOOKUP(G30,G31:G33,1,false)),"Error","Good") -> Error | AD30: =if(isna(VLOOKUP(H30,H31:H33,1,false)),"Error","Good") -> Error
A31: 8 | I31: =sum(F31:H31) -> 0 | K31: =A31 -> 8 | O31: =if(F31=max(F$30:F$33),1,0) -> 1 | P31: =if(G31=max(G$30:G$33),1,0) -> 1 | Q31: =if(H31=max(H$30:H$33),1,0) -> 1 | R31: =sum(O31:Q31) -> 3 | AB31: =if(isna(VLOOKUP(F31,F32:F33,1,false)),"Error","Good") -> Error | AC31: =if(isna(VLOOKUP(G31,G32:G33,1,false)),"Error","Good") -> Error | AD31: =if(isna(VLOOKUP(H31,H32:H33,1,false)),"Error","Good") -> Error
A32: 8 | I32: =sum(F32:H32) -> 0 | K32: =A32 -> 8 | O32: =if(F32=max(F$30:F$33),1,0) -> 1 | P32: =if(G32=max(G$30:G$33),1,0) -> 1 | Q32: =if(H32=max(H$30:H$33),1,0) -> 1 | R32: =sum(O32:Q32) -> 3 | AB32: =if(F32=F33,"Good") -> Good | AC32: =if(G32=G33,"Good") -> Good | AD32: =if(H32=H33,"Good") -> Good
A33: 8 | I33: =sum(F33:H33) -> 0 | K33: =A33 -> 8 | O33: =if(F33=max(F$30:F$33),1,0) -> 1 | P33: =if(G33=max(G$30:G$33),1,0) -> 1 | Q33: =if(H33=max(H$30:H$33),1,0) -> 1 | R33: =sum(O33:Q33) -> 3 | AJ33: Chinna Ponnaganti
A34: 9 | I34: =sum(F34:H34) -> 0 | K34: =A34 -> 9 | O34: =if(F34=max(F$34:F$37),1,0) -> 1 | P34: =if(G34=max(G$34:G$37),1,0) -> 1 | Q34: =if(H34=max(H$34:H$37),1,0) -> 1 | R34: =sum(O34:Q34) -> 3 | U34: =if(COUNTIF(AB34:AB36,"Good")=2,"Good","Error") -> Error | V34: =if(COUNTIF(AC34:AC36,"Good")=2,"Good","Error") -> Error | W34: =if(COUNTIF(AD34:AD36,"Good")=2,"Good","Error") -> Error | Y34: =sum(J34:J37) -> 0 | Z34: =if(Y34=0,"",if(Y34=6,"Good","ERROR")) | AB34: =if(isna(VLOOKUP(F34,F35:F37,1,false)),"Error","Good") -> Error | AC34: =if(isna(VLOOKUP(G34,G35:G37,1,false)),"Error","Good") -> Error | AD34: =if(isna(VLOOKUP(H34,H35:H37,1,false)),"Error","Good") -> Error | AJ34: Mauricio Palacios
A35: 9 | I35: =sum(F35:H35) -> 0 | K35: =A35 -> 9 | O35: =if(F35=max(F$34:F$37),1,0) -> 1 | P35: =if(G35=max(G$34:G$37),1,0) -> 1 | Q35: =if(H35=max(H$34:H$37),1,0) -> 1 | R35: =sum(O35:Q35) -> 3 | AB35: =if(isna(VLOOKUP(F35,F36:F37,1,false)),"Error","Good") -> Error | AC35: =if(isna(VLOOKUP(G35,G36:G37,1,false)),"Error","Good") -> Error | AD35: =if(isna(VLOOKUP(H35,H36:H37,1,false)),"Error","Good") -> Error | AJ35: Joyce Zhu
A36: 9 | I36: =sum(F36:H36) -> 0 | K36: =A36 -> 9 | O36: =if(F36=max(F$34:F$37),1,0) -> 1 | P36: =if(G36=max(G$34:G$37),1,0) -> 1 | Q36: =if(H36=max(H$34:H$37),1,0) -> 1 | R36: =sum(O36:Q36) -> 3 | AB36: =if(F36=F37,"Good") -> Good | AC36: =if(G36=G37,"Good") -> Good | AD36: =if(H36=H37,"Good") -> Good | AJ36: Balaji Alahari
A37: 9 | I37: =sum(F37:H37) -> 0 | K37: =A37 -> 9 | O37: =if(F37=max(F$34:F$37),1,0) -> 1 | P37: =if(G37=max(G$34:G$37),1,0) -> 1 | Q37: =if(H37=max(H$34:H$37),1,0) -> 1 | R37: =sum(O37:Q37) -> 3
A38: 10 | I38: =sum(F38:H38) -> 0 | K38: =A38 -> 10 | O38: =if(F38=max(F$34:F$37),1,0) -> 1 | P38: =if(G38=max(G$34:G$37),1,0) -> 1 | Q38: =if(H38=max(H$34:H$37),1,0) -> 1 | R38: =sum(O38:Q38) -> 3 | U38: =if(COUNTIF(AB38:AB40,"Good")=2,"Good","Error") -> Error | V38: =if(COUNTIF(AC38:AC40,"Good")=2,"Good","Error") -> Error | W38: =if(COUNTIF(AD38:AD40,"Good")=2,"Good","Error") -> Error | Y38: =sum(J38:J41) -> 0 | Z38: =if(Y38=0,"",if(Y38=6,"Good","ERROR")) | AB38: =if(isna(VLOOKUP(F38,F39:F41,1,false)),"Error","Good") -> Error | AC38: =if(isna(VLOOKUP(G38,G39:G41,1,false)),"Error","Good") -> Error | AD38: =if(isna(VLOOKUP(H38,H39:H41,1,false)),"Error","Good") -> Error
A39: 10 | I39: =sum(F39:H39) -> 0 | K39: =A39 -> 10 | O39: =if(F39=max(F$34:F$37),1,0) -> 1 | P39: =if(G39=max(G$34:G$37),1,0) -> 1 | Q39: =if(H39=max(H$34:H$37),1,0) -> 1 | R39: =sum(O39:Q39) -> 3 | AB39: =if(isna(VLOOKUP(F39,F40:F41,1,false)),"Error","Good") -> Error | AC39: =if(isna(VLOOKUP(G39,G40:G41,1,false)),"Error","Good") -> Error | AD39: =if(isna(VLOOKUP(H39,H40:H41,1,false)),"Error","Good") -> Error
A40: 10 | I40: =sum(F40:H40) -> 0 | K40: =A40 -> 10 | O40: =if(F40=max(F$34:F$37),1,0) -> 1 | P40: =if(G40=max(G$34:G$37),1,0) -> 1 | Q40: =if(H40=max(H$34:H$37),1,0) -> 1 | R40: =sum(O40:Q40) -> 3 | AB40: =if(F40=F41,"Good") -> Good | AC40: =if(G40=G41,"Good") -> Good | AD40: =if(H40=H41,"Good") -> Good
...

Sheet Checkin
A1: Name of the Player | B1: Check in | C1: Previous sitouts | E1: Sl.No | F1: Playing(1) | G1: Out(3) | H1: Out-Can Play(4) | I1: To Respond | J1: Sitouts(5) | K1: Playing-Can Sit(2) | L1: Previous sitouts | M1: Sit Outs Needed
A2: =IFERROR(__xludf.DUMMYFUNCTION("IMPORTRANGE(""1uZFF2o7rrfB0YZtASdZnP52Ef50ZinvtOPb1Tbuq8J4"",""CheckIn!C1:D99"")"),"Adrian Tay") -> Adrian Tay | B2: =IFERROR(__xludf.DUMMYFUNCTION("""COMPUTED_VALUE"""),3.0) -> 3 | C2: =iferror(VLOOKUP(A2,indirect("'" & "Current" & "'!$B:$T"),19,false),"") -> 0 | D2: =IF(COUNTIF(A:A, A2) > 1, "Duplicate", "") | E2: 1 | F2: =IFERROR(__xludf.DUMMYFUNCTION("QUERY(A2:B99, ""Select A where B = 1 order by A"")"),"Allen Zhang") -> Allen Zhang | G2: =IFERROR(__xludf.DUMMYFUNCTION("QUERY($A2:$B99, ""Select A where B = 3 order by A"")"),"Adrian Tay") -> Adrian Tay | H2: =IFERROR(__xludf.DUMMYFUNCTION("QUERY($A2:$B99, ""Select A where B = 4"")"),"#N/A") -> #N/A | I2: =IFERROR(__xludf.DUMMYFUNCTION("QUERY(Current!B5:F69, ""Select B where F = 0 order by B"")"),"Balaji Alahari") -> Balaji Alahari | J2: =IFERROR(__xludf.DUMMYFUNCTION("QUERY($A2:$C99, ""Select A where B = 5 order by C"")"),"Ranjith Doraiswamy") -> Ranjith Doraiswamy | K2: =IFERROR(__xludf.DUMMYFUNCTION("QUERY($A2:$C99, ""Select A,C where B = 2 order by C"")"),"Camille Jung") -> Camille Jung | M2: =if(P21>0,1,"")
A3: =IFERROR(__xludf.DUMMYFUNCTION("""COMPUTED_VALUE"""),"Wayne Liu") -> Wayne Liu | B3: =IFERROR(__xludf.DUMMYFUNCTION("""COMPUTED_VALUE"""),3.0) -> 3 | C3: =iferror(VLOOKUP(A3,indirect("'" & "Current" & "'!$B:$T"),19,false),"") -> 0 | D3: =IF(COUNTIF(A:A, A3) > 1, "Duplicate", "") | E3: =E2+1 -> 2 | F3: =IFERROR(__xludf.DUMMYFUNCTION("""COMPUTED_VALUE"""),"Andrew Yao") -> Andrew Yao | G3: =IFERROR(__xludf.DUMMYFUNCTION("""COMPUTED_VALUE"""),"Alejandro Mejia") -> Alejandro Mejia | I3: =IFERROR(__xludf.DUMMYFUNCTION("""COMPUTED_VALUE"""),"Barathi Sundaram") -> Barathi Sundaram | J3: =IFERROR(__xludf.DUMMYFUNCTION("""COMPUTED_VALUE"""),"Scott Li") -> Scott Li | K3: =IFERROR(__xludf.DUMMYFUNCTION("""COMPUTED_VALUE"""),"Suleman Alidina") -> Suleman Alidina | L3: =IFERROR(__xludf.DUMMYFUNCTION("""COMPUTED_VALUE"""),0.0) -> 0 | M3: =if(AND(M2>0, counta($K$2:K3)<=$P$21),M2+1,"")
A4: =IFERROR(__xludf.DUMMYFUNCTION("""COMPUTED_VALUE"""),"Tom Le") -> Tom Le | B4: =IFERROR(__xludf.DUMMYFUNCTION("""COMPUTED_VALUE"""),3.0) -> 3 | C4: =iferror(VLOOKUP(A4,indirect("'" & "Current" & "'!$B:$T"),19,false),"") -> 1 | D4: =IF(COUNTIF(A:A, A4) > 1, "Duplicate", "") | E4: =E3+1 -> 3 | F4: =IFERROR(__xludf.DUMMYFUNCTION("""COMPUTED_VALUE"""),"Coco Yan") -> Coco Yan | G4: =IFERROR(__xludf.DUMMYFUNCTION("""COMPUTED_VALUE"""),"Alex Hou") -> Alex Hou | I4: =IFERROR(__xludf.DUMMYFUNCTION("""COMPUTED_VALUE"""),"Hubert J Sung") -> Hubert J Sung | J4: =IFERROR(__xludf.DUMMYFUNCTION("""COMPUTED_VALUE"""),"Herman Au") -> Herman Au | M4: =if(AND(M3>0, counta($K$2:K4)<=$P$21),M3+1,"") | O4: Last update | P4: =now() -> 46311.699 | R4: Whatsapp Message
A5: =IFERROR(__xludf.DUMMYFUNCTION("""COMPUTED_VALUE"""),"Chinna Ponnaganti") -> Chinna Ponnaganti | B5: =IFERROR(__xludf.DUMMYFUNCTION("""COMPUTED_VALUE"""),3.0) -> 3 | C5: =iferror(VLOOKUP(A5,indirect("'" & "Current" & "'!$B:$T"),19,false),"") -> 0 | D5: =IF(COUNTIF(A:A, A5) > 1, "Duplicate", "") | E5: =E4+1 -> 4 | F5: =IFERROR(__xludf.DUMMYFUNCTION("""COMPUTED_VALUE"""),"David Shin") -> David Shin | G5: =IFERROR(__xludf.DUMMYFUNCTION("""COMPUTED_VALUE"""),"Andrew Wen") -> Andrew Wen | I5: =IFERROR(__xludf.DUMMYFUNCTION("""COMPUTED_VALUE"""),"James Phan") -> James Phan | M5: =if(AND(M4>0, counta($K$2:K5)<=$P$21),M4+1,"")
A6: =IFERROR(__xludf.DUMMYFUNCTION("""COMPUTED_VALUE"""),"Joyce Zhu") -> Joyce Zhu | B6: =IFERROR(__xludf.DUMMYFUNCTION("""COMPUTED_VALUE"""),3.0) -> 3 | C6: =iferror(VLOOKUP(A6,indirect("'" & "Current" & "'!$B:$T"),19,false),"") -> 0 | D6: =IF(COUNTIF(A:A, A6) > 1, "Duplicate", "") | E6: =E5+1 -> 5 | F6: =IFERROR(__xludf.DUMMYFUNCTION("""COMPUTED_VALUE"""),"Elayaraja Thangaraj") -> Elayaraja Thangaraj | G6: =IFERROR(__xludf.DUMMYFUNCTION("""COMPUTED_VALUE"""),"Art Hui") -> Art Hui | I6: =IFERROR(__xludf.DUMMYFUNCTION("""COMPUTED_VALUE"""),"Leigh-Anh Nguyen") -> Leigh-Anh Nguyen | M6: =if(AND(M5>0, counta($K$2:K6)<=$P$21),M5+1,"") | O6: Playing | P6: =if(isna(F2),0,COUNTA(F$2:F$58)) -> 26 | R6: =CONCATENATE( "*",P$15," Courts Full*") -> *7 Courts Full*
A7: =IFERROR(__xludf.DUMMYFUNCTION("""COMPUTED_VALUE"""),"Erik Hoeckmann") -> Erik Hoeckmann | B7: =IFERROR(__xludf.DUMMYFUNCTION("""COMPUTED_VALUE"""),1.0) -> 1 | C7: =iferror(VLOOKUP(A7,indirect("'" & "Current" & "'!$B:$T"),19,false),"") -> 1 | D7: =IF(COUNTIF(A:A, A7) > 1, "Duplicate", "") | E7: =E6+1 -> 6 | F7: =IFERROR(__xludf.DUMMYFUNCTION("""COMPUTED_VALUE"""),"Erik Hoeckmann") -> Erik Hoeckmann | G7: =IFERROR(__xludf.DUMMYFUNCTION("""COMPUTED_VALUE"""),"Basudev Thoppai Vidyasankar") -> Basudev Thoppai Vidyasankar | I7: =IFERROR(__xludf.DUMMYFUNCTION("""COMPUTED_VALUE"""),"Sandy Weyant") -> Sandy Weyant | M7: =if(AND(M6>0, counta($K$2:K7)<=$P$21),M6+1,"") | O7: Playing-Can Sit | P7: =if(isna(K2),0,COUNTA(K2:K99)) -> 2
A8: =IFERROR(__xludf.DUMMYFUNCTION("""COMPUTED_VALUE"""),"Joe Luzzi") -> Joe Luzzi | B8: =IFERROR(__xludf.DUMMYFUNCTION("""COMPUTED_VALUE"""),1.0) -> 1 | C8: =iferror(VLOOKUP(A8,indirect("'" & "Current" & "'!$B:$T"),19,false),"") -> 1 | D8: =IF(COUNTIF(A:A, A8) > 1, "Duplicate", "") | E8: =E7+1 -> 7 | F8: =IFERROR(__xludf.DUMMYFUNCTION("""COMPUTED_VALUE"""),"Ethan Gu") -> Ethan Gu | G8: =IFERROR(__xludf.DUMMYFUNCTION("""COMPUTED_VALUE"""),"Chinna Ponnaganti") -> Chinna Ponnaganti | I8: =IFERROR(__xludf.DUMMYFUNCTION("""COMPUTED_VALUE"""),"Tyler Leong") -> Tyler Leong | M8: =if(AND(M7>0, counta($K$2:K8)<=$P$21),M7+1,"") | O8: Out/Can Play | P8: =if(isna(H2),0,COUNTA(H$2:H$58)) -> 0 | R8: =CONCATENATE(O$16," -- *",P$16,"*") -> Playing -- *28*
A9: =IFERROR(__xludf.DUMMYFUNCTION("""COMPUTED_VALUE"""),"Santosh Sundaresan") -> Santosh Sundaresan | B9: =IFERROR(__xludf.DUMMYFUNCTION("""COMPUTED_VALUE"""),3.0) -> 3 | C9: =iferror(VLOOKUP(A9,indirect("'" & "Current" & "'!$B:$T"),19,false),"") -> 0 | D9: =IF(COUNTIF(A:A, A9) > 1, "Duplicate", "") | E9: =E8+1 -> 8 | F9: =IFERROR(__xludf.DUMMYFUNCTION("""COMPUTED_VALUE"""),"Hongyuan Wen") -> Hongyuan Wen | G9: =IFERROR(__xludf.DUMMYFUNCTION("""COMPUTED_VALUE"""),"Cid Macaraeg") -> Cid Macaraeg | M9: =if(AND(M8>0, counta($K$2:K9)<=$P$21),M8+1,"") | O9: Out | P9: =if(isna(G2),0,COUNTA(G$2:G$58)) -> 36 | R9: =CONCATENATE(O$17," ------ ",P$17) -> Out ------ 36
A10: =IFERROR(__xludf.DUMMYFUNCTION("""COMPUTED_VALUE"""),"Sanjaye Elayattu") -> Sanjaye Elayattu | B10: =IFERROR(__xludf.DUMMYFUNCTION("""COMPUTED_VALUE"""),3.0) -> 3 | C10: =iferror(VLOOKUP(A10,indirect("'" & "Current" & "'!$B:$T"),19,false),"") -> 0 | D10: =IF(COUNTIF(A:A, A10) > 1, "Duplicate", "") | E10: =E9+1 -> 9 | F10: =IFERROR(__xludf.DUMMYFUNCTION("""COMPUTED_VALUE"""),"Jaya Sogata") -> Jaya Sogata | G10: =IFERROR(__xludf.DUMMYFUNCTION("""COMPUTED_VALUE"""),"Darren Wong") -> Darren Wong | M10: =if(AND(M9>0, counta($K$2:K10)<=$P$21),M9+1,"") | O10: Sitouts | P10: =if(isna(J2),0,COUNTA(J$2:J$29)) -> 3 | R10: =CONCATENATE(O$18," ------ ",P$18) -> TBD ------ 7
A11: =IFERROR(__xludf.DUMMYFUNCTION("""COMPUTED_VALUE"""),"Cid Macaraeg") -> Cid Macaraeg | B11: =IFERROR(__xludf.DUMMYFUNCTION("""COMPUTED_VALUE"""),3.0) -> 3 | C11: =iferror(VLOOKUP(A11,indirect("'" & "Current" & "'!$B:$T"),19,false),"") -> 0 | D11: =IF(COUNTIF(A:A, A11) > 1, "Duplicate", "") | E11: =E10+1 -> 10 | F11: =IFERROR(__xludf.DUMMYFUNCTION("""COMPUTED_VALUE"""),"Jim Miao") -> Jim Miao | G11: =IFERROR(__xludf.DUMMYFUNCTION("""COMPUTED_VALUE"""),"Eric Pan") -> Eric Pan | M11: =if(AND(M10>0, counta($K$2:K11)<=$P$21),M10+1,"") | O11: TBD | P11: =if(isna(I2),0,COUNTA(I$2:I$99)) -> 7
A12: =IFERROR(__xludf.DUMMYFUNCTION("""COMPUTED_VALUE"""),"Troy Wong") -> Troy Wong | B12: =IFERROR(__xludf.DUMMYFUNCTION("""COMPUTED_VALUE"""),3.0) -> 3 | C12: =iferror(VLOOKUP(A12,indirect("'" & "Current" & "'!$B:$T"),19,false),"") -> 0 | D12: =IF(COUNTIF(A:A, A12) > 1, "Duplicate", "") | E12: =E11+1 -> 11 | F12: =IFERROR(__xludf.DUMMYFUNCTION("""COMPUTED_VALUE"""),"Jimmy Awolesi") -> Jimmy Awolesi | G12: =IFERROR(__xludf.DUMMYFUNCTION("""COMPUTED_VALUE"""),"Eric Tan") -> Eric Tan | M12: =if(AND(M11>0, counta($K$2:K12)<=$P$21),M11+1,"") | O12: Total | P12: =sum(P6:P11) -> 74 | R12: *Sent Reminders*
A13: =IFERROR(__xludf.DUMMYFUNCTION("""COMPUTED_VALUE"""),"Eric Tan") -> Eric Tan | B13: =IFERROR(__xludf.DUMMYFUNCTION("""COMPUTED_VALUE"""),3.0) -> 3 | C13: =iferror(VLOOKUP(A13,indirect("'" & "Current" & "'!$B:$T"),19,false),"") -> 0 | D13: =IF(COUNTIF(A:A, A13) > 1, "Duplicate", "") | E13: =E12+1 -> 12 | F13: =IFERROR(__xludf.DUMMYFUNCTION("""COMPUTED_VALUE"""),"Joe Luzzi") -> Joe Luzzi | G13: =IFERROR(__xludf.DUMMYFUNCTION("""COMPUTED_VALUE"""),"Frank Moon") -> Frank Moon | M13: =if(AND(M12>0, counta($K$2:K13)<=$P$21),M12+1,"")
A14: =IFERROR(__xludf.DUMMYFUNCTION("""COMPUTED_VALUE"""),"Trish Newlin") -> Trish Newlin | B14: =IFERROR(__xludf.DUMMYFUNCTION("""COMPUTED_VALUE"""),3.0) -> 3 | C14: =iferror(VLOOKUP(A14,indirect("'" & "Current" & "'!$B:$T"),19,false),"") -> 1 | D14: =IF(COUNTIF(A:A, A14) > 1, "Duplicate", "") | E14: =E13+1 -> 13 | F14: =IFERROR(__xludf.DUMMYFUNCTION("""COMPUTED_VALUE"""),"Lloyd Sagar") -> Lloyd Sagar | G14: =IFERROR(__xludf.DUMMYFUNCTION("""COMPUTED_VALUE"""),"Jonathan Phan") -> Jonathan Phan | M14: =if(AND(M13>0, counta($K$2:K14)<=$P$21),M13+1,"")
A15: =IFERROR(__xludf.DUMMYFUNCTION("""COMPUTED_VALUE"""),"Pavan Akkimsetty") -> Pavan Akkimsetty | B15: =IFERROR(__xludf.DUMMYFUNCTION("""COMPUTED_VALUE"""),3.0) -> 3 | C15: =iferror(VLOOKUP(A15,indirect("'" & "Current" & "'!$B:$T"),19,false),"") -> 0 | D15: =IF(COUNTIF(A:A, A15) > 1, "Duplicate", "") | E15: =E14+1 -> 14 | F15: =IFERROR(__xludf.DUMMYFUNCTION("""COMPUTED_VALUE"""),"Luis Hsu") -> Luis Hsu | G15: =IFERROR(__xludf.DUMMYFUNCTION("""COMPUTED_VALUE"""),"Joyce Zhu") -> Joyce Zhu | M15: =if(AND(M14>0, counta($K$2:K15)<=$P$21),M14+1,"") | O15: Courts Full | P15: =rounddown(P16/4,0) -> 7 | R15: End of Season
A16: =IFERROR(__xludf.DUMMYFUNCTION("""COMPUTED_VALUE"""),"Sandeep Kamalon") -> Sandeep Kamalon | B16: =IFERROR(__xludf.DUMMYFUNCTION("""COMPUTED_VALUE"""),3.0) -> 3 | C16: =iferror(VLOOKUP(A16,indirect("'" & "Current" & "'!$B:$T"),19,false),"") -> 1 | D16: =IF(COUNTIF(A:A, A16) > 1, "Duplicate", "") | E16: =E15+1 -> 15 | F16: =IFERROR(__xludf.DUMMYFUNCTION("""COMPUTED_VALUE"""),"Manish Anand") -> Manish Anand | G16: =IFERROR(__xludf.DUMMYFUNCTION("""COMPUTED_VALUE"""),"Kumar Palakeel") -> Kumar Palakeel | M16: =if(AND(M15>0, counta($K$2:K16)<=$P$21),M15+1,"") | O16: Playing | P16: =sum(P6:P7) -> 28 | R16: 46018
A17: =IFERROR(__xludf.DUMMYFUNCTION("""COMPUTED_VALUE"""),"Robert Chang") -> Robert Chang | B17: =IFERROR(__xludf.DUMMYFUNCTION("""COMPUTED_VALUE"""),3.0) -> 3 | C17: =iferror(VLOOKUP(A17,indirect("'" & "Current" & "'!$B:$T"),19,false),"") -> 0 | D17: =IF(COUNTIF(A:A, A17) > 1, "Duplicate", "") | E17: =E16+1 -> 16 | F17: =IFERROR(__xludf.DUMMYFUNCTION("""COMPUTED_VALUE"""),"Mauricio Palacios") -> Mauricio Palacios | G17: =IFERROR(__xludf.DUMMYFUNCTION("""COMPUTED_VALUE"""),"Lam Bui") -> Lam Bui | M17: =if(AND(M16>0, counta($K$2:K17)<=$P$21),M16+1,"") | O17: Out | P17: =P9+P8 -> 36
A18: =IFERROR(__xludf.DUMMYFUNCTION("""COMPUTED_VALUE"""),"Oscar Bonilla") -> Oscar Bonilla | B18: =IFERROR(__xludf.DUMMYFUNCTION("""COMPUTED_VALUE"""),3.0) -> 3 | C18: =iferror(VLOOKUP(A18,indirect("'" & "Current" & "'!$B:$T"),19,false),"") -> 0 | D18: =IF(COUNTIF(A:A, A18) > 1, "Duplicate", "") | E18: =E17+1 -> 17 | F18: =IFERROR(__xludf.DUMMYFUNCTION("""COMPUTED_VALUE"""),"Naveen Raj") -> Naveen Raj | G18: =IFERROR(__xludf.DUMMYFUNCTION("""COMPUTED_VALUE"""),"Lenin Belangonda") -> Lenin Belangonda | M18: =if(AND(M17>0, counta($K$2:K18)<=$P$21),M17+1,"") | O18: TBD | P18: =P11 -> 7
A19: =IFERROR(__xludf.DUMMYFUNCTION("""COMPUTED_VALUE"""),"Jim Miao") -> Jim Miao | B19: =IFERROR(__xludf.DUMMYFUNCTION("""COMPUTED_VALUE"""),1.0) -> 1 | C19: =iferror(VLOOKUP(A19,indirect("'" & "Current" & "'!$B:$T"),19,false),"") -> 0 | D19: =IF(COUNTIF(A:A, A19) > 1, "Duplicate", "") | E19: =E18+1 -> 18 | F19: =IFERROR(__xludf.DUMMYFUNCTION("""COMPUTED_VALUE"""),"Nicole Ni") -> Nicole Ni | G19: =IFERROR(__xludf.DUMMYFUNCTION("""COMPUTED_VALUE"""),"Manuel Rivera") -> Manuel Rivera | M19: =if(AND(M18>0, counta($K$2:K19)<=$P$21),M18+1,"") | O19: Total | P19: =sum(P16:P18) -> 71 | Q19: =if(P19>65,"Check duplicates","") -> Check duplicates | R19: Next UTC
A20: =IFERROR(__xludf.DUMMYFUNCTION("""COMPUTED_VALUE"""),"Coco Yan") -> Coco Yan | B20: =IFERROR(__xludf.DUMMYFUNCTION("""COMPUTED_VALUE"""),1.0) -> 1 | C20: =iferror(VLOOKUP(A20,indirect("'" & "Current" & "'!$B:$T"),19,false),"") -> 0 | D20: =IF(COUNTIF(A:A, A20) > 1, "Duplicate", "") | E20: =E19+1 -> 19 | F20: =IFERROR(__xludf.DUMMYFUNCTION("""COMPUTED_VALUE"""),"Pulkit Mathur") -> Pulkit Mathur | G20: =IFERROR(__xludf.DUMMYFUNCTION("""COMPUTED_VALUE"""),"Matthew Huang") -> Matthew Huang | M20: =if(AND(M19>0, counta($K$2:K20)<=$P$21),M19+1,"") | R20: =TODAY() + IF(MOD(7 - WEEKDAY(TODAY()), 7) = 0, 7, MOD(7 - WEEKDAY(TODAY()), 7)) -> 46312
