Workbook

Sheet Current
B1: Standings as of | C1: 46305
B2: Number of Weeks Played | D2: 15 | AC2: =text(C1,"mm/dd/yy") -> 10/10/26
C3: Beginning of week | F3: Current Week Scores | N3: End of week | Q3: Jan-Jun 2026 | R3: Jul-Dec 2026
A4: Ranking | B4: Name of Player | C4: Games Won | D4: Sets Won | E4: Games Won / Match | F4: Check IN | G4: Court # | H4: Set 0 | I4: Set 1 | J4: Set 2 | K4: Set 3 | L4: Games Won | M4: Sets Won | N4: Games Won | O4: Sets Won | P4: Waiver | Q4: Fee | R4: Fee | S4: Games Played | T4: Sit outs | U4: No Shows | V4: Absent | W4: Positions Gained/Lost | X4: Ranking | Y4: Perfect attendence | Z4: Check
A5: 1 | B5: Andrew Yao | C5: 223 | D5: 22 | E5: =if(S5>0,(C5-(V5*9)-(T5*13))/S5,0) -> 15.153846 | F5: =if(isna(VLOOKUP(B5,Checkin!A:B,2,false)),0,VLOOKUP(B5,Checkin!A:B,2,false)) -> 0 | G5: =if(OR($F5=1, $F5=2),VLOOKUP($B5,Courts!$B$2:$K$50,10,false),0) -> 0 | H5: =IF(OR(F5=3,F5=4),9,IF(F5=5,13,0)) -> 0 | I5: =if(OR($F5=1, $F5=2),VLOOKUP($B5,Courts!$B$2:$J$50,5,false),0) -> 0 | J5: =if(OR($F5=1, $F5=2),VLOOKUP($B5,Courts!$B$2:$J$50,6,false),0) -> 0 | K5: =if(OR($F5=1, $F5=2),VLOOKUP($B5,Courts!$B$2:$J$50,7,false),0) -> 0 | L5: =H5+I5+J5+K5 -> 0 | M5: =if(OR($F5=1, $F5=2),VLOOKUP($B5,Courts!$B$2:$J$50,9,false),0) -> 0 | N5: =C5+L5 -> 223 | O5: =D5+M5 -> 22 | P5: X | Q5: X | R5: X | S5: =vlookup(B5,indirect("'" & AC$2 & "'!B5:W71"),18,false)++if(text(C$1,"mm/dd/yy")=$AC$2,0,if(H5>0,0,1)) -> 13 | T5: =if(H5=13,1,0)+vlookup(B5,indirect("'" & AC$2 & "'!B5:W71"),19,false) -> 2 | V5: =vlookup(B5,indirect("'" & AC$2 & "'!B5:W71"),21,false)+if(text(C$1,"mm/dd/yy")=$AC$2,0,if(H5=9,1,0)) -> 0 | W5: =vlookup(B5,indirect("'" & AC$2 & "'!B5:x71"),23,false)-X5 -> 1 | X5: 1 | Y5: =if(S5=D$2,"Y","N") -> N | Z5: =if($D$2=sum(S5:V5),"","Error")
A6: =A5+1 -> 2 | B6: Tom Le | C6: 222 | D6: 24 | E6: =if(S6>0,(C6-(V6*9)-(T6*13))/S6,0) -> 16.909091 | F6: =if(isna(VLOOKUP(B6,Checkin!A:B,2,false)),0,VLOOKUP(B6,Checkin!A:B,2,false)) -> 0 | G6: =if(OR($F6=1, $F6=2),VLOOKUP($B6,Courts!$B$2:$K$50,10,false),0) -> 0 | H6: =IF(OR(F6=3,F6=4),9,IF(F6=5,13,0)) -> 0 | I6: =if(OR($F6=1, $F6=2),VLOOKUP($B6,Courts!$B$2:$J$50,5,false),0) -> 0 | J6: =if(OR($F6=1, $F6=2),VLOOKUP($B6,Courts!$B$2:$J$50,6,false),0) -> 0 | K6: =if(OR($F6=1, $F6=2),VLOOKUP($B6,Courts!$B$2:$J$50,7,false),0) -> 0 | L6: =H6+I6+J6+K6 -> 0 | M6: =if(OR($F6=1, $F6=2),VLOOKUP($B6,Courts!$B$2:$J$50,9,false),0) -> 0 | N6: =C6+L6 -> 222 | O6: =D6+M6 -> 24 | P6: X | Q6: X | R6: X | S6: =vlookup(B6,indirect("'" & AC$2 & "'!B5:W71"),18,false)++if(text(C$1,"mm/dd/yy")=$AC$2,0,if(H6>0,0,1)) -> 11 | T6: =if(H6=13,1,0)+vlookup(B6,indirect("'" & AC$2 & "'!B5:W71"),19,false) -> 0 | V6: =vlookup(B6,indirect("'" & AC$2 & "'!B5:W71"),21,false)+if(text(C$1,"mm/dd/yy")=$AC$2,0,if(H6=9,1,0)) -> 4 | W6: =vlookup(B6,indirect("'" & AC$2 & "'!B5:x71"),23,false)-X6 -> -1 | X6: =X5+1 -> 2 | Y6: =if(S6=D$2,"Y","N") -> N | Z6: =if($D$2=sum(S6:V6),"","Error")
A7: =A6+1 -> 3 | B7: Pavan Akkimsetty | C7: 218 | D7: 22 | E7: =if(S7>0,(C7-(V7*9)-(T7*13))/S7,0) -> 15.076923 | F7: =if(isna(VLOOKUP(B7,Checkin!A:B,2,false)),0,VLOOKUP(B7,Checkin!A:B,2,false)) -> 0 | G7: =if(OR($F7=1, $F7=2),VLOOKUP($B7,Courts!$B$2:$K$50,10,false),0) -> 0 | H7: =IF(OR(F7=3,F7=4),9,IF(F7=5,13,0)) -> 0 | I7: =if(OR($F7=1, $F7=2),VLOOKUP($B7,Courts!$B$2:$J$50,5,false),0) -> 0 | J7: =if(OR($F7=1, $F7=2),VLOOKUP($B7,Courts!$B$2:$J$50,6,false),0) -> 0 | K7: =if(OR($F7=1, $F7=2),VLOOKUP($B7,Courts!$B$2:$J$50,7,false),0) -> 0 | L7: =H7+I7+J7+K7 -> 0 | M7: =if(OR($F7=1, $F7=2),VLOOKUP($B7,Courts!$B$2:$J$50,9,false),0) -> 0 | N7: =C7+L7 -> 218 | O7: =D7+M7 -> 22 | P7: X | Q7: X | R7: X | S7: =vlookup(B7,indirect("'" & AC$2 & "'!B5:W71"),18,false)++if(text(C$1,"mm/dd/yy")=$AC$2,0,if(H7>0,0,1)) -> 13 | T7: =if(H7=13,1,0)+vlookup(B7,indirect("'" & AC$2 & "'!B5:W71"),19,false) -> 1 | V7: =vlookup(B7,indirect("'" & AC$2 & "'!B5:W71"),21,false)+if(text(C$1,"mm/dd/yy")=$AC$2,0,if(H7=9,1,0)) -> 1 | W7: =vlookup(B7,indirect("'" & AC$2 & "'!B5:x71"),23,false)-X7 -> 0 | X7: =X6+1 -> 3 | Y7: =if(S7=D$2,"Y","N") -> N | Z7: =if($D$2=sum(S7:V7),"","Error")
A8: =A7+1 -> 4 | B8: Rudy Tatang | C8: 217 | D8: 19 | E8: =if(S8>0,(C8-(V8*9)-(T8*13))/S8,0) -> 16.4 | F8: =if(isna(VLOOKUP(B8,Checkin!A:B,2,false)),0,VLOOKUP(B8,Checkin!A:B,2,false)) -> 0 | G8: =if(OR($F8=1, $F8=2),VLOOKUP($B8,Courts!$B$2:$K$50,10,false),0) -> 0 | H8: =IF(OR(F8=3,F8=4),9,IF(F8=5,13,0)) -> 0 | I8: =if(OR($F8=1, $F8=2),VLOOKUP($B8,Courts!$B$2:$J$50,5,false),0) -> 0 | J8: =if(OR($F8=1, $F8=2),VLOOKUP($B8,Courts!$B$2:$J$50,6,false),0) -> 0 | K8: =if(OR($F8=1, $F8=2),VLOOKUP($B8,Courts!$B$2:$J$50,7,false),0) -> 0 | L8: =H8+I8+J8+K8 -> 0 | M8: =if(OR($F8=1, $F8=2),VLOOKUP($B8,Courts!$B$2:$J$50,9,false),0) -> 0 | N8: =C8+L8 -> 217 | O8: =D8+M8 -> 19 | P8: X | Q8: X | R8: X | S8: =vlookup(B8,indirect("'" & AC$2 & "'!B5:W71"),18,false)++if(text(C$1,"mm/dd/yy")=$AC$2,0,if(H8>0,0,1)) -> 10 | T8: =if(H8=13,1,0)+vlookup(B8,indirect("'" & AC$2 & "'!B5:W71"),19,false) -> 2 | V8: =vlookup(B8,indirect("'" & AC$2 & "'!B5:W71"),21,false)+if(text(C$1,"mm/dd/yy")=$AC$2,0,if(H8=9,1,0)) -> 3 | W8: =vlookup(B8,indirect("'" & AC$2 & "'!B5:x71"),23,false)-X8 -> 2 | X8: =X7+1 -> 4 | Y8: =if(S8=D$2,"Y","N") -> N | Z8: =if($D$2=sum(S8:V8),"","Error")
A9: =A8+1 -> 5 | B9: Pulkit Mathur | C9: 216 | D9: 24 | E9: =if(S9>0,(C9-(V9*9)-(T9*13))/S9,0) -> 16.3 | F9: =if(isna(VLOOKUP(B9,Checkin!A:B,2,false)),0,VLOOKUP(B9,Checkin!A:B,2,false)) -> 0 | G9: =if(OR($F9=1, $F9=2),VLOOKUP($B9,Courts!$B$2:$K$50,10,false),0) -> 0 | H9: =IF(OR(F9=3,F9=4),9,IF(F9=5,13,0)) -> 0 | I9: =if(OR($F9=1, $F9=2),VLOOKUP($B9,Courts!$B$2:$J$50,5,false),0) -> 0 | J9: =if(OR($F9=1, $F9=2),VLOOKUP($B9,Courts!$B$2:$J$50,6,false),0) -> 0 | K9: =if(OR($F9=1, $F9=2),VLOOKUP($B9,Courts!$B$2:$J$50,7,false),0) -> 0 | L9: =H9+I9+J9+K9 -> 0 | M9: =if(OR($F9=1, $F9=2),VLOOKUP($B9,Courts!$B$2:$J$50,9,false),0) -> 0 | N9: =C9+L9 -> 216 | O9: =D9+M9 -> 24 | P9: X | Q9: X | R9: X | S9: =vlookup(B9,indirect("'" & AC$2 & "'!B5:W71"),18,false)++if(text(C$1,"mm/dd/yy")=$AC$2,0,if(H9>0,0,1)) -> 10 | T9: =if(H9=13,1,0)+vlookup(B9,indirect("'" & AC$2 & "'!B5:W71"),19,false) -> 2 | V9: =vlookup(B9,indirect("'" & AC$2 & "'!B5:W71"),21,false)+if(text(C$1,"mm/dd/yy")=$AC$2,0,if(H9=9,1,0)) -> 3 | W9: =vlookup(B9,indirect("'" & AC$2 & "'!B5:x71"),23,false)-X9 -> -1 | X9: =X8+1 -> 5 | Y9: =if(S9=D$2,"Y","N") -> N | Z9: =if($D$2=sum(S9:V9),"","Error")
A10: =A9+1 -> 6 | B10: David Shin | C10: 210 | D10: 21 | E10: =if(S10>0,(C10-(V10*9)-(T10*13))/S10,0) -> 14.461538 | F10: =if(isna(VLOOKUP(B10,Checkin!A:B,2,false)),0,VLOOKUP(B10,Checkin!A:B,2,false)) -> 0 | G10: =if(OR($F10=1, $F10=2),VLOOKUP($B10,Courts!$B$2:$K$50,10,false),0) -> 0 | H10: =IF(OR(F10=3,F10=4),9,IF(F10=5,13,0)) -> 0 | I10: =if(OR($F10=1, $F10=2),VLOOKUP($B10,Courts!$B$2:$J$50,5,false),0) -> 0 | J10: =if(OR($F10=1, $F10=2),VLOOKUP($B10,Courts!$B$2:$J$50,6,false),0) -> 0 | K10: =if(OR($F10=1, $F10=2),VLOOKUP($B10,Courts!$B$2:$J$50,7,false),0) -> 0 | L10: =H10+I10+J10+K10 -> 0 | M10: =if(OR($F10=1, $F10=2),VLOOKUP($B10,Courts!$B$2:$J$50,9,false),0) -> 0 | N10: =C10+L10 -> 210 | O10: =D10+M10 -> 21 | P10: X | Q10: X | R10: X | S10: =vlookup(B10,indirect("'" & AC$2 & "'!B5:W71"),18,false)++if(text(C$1,"mm/dd/yy")=$AC$2,0,if(H10>0,0,1)) -> 13 | T10: =if(H10=13,1,0)+vlookup(B10,indirect("'" & AC$2 & "'!B5:W71"),19,false) -> 1 | V10: =vlookup(B10,indirect("'" & AC$2 & "'!B5:W71"),21,false)+if(text(C$1,"mm/dd/yy")=$AC$2,0,if(H10=9,1,0)) -> 1 | W10: =vlookup(B10,indirect("'" & AC$2 & "'!B5:x71"),23,false)-X10 -> -1 | X10: =X9+1 -> 6 | Y10: =if(S10=D$2,"Y","N") -> N | Z10: =if($D$2=sum(S10:V10),"","Error")
A11: =A10+1 -> 7 | B11: Jaya Sogata | C11: 210 | D11: 15 | E11: =if(S11>0,(C11-(V11*9)-(T11*13))/S11,0) -> 15.555556 | F11: =if(isna(VLOOKUP(B11,Checkin!A:B,2,false)),0,VLOOKUP(B11,Checkin!A:B,2,false)) -> 0 | G11: =if(OR($F11=1, $F11=2),VLOOKUP($B11,Courts!$B$2:$K$50,10,false),0) -> 0 | H11: =IF(OR(F11=3,F11=4),9,IF(F11=5,13,0)) -> 0 | I11: =if(OR($F11=1, $F11=2),VLOOKUP($B11,Courts!$B$2:$J$50,5,false),0) -> 0 | J11: =if(OR($F11=1, $F11=2),VLOOKUP($B11,Courts!$B$2:$J$50,6,false),0) -> 0 | K11: =if(OR($F11=1, $F11=2),VLOOKUP($B11,Courts!$B$2:$J$50,7,false),0) -> 0 | L11: =H11+I11+J11+K11 -> 0 | M11: =if(OR($F11=1, $F11=2),VLOOKUP($B11,Courts!$B$2:$J$50,9,false),0) -> 0 | N11: =C11+L11 -> 210 | O11: =D11+M11 -> 15 | P11: X | Q11: X | R11: X | S11: =vlookup(B11,indirect("'" & AC$2 & "'!B5:W71"),18,false)++if(text(C$1,"mm/dd/yy")=$AC$2,0,if(H11>0,0,1)) -> 9 | T11: =if(H11=13,1,0)+vlookup(B11,indirect("'" & AC$2 & "'!B5:W71"),19,false) -> 4 | V11: =vlookup(B11,indirect("'" & AC$2 & "'!B5:W71"),21,false)+if(text(C$1,"mm/dd/yy")=$AC$2,0,if(H11=9,1,0)) -> 2 | W11: =vlookup(B11,indirect("'" & AC$2 & "'!B5:x71"),23,false)-X11 -> 2 | X11: =X10+1 -> 7 | Y11: =if(S11=D$2,"Y","N") -> N | Z11: =if($D$2=sum(S11:V11),"","Error")
A12: =A11+1 -> 8 | B12: Suleman Alidina | C12: 206 | D12: 14 | E12: =if(S12>0,(C12-(V12*9)-(T12*13))/S12,0) -> 15.375 | F12: =if(isna(VLOOKUP(B12,Checkin!A:B,2,false)),0,VLOOKUP(B12,Checkin!A:B,2,false)) -> 0 | G12: =if(OR($F12=1, $F12=2),VLOOKUP($B12,Courts!$B$2:$K$50,10,false),0) -> 0 | H12: =IF(OR(F12=3,F12=4),9,IF(F12=5,13,0)) -> 0 | I12: =if(OR($F12=1, $F12=2),VLOOKUP($B12,Courts!$B$2:$J$50,5,false),0) -> 0 | J12: =if(OR($F12=1, $F12=2),VLOOKUP($B12,Courts!$B$2:$J$50,6,false),0) -> 0 | K12: =if(OR($F12=1, $F12=2),VLOOKUP($B12,Courts!$B$2:$J$50,7,false),0) -> 0 | L12: =H12+I12+J12+K12 -> 0 | M12: =if(OR($F12=1, $F12=2),VLOOKUP($B12,Courts!$B$2:$J$50,9,false),0) -> 0 | N12: =C12+L12 -> 206 | O12: =D12+M12 -> 14 | P12: X | Q12: X | R12: X | S12: =vlookup(B12,indirect("'" & AC$2 & "'!B5:W71"),18,false)++if(text(C$1,"mm/dd/yy")=$AC$2,0,if(H12>0,0,1)) -> 8 | T12: =if(H12=13,1,0)+vlookup(B12,indirect("'" & AC$2 & "'!B5:W71"),19,false) -> 5 | V12: =vlookup(B12,indirect("'" & AC$2 & "'!B5:W71"),21,false)+if(text(C$1,"mm/dd/yy")=$AC$2,0,if(H12=9,1,0)) -> 2 | W12: =vlookup(B12,indirect("'" & AC$2 & "'!B5:x71"),23,false)-X12 -> 4 | X12: =X11+1 -> 8 | Y12: =if(S12=D$2,"Y","N") -> N | Z12: =if($D$2=sum(S12:V12),"","Error")
A13: =A12+1 -> 9 | B13: Vinotkumar Nagappan | C13: 205 | D13: 16 | E13: =if(S13>0,(C13-(V13*9)-(T13*13))/S13,0) -> 13.666667 | F13: =if(isna(VLOOKUP(B13,Checkin!A:B,2,false)),0,VLOOKUP(B13,Checkin!A:B,2,false)) -> 0 | G13: =if(OR($F13=1, $F13=2),VLOOKUP($B13,Courts!$B$2:$K$50,10,false),0) -> 0 | H13: =IF(OR(F13=3,F13=4),9,IF(F13=5,13,0)) -> 0 | I13: =if(OR($F13=1, $F13=2),VLOOKUP($B13,Courts!$B$2:$J$50,5,false),0) -> 0 | J13: =if(OR($F13=1, $F13=2),VLOOKUP($B13,Courts!$B$2:$J$50,6,false),0) -> 0 | K13: =if(OR($F13=1, $F13=2),VLOOKUP($B13,Courts!$B$2:$J$50,7,false),0) -> 0 | L13: =H13+I13+J13+K13 -> 0 | M13: =if(OR($F13=1, $F13=2),VLOOKUP($B13,Courts!$B$2:$J$50,9,false),0) -> 0 | N13: =C13+L13 -> 205 | O13: =D13+M13 -> 16 | P13: X | Q13: X | R13: X | S13: =vlookup(B13,indirect("'" & AC$2 & "'!B5:W71"),18,false)++if(text(C$1,"mm/dd/yy")=$AC$2,0,if(H13>0,0,1)) -> 15 | T13: =if(H13=13,1,0)+vlookup(B13,indirect("'" & AC$2 & "'!B5:W71"),19,false) -> 0 | V13: =vlookup(B13,indirect("'" & AC$2 & "'!B5:W71"),21,false)+if(text(C$1,"mm/dd/yy")=$AC$2,0,if(H13=9,1,0)) -> 0 | W13: =vlookup(B13,indirect("'" & AC$2 & "'!B5:x71"),23,false)-X13 -> -1 | X13: =X12+1 -> 9 | Y13: =if(S13=D$2,"Y","N") -> Y | Z13: =if($D$2=sum(S13:V13),"","Error")
A14: =A13+1 -> 10 | B14: Ruben Ron | C14: 205 | D14: 15 | E14: =if(S14>0,(C14-(V14*9)-(T14*13))/S14,0) -> 16.714286 | F14: =if(isna(VLOOKUP(B14,Checkin!A:B,2,false)),0,VLOOKUP(B14,Checkin!A:B,2,false)) -> 0 | G14: =if(OR($F14=1, $F14=2),VLOOKUP($B14,Courts!$B$2:$K$50,10,false),0) -> 0 | H14: =IF(OR(F14=3,F14=4),9,IF(F14=5,13,0)) -> 0 | I14: =if(OR($F14=1, $F14=2),VLOOKUP($B14,Courts!$B$2:$J$50,5,false),0) -> 0 | J14: =if(OR($F14=1, $F14=2),VLOOKUP($B14,Courts!$B$2:$J$50,6,false),0) -> 0 | K14: =if(OR($F14=1, $F14=2),VLOOKUP($B14,Courts!$B$2:$J$50,7,false),0) -> 0 | L14: =H14+I14+J14+K14 -> 0 | M14: =if(OR($F14=1, $F14=2),VLOOKUP($B14,Courts!$B$2:$J$50,9,false),0) -> 0 | N14: =C14+L14 -> 205 | O14: =D14+M14 -> 15 | P14: X | Q14: X | R14: X | S14: =vlookup(B14,indirect("'" & AC$2 & "'!B5:W71"),18,false)++if(text(C$1,"mm/dd/yy")=$AC$2,0,if(H14>0,0,1)) -> 7 | T14: =if(H14=13,1,0)+vlookup(B14,indirect("'" & AC$2 & "'!B5:W71"),19,false) -> 4 | V14: =vlookup(B14,indirect("'" & AC$2 & "'!B5:W71"),21,false)+if(text(C$1,"mm/dd/yy")=$AC$2,0,if(H14=9,1,0)) -> 4 | W14: =vlookup(B14,indirect("'" & AC$2 & "'!B5:x71"),23,false)-X14 -> 1 | X14: =X13+1 -> 10 | Y14: =if(S14=D$2,"Y","N") -> N | Z14: =if($D$2=sum(S14:V14),"","Error")
A15: =A14+1 -> 11 | B15: Manish Anand | C15: 204 | D15: 18 | E15: =if(S15>0,(C15-(V15*9)-(T15*13))/S15,0) -> 14.416667 | F15: =if(isna(VLOOKUP(B15,Checkin!A:B,2,false)),0,VLOOKUP(B15,Checkin!A:B,2,false)) -> 0 | G15: =if(OR($F15=1, $F15=2),VLOOKUP($B15,Courts!$B$2:$K$50,10,false),0) -> 0 | H15: =IF(OR(F15=3,F15=4),9,IF(F15=5,13,0)) -> 0 | I15: =if(OR($F15=1, $F15=2),VLOOKUP($B15,Courts!$B$2:$J$50,5,false),0) -> 0 | J15: =if(OR($F15=1, $F15=2),VLOOKUP($B15,Courts!$B$2:$J$50,6,false),0) -> 0 | K15: =if(OR($F15=1, $F15=2),VLOOKUP($B15,Courts!$B$2:$J$50,7,false),0) -> 0 | L15: =H15+I15+J15+K15 -> 0 | M15: =if(OR($F15=1, $F15=2),VLOOKUP($B15,Courts!$B$2:$J$50,9,false),0) -> 0 | N15: =C15+L15 -> 204 | O15: =D15+M15 -> 18 | P15: X | Q15: X | R15: X | S15: =vlookup(B15,indirect("'" & AC$2 & "'!B5:W71"),18,false)++if(text(C$1,"mm/dd/yy")=$AC$2,0,if(H15>0,0,1)) -> 12 | T15: =if(H15=13,1,0)+vlookup(B15,indirect("'" & AC$2 & "'!B5:W71"),19,false) -> 1 | V15: =vlookup(B15,indirect("'" & AC$2 & "'!B5:W71"),21,false)+if(text(C$1,"mm/dd/yy")=$AC$2,0,if(H15=9,1,0)) -> 2 | W15: =vlookup(B15,indirect("'" & AC$2 & "'!B5:x71"),23,false)-X15 -> -4 | X15: =X14+1 -> 11 | Y15: =if(S15=D$2,"Y","N") -> N | Z15: =if($D$2=sum(S15:V15),"","Error")
A16: =A15+1 -> 12 | B16: Rajasekar Ramasamy | C16: 203 | D16: 19 | E16: =if(S16>0,(C16-(V16*9)-(T16*13))/S16,0) -> 13.615385 | F16: =if(isna(VLOOKUP(B16,Checkin!A:B,2,false)),0,VLOOKUP(B16,Checkin!A:B,2,false)) -> 0 | G16: =if(OR($F16=1, $F16=2),VLOOKUP($B16,Courts!$B$2:$K$50,10,false),0) -> 0 | H16: =IF(OR(F16=3,F16=4),9,IF(F16=5,13,0)) -> 0 | I16: =if(OR($F16=1, $F16=2),VLOOKUP($B16,Courts!$B$2:$J$50,5,false),0) -> 0 | J16: =if(OR($F16=1, $F16=2),VLOOKUP($B16,Courts!$B$2:$J$50,6,false),0) -> 0 | K16: =if(OR($F16=1, $F16=2),VLOOKUP($B16,Courts!$B$2:$J$50,7,false),0) -> 0 | L16: =H16+I16+J16+K16 -> 0 | M16: =if(OR($F16=1, $F16=2),VLOOKUP($B16,Courts!$B$2:$J$50,9,false),0) -> 0 | N16: =C16+L16 -> 203 | O16: =D16+M16 -> 19 | P16: X | Q16: X | R16: X | S16: =vlookup(B16,indirect("'" & AC$2 & "'!B5:W71"),18,false)++if(text(C$1,"mm/dd/yy")=$AC$2,0,if(H16>0,0,1)) -> 13 | T16: =if(H16=13,1,0)+vlookup(B16,indirect("'" & AC$2 & "'!B5:W71"),19,false) -> 2 | V16: =vlookup(B16,indirect("'" & AC$2 & "'!B5:W71"),21,false)+if(text(C$1,"mm/dd/yy")=$AC$2,0,if(H16=9,1,0)) -> 0 | W16: =vlookup(B16,indirect("'" & AC$2 & "'!B5:x71"),23,false)-X16 -> -2 | X16: =X15+1 -> 12 | Y16: =if(S16=D$2,"Y","N") -> N | Z16: =if($D$2=sum(S16:V16),"","Error")
A17: =A16+1 -> 13 | B17: Sandeep Kamalon | C17: 200 | D17: 18 | E17: =if(S17>0,(C17-(V17*9)-(T17*13))/S17,0) -> 15.333333 | F17: =if(isna(VLOOKUP(B17,Checkin!A:B,2,false)),0,VLOOKUP(B17,Checkin!A:B,2,false)) -> 0 | G17: =if(OR($F17=1, $F17=2),VLOOKUP($B17,Courts!$B$2:$K$50,10,false),0) -> 0 | H17: =IF(OR(F17=3,F17=4),9,IF(F17=5,13,0)) -> 0 | I17: =if(OR($F17=1, $F17=2),VLOOKUP($B17,Courts!$B$2:$J$50,5,false),0) -> 0 | J17: =if(OR($F17=1, $F17=2),VLOOKUP($B17,Courts!$B$2:$J$50,6,false),0) -> 0 | K17: =if(OR($F17=1, $F17=2),VLOOKUP($B17,Courts!$B$2:$J$50,7,false),0) -> 0 | L17: =H17+I17+J17+K17 -> 0 | M17: =if(OR($F17=1, $F17=2),VLOOKUP($B17,Courts!$B$2:$J$50,9,false),0) -> 0 | N17: =C17+L17 -> 200 | O17: =D17+M17 -> 18 | P17: X | Q17: X | R17: X | S17: =vlookup(B17,indirect("'" & AC$2 & "'!B5:W71"),18,false)++if(text(C$1,"mm/dd/yy")=$AC$2,0,if(H17>0,0,1)) -> 9 | T17: =if(H17=13,1,0)+vlookup(B17,indirect("'" & AC$2 & "'!B5:W71"),19,false) -> 2 | V17: =vlookup(B17,indirect("'" & AC$2 & "'!B5:W71"),21,false)+if(text(C$1,"mm/dd/yy")=$AC$2,0,if(H17=9,1,0)) -> 4 | W17: =vlookup(B17,indirect("'" & AC$2 & "'!B5:x71"),23,false)-X17 -> 4 | X17: =X16+1 -> 13 | Y17: =if(S17=D$2,"Y","N") -> N | Z17: =if($D$2=sum(S17:V17),"","Error")
... A71: =A70+1 -> 67 | B71: Vicki Martinet | C71: 135 | D71: 0 | E71: =if(S71>0,(C71-(V71*9)-(T71*13))/S71,0) -> 5 | F71: =if(isna(VLOOKUP(B71,Checkin!A:B,2,false)),0,VLOOKUP(B71,Checkin!A:B,2,false)) -> 0 | G71: =if(OR($F71=1, $F71=2),VLOOKUP($B71,Courts!$B$2:$K$50,10,false),0) -> 0 | H71: =IF(OR(F71=3,F71=4),9,IF(F71=5,13,0)) -> 0 | I71: =if(OR($F71=1, $F71=2),VLOOKUP($B71,Courts!$B$2:$J$50,5,false),0) -> 0 | J71: =if(OR($F71=1, $F71=2),VLOOKUP($B71,Courts!$B$2:$J$50,6,false),0) -> 0 | K71: =if(OR($F71=1, $F71=2),VLOOKUP($B71,Courts!$B$2:$J$50,7,false),0) -> 0 | L71: =H71+I71+J71+K71 -> 0 | M71: =if(OR($F71=1, $F71=2),VLOOKUP($B71,Courts!$B$2:$J$50,9,false),0) -> 0 | N71: =C71+L71 -> 135 | O71: =D71+M71 -> 0 | P71: X | Q71: X | R71: X | S71: =vlookup(B71,indirect("'" & AC$2 & "'!B5:W71"),18,false)++if(text(C$1,"mm/dd/yy")=$AC$2,0,if(H71>0,0,1)) -> 1 | T71: =if(H71=13,1,0)+vlookup(B71,indirect("'" & AC$2 & "'!B5:W71"),19,false) -> 1 | V71: =vlookup(B71,indirect("'" & AC$2 & "'!B5:W71"),21,false)+if(text(C$1,"mm/dd/yy")=$AC$2,0,if(H71=9,1,0)) -> 13 | W71: =vlookup(B71,indirect("'" & AC$2 & "'!B5:x71"),23,false)-X71 -> 0 | X71: =X70+1 -> 67 | Y71: =if(S71=D$2,"Y","N") -> N | Z71: =if($D$2=sum(S71:V71),"","Error")
P75: Membership Renewals
P76: Renewed | R76: =countif(R5:R71,"X") -> 67 | S76: =R76/R79 -> 1
B77: For Publishing in the WhatsApp Group for the score updates on saturday | P77: Not Renewing | R77: =countif(R5:R71,"N") -> 0
P78: To Renew | R78: =countif(R5:R71,"") -> 0
P79: Total | R79: =sum(R76:R78) -> 67
B80: =concatenate("Top Scores : " &AC2) -> Top Scores : 10/10/26
B82: Name of Player | C82: Games | D82: Sets | E82: Court #
B83: =IFERROR(__xludf.DUMMYFUNCTION("QUERY(indirect(AC2 & ""!B5:M79""),""Select B, L, M, G where L >= 18 order by L desc,M desc"",0)"),"Naveen Raj") -> Naveen Raj | C83: =IFERROR(__xludf.DUMMYFUNCTION("""COMPUTED_VALUE"""),19.0) -> 19 | D83: =IFERROR(__xludf.DUMMYFUNCTION("""COMPUTED_VALUE"""),3.0) -> 3 | E83: =IFERROR(__xludf.DUMMYFUNCTION("""COMPUTED_VALUE"""),6.0) -> 6
B84: =IFERROR(__xludf.DUMMYFUNCTION("""COMPUTED_VALUE"""),"Suleman Alidina") -> Suleman Alidina | C84: =IFERROR(__xludf.DUMMYFUNCTION("""COMPUTED_VALUE"""),18.0) -> 18 | D84: =IFERROR(__xludf.DUMMYFUNCTION("""COMPUTED_VALUE"""),3.0) -> 3 | E84: =IFERROR(__xludf.DUMMYFUNCTION("""COMPUTED_VALUE"""),3.0) -> 3
B85: =IFERROR(__xludf.DUMMYFUNCTION("""COMPUTED_VALUE"""),"Sandeep Kamalon") -> Sandeep Kamalon | C85: =IFERROR(__xludf.DUMMYFUNCTION("""COMPUTED_VALUE"""),18.0) -> 18 | D85: =IFERROR(__xludf.DUMMYFUNCTION("""COMPUTED_VALUE"""),3.0) -> 3 | E85: =IFERROR(__xludf.DUMMYFUNCTION("""COMPUTED_VALUE"""),4.0) -> 4
B86: =IFERROR(__xludf.DUMMYFUNCTION("""COMPUTED_VALUE"""),"Andrew Yao") -> Andrew Yao | C86: =IFERROR(__xludf.DUMMYFUNCTION("""COMPUTED_VALUE"""),18.0) -> 18 | D86: =IFERROR(__xludf.DUMMYFUNCTION("""COMPUTED_VALUE"""),2.0) -> 2 | E86: =IFERROR(__xludf.DUMMYFUNCTION("""COMPUTED_VALUE"""),1.0) -> 1
B87: =IFERROR(__xludf.DUMMYFUNCTION("""COMPUTED_VALUE"""),"Jaya Sogata") -> Jaya Sogata | C87: =IFERROR(__xludf.DUMMYFUNCTION("""COMPUTED_VALUE"""),18.0) -> 18 | D87: =IFERROR(__xludf.DUMMYFUNCTION("""COMPUTED_VALUE"""),2.0) -> 2 | E87: =IFERROR(__xludf.DUMMYFUNCTION("""COMPUTED_VALUE"""),2.0) -> 2
B99: Top 10 Climbers
B101: Name of Player | C101: Positions Moved | D101: Position Last week | E101: Position This week | F101: Points this week | G101: Court | L101: Cross Check
B102: =IFERROR(__xludf.DUMMYFUNCTION("query(B5:W71,""select B, W order by W Desc Limit 10"")"),"Naveen Raj") -> Naveen Raj | C102: =IFERROR(__xludf.DUMMYFUNCTION("""COMPUTED_VALUE"""),9.0) -> 9 | D102: =VLOOKUP(B102,indirect($AC$2&"!B$5:X$79"),23, false) -> 33 | E102: =VLOOKUP(B102,B$5:X$71,23, false) -> 24 | F102: =VLOOKUP(B102,indirect($AC$2&"!B$5:U$79"),11, false) -> 19 | G102: =VLOOKUP(B102,indirect($AC$2&"!B$5:U$79"),6, false) -> 6 | L102: =if(D102-E102=C102,"ok","Error") -> ok
B103: =IFERROR(__xludf.DUMMYFUNCTION("""COMPUTED_VALUE"""),"Alex Hou") -> Alex Hou | C103: =IFERROR(__xludf.DUMMYFUNCTION("""COMPUTED_VALUE"""),9.0) -> 9 | D103: =VLOOKUP(B103,indirect($AC$2&"!B$5:X$79"),23, false) -> 51 | E103: =VLOOKUP(B103,B$5:X$71,23, false) -> 42 | F103: =VLOOKUP(B103,indirect($AC$2&"!B$5:U$79"),11, false) -> 17 | G103: =VLOOKUP(B103,indirect($AC$2&"!B$5:U$79"),6, false) -> 8 | L103: =if(D103-E103=C103,"ok","Error") -> ok
B104: =IFERROR(__xludf.DUMMYFUNCTION("""COMPUTED_VALUE"""),"Ramesh Bandaru") -> Ramesh Bandaru | C104: =IFERROR(__xludf.DUMMYFUNCTION("""COMPUTED_VALUE"""),6.0) -> 6 | D104: =VLOOKUP(B104,indirect($AC$2&"!B$5:X$79"),23, false) -> 39 | E104: =VLOOKUP(B104,B$5:X$71,23, false) -> 33 | F104: =VLOOKUP(B104,indirect($AC$2&"!B$5:U$79"),11, false) -> 16 | G104: =VLOOKUP(B104,indirect($AC$2&"!B$5:U$79"),6, false) -> 7 | L104: =if(D104-E104=C104,"ok","Error") -> ok
B105: =IFERROR(__xludf.DUMMYFUNCTION("""COMPUTED_VALUE"""),"Suleman Alidina") -> Suleman Alidina | C105: =IFERROR(__xludf.DUMMYFUNCTION("""COMPUTED_VALUE"""),4.0) -> 4 | D105: =VLOOKUP(B105,indirect($AC$2&"!B$5:X$79"),23, false) -> 12 | E105: =VLOOKUP(B105,B$5:X$71,23, false) -> 8 | F105: =VLOOKUP(B105,indirect($AC$2&"!B$5:U$79"),11, false) -> 18 | G105: =VLOOKUP(B105,indirect($AC$2&"!B$5:U$79"),6, false) -> 3 | L105: =if(D105-E105=C105,"ok","Error") -> ok
B106: =IFERROR(__xludf.DUMMYFUNCTION("""COMPUTED_VALUE"""),"Sandeep Kamalon") -> Sandeep Kamalon | C106: =IFERROR(__xludf.DUMMYFUNCTION("""COMPUTED_VALUE"""),4.0) -> 4 | D106: =VLOOKUP(B106,indirect($AC$2&"!B$5:X$79"),23, false) -> 17 | E106: =VLOOKUP(B106,B$5:X$71,23, false) -> 13 | F106: =VLOOKUP(B106,indirect($AC$2&"!B$5:U$79"),11, false) -> 18 | G106: =VLOOKUP(B106,indirect($AC$2&"!B$5:U$79"),6, false) -> 4 | L106: =if(D106-E106=C106,"ok","Error") -> ok
B107: =IFERROR(__xludf.DUMMYFUNCTION("""COMPUTED_VALUE"""),"Lloyd Sagar") -> Lloyd Sagar | C107: =IFERROR(__xludf.DUMMYFUNCTION("""COMPUTED_VALUE"""),4.0) -> 4 | D107: =VLOOKUP(B107,indirect($AC$2&"!B$5:X$79"),23, false) -> 31 | E107: =VLOOKUP(B107,B$5:X$71,23, false) -> 27 | F107: =VLOOKUP(B107,indirect($AC$2&"!B$5:U$79"),11, false) -> 16 | G107: =VLOOKUP(B107,indirect($AC$2&"!B$5:U$79"),6, false) -> 5 | L107: =if(D107-E107=C107,"ok","Error") -> ok
B108: =IFERROR(__xludf.DUMMYFUNCTION("""COMPUTED_VALUE"""),"Lenin Belangonda") -> Lenin Belangonda | C108: =IFERROR(__xludf.DUMMYFUNCTION("""COMPUTED_VALUE"""),4.0) -> 4 | D108: =VLOOKUP(B108,indirect($AC$2&"!B$5:X$79"),23, false) -> 61 | E108: =VLOOKUP(B108,B$5:X$71,23, false) -> 57 | F108: =VLOOKUP(B108,indirect($AC$2&"!B$5:U$79"),11, false) -> 13 | G108: =VLOOKUP(B108,indirect($AC$2&"!B$5:U$79"),6, false) -> 0 | L108: =if(D108-E108=C108,"ok","Error") -> ok
B109: =IFERROR(__xludf.DUMMYFUNCTION("""COMPUTED_VALUE"""),"Ethan Gu") -> Ethan Gu | C109: =IFERROR(__xludf.DUMMYFUNCTION("""COMPUTED_VALUE"""),3.0) -> 3 | D109: =VLOOKUP(B109,indirect($AC$2&"!B$5:X$79"),23, false) -> 28 | E109: =VLOOKUP(B109,B$5:X$71,23, false) -> 25 | F109: =VLOOKUP(B109,indirect($AC$2&"!B$5:U$79"),11, false) -> 14 | G109: =VLOOKUP(B109,indirect($AC$2&"!B$5:U$79"),6, false) -> 5 | L109: =if(D109-E109=C109,"ok","Error") -> ok
...

Sheet Courts
A1: Court # | B1: Name of the Player | C1: Games Won | D1: Sets Won | E1: Check In | F1: Set 1 | G1: Set 2 | H1: Set 3 | I1: Total Games won | J1: Sets Won | K1: Court # | L1: Scores Entered by | M1: WHS | N1: Count of Player at WHS | O1: Suggestion for WHS | P1: Admin | Q1: No WHS | S1: Set 1 | T1: Set 2 | U1: Set 3 | V1: Sets Won | AA1: Court # | AQ1: court # | AR1: Admin | AS1: Players
A2: 1 | B2: =IFERROR(__xludf.DUMMYFUNCTION("QUERY(indirect(""'"" & ""Current"" & ""'!B5:F79""),""Select B, C, D, F where F = 1 or F = 2 "",0)"),"#N/A") -> #N/A | I2: =sum(F2:H2) -> 0 | J2: =if(sum(F2:F5)=0,0,if(max(F2:F5)=F2,1,0)+if(max(G2:G5)=G2,1,0)+if(max(H2:H5)=H2,1,0)) -> 0 | K2: =A2 -> 1 | O2: =sum(N2:N5) -> 0 | P2: =countif(Z$73:Z$79,B2) -> 0 | Q2: =sum(P2:P5) -> 0 | S2: =if(sum(F2:F5)=0,"",if(or(max(F2:F5)=6, max(F2:F5)=7),"G","E")) | T2: =if(sum(G2:G5)=0,"",if(or(max(G2:G5)=6, max(G2:G5)=7),"G","E")) | U2: =if(sum(H2:H5)=0,"",if(or(max(H2:H5)=6, max(H2:H5)=7),"G","E")) | V2: =if(sum(F2:F5)=0,0,if(max(F2:F5)=F2,1,0)+if(max(G2:G5)=G2,1,0)+if(max(H2:H5)=H2,1,0)) -> 0 | W2: Max=6/7 | AA2: =if(M2<>"","W" & vlookup(B2,B$122:E$133,4,false),"D" & vlookup(B2,B44:E75,4,false)) -> #N/A | AQ2: =K2 -> 1 | AR2: =P2 -> 0 | AS2: =counta(B2) -> 1
A3: 1 | I3: =sum(F3:H3) -> 0 | J3: =if(sum(F2:F5)=0,0,if(max(F2:F5)=F3,1,0)+if(max(G2:G5)=G3,1,0)+if(max(H2:H5)=H3,1,0)) -> 0 | K3: =A3 -> 1 | P3: =countif(Z$73:Z$79,B3) -> 0 | S3: =if(sum(F2:F5)=0,"",if(SUMPRODUCT(1/COUNTIF(F2:F5, F2:F5))=2,"G","E")) | T3: =if(sum(G2:G5)=0,"",if(SUMPRODUCT(1/COUNTIF(G2:G5, G2:G5))=2,"G","E")) | U3: =if(sum(H2:H5)=0,"",if(SUMPRODUCT(1/COUNTIF(H2:H5, H2:H5))=2,"G","E")) | V3: =if(sum(F2:F5)=0,0,if(max(F2:F5)=F3,1,0)+if(max(G2:G5)=G3,1,0)+if(max(H2:H5)=H3,1,0)) -> 0 | W3: two equal scores | AA3: =if(M3<>"","W" & vlookup(B3,B$122:E$133,4,false),"D" & vlookup(B3,B45:E76,4,false)) -> #N/A | AD3: Court # | AE3: Scores | AQ3: =K3 -> 1 | AR3: =P3 -> 0 | AS3: =counta(B3) -> 0
A4: 1 | I4: =sum(F4:H4) -> 0 | J4: =if(sum(F2:F5)=0,0,if(max(F2:F5)=F4,1,0)+if(max(G2:G5)=G4,1,0)+if(max(H2:H5)=H4,1,0)) -> 0 | K4: =A4 -> 1 | P4: =countif(Z$73:Z$79,B4) -> 0 | S4: =if(sum(F2:F5)=0,"",if(and(max(F2:F5)=7, min(F2:F5)=6),"G",if(max(F2:F5)-min(F2:F5)>=2,"G","E"))) | T4: =if(sum(G2:G5)=0,"",if(and(max(G2:G5)=7, min(G2:G5)=6),"G",if(max(G2:G5)-min(G2:G5)>=2,"G","E"))) | U4: =if(sum(H2:H5)=0,"",if(and(max(H2:H5)=7, min(H2:H5)=6),"G",if(max(H2:H5)-min(H2:H5)>=2,"G","E"))) | V4: =if(sum(F2:F5)=0,0,if(max(F2:F5)=F4,1,0)+if(max(G2:G5)=G4,1,0)+if(max(H2:H5)=H4,1,0)) -> 0 | W4: Diff of 2 or tie breaker | AA4: =if(M4<>"","W" & vlookup(B4,B$122:E$133,4,false),"D" & vlookup(B4,B46:E77,4,false)) -> #N/A | AD4: 1 | AE4: =IF(B2="", "X", IF(COUNTA(F2:H2)=0, "N", "Y")) -> #N/A | AQ4: =K4 -> 1 | AR4: =P4 -> 0 | AS4: =counta(B4) -> 0
A5: 1 | I5: =sum(F5:H5) -> 0 | J5: =if(sum(F2:F5)=0,0,if(max(F2:F5)=F5,1,0)+if(max(G2:G5)=G5,1,0)+if(max(H2:H5)=H5,1,0)) -> 0 | K5: =A5 -> 1 | P5: =countif(Z$73:Z$79,B5) -> 0 | S5: =IF(COUNTIF(S2:S4, "") = 3, "", IF(COUNTIF(S2:S4, "G") = 3, "G", "E")) | T5: =IF(COUNTIF(T2:T4, "") = 3, "", IF(COUNTIF(T2:T4, "G") = 3, "G", "E")) | U5: =IF(COUNTIF(U2:U4, "") = 3, "", IF(COUNTIF(U2:U4, "G") = 3, "G", "E")) | V5: =if(sum(F2:F5)=0,0,if(max(F2:F5)=F5,1,0)+if(max(G2:G5)=G5,1,0)+if(max(H2:H5)=H5,1,0)) -> 0 | W5: All Good | AA5: =if(M5<>"","W" & vlookup(B5,B$122:E$133,4,false),"D" & vlookup(B5,B47:E78,4,false)) -> #N/A | AD5: 2 | AE5: =IF(B6="", "X", IF(COUNTA(F6:H6)=0, "N", "Y")) -> X | AQ5: =K5 -> 1 | AR5: =P5 -> 0 | AS5: =counta(B5) -> 0
A6: 2 | I6: =sum(F6:H6) -> 0 | J6: =if(sum(F6:F9)=0,0,if(max(F6:F9)=F6,1,0)+if(max(G6:G9)=G6,1,0)+if(max(H6:H9)=H6,1,0)) -> 0 | K6: =A6 -> 2 | O6: =sum(N6:N9) -> 0 | P6: =countif(Z$73:Z$79,B6) -> 0 | Q6: =sum(P6:P9) -> 0 | S6: =if(sum(F6:F9)=0,"",if(or(max(F6:F9)=6, max(F6:F9)=7),"G","E")) | T6: =if(sum(G6:G9)=0,"",if(or(max(G6:G9)=6, max(G6:G9)=7),"G","E")) | U6: =if(sum(H6:H9)=0,"",if(or(max(H6:H9)=6, max(H6:H9)=7),"G","E")) | V6: =if(sum(F6:F9)=0,0,if(max(F6:F9)=F6,1,0)+if(max(G6:G9)=G6,1,0)+if(max(H6:H9)=H6,1,0)) -> 0 | W6: Max=6/7 | AA6: =if(M6<>"","W" & vlookup(B6,B$122:E$133,4,false),"D" & vlookup(B6,B48:E79,4,false)) -> #N/A | AD6: 3 | AE6: =IF(B10="", "X", IF(COUNTA(F10:H10)=0, "N", "Y")) -> X | AQ6: =K6 -> 2 | AR6: =P6 -> 0 | AS6: =counta(B6) -> 0
A7: 2 | I7: =sum(F7:H7) -> 0 | J7: =if(sum(F6:F9)=0,0,if(max(F6:F9)=F7,1,0)+if(max(G6:G9)=G7,1,0)+if(max(H6:H9)=H7,1,0)) -> 0 | K7: =A7 -> 2 | P7: =countif(Z$73:Z$79,B7) -> 0 | S7: =if(sum(F6:F9)=0,"",if(SUMPRODUCT(1/COUNTIF(F6:F9, F6:F9))=2,"G","E")) | T7: =if(sum(G6:G9)=0,"",if(SUMPRODUCT(1/COUNTIF(G6:G9, G6:G9))=2,"G","E")) | U7: =if(sum(H6:H9)=0,"",if(SUMPRODUCT(1/COUNTIF(H6:H9, H6:H9))=2,"G","E")) | V7: =if(sum(F6:F9)=0,0,if(max(F6:F9)=F7,1,0)+if(max(G6:G9)=G7,1,0)+if(max(H6:H9)=H7,1,0)) -> 0 | W7: two equal scores | AA7: =if(M7<>"","W" & vlookup(B7,B$122:E$133,4,false),"D" & vlookup(B7,B49:E80,4,false)) -> #N/A | AD7: 4 | AE7: =IF(B14="", "X", IF(COUNTA(F14:H14)=0, "N", "Y")) -> X | AQ7: =K7 -> 2 | AR7: =P7 -> 0 | AS7: =counta(B7) -> 0
A8: 2 | I8: =sum(F8:H8) -> 0 | J8: =if(sum(F6:F9)=0,0,if(max(F6:F9)=F8,1,0)+if(max(G6:G9)=G8,1,0)+if(max(H6:H9)=H8,1,0)) -> 0 | K8: =A8 -> 2 | P8: =countif(Z$73:Z$79,B8) -> 0 | S8: =if(sum(F6:F9)=0,"",if(and(max(F6:F9)=7, min(F6:F9)=6),"G",if(max(F6:F9)-min(F6:F9)>=2,"G","E"))) | T8: =if(sum(G6:G9)=0,"",if(and(max(G6:G9)=7, min(G6:G9)=6),"G",if(max(G6:G9)-min(G6:G9)>=2,"G","E"))) | U8: =if(sum(H6:H9)=0,"",if(and(max(H6:H9)=7, min(H6:H9)=6),"G",if(max(H6:H9)-min(H6:H9)>=2,"G","E"))) | V8: =if(sum(F6:F9)=0,0,if(max(F6:F9)=F8,1,0)+if(max(G6:G9)=G8,1,0)+if(max(H6:H9)=H8,1,0)) -> 0 | W8: Diff of 2 or tie breaker | AA8: =if(M8<>"","W" & vlookup(B8,B$122:E$133,4,false),"D" & vlookup(B8,B50:E81,4,false)) -> #N/A | AD8: 5 | AE8: =IF(B18="", "X", IF(COUNTA(F18:H18)=0, "N", "Y")) -> X | AQ8: =K8 -> 2 | AR8: =P8 -> 0 | AS8: =counta(B8) -> 0
A9: 2 | I9: =sum(F9:H9) -> 0 | J9: =if(sum(F6:F9)=0,0,if(max(F6:F9)=F9,1,0)+if(max(G6:G9)=G9,1,0)+if(max(H6:H9)=H9,1,0)) -> 0 | K9: =A9 -> 2 | P9: =countif(Z$73:Z$79,B9) -> 0 | S9: =IF(COUNTIF(S6:S8, "") = 3, "", IF(COUNTIF(S6:S8, "G") = 3, "G", "E")) | T9: =IF(COUNTIF(T6:T8, "") = 3, "", IF(COUNTIF(T6:T8, "G") = 3, "G", "E")) | U9: =IF(COUNTIF(U6:U8, "") = 3, "", IF(COUNTIF(U6:U8, "G") = 3, "G", "E")) | V9: =if(sum(F6:F9)=0,0,if(max(F6:F9)=F9,1,0)+if(max(G6:G9)=G9,1,0)+if(max(H6:H9)=H9,1,0)) -> 0 | AA9: =if(M9<>"","W" & vlookup(B9,B$122:E$133,4,false),"D" & vlookup(B9,B51:E82,4,false)) -> #N/A | AD9: 6 | AE9: =IF(B22="", "X", IF(COUNTA(F22:H22)=0, "N", "Y")) -> X | AQ9: =K9 -> 2 | AR9: =P9 -> 0 | AS9: =counta(B9) -> 0
A10: 3 | I10: =sum(F10:H10) -> 0 | J10: =if(sum(F10:F13)=0,0,if(max(F10:F13)=F10,1,0)+if(max(G10:G13)=G10,1,0)+if(max(H10:H13)=H10,1,0)) -> 0 | K10: =A10 -> 3 | O10: =sum(N10:N13) -> 0 | P10: =countif(Z$73:Z$79,B10) -> 0 | Q10: =sum(P10:P13) -> 0 | S10: =if(sum(F10:F13)=0,"",if(or(max(F10:F13)=6, max(F10:F13)=7),"G","E")) | T10: =if(sum(G10:G13)=0,"",if(or(max(G10:G13)=6, max(G10:G13)=7),"G","E")) | U10: =if(sum(H10:H13)=0,"",if(or(max(H10:H13)=6, max(H10:H13)=7),"G","E")) | V10: =if(sum(F10:F13)=0,0,if(max(F10:F13)=F10,1,0)+if(max(G10:G13)=G10,1,0)+if(max(H10:H13)=H10,1,0)) -> 0 | W10: Max=6/7 | AA10: =if(M10<>"","W" & vlookup(B10,B$122:E$133,4,false),"D" & vlookup(B10,B52:E83,4,false)) -> #N/A | AD10: 7 | AE10: =IF(B26="", "X", IF(COUNTA(F26:H26)=0, "N", "Y")) -> X | AQ10: =K10 -> 3 | AR10: =P10 -> 0 | AS10: =counta(B10) -> 0
A11: 3 | I11: =sum(F11:H11) -> 0 | J11: =if(sum(F10:F13)=0,0,if(max(F10:F13)=F11,1,0)+if(max(G10:G13)=G11,1,0)+if(max(H10:H13)=H11,1,0)) -> 0 | K11: =A11 -> 3 | P11: =countif(Z$73:Z$79,B11) -> 0 | S11: =if(sum(F10:F13)=0,"",if(SUMPRODUCT(1/COUNTIF(F10:F13, F10:F13))=2,"G","E")) | T11: =if(sum(G10:G13)=0,"",if(SUMPRODUCT(1/COUNTIF(G10:G13, G10:G13))=2,"G","E")) | U11: =if(sum(H10:H13)=0,"",if(SUMPRODUCT(1/COUNTIF(H10:H13, H10:H13))=2,"G","E")) | V11: =if(sum(F10:F13)=0,0,if(max(F10:F13)=F11,1,0)+if(max(G10:G13)=G11,1,0)+if(max(H10:H13)=H11,1,0)) -> 0 | W11: two equal scores | AA11: =if(M11<>"","W" & vlookup(B11,B$122:E$133,4,false),"D" & vlookup(B11,B53:E84,4,false)) -> #N/A | AD11: 8 | AE11: =IF(B30="", "X", IF(COUNTA(F30:H30)=0, "N", "Y")) -> X | AQ11: =K11 -> 3 | AR11: =P11 -> 0 | AS11: =counta(B11) -> 0
A12: 3 | I12: =sum(F12:H12) -> 0 | J12: =if(sum(F10:F13)=0,0,if(max(F10:F13)=F12,1,0)+if(max(G10:G13)=G12,1,0)+if(max(H10:H13)=H12,1,0)) -> 0 | K12: =A12 -> 3 | P12: =countif(Z$73:Z$79,B12) -> 0 | S12: =if(sum(F10:F13)=0,"",if(and(max(F10:F13)=7, min(F10:F13)=6),"G",if(max(F10:F13)-min(F10:F13)>=2,"G","E"))) | T12: =if(sum(G10:G13)=0,"",if(and(max(G10:G13)=7, min(G10:G13)=6),"G",if(max(G10:G13)-min(G10:G13)>=2,"G","E"))) | U12: =if(sum(H10:H13)=0,"",if(and(max(H10:H13)=7, min(H10:H13)=6),"G",if(max(H10:H13)-min(H10:H13)>=2,"G","E"))) | V12: =if(sum(F10:F13)=0,0,if(max(F10:F13)=F12,1,0)+if(max(G10:G13)=G12,1,0)+if(max(H10:H13)=H12,1,0)) -> 0 | W12: Diff of 2 or tie breaker | AA12: =if(M12<>"","W" & vlookup(B12,B$122:E$133,4,false),"D" & vlookup(B12,B54:E85,4,false)) -> #N/A | AQ12: =K12 -> 3 | AR12: =P12 -> 0 | AS12: =counta(B12) -> 0
A13: 3 | I13: =sum(F13:H13) -> 0 | J13: =if(sum(F10:F13)=0,0,if(max(F10:F13)=F13,1,0)+if(max(G10:G13)=G13,1,0)+if(max(H10:H13)=H13,1,0)) -> 0 | K13: =A13 -> 3 | P13: =countif(Z$73:Z$79,B13) -> 0 | S13: =IF(COUNTIF(S10:S12, "") = 3, "", IF(COUNTIF(S10:S12, "G") = 3, "G", "E")) | T13: =IF(COUNTIF(T10:T12, "") = 3, "", IF(COUNTIF(T10:T12, "G") = 3, "G", "E")) | U13: =IF(COUNTIF(U10:U12, "") = 3, "", IF(COUNTIF(U10:U12, "G") = 3, "G", "E")) | V13: =if(sum(F10:F13)=0,0,if(max(F10:F13)=F13,1,0)+if(max(G10:G13)=G13,1,0)+if(max(H10:H13)=H13,1,0)) -> 0 | AA13: =if(M13<>"","W" & vlookup(B13,B$122:E$133,4,false),"D" & vlookup(B13,B55:E86,4,false)) -> #N/A | AD13: Pending Scores | AE13: Status | AQ13: =K13 -> 3 | AR13: =P13 -> 0 | AS13: =counta(B13) -> 0
A14: 4 | I14: =sum(F14:H14) -> 0 | J14: =if(sum(F14:F17)=0,0,if(max(F14:F17)=F14,1,0)+if(max(G14:G17)=G14,1,0)+if(max(H14:H17)=H14,1,0)) -> 0 | K14: =A14 -> 4 | O14: =sum(N14:N17) -> 0 | P14: =countif(Z$73:Z$79,B14) -> 0 | Q14: =sum(P14:P17) -> 0 | S14: =if(sum(F14:F17)=0,"",if(or(max(F14:F17)=6, max(F14:F17)=7),"G","E")) | T14: =if(sum(G14:G17)=0,"",if(or(max(G14:G17)=6, max(G14:G17)=7),"G","E")) | U14: =if(sum(H14:H17)=0,"",if(or(max(H14:H17)=6, max(H14:H17)=7),"G","E")) | V14: =if(sum(F14:F17)=0,0,if(max(F14:F17)=F14,1,0)+if(max(G14:G17)=G14,1,0)+if(max(H14:H17)=H14,1,0)) -> 0 | W14: Max=6/7 | AA14: =if(M14<>"","W" & vlookup(B14,B$122:E$133,4,false),"D" & vlookup(B14,B56:E87,4,false)) -> #N/A | AQ14: =K14 -> 4 | AR14: =P14 -> 0 | AS14: =counta(B14) -> 0
A15: 4 | I15: =sum(F15:H15) -> 0 | J15: =if(sum(F14:F17)=0,0,if(max(F14:F17)=F15,1,0)+if(max(G14:G17)=G15,1,0)+if(max(H14:H17)=H15,1,0)) -> 0 | K15: =A15 -> 4 | P15: =countif(Z$73:Z$79,B15) -> 0 | S15: =if(sum(F14:F17)=0,"",if(SUMPRODUCT(1/COUNTIF(F14:F17, F14:F17))=2,"G","E")) | T15: =if(sum(G14:G17)=0,"",if(SUMPRODUCT(1/COUNTIF(G14:G17, G14:G17))=2,"G","E")) | U15: =if(sum(H14:H17)=0,"",if(SUMPRODUCT(1/COUNTIF(H14:H17, H14:H17))=2,"G","E")) | V15: =if(sum(F14:F17)=0,0,if(max(F14:F17)=F15,1,0)+if(max(G14:G17)=G15,1,0)+if(max(H14:H17)=H15,1,0)) -> 0 | W15: two equal scores | AA15: =if(M15<>"","W" & vlookup(B15,B$122:E$133,4,false),"D" & vlookup(B15,B57:E88,4,false)) -> #N/A | AD15: =IFERROR(__xludf.DUMMYFUNCTION("IFERROR(QUERY(AD4:AE11, ""SELECT AD WHERE AE = 'N'"", 0), """")"),"") | AE15: =IF(AND(COUNTIF(AE4:AE11, "N")=0, COUNTIF(AE4:AE11, "Y")>0), "Y", "N") -> N | AQ15: =K15 -> 4 | AR15: =P15 -> 0 | AS15: =counta(B15) -> 0
A16: 4 | I16: =sum(F16:H16) -> 0 | J16: =if(sum(F14:F17)=0,0,if(max(F14:F17)=F16,1,0)+if(max(G14:G17)=G16,1,0)+if(max(H14:H17)=H16,1,0)) -> 0 | K16: =A16 -> 4 | P16: =countif(Z$73:Z$79,B16) -> 0 | S16: =if(sum(F14:F17)=0,"",if(and(max(F14:F17)=7, min(F14:F17)=6),"G",if(max(F14:F17)-min(F14:F17)>=2,"G","E"))) | T16: =if(sum(G14:G17)=0,"",if(and(max(G14:G17)=7, min(G14:G17)=6),"G",if(max(G14:G17)-min(G14:G17)>=2,"G","E"))) | U16: =if(sum(H14:H17)=0,"",if(and(max(H14:H17)=7, min(H14:H17)=6),"G",if(max(H14:H17)-min(H14:H17)>=2,"G","E"))) | V16: =if(sum(F14:F17)=0,0,if(max(F14:F17)=F16,1,0)+if(max(G14:G17)=G16,1,0)+if(max(H14:H17)=H16,1,0)) -> 0 | W16: Diff of 2 or tie breaker | AA16: =if(M16<>"","W" & vlookup(B16,B$122:E$133,4,false),"D" & vlookup(B16,B58:E89,4,false)) -> #N/A | AQ16: =K16 -> 4 | AR16: =P16 -> 0 | AS16: =counta(B16) -> 0
A17: 4 | I17: =sum(F17:H17) -> 0 | J17: =if(sum(F14:F17)=0,0,if(max(F14:F17)=F17,1,0)+if(max(G14:G17)=G17,1,0)+if(max(H14:H17)=H17,1,0)) -> 0 | K17: =A17 -> 4 | P17: =countif(Z$73:Z$79,B17) -> 0 | S17: =IF(COUNTIF(S14:S16, "") = 3, "", IF(COUNTIF(S14:S16, "G") = 3, "G", "E")) | T17: =IF(COUNTIF(T14:T16, "") = 3, "", IF(COUNTIF(T14:T16, "G") = 3, "G", "E")) | U17: =IF(COUNTIF(U14:U16, "") = 3, "", IF(COUNTIF(U14:U16, "G") = 3, "G", "E")) | V17: =if(sum(F14:F17)=0,0,if(max(F14:F17)=F17,1,0)+if(max(G14:G17)=G17,1,0)+if(max(H14:H17)=H17,1,0)) -> 0 | AA17: =if(M17<>"","W" & vlookup(B17,B$122:E$133,4,false),"D" & vlookup(B17,B59:E90,4,false)) -> #N/A | AQ17: =K17 -> 4 | AR17: =P17 -> 0 | AS17: =counta(B17) -> 0
A18: 5 | I18: =sum(F18:H18) -> 0 | J18: =if(sum(F18:F21)=0,0,if(max(F18:F21)=F18,1,0)+if(max(G18:G21)=G18,1,0)+if(max(H18:H21)=H18,1,0)) -> 0 | K18: =A18 -> 5 | O18: =sum(N18:N21) -> 0 | P18: =countif(Z$73:Z$79,B18) -> 0 | Q18: =sum(P18:P21) -> 0 | S18: =if(sum(F18:F21)=0,"",if(or(max(F18:F21)=6, max(F18:F21)=7),"G","E")) | T18: =if(sum(G18:G21)=0,"",if(or(max(G18:G21)=6, max(G18:G21)=7),"G","E")) | U18: =if(sum(H18:H21)=0,"",if(or(max(H18:H21)=6, max(H18:H21)=7),"G","E")) | V18: =if(sum(F18:F21)=0,0,if(max(F18:F21)=F18,1,0)+if(max(G18:G21)=G18,1,0)+if(max(H18:H21)=H18,1,0)) -> 0 | W18: Max=6/7 | AA18: =if(M18<>"","W" & vlookup(B18,B$122:E$133,4,false),"D" & vlookup(B18,B60:E91,4,false)) -> #N/A | AQ18: =K18 -> 5 | AR18: =P18 -> 0 | AS18: =counta(B18) -> 0
A19: 5 | I19: =sum(F19:H19) -> 0 | J19: =if(sum(F18:F21)=0,0,if(max(F18:F21)=F19,1,0)+if(max(G18:G21)=G19,1,0)+if(max(H18:H21)=H19,1,0)) -> 0 | K19: =A19 -> 5 | P19: =countif(Z$73:Z$79,B19) -> 0 | S19: =if(sum(F18:F21)=0,"",if(SUMPRODUCT(1/COUNTIF(F18:F21, F18:F21))=2,"G","E")) | T19: =if(sum(G18:G21)=0,"",if(SUMPRODUCT(1/COUNTIF(G18:G21, G18:G21))=2,"G","E")) | U19: =if(sum(H18:H21)=0,"",if(SUMPRODUCT(1/COUNTIF(H18:H21, H18:H21))=2,"G","E")) | V19: =if(sum(F18:F21)=0,0,if(max(F18:F21)=F19,1,0)+if(max(G18:G21)=G19,1,0)+if(max(H18:H21)=H19,1,0)) -> 0 | W19: two equal scores | AA19: =if(M19<>"","W" & vlookup(B19,B$122:E$133,4,false),"D" & vlookup(B19,B61:E92,4,false)) -> #N/A | AQ19: =K19 -> 5 | AR19: =P19 -> 0 | AS19: =counta(B19) -> 0
A20: 5 | I20: =sum(F20:H20) -> 0 | J20: =if(sum(F18:F21)=0,0,if(max(F18:F21)=F20,1,0)+if(max(G18:G21)=G20,1,0)+if(max(H18:H21)=H20,1,0)) -> 0 | K20: =A20 -> 5 | P20: =countif(Z$73:Z$79,B20) -> 0 | S20: =if(sum(F18:F21)=0,"",if(and(max(F18:F21)=7, min(F18:F21)=6),"G",if(max(F18:F21)-min(F18:F21)>=2,"G","E"))) | T20: =if(sum(G18:G21)=0,"",if(and(max(G18:G21)=7, min(G18:G21)=6),"G",if(max(G18:G21)-min(G18:G21)>=2,"G","E"))) | U20: =if(sum(H18:H21)=0,"",if(and(max(H18:H21)=7, min(H18:H21)=6),"G",if(max(H18:H21)-min(H18:H21)>=2,"G","E"))) | V20: =if(sum(F18:F21)=0,0,if(max(F18:F21)=F20,1,0)+if(max(G18:G21)=G20,1,0)+if(max(H18:H21)=H20,1,0)) -> 0 | W20: Diff of 2 or tie breaker | AA20: =if(M20<>"","W" & vlookup(B20,B$122:E$133,4,false),"D" & vlookup(B20,B62:E93,4,false)) -> #N/A | AQ20: =K20 -> 5 | AR20: =P20 -> 0 | AS20: =counta(B20) -> 0
A21: 5 | I21: =sum(F21:H21) -> 0 | J21: =if(sum(F18:F21)=0,0,if(max(F18:F21)=F21,1,0)+if(max(G18:G21)=G21,1,0)+if(max(H18:H21)=H21,1,0)) -> 0 | K21: =A21 -> 5 | P21: =countif(Z$73:Z$79,B21) -> 0 | S21: =IF(COUNTIF(S18:S20, "") = 3, "", IF(COUNTIF(S18:S20, "G") = 3, "G", "E")) | T21: =IF(COUNTIF(T18:T20, "") = 3, "", IF(COUNTIF(T18:T20, "G") = 3, "G", "E")) | U21: =IF(COUNTIF(U18:U20, "") = 3, "", IF(COUNTIF(U18:U20, "G") = 3, "G", "E")) | V21: =if(sum(F18:F21)=0,0,if(max(F18:F21)=F21,1,0)+if(max(G18:G21)=G21,1,0)+if(max(H18:H21)=H21,1,0)) -> 0 | AA21: =if(M21<>"","W" & vlookup(B21,B$122:E$133,4,false),"D" & vlookup(B21,B63:E94,4,false)) -> #N/A | AQ21: =K21 -> 5 | AR21: =P21 -> 0 | AS21: =counta(B21) -> 0
A22: 6 | I22: =sum(F22:H22) -> 0 | J22: =if(sum(F22:F25)=0,0,if(max(F22:F25)=F22,1,0)+if(max(G22:G25)=G22,1,0)+if(max(H22:H25)=H22,1,0)) -> 0 | K22: =A22 -> 6 | O22: =sum(N22:N25) -> 0 | P22: =countif(Z$73:Z$79,B22) -> 0 | Q22: =sum(P22:P25) -> 0 | S22: =if(sum(F22:F25)=0,"",if(or(max(F22:F25)=6, max(F22:F25)=7),"G","E")) | T22: =if(sum(G22:G25)=0,"",if(or(max(G22:G25)=6, max(G22:G25)=7),"G","E")) | U22: =if(sum(H22:H25)=0,"",if(or(max(H22:H25)=6, max(H22:H25)=7),"G","E")) | V22: =if(sum(F22:F25)=0,0,if(max(F22:F25)=F22,1,0)+if(max(G22:G25)=G22,1,0)+if(max(H22:H25)=H22,1,0)) -> 0 | W22: Max=6/7 | AA22: =if(M22<>"","W" & vlookup(B22,B$122:E$133,4,false),"D" & vlookup(B22,B64:E95,4,false)) -> #N/A | AQ22: =K22 -> 6 | AR22: =P22 -> 0 | AS22: =counta(B22) -> 0
A23: 6 | I23: =sum(F23:H23) -> 0 | J23: =if(sum(F22:F25)=0,0,if(max(F22:F25)=F23,1,0)+if(max(G22:G25)=G23,1,0)+if(max(H22:H25)=H23,1,0)) -> 0 | K23: =A23 -> 6 | P23: =countif(Z$73:Z$79,B23) -> 0 | S23: =if(sum(F22:F25)=0,"",if(SUMPRODUCT(1/COUNTIF(F22:F25, F22:F25))=2,"G","E")) | T23: =if(sum(G22:G25)=0,"",if(SUMPRODUCT(1/COUNTIF(G22:G25, G22:G25))=2,"G","E")) | U23: =if(sum(H22:H25)=0,"",if(SUMPRODUCT(1/COUNTIF(H22:H25, H22:H25))=2,"G","E")) | V23: =if(sum(F22:F25)=0,0,if(max(F22:F25)=F23,1,0)+if(max(G22:G25)=G23,1,0)+if(max(H22:H25)=H23,1,0)) -> 0 | W23: two equal scores | AA23: =if(M23<>"","W" & vlookup(B23,B$122:E$133,4,false),"D" & vlookup(B23,B65:E96,4,false)) -> #N/A | AQ23: =K23 -> 6 | AR23: =P23 -> 0 | AS23: =counta(B23) -> 0
A24: 6 | I24: =sum(F24:H24) -> 0 | J24: =if(sum(F22:F25)=0,0,if(max(F22:F25)=F24,1,0)+if(max(G22:G25)=G24,1,0)+if(max(H22:H25)=H24,1,0)) -> 0 | K24: =A24 -> 6 | P24: =countif(Z$73:Z$79,B24) -> 0 | S24: =if(sum(F22:F25)=0,"",if(and(max(F22:F25)=7, min(F22:F25)=6),"G",if(max(F22:F25)-min(F22:F25)>=2,"G","E"))) | T24: =if(sum(G22:G25)=0,"",if(and(max(G22:G25)=7, min(G22:G25)=6),"G",if(max(G22:G25)-min(G22:G25)>=2,"G","E"))) | U24: =if(sum(H22:H25)=0,"",if(and(max(H22:H25)=7, min(H22:H25)=6),"G",if(max(H22:H25)-min(H22:H25)>=2,"G","E"))) | V24: =if(sum(F22:F25)=0,0,if(max(F22:F25)=F24,1,0)+if(max(G22:G25)=G24,1,0)+if(max(H22:H25)=H24,1,0)) -> 0 | W24: Diff of 2 or tie breaker | AA24: =if(M24<>"","W" & vlookup(B24,B$122:E$133,4,false),"D" & vlookup(B24,B66:E97,4,false)) -> #N/A | AQ24: =K24 -> 6 | AR24: =P24 -> 0 | AS24: =counta(B24) -> 0
A25: 6 | I25: =sum(F25:H25) -> 0 | J25: =if(sum(F22:F25)=0,0,if(max(F22:F25)=F25,1,0)+if(max(G22:G25)=G25,1,0)+if(max(H22:H25)=H25,1,0)) -> 0 | K25: =A25 -> 6 | P25: =countif(Z$73:Z$79,B25) -> 0 | S25: =IF(COUNTIF(S22:S24, "") = 3, "", IF(COUNTIF(S22:S24, "G") = 3, "G", "E")) | T25: =IF(COUNTIF(T22:T24, "") = 3, "", IF(COUNTIF(T22:T24, "G") = 3, "G", "E")) | U25: =IF(COUNTIF(U22:U24, "") = 3, "", IF(COUNTIF(U22:U24, "G") = 3, "G", "E")) | V25: =if(sum(F22:F25)=0,0,if(max(F22:F25)=F25,1,0)+if(max(G22:G25)=G25,1,0)+if(max(H22:H25)=H25,1,0)) -> 0 | AA25: =if(M25<>"","W" & vlookup(B25,B$122:E$133,4,false),"D" & vlookup(B25,B67:E98,4,false)) -> #N/A | AQ25: =K25 -> 6 | AR25: =P25 -> 0 | AS25: =counta(B25) -> 0
A26: 7 | I26: =sum(F26:H26) -> 0 | J26: =if(sum(F26:F29)=0,0,if(max(F26:F29)=F26,1,0)+if(max(G26:G29)=G26,1,0)+if(max(H26:H29)=H26,1,0)) -> 0 | K26: =A26 -> 7 | O26: =sum(N26:N29) -> 0 | P26: =countif(Z$73:Z$79,B26) -> 0 | Q26: =sum(P26:P29) -> 0 | S26: =if(sum(F26:F29)=0,"",if(or(max(F26:F29)=6, max(F26:F29)=7),"G","E")) | T26: =if(sum(G26:G29)=0,"",if(or(max(G26:G29)=6, max(G26:G29)=7),"G","E")) | U26: =if(sum(H26:H29)=0,"",if(or(max(H26:H29)=6, max(H26:H29)=7),"G","E")) | V26: =if(sum(F26:F29)=0,0,if(max(F26:F29)=F26,1,0)+if(max(G26:G29)=G26,1,0)+if(max(H26:H29)=H26,1,0)) -> 0 | W26: Max=6/7 | AA26: =if(M26<>"","W" & vlookup(B26,B$122:E$133,4,false),"D" & vlookup(B26,B68:E99,4,false)) -> #N/A | AQ26: =K26 -> 7 | AR26: =P26 -> 0 | AS26: =counta(B26) -> 0
A27: 7 | I27: =sum(F27:H27) -> 0 | J27: =if(sum(F26:F29)=0,0,if(max(F26:F29)=F27,1,0)+if(max(G26:G29)=G27,1,0)+if(max(H26:H29)=H27,1,0)) -> 0 | K27: =A27 -> 7 | P27: =countif(Z$73:Z$79,B27) -> 0 | S27: =if(sum(F26:F29)=0,"",if(SUMPRODUCT(1/COUNTIF(F26:F29, F26:F29))=2,"G","E")) | T27: =if(sum(G26:G29)=0,"",if(SUMPRODUCT(1/COUNTIF(G26:G29, G26:G29))=2,"G","E")) | U27: =if(sum(H26:H29)=0,"",if(SUMPRODUCT(1/COUNTIF(H26:H29, H26:H29))=2,"G","E")) | V27: =if(sum(F26:F29)=0,0,if(max(F26:F29)=F27,1,0)+if(max(G26:G29)=G27,1,0)+if(max(H26:H29)=H27,1,0)) -> 0 | W27: two equal scores | AA27: =if(M27<>"","W" & vlookup(B27,B$122:E$133,4,false),"D" & vlookup(B27,B69:E100,4,false)) -> #N/A | AQ27: =K27 -> 7 | AR27: =P27 -> 0 | AS27: =counta(B27) -> 0
A28: 7 | I28: =sum(F28:H28) -> 0 | J28: =if(sum(F26:F29)=0,0,if(max(F26:F29)=F28,1,0)+if(max(G26:G29)=G28,1,0)+if(max(H26:H29)=H28,1,0)) -> 0 | K28: =A28 -> 7 | P28: =countif(Z$73:Z$79,B28) -> 0 | S28: =if(sum(F26:F29)=0,"",if(and(max(F26:F29)=7, min(F26:F29)=6),"G",if(max(F26:F29)-min(F26:F29)>=2,"G","E"))) | T28: =if(sum(G26:G29)=0,"",if(and(max(G26:G29)=7, min(G26:G29)=6),"G",if(max(G26:G29)-min(G26:G29)>=2,"G","E"))) | U28: =if(sum(H26:H29)=0,"",if(and(max(H26:H29)=7, min(H26:H29)=6),"G",if(max(H26:H29)-min(H26:H29)>=2,"G","E"))) | V28: =if(sum(F26:F29)=0,0,if(max(F26:F29)=F28,1,0)+if(max(G26:G29)=G28,1,0)+if(max(H26:H29)=H28,1,0)) -> 0 | W28: Diff of 2 or tie breaker | AA28: =if(M28<>"","W" & vlookup(B28,B$122:E$133,4,false),"D" & vlookup(B28,B70:E101,4,false)) -> #N/A | AQ28: =K28 -> 7 | AR28: =P28 -> 0 | AS28: =counta(B28) -> 0
A29: 7 | I29: =sum(F29:H29) -> 0 | J29: =if(sum(F26:F29)=0,0,if(max(F26:F29)=F29,1,0)+if(max(G26:G29)=G29,1,0)+if(max(H26:H29)=H29,1,0)) -> 0 | K29: =A29 -> 7 | P29: =countif(Z$73:Z$79,B29) -> 0 | S29: =IF(COUNTIF(S26:S28, "") = 3, "", IF(COUNTIF(S26:S28, "G") = 3, "G", "E")) | T29: =IF(COUNTIF(T26:T28, "") = 3, "", IF(COUNTIF(T26:T28, "G") = 3, "G", "E")) | U29: =IF(COUNTIF(U26:U28, "") = 3, "", IF(COUNTIF(U26:U28, "G") = 3, "G", "E")) | V29: =if(sum(F26:F29)=0,0,if(max(F26:F29)=F29,1,0)+if(max(G26:G29)=G29,1,0)+if(max(H26:H29)=H29,1,0)) -> 0 | AA29: =if(M29<>"","W" & vlookup(B29,B$122:E$133,4,false),"D" & vlookup(B29,B71:E102,4,false)) -> #N/A | AQ29: =K29 -> 7 | AR29: =P29 -> 0 | AS29: =counta(B29) -> 0
A30: 8 | I30: =sum(F30:H30) -> 0 | J30: =if(sum(F30:F33)=0,0,if(max(F30:F33)=F30,1,0)+if(max(G30:G33)=G30,1,0)+if(max(H30:H33)=H30,1,0)) -> 0 | K30: =A30 -> 8 | O30: =sum(N30:N33) -> 0 | P30: =countif(Z$73:Z$79,B30) -> 0 | Q30: =sum(P30:P33) -> 0 | S30: =if(sum(F30:F33)=0,"",if(or(max(F30:F33)=6, max(F30:F33)=7),"G","E")) | T30: =if(sum(G30:G33)=0,"",if(or(max(G30:G33)=6, max(G30:G33)=7),"G","E")) | U30: =if(sum(H30:H33)=0,"",if(or(max(H30:H33)=6, max(H30:H33)=7),"G","E")) | V30: =if(sum(F30:F33)=0,0,if(max(F30:F33)=F30,1,0)+if(max(G30:G33)=G30,1,0)+if(max(H30:H33)=H30,1,0)) -> 0 | W30: Max=6/7 | AA30: =if(M30<>"","W" & vlookup(B30,B$122:E$133,4,false),"D" & vlookup(B30,B72:E103,4,false)) -> #N/A | AQ30: =K30 -> 8 | AR30: =P30 -> 0 | AS30: =counta(B30) -> 0
A31: 8 | I31: =sum(F31:H31) -> 0 | J31: =if(sum(F30:F33)=0,0,if(max(F30:F33)=F31,1,0)+if(max(G30:G33)=G31,1,0)+if(max(H30:H33)=H31,1,0)) -> 0 | K31: =A31 -> 8 | P31: =countif(Z$73:Z$79,B31) -> 0 | S31: =if(sum(F30:F33)=0,"",if(SUMPRODUCT(1/COUNTIF(F30:F33, F30:F33))=2,"G","E")) | T31: =if(sum(G30:G33)=0,"",if(SUMPRODUCT(1/COUNTIF(G30:G33, G30:G33))=2,"G","E")) | U31: =if(sum(H30:H33)=0,"",if(SUMPRODUCT(1/COUNTIF(H30:H33, H30:H33))=2,"G","E")) | V31: =if(sum(F30:F33)=0,0,if(max(F30:F33)=F31,1,0)+if(max(G30:G33)=G31,1,0)+if(max(H30:H33)=H31,1,0)) -> 0 | W31: two equal scores | AA31: =if(M31<>"","W" & vlookup(B31,B$122:E$133,4,false),"D" & vlookup(B31,B73:E104,4,false)) -> #N/A | AQ31: =K31 -> 8 | AR31: =P31 -> 0 | AS31: =counta(B31) -> 0
A32: 8 | I32: =sum(F32:H32) -> 0 | J32: =if(sum(F30:F33)=0,0,if(max(F30:F33)=F32,1,0)+if(max(G30:G33)=G32,1,0)+if(max(H30:H33)=H32,1,0)) -> 0 | K32: =A32 -> 8 | P32: =countif(Z$73:Z$79,B32) -> 0 | S32: =if(sum(F30:F33)=0,"",if(and(max(F30:F33)=7, min(F30:F33)=6),"G",if(max(F30:F33)-min(F30:F33)>=2,"G","E"))) | T32: =if(sum(G30:G33)=0,"",if(and(max(G30:G33)=7, min(G30:G33)=6),"G",if(max(G30:G33)-min(G30:G33)>=2,"G","E"))) | U32: =if(sum(H30:H33)=0,"",if(and(max(H30:H33)=7, min(H30:H33)=6),"G",if(max(H30:H33)-min(H30:H33)>=2,"G","E"))) | V32: =if(sum(F30:F33)=0,0,if(max(F30:F33)=F32,1,0)+if(max(G30:G33)=G32,1,0)+if(max(H30:H33)=H32,1,0)) -> 0 | W32: Diff of 2 or tie breaker | AA32: =if(M32<>"","W" & vlookup(B32,B$122:E$133,4,false),"D" & vlookup(B32,B74:E105,4,false)) -> #N/A | AQ32: =K32 -> 8 | AR32: =P32 -> 0 | AS32: =counta(B32) -> 0
A33: 8 | I33: =sum(F33:H33) -> 0 | J33: =if(sum(F30:F33)=0,0,if(max(F30:F33)=F33,1,0)+if(max(G30:G33)=G33,1,0)+if(max(H30:H33)=H33,1,0)) -> 0 | K33: =A33 -> 8 | P33: =countif(Z$73:Z$79,B33) -> 0 | S33: =IF(COUNTIF(S30:S32, "") = 3, "", IF(COUNTIF(S30:S32, "G") = 3, "G", "E")) | T33: =IF(COUNTIF(T30:T32, "") = 3, "", IF(COUNTIF(T30:T32, "G") = 3, "G", "E")) | U33: =IF(COUNTIF(U30:U32, "") = 3, "", IF(COUNTIF(U30:U32, "G") = 3, "G", "E")) | V33: =if(sum(F30:F33)=0,0,if(max(F30:F33)=F33,1,0)+if(max(G30:G33)=G33,1,0)+if(max(H30:H33)=H33,1,0)) -> 0 | AA33: =if(M33<>"","W" & vlookup(B33,B$122:E$133,4,false),"D" & vlookup(B33,B75:E106,4,false)) -> #N/A | AQ33: =K33 -> 8 | AR33: =P33 -> 0 | AS33: =counta(B33) -> 0
A34: 9 | I34: =sum(F34:H34) -> 0 | J34: =if(sum(F34:F37)=0,0,if(max(F34:F37)=F34,1,0)+if(max(G34:G37)=G34,1,0)+if(max(H34:H37)=H34,1,0)) -> 0 | K34: =A34 -> 9 | M34: =IF(AND(A34<>0, OR(VALUE(A34)=VALUE($Y$64), VALUE(A34)=VALUE($Y$65), VALUE(A34)=VALUE($Y$66))), "X", "") | N34: =iferror(VLOOKUP(B34,#REF!,2,false),"") | O34: =sum(N34:N37) -> 0 | P34: =countif(Z$73:Z$79,B34) -> 0 | Q34: =sum(P34:P37) -> 0 | S34: =if(sum(F34:F37)=0,"",if(or(max(F34:F37)=6, max(F34:F37)=7),"G","E")) | T34: =if(sum(G34:G37)=0,"",if(or(max(G34:G37)=6, max(G34:G37)=7),"G","E")) | U34: =if(sum(H34:H37)=0,"",if(or(max(H34:H37)=6, max(H34:H37)=7),"G","E")) | V34: =if(sum(F34:F37)=0,0,if(max(F34:F37)=F34,1,0)+if(max(G34:G37)=G34,1,0)+if(max(H34:H37)=H34,1,0)) -> 0 | W34: Max=6/7 | AA34: =if(M34<>"","W" & vlookup(B34,B$122:E$133,4,false),"D" & vlookup(B34,B76:E107,4,false)) -> #N/A | AQ34: =K34 -> 9 | AR34: =P34 -> 0 | AS34: =counta(B34) -> 0
A35: 9 | I35: =sum(F35:H35) -> 0 | J35: =if(sum(F34:F37)=0,0,if(max(F34:F37)=F35,1,0)+if(max(G34:G37)=G35,1,0)+if(max(H34:H37)=H35,1,0)) -> 0 | K35: =A35 -> 9 | M35: =IF(AND(A35<>0, OR(VALUE(A35)=VALUE($Y$64), VALUE(A35)=VALUE($Y$65), VALUE(A35)=VALUE($Y$66))), "X", "") | N35: =iferror(VLOOKUP(B35,#REF!,2,false),"") | P35: =countif(Z$73:Z$79,B35) -> 0 | S35: =if(sum(F34:F37)=0,"",if(SUMPRODUCT(1/COUNTIF(F34:F37, F34:F37))=2,"G","E")) | T35: =if(sum(G34:G37)=0,"",if(SUMPRODUCT(1/COUNTIF(G34:G37, G34:G37))=2,"G","E")) | U35: =if(sum(H34:H37)=0,"",if(SUMPRODUCT(1/COUNTIF(H34:H37, H34:H37))=2,"G","E")) | V35: =if(sum(F34:F37)=0,0,if(max(F34:F37)=F35,1,0)+if(max(G34:G37)=G35,1,0)+if(max(H34:H37)=H35,1,0)) -> 0 | W35: two equal scores | AA35: =if(M35<>"","W" & vlookup(B35,B$122:E$133,4,false),"D" & vlookup(B35,B77:E108,4,false)) -> #N/A | AQ35: =K35 -> 9 | AR35: =P35 -> 0 | AS35: =counta(B35) -> 0
A36: 9 | I36: =sum(F36:H36) -> 0 | J36: =if(sum(F34:F37)=0,0,if(max(F34:F37)=F36,1,0)+if(max(G34:G37)=G36,1,0)+if(max(H34:H37)=H36,1,0)) -> 0 | K36: =A36 -> 9 | M36: =IF(AND(A36<>0, OR(VALUE(A36)=VALUE($Y$64), VALUE(A36)=VALUE($Y$65), VALUE(A36)=VALUE($Y$66))), "X", "") | N36: =iferror(VLOOKUP(B36,#REF!,2,false),"") | P36: =countif(Z$73:Z$79,B36) -> 0 | S36: =if(sum(F34:F37)=0,"",if(and(max(F34:F37)=7, min(F34:F37)=6),"G",if(max(F34:F37)-min(F34:F37)>=2,"G","E"))) | T36: =if(sum(G34:G37)=0,"",if(and(max(G34:G37)=7, min(G34:G37)=6),"G",if(max(G34:G37)-min(G34:G37)>=2,"G","E"))) | U36: =if(sum(H34:H37)=0,"",if(and(max(H34:H37)=7, min(H34:H37)=6),"G",if(max(H34:H37)-min(H34:H37)>=2,"G","E"))) | V36: =if(sum(F34:F37)=0,0,if(max(F34:F37)=F36,1,0)+if(max(G34:G37)=G36,1,0)+if(max(H34:H37)=H36,1,0)) -> 0 | W36: Diff of 2 or tie breaker | AA36: =if(M36<>"","W" & vlookup(B36,B$122:E$133,4,false),"D" & vlookup(B36,B78:E109,4,false)) -> #N/A | AQ36: =K36 -> 9 | AR36: =P36 -> 0 | AS36: =counta(B36) -> 0
A37: 9 | I37: =sum(F37:H37) -> 0 | J37: =if(sum(F34:F37)=0,0,if(max(F34:F37)=F37,1,0)+if(max(G34:G37)=G37,1,0)+if(max(H34:H37)=H37,1,0)) -> 0 | K37: =A37 -> 9 | M37: =IF(AND(A37<>0, OR(VALUE(A37)=VALUE($Y$64), VALUE(A37)=VALUE($Y$65), VALUE(A37)=VALUE($Y$66))), "X", "") | N37: =iferror(VLOOKUP(B37,#REF!,2,false),"") | P37: =countif(Z$73:Z$79,B37) -> 0 | S37: =IF(COUNTIF(S34:S36, "") = 3, "", IF(COUNTIF(S34:S36, "G") = 3, "G", "E")) | T37: =IF(COUNTIF(T34:T36, "") = 3, "", IF(COUNTIF(T34:T36, "G") = 3, "G", "E")) | U37: =IF(COUNTIF(U34:U36, "") = 3, "", IF(COUNTIF(U34:U36, "G") = 3, "G", "E")) | V37: =if(sum(F34:F37)=0,0,if(max(F34:F37)=F37,1,0)+if(max(G34:G37)=G37,1,0)+if(max(H34:H37)=H37,1,0)) -> 0 | AA37: =if(M37<>"","W" & vlookup(B37,B$122:E$133,4,false),"D" & vlookup(B37,B79:E110,4,false)) -> #N/A | AQ37: =K37 -> 9 | AR37: =P37 -> 0 | AS37: =counta(B37) -> 0
A38: 10 | I38: =sum(F38:H38) -> 0 | J38: =if(sum(F38:F41)=0,0,if(max(F38:F41)=F38,1,0)+if(max(G38:G41)=G38,1,0)+if(max(H38:H41)=H38,1,0)) -> 0 | K38: =A38 -> 10 | M38: =IF(AND(A38<>0, OR(VALUE(A38)=VALUE($Y$64), VALUE(A38)=VALUE($Y$65), VALUE(A38)=VALUE($Y$66))), "X", "") | N38: =iferror(VLOOKUP(B38,#REF!,2,false),"") | O38: =sum(N38:N41) -> 0 | P38: =countif(Z$73:Z$79,B38) -> 0 | Q38: =sum(P38:P41) -> 0 | S38: =if(sum(F38:F41)=0,"",if(or(max(F38:F41)=6, max(F38:F41)=7),"G","E")) | T38: =if(sum(G38:G41)=0,"",if(or(max(G38:G41)=6, max(G38:G41)=7),"G","E")) | U38: =if(sum(H38:H41)=0,"",if(or(max(H38:H41)=6, max(H38:H41)=7),"G","E")) | V38: =if(sum(F38:F41)=0,0,if(max(F38:F41)=F38,1,0)+if(max(G38:G41)=G38,1,0)+if(max(H38:H41)=H38,1,0)) -> 0 | W38: Max=6/7 | AA38: =if(M38<>"","W" & vlookup(B38,B$122:E$133,4,false),"D" & vlookup(B38,B80:E111,4,false)) -> #N/A | AQ38: =K38 -> 10 | AR38: =P38 -> 0 | AS38: =counta(B38) -> 0
A39: 10 | I39: =sum(F39:H39) -> 0 | J39: =if(sum(F38:F41)=0,0,if(max(F38:F41)=F39,1,0)+if(max(G38:G41)=G39,1,0)+if(max(H38:H41)=H39,1,0)) -> 0 | K39: =A39 -> 10 | M39: =IF(AND(A39<>0, OR(VALUE(A39)=VALUE($Y$64), VALUE(A39)=VALUE($Y$65), VALUE(A39)=VALUE($Y$66))), "X", "") | N39: =iferror(VLOOKUP(B39,#REF!,2,false),"") | P39: =countif(Z$73:Z$79,B39) -> 0 | S39: =if(sum(F38:F41)=0,"",if(SUMPRODUCT(1/COUNTIF(F38:F41, F38:F41))=2,"G","E")) | T39: =if(sum(G38:G41)=0,"",if(SUMPRODUCT(1/COUNTIF(G38:G41, G38:G41))=2,"G","E")) | U39: =if(sum(H38:H41)=0,"",if(SUMPRODUCT(1/COUNTIF(H38:H41, H38:H41))=2,"G","E")) | V39: =if(sum(F38:F41)=0,0,if(max(F38:F41)=F39,1,0)+if(max(G38:G41)=G39,1,0)+if(max(H38:H41)=H39,1,0)) -> 0 | W39: two equal scores | AA39: =if(M39<>"","W" & vlookup(B39,B$122:E$133,4,false),"D" & vlookup(B39,B81:E112,4,false)) -> #N/A | AQ39: =K39 -> 10 | AR39: =P39 -> 0 | AS39: =counta(B39) -> 0
A40: 10 | I40: =sum(F40:H40) -> 0 | J40: =if(sum(F38:F41)=0,0,if(max(F38:F41)=F40,1,0)+if(max(G38:G41)=G40,1,0)+if(max(H38:H41)=H40,1,0)) -> 0 | K40: =A40 -> 10 | M40: =IF(AND(A40<>0, OR(VALUE(A40)=VALUE($Y$64), VALUE(A40)=VALUE($Y$65), VALUE(A40)=VALUE($Y$66))), "X", "") | N40: =iferror(VLOOKUP(B40,#REF!,2,false),"") | P40: =countif(Z$73:Z$79,B40) -> 0 | S40: =if(sum(F38:F41)=0,"",if(and(max(F38:F41)=7, min(F38:F41)=6),"G",if(max(F38:F41)-min(F38:F41)>=2,"G","E"))) | T40: =if(sum(G38:G41)=0,"",if(and(max(G38:G41)=7, min(G38:G41)=6),"G",if(max(G38:G41)-min(G38:G41)>=2,"G","E"))) | U40: =if(sum(H38:H41)=0,"",if(and(max(H38:H41)=7, min(H38:H41)=6),"G",if(max(H38:H41)-min(H38:H41)>=2,"G","E"))) | V40: =if(sum(F38:F41)=0,0,if(max(F38:F41)=F40,1,0)+if(max(G38:G41)=G40,1,0)+if(max(H38:H41)=H40,1,0)) -> 0 | W40: Diff of 2 or tie breaker | AA40: =if(M40<>"","W" & vlookup(B40,B$122:E$133,4,false),"D" & vlookup(B40,B82:E113,4,false)) -> #N/A | AQ40: =K40 -> 10 | AR40: =P40 -> 0 | AS40: =counta(B40) -> 0
...

Sheet Checkin
A1: Name of the Player | B1: Check in | C1: Previous sitouts | E1: Sl.No | F1: Playing(1) | G1: Out(3) | H1: Out-Can Play(4) | I1: To Respond | J1: Sitouts(5) | K1: Playing-Can Sit(2) | L1: Previous sitouts | M1: Sit Outs Needed | U1: List for Random Sit Outs (if needed) | V1: randomly selected players
A2: =IFERROR(__xludf.DUMMYFUNCTION("IMPORTRANGE(""1uZFF2o7rrfB0YZtASdZnP52Ef50ZinvtOPb1Tbuq8J4"",""CheckIn!C1:D99"")"),"#REF!") -> #REF! | C2: =iferror(VLOOKUP(A2,indirect("'" & "Current" & "'!$B:$T"),19,false),"") | D2: =IF(COUNTIF(A:A, A2) > 1, "Duplicate", "") | E2: 1 | F2: =IFERROR(__xludf.DUMMYFUNCTION("QUERY(A2:B99, ""Select A where B = 1 order by A"")"),"#N/A") -> #N/A | G2: =IFERROR(__xludf.DUMMYFUNCTION("QUERY($A2:$B99, ""Select A where B = 3 order by A"")"),"#N/A") -> #N/A | H2: =IFERROR(__xludf.DUMMYFUNCTION("IFERROR(QUERY($A2:$B99, ""Select A where B = 4""),"""")"),"") | I2: =IFERROR(__xludf.DUMMYFUNCTION("IFERROR(QUERY(Current!B5:F71, ""Select B where F = 0 order by B""), """")"),"Adrian Tay") -> Adrian Tay | J2: =IFERROR(__xludf.DUMMYFUNCTION("iferror(QUERY($A2:$C99, ""Select A where B = 5 order by C""),"""")"),"") | K2: =IFERROR(__xludf.DUMMYFUNCTION("iferror(QUERY($A2:$C99, ""Select A,C where B = 2 order by C""),"""")"),"") | M2: =if(P21>0,1,"") | U2: =IFERROR(__xludf.DUMMYFUNCTION("FILTER(A2:A70, B2:B70 = 1, C2:C70 = 0)"),"#N/A") -> #N/A
C3: =iferror(VLOOKUP(A3,indirect("'" & "Current" & "'!$B:$T"),19,false),"") | D3: =IF(COUNTIF(A:A, A3) > 1, "Duplicate", "") | E3: =E2+1 -> 2 | I3: =IFERROR(__xludf.DUMMYFUNCTION("""COMPUTED_VALUE"""),"Alejandro Mejia") -> Alejandro Mejia | M3: =if(M2="","",if(P$21>M2,M2+1,""))
C4: =iferror(VLOOKUP(A4,indirect("'" & "Current" & "'!$B:$T"),19,false),"") | D4: =IF(COUNTIF(A:A, A4) > 1, "Duplicate", "") | E4: =E3+1 -> 3 | I4: =IFERROR(__xludf.DUMMYFUNCTION("""COMPUTED_VALUE"""),"Alex Hou") -> Alex Hou | M4: =if(M3="","",if(P$21>M3,M3+1,"")) | R4: Whatsapp Message
C5: =iferror(VLOOKUP(A5,indirect("'" & "Current" & "'!$B:$T"),19,false),"") | D5: =IF(COUNTIF(A:A, A5) > 1, "Duplicate", "") | E5: =E4+1 -> 4 | I5: =IFERROR(__xludf.DUMMYFUNCTION("""COMPUTED_VALUE"""),"Allen Zhang") -> Allen Zhang | M5: =if(M4="","",if(P$21>M4,M4+1,""))
C6: =iferror(VLOOKUP(A6,indirect("'" & "Current" & "'!$B:$T"),19,false),"") | D6: =IF(COUNTIF(A:A, A6) > 1, "Duplicate", "") | E6: =E5+1 -> 5 | I6: =IFERROR(__xludf.DUMMYFUNCTION("""COMPUTED_VALUE"""),"Andrew Wen") -> Andrew Wen | M6: =if(M5="","",if(P$21>M5,M5+1,"")) | O6: Playing | P6: =COUNTIF(F2:F99, "?*") -> 0 | R6: =CONCATENATE( "*",P$14," Courts Full*") -> *0 Courts Full* | S6: Sitouts req | T6: =P21 -> 0
C7: =iferror(VLOOKUP(A7,indirect("'" & "Current" & "'!$B:$T"),19,false),"") | D7: =IF(COUNTIF(A:A, A7) > 1, "Duplicate", "") | E7: =E6+1 -> 6 | I7: =IFERROR(__xludf.DUMMYFUNCTION("""COMPUTED_VALUE"""),"Andrew Yao") -> Andrew Yao | M7: =if(M6="","",if(P$21>M6,M6+1,"")) | O7: Playing-Can Sit | P7: =COUNTIF(K2:K99, "?*") -> 0 | R7: =CONCATENATE(O$15," --- ",P$15) -> Playing --- 0 | S7: =O7 -> Playing-Can Sit | T7: =P7 -> 0
C8: =iferror(VLOOKUP(A8,indirect("'" & "Current" & "'!$B:$T"),19,false),"") | D8: =IF(COUNTIF(A:A, A8) > 1, "Duplicate", "") | E8: =E7+1 -> 7 | I8: =IFERROR(__xludf.DUMMYFUNCTION("""COMPUTED_VALUE"""),"Art Hui") -> Art Hui | M8: =if(M7="","",if(P$21>M7,M7+1,"")) | O8: Out/Can Play | P8: =COUNTIF(H2:H99, "?*") -> 0 | R8: =CONCATENATE(O$17," ------ ",P$17) -> Out ------ 0 | S8: do we need more sitiouts | T8: =T6-T7 -> 0
C9: =iferror(VLOOKUP(A9,indirect("'" & "Current" & "'!$B:$T"),19,false),"") | D9: =IF(COUNTIF(A:A, A9) > 1, "Duplicate", "") | E9: =E8+1 -> 8 | I9: =IFERROR(__xludf.DUMMYFUNCTION("""COMPUTED_VALUE"""),"Basudev Thoppai Vidyasankar") -> Basudev Thoppai Vidyasankar | M9: =if(M8="","",if(P$21>M8,M8+1,"")) | O9: Out | P9: =COUNTIF(G2:G99, "?*") -> 0 | R9: =CONCATENATE(O$18," ------ ",P$18) -> TBD ------ 67 | S9: Players who didnot satout | T9: =counta(U2:U978) -> 1
C10: =iferror(VLOOKUP(A10,indirect("'" & "Current" & "'!$B:$T"),19,false),"") | D10: =IF(COUNTIF(A:A, A10) > 1, "Duplicate", "") | E10: =E9+1 -> 9 | I10: =IFERROR(__xludf.DUMMYFUNCTION("""COMPUTED_VALUE"""),"Camille Jung") -> Camille Jung | M10: =if(M9="","",if(P$21>M9,M9+1,"")) | O10: Sitouts | P10: =COUNTIF(J2:J99, "?*") -> 0 | R10: =CONCATENATE(O$19," ------ ",P$19) -> Total ------ 67
