Workbook

Sheet Current
B1: Standings as of | C1: 45654
B2: Number of Weeks Played | D2: 26 | AB2: =text(C1,"mm/dd/yy") -> 12/28/24
C3: Beginning of week | F3: Current Week Scores | N3: End of week | Q3: Jul-Dec 2024 | R3: Jan-Jun 2025
A4: Ranking | B4: Name of Player | C4: Games Won | D4: Sets Won | E4: Games Won / Match | F4: Check IN | G4: Court # | H4: Set 0 | I4: Set 1 | J4: Set 2 | K4: Set 3 | L4: Games Won | M4: Sets Won | N4: Games Won | O4: Sets Won | P4: Waiver | Q4: Fee | R4: Fee | S4: Sit outs | T4: No Shows | U4: Absent | V4: Positions Gained/Lost | W4: Ranking
A5: 1 | B5: Adrian Tay | C5: 401 | D5: 47 | E5: =(C5-(U5*9)-(S5*13))/($D$2-U5-S5) -> 17.833333 | F5: =if(isna(VLOOKUP(B5,Checkin!A:B,2,false)),0,VLOOKUP(B5,Checkin!A:B,2,false)) -> 0 | G5: =if(OR($F5=1, $F5=2),VLOOKUP($B5,Courts!$B$2:$K$50,10,false),0) -> 0 | H5: =IF(OR(F5=3,F5=4),9,IF(F5=5,13,0)) -> 0 | I5: =if(OR($F5=1, $F5=2),VLOOKUP($B5,Courts!$B$2:$J$50,5,false),0) -> 0 | J5: =if(OR($F5=1, $F5=2),VLOOKUP($B5,Courts!$B$2:$J$50,6,false),0) -> 0 | K5: =if(OR($F5=1, $F5=2),VLOOKUP($B5,Courts!$B$2:$J$50,7,false),0) -> 0 | L5: =H5+I5+J5+K5 -> 0 | M5: =if(OR($F5=1, $F5=2),VLOOKUP($B5,Courts!$B$2:$J$50,9,false),0) -> 0 | N5: =C5+L5 -> 401 | O5: =D5+M5 -> 47 | P5: X | Q5: X | R5: X | S5: =if(H5=13,1,0)+VLOOKUP(B5,indirect($AB$2&"!B:T"),18,false) -> 2 | U5: =if(H5=9,1,0)+VLOOKUP(B5,indirect($AB$2&"!B:U"),20,false) -> 6 | V5: =VLOOKUP(B5,indirect($AB$2&"!B$5:w$70"),22,false)-A5 -> 0 | W5: 1
A6: =A5+1 -> 2 | B6: David Shin | C6: 354 | D6: 30 | E6: =(C6-(U6*9)-(S6*13))/($D$2-U6-S6) -> 15 | F6: =if(isna(VLOOKUP(B6,Checkin!A:B,2,false)),0,VLOOKUP(B6,Checkin!A:B,2,false)) -> 0 | G6: =if(OR($F6=1, $F6=2),VLOOKUP($B6,Courts!$B$2:$K$50,10,false),0) -> 0 | H6: =IF(OR(F6=3,F6=4),9,IF(F6=5,13,0)) -> 0 | I6: =if(OR($F6=1, $F6=2),VLOOKUP($B6,Courts!$B$2:$J$50,5,false),0) -> 0 | J6: =if(OR($F6=1, $F6=2),VLOOKUP($B6,Courts!$B$2:$J$50,6,false),0) -> 0 | K6: =if(OR($F6=1, $F6=2),VLOOKUP($B6,Courts!$B$2:$J$50,7,false),0) -> 0 | L6: =H6+I6+J6+K6 -> 0 | M6: =if(OR($F6=1, $F6=2),VLOOKUP($B6,Courts!$B$2:$J$50,9,false),0) -> 0 | N6: =C6+L6 -> 354 | O6: =D6+M6 -> 30 | P6: X | Q6: X | R6: X | S6: =if(H6=13,1,0)+VLOOKUP(B6,indirect($AB$2&"!B:T"),18,false) -> 3 | U6: =if(H6=9,1,0)+VLOOKUP(B6,indirect($AB$2&"!B:U"),20,false) -> 5 | V6: =VLOOKUP(B6,indirect($AB$2&"!B$5:w$70"),22,false)-A6 -> 0 | W6: =W5+1 -> 2
A7: =A6+1 -> 3 | B7: Tom Le | C7: 350 | D7: 34 | E7: =(C7-(U7*9)-(S7*13))/($D$2-U7-S7) -> 15.105263 | F7: =if(isna(VLOOKUP(B7,Checkin!A:B,2,false)),0,VLOOKUP(B7,Checkin!A:B,2,false)) -> 0 | G7: =if(OR($F7=1, $F7=2),VLOOKUP($B7,Courts!$B$2:$K$50,10,false),0) -> 0 | H7: =IF(OR(F7=3,F7=4),9,IF(F7=5,13,0)) -> 0 | I7: =if(OR($F7=1, $F7=2),VLOOKUP($B7,Courts!$B$2:$J$50,5,false),0) -> 0 | J7: =if(OR($F7=1, $F7=2),VLOOKUP($B7,Courts!$B$2:$J$50,6,false),0) -> 0 | K7: =if(OR($F7=1, $F7=2),VLOOKUP($B7,Courts!$B$2:$J$50,7,false),0) -> 0 | L7: =H7+I7+J7+K7 -> 0 | M7: =if(OR($F7=1, $F7=2),VLOOKUP($B7,Courts!$B$2:$J$50,9,false),0) -> 0 | N7: =C7+L7 -> 350 | O7: =D7+M7 -> 34 | P7: X | Q7: X | R7: X | S7: =if(H7=13,1,0)+VLOOKUP(B7,indirect($AB$2&"!B:T"),18,false) -> 0 | U7: =if(H7=9,1,0)+VLOOKUP(B7,indirect($AB$2&"!B:U"),20,false) -> 7 | V7: =VLOOKUP(B7,indirect($AB$2&"!B$5:w$70"),22,false)-A7 -> 0 | W7: =W6+1 -> 3
A8: =A7+1 -> 4 | B8: Pulkit Mathur | C8: 346 | D8: 32 | E8: =(C8-(U8*9)-(S8*13))/($D$2-U8-S8) -> 17.666667 | F8: =if(isna(VLOOKUP(B8,Checkin!A:B,2,false)),0,VLOOKUP(B8,Checkin!A:B,2,false)) -> 0 | G8: =if(OR($F8=1, $F8=2),VLOOKUP($B8,Courts!$B$2:$K$50,10,false),0) -> 0 | H8: =IF(OR(F8=3,F8=4),9,IF(F8=5,13,0)) -> 0 | I8: =if(OR($F8=1, $F8=2),VLOOKUP($B8,Courts!$B$2:$J$50,5,false),0) -> 0 | J8: =if(OR($F8=1, $F8=2),VLOOKUP($B8,Courts!$B$2:$J$50,6,false),0) -> 0 | K8: =if(OR($F8=1, $F8=2),VLOOKUP($B8,Courts!$B$2:$J$50,7,false),0) -> 0 | L8: =H8+I8+J8+K8 -> 0 | M8: =if(OR($F8=1, $F8=2),VLOOKUP($B8,Courts!$B$2:$J$50,9,false),0) -> 0 | N8: =C8+L8 -> 346 | O8: =D8+M8 -> 32 | P8: X | Q8: X | R8: X | S8: =if(H8=13,1,0)+VLOOKUP(B8,indirect($AB$2&"!B:T"),18,false) -> 2 | U8: =if(H8=9,1,0)+VLOOKUP(B8,indirect($AB$2&"!B:U"),20,false) -> 12 | V8: =VLOOKUP(B8,indirect($AB$2&"!B$5:w$70"),22,false)-A8 -> 5 | W8: =W7+1 -> 4
A9: =A8+1 -> 5 | B9: Ted Shen | C9: 345 | D9: 32 | E9: =(C9-(U9*9)-(S9*13))/($D$2-U9-S9) -> 13.652174 | F9: =if(isna(VLOOKUP(B9,Checkin!A:B,2,false)),0,VLOOKUP(B9,Checkin!A:B,2,false)) -> 0 | G9: =if(OR($F9=1, $F9=2),VLOOKUP($B9,Courts!$B$2:$K$50,10,false),0) -> 0 | H9: =IF(OR(F9=3,F9=4),9,IF(F9=5,13,0)) -> 0 | I9: =if(OR($F9=1, $F9=2),VLOOKUP($B9,Courts!$B$2:$J$50,5,false),0) -> 0 | J9: =if(OR($F9=1, $F9=2),VLOOKUP($B9,Courts!$B$2:$J$50,6,false),0) -> 0 | K9: =if(OR($F9=1, $F9=2),VLOOKUP($B9,Courts!$B$2:$J$50,7,false),0) -> 0 | L9: =H9+I9+J9+K9 -> 0 | M9: =if(OR($F9=1, $F9=2),VLOOKUP($B9,Courts!$B$2:$J$50,9,false),0) -> 0 | N9: =C9+L9 -> 345 | O9: =D9+M9 -> 32 | P9: X | Q9: X | R9: X | S9: =if(H9=13,1,0)+VLOOKUP(B9,indirect($AB$2&"!B:T"),18,false) -> 1 | U9: =if(H9=9,1,0)+VLOOKUP(B9,indirect($AB$2&"!B:U"),20,false) -> 2 | V9: =VLOOKUP(B9,indirect($AB$2&"!B$5:w$70"),22,false)-A9 -> -1 | W9: =W8+1 -> 5
A10: =A9+1 -> 6 | B10: Suleman Alidina | C10: 342 | D10: 32 | E10: =(C10-(U10*9)-(S10*13))/($D$2-U10-S10) -> 14.2 | F10: =if(isna(VLOOKUP(B10,Checkin!A:B,2,false)),0,VLOOKUP(B10,Checkin!A:B,2,false)) -> 0 | G10: =if(OR($F10=1, $F10=2),VLOOKUP($B10,Courts!$B$2:$K$50,10,false),0) -> 0 | H10: =IF(OR(F10=3,F10=4),9,IF(F10=5,13,0)) -> 0 | I10: =if(OR($F10=1, $F10=2),VLOOKUP($B10,Courts!$B$2:$J$50,5,false),0) -> 0 | J10: =if(OR($F10=1, $F10=2),VLOOKUP($B10,Courts!$B$2:$J$50,6,false),0) -> 0 | K10: =if(OR($F10=1, $F10=2),VLOOKUP($B10,Courts!$B$2:$J$50,7,false),0) -> 0 | L10: =H10+I10+J10+K10 -> 0 | M10: =if(OR($F10=1, $F10=2),VLOOKUP($B10,Courts!$B$2:$J$50,9,false),0) -> 0 | N10: =C10+L10 -> 342 | O10: =D10+M10 -> 32 | P10: X | Q10: X | R10: X | S10: =if(H10=13,1,0)+VLOOKUP(B10,indirect($AB$2&"!B:T"),18,false) -> 1 | U10: =if(H10=9,1,0)+VLOOKUP(B10,indirect($AB$2&"!B:U"),20,false) -> 5 | V10: =VLOOKUP(B10,indirect($AB$2&"!B$5:w$70"),22,false)-A10 -> 2 | W10: =W9+1 -> 6
A11: =A10+1 -> 7 | B11: Scott Li | C11: 340 | D11: 25 | E11: =(C11-(U11*9)-(S11*13))/($D$2-U11-S11) -> 14.1 | F11: =if(isna(VLOOKUP(B11,Checkin!A:B,2,false)),0,VLOOKUP(B11,Checkin!A:B,2,false)) -> 0 | G11: =if(OR($F11=1, $F11=2),VLOOKUP($B11,Courts!$B$2:$K$50,10,false),0) -> 0 | H11: =IF(OR(F11=3,F11=4),9,IF(F11=5,13,0)) -> 0 | I11: =if(OR($F11=1, $F11=2),VLOOKUP($B11,Courts!$B$2:$J$50,5,false),0) -> 0 | J11: =if(OR($F11=1, $F11=2),VLOOKUP($B11,Courts!$B$2:$J$50,6,false),0) -> 0 | K11: =if(OR($F11=1, $F11=2),VLOOKUP($B11,Courts!$B$2:$J$50,7,false),0) -> 0 | L11: =H11+I11+J11+K11 -> 0 | M11: =if(OR($F11=1, $F11=2),VLOOKUP($B11,Courts!$B$2:$J$50,9,false),0) -> 0 | N11: =C11+L11 -> 340 | O11: =D11+M11 -> 25 | P11: X | Q11: X | R11: X | S11: =if(H11=13,1,0)+VLOOKUP(B11,indirect($AB$2&"!B:T"),18,false) -> 1 | U11: =if(H11=9,1,0)+VLOOKUP(B11,indirect($AB$2&"!B:U"),20,false) -> 5 | V11: =VLOOKUP(B11,indirect($AB$2&"!B$5:w$70"),22,false)-A11 -> -1 | W11: =W10+1 -> 7
A12: =A11+1 -> 8 | B12: Frank Moon | C12: 338 | D12: 31 | E12: =(C12-(U12*9)-(S12*13))/($D$2-U12-S12) -> 13.333333 | F12: =if(isna(VLOOKUP(B12,Checkin!A:B,2,false)),0,VLOOKUP(B12,Checkin!A:B,2,false)) -> 0 | G12: =if(OR($F12=1, $F12=2),VLOOKUP($B12,Courts!$B$2:$K$50,10,false),0) -> 0 | H12: =IF(OR(F12=3,F12=4),9,IF(F12=5,13,0)) -> 0 | I12: =if(OR($F12=1, $F12=2),VLOOKUP($B12,Courts!$B$2:$J$50,5,false),0) -> 0 | J12: =if(OR($F12=1, $F12=2),VLOOKUP($B12,Courts!$B$2:$J$50,6,false),0) -> 0 | K12: =if(OR($F12=1, $F12=2),VLOOKUP($B12,Courts!$B$2:$J$50,7,false),0) -> 0 | L12: =H12+I12+J12+K12 -> 0 | M12: =if(OR($F12=1, $F12=2),VLOOKUP($B12,Courts!$B$2:$J$50,9,false),0) -> 0 | N12: =C12+L12 -> 338 | O12: =D12+M12 -> 31 | P12: X | Q12: X | R12: X | S12: =if(H12=13,1,0)+VLOOKUP(B12,indirect($AB$2&"!B:T"),18,false) -> 0 | U12: =if(H12=9,1,0)+VLOOKUP(B12,indirect($AB$2&"!B:U"),20,false) -> 2 | V12: =VLOOKUP(B12,indirect($AB$2&"!B$5:w$70"),22,false)-A12 -> -3 | W12: =W11+1 -> 8
A13: =A12+1 -> 9 | B13: Lam Bui | C13: 336 | D13: 27 | E13: =(C13-(U13*9)-(S13*13))/($D$2-U13-S13) -> 16.230769 | F13: =if(isna(VLOOKUP(B13,Checkin!A:B,2,false)),0,VLOOKUP(B13,Checkin!A:B,2,false)) -> 0 | G13: =if(OR($F13=1, $F13=2),VLOOKUP($B13,Courts!$B$2:$K$50,10,false),0) -> 0 | H13: =IF(OR(F13=3,F13=4),9,IF(F13=5,13,0)) -> 0 | I13: =if(OR($F13=1, $F13=2),VLOOKUP($B13,Courts!$B$2:$J$50,5,false),0) -> 0 | J13: =if(OR($F13=1, $F13=2),VLOOKUP($B13,Courts!$B$2:$J$50,6,false),0) -> 0 | K13: =if(OR($F13=1, $F13=2),VLOOKUP($B13,Courts!$B$2:$J$50,7,false),0) -> 0 | L13: =H13+I13+J13+K13 -> 0 | M13: =if(OR($F13=1, $F13=2),VLOOKUP($B13,Courts!$B$2:$J$50,9,false),0) -> 0 | N13: =C13+L13 -> 336 | O13: =D13+M13 -> 27 | P13: X | Q13: X | R13: X | S13: =if(H13=13,1,0)+VLOOKUP(B13,indirect($AB$2&"!B:T"),18,false) -> 2 | U13: =if(H13=9,1,0)+VLOOKUP(B13,indirect($AB$2&"!B:U"),20,false) -> 11 | V13: =VLOOKUP(B13,indirect($AB$2&"!B$5:w$70"),22,false)-A13 -> -2 | W13: =W12+1 -> 9
A14: =A13+1 -> 10 | B14: James Phan | C14: 335 | D14: 26 | E14: =(C14-(U14*9)-(S14*13))/($D$2-U14-S14) -> 17.454545 | F14: =if(isna(VLOOKUP(B14,Checkin!A:B,2,false)),0,VLOOKUP(B14,Checkin!A:B,2,false)) -> 0 | G14: =if(OR($F14=1, $F14=2),VLOOKUP($B14,Courts!$B$2:$K$50,10,false),0) -> 0 | H14: =IF(OR(F14=3,F14=4),9,IF(F14=5,13,0)) -> 0 | I14: =if(OR($F14=1, $F14=2),VLOOKUP($B14,Courts!$B$2:$J$50,5,false),0) -> 0 | J14: =if(OR($F14=1, $F14=2),VLOOKUP($B14,Courts!$B$2:$J$50,6,false),0) -> 0 | K14: =if(OR($F14=1, $F14=2),VLOOKUP($B14,Courts!$B$2:$J$50,7,false),0) -> 0 | L14: =H14+I14+J14+K14 -> 0 | M14: =if(OR($F14=1, $F14=2),VLOOKUP($B14,Courts!$B$2:$J$50,9,false),0) -> 0 | N14: =C14+L14 -> 335 | O14: =D14+M14 -> 26 | P14: X | Q14: X | R14: X | S14: =if(H14=13,1,0)+VLOOKUP(B14,indirect($AB$2&"!B:T"),18,false) -> 2 | U14: =if(H14=9,1,0)+VLOOKUP(B14,indirect($AB$2&"!B:U"),20,false) -> 13 | V14: =VLOOKUP(B14,indirect($AB$2&"!B$5:w$70"),22,false)-A14 -> 3 | W14: =W13+1 -> 10
A15: =A14+1 -> 11 | B15: Herman Au | C15: 335 | D15: 22 | E15: =(C15-(U15*9)-(S15*13))/($D$2-U15-S15) -> 13.238095 | F15: =if(isna(VLOOKUP(B15,Checkin!A:B,2,false)),0,VLOOKUP(B15,Checkin!A:B,2,false)) -> 0 | G15: =if(OR($F15=1, $F15=2),VLOOKUP($B15,Courts!$B$2:$K$50,10,false),0) -> 0 | H15: =IF(OR(F15=3,F15=4),9,IF(F15=5,13,0)) -> 0 | I15: =if(OR($F15=1, $F15=2),VLOOKUP($B15,Courts!$B$2:$J$50,5,false),0) -> 0 | J15: =if(OR($F15=1, $F15=2),VLOOKUP($B15,Courts!$B$2:$J$50,6,false),0) -> 0 | K15: =if(OR($F15=1, $F15=2),VLOOKUP($B15,Courts!$B$2:$J$50,7,false),0) -> 0 | L15: =H15+I15+J15+K15 -> 0 | M15: =if(OR($F15=1, $F15=2),VLOOKUP($B15,Courts!$B$2:$J$50,9,false),0) -> 0 | N15: =C15+L15 -> 335 | O15: =D15+M15 -> 22 | P15: X | Q15: X | R15: X | S15: =if(H15=13,1,0)+VLOOKUP(B15,indirect($AB$2&"!B:T"),18,false) -> 3 | U15: =if(H15=9,1,0)+VLOOKUP(B15,indirect($AB$2&"!B:U"),20,false) -> 2 | V15: =VLOOKUP(B15,indirect($AB$2&"!B$5:w$70"),22,false)-A15 -> 1 | W15: =W14+1 -> 11
A16: =A15+1 -> 12 | B16: Alejandro Mejia | C16: 334 | D16: 34 | E16: =(C16-(U16*9)-(S16*13))/($D$2-U16-S16) -> 14.263158 | F16: =if(isna(VLOOKUP(B16,Checkin!A:B,2,false)),0,VLOOKUP(B16,Checkin!A:B,2,false)) -> 0 | G16: =if(OR($F16=1, $F16=2),VLOOKUP($B16,Courts!$B$2:$K$50,10,false),0) -> 0 | H16: =IF(OR(F16=3,F16=4),9,IF(F16=5,13,0)) -> 0 | I16: =if(OR($F16=1, $F16=2),VLOOKUP($B16,Courts!$B$2:$J$50,5,false),0) -> 0 | J16: =if(OR($F16=1, $F16=2),VLOOKUP($B16,Courts!$B$2:$J$50,6,false),0) -> 0 | K16: =if(OR($F16=1, $F16=2),VLOOKUP($B16,Courts!$B$2:$J$50,7,false),0) -> 0 | L16: =H16+I16+J16+K16 -> 0 | M16: =if(OR($F16=1, $F16=2),VLOOKUP($B16,Courts!$B$2:$J$50,9,false),0) -> 0 | N16: =C16+L16 -> 334 | O16: =D16+M16 -> 34 | P16: X | Q16: X | R16: X | S16: =if(H16=13,1,0)+VLOOKUP(B16,indirect($AB$2&"!B:T"),18,false) -> 0 | U16: =if(H16=9,1,0)+VLOOKUP(B16,indirect($AB$2&"!B:U"),20,false) -> 7 | V16: =VLOOKUP(B16,indirect($AB$2&"!B$5:w$70"),22,false)-A16 -> -2 | W16: =W15+1 -> 12
A17: =A16+1 -> 13 | B17: Pavan Akkimsetty | C17: 333 | D17: 26 | E17: =(C17-(U17*9)-(S17*13))/($D$2-U17-S17) -> 15.1875 | F17: =if(isna(VLOOKUP(B17,Checkin!A:B,2,false)),0,VLOOKUP(B17,Checkin!A:B,2,false)) -> 0 | G17: =if(OR($F17=1, $F17=2),VLOOKUP($B17,Courts!$B$2:$K$50,10,false),0) -> 0 | H17: =IF(OR(F17=3,F17=4),9,IF(F17=5,13,0)) -> 0 | I17: =if(OR($F17=1, $F17=2),VLOOKUP($B17,Courts!$B$2:$J$50,5,false),0) -> 0 | J17: =if(OR($F17=1, $F17=2),VLOOKUP($B17,Courts!$B$2:$J$50,6,false),0) -> 0 | K17: =if(OR($F17=1, $F17=2),VLOOKUP($B17,Courts!$B$2:$J$50,7,false),0) -> 0 | L17: =H17+I17+J17+K17 -> 0 | M17: =if(OR($F17=1, $F17=2),VLOOKUP($B17,Courts!$B$2:$J$50,9,false),0) -> 0 | N17: =C17+L17 -> 333 | O17: =D17+M17 -> 26 | P17: X | Q17: X | R17: X | S17: =if(H17=13,1,0)+VLOOKUP(B17,indirect($AB$2&"!B:T"),18,false) -> 0 | U17: =if(H17=9,1,0)+VLOOKUP(B17,indirect($AB$2&"!B:U"),20,false) -> 10 | V17: =VLOOKUP(B17,indirect($AB$2&"!B$5:w$70"),22,false)-A17 -> -2 | W17: =W16+1 -> 13
... A65: =A64+1 -> 61 | B65: Eric Pan | C65: 243 | D65: 3 | E65: =(C65-(U65*9)-(S65*13))/($D$2-U65-S65) -> 18 | F65: =if(isna(VLOOKUP(B65,Checkin!A:B,2,false)),0,VLOOKUP(B65,Checkin!A:B,2,false)) -> 0 | G65: =if(OR($F65=1, $F65=2),VLOOKUP($B65,Courts!$B$2:$K$50,10,false),0) -> 0 | H65: =IF(OR(F65=3,F65=4),9,IF(F65=5,13,0)) -> 0 | I65: =if(OR($F65=1, $F65=2),VLOOKUP($B65,Courts!$B$2:$J$50,5,false),0) -> 0 | J65: =if(OR($F65=1, $F65=2),VLOOKUP($B65,Courts!$B$2:$J$50,6,false),0) -> 0 | K65: =if(OR($F65=1, $F65=2),VLOOKUP($B65,Courts!$B$2:$J$50,7,false),0) -> 0 | L65: =H65+I65+J65+K65 -> 0 | M65: =if(OR($F65=1, $F65=2),VLOOKUP($B65,Courts!$B$2:$J$50,9,false),0) -> 0 | N65: =C65+L65 -> 243 | O65: =D65+M65 -> 3 | P65: X | Q65: X | R65: X | S65: =if(H65=13,1,0)+VLOOKUP(B65,indirect($AB$2&"!B:T"),18,false) -> 0 | U65: =if(H65=9,1,0)+VLOOKUP(B65,indirect($AB$2&"!B:U"),20,false) -> 25 | V65: =VLOOKUP(B65,indirect($AB$2&"!B$5:w$70"),22,false)-A65 -> 0 | W65: =W64+1 -> 61
A66: =A65+1 -> 62 | B66: Peter Homsey | C66: 238 | D66: 0 | E66: =(C66-(U66*9)-(S66*13))/($D$2-U66-S66) -> 9 | F66: =if(isna(VLOOKUP(B66,Checkin!A:B,2,false)),0,VLOOKUP(B66,Checkin!A:B,2,false)) -> 0 | H66: =IF(OR(F66=3,F66=4),9,IF(F66=5,13,0)) -> 0 | L66: =H66+I66+J66+K66 -> 0 | N66: =C66+L66 -> 238 | O66: =D66+M66 -> 0 | P66: X | Q66: X | R66: N | S66: =if(H66=13,1,0)+VLOOKUP(B66,indirect($AB$2&"!B:T"),18,false) -> 1 | U66: =if(H66=9,1,0)+VLOOKUP(B66,indirect($AB$2&"!B:U"),20,false) -> 23 | W66: =W65+1 -> 62
A67: =A66+1 -> 63 | B67: Amit Patel | C67: 238 | D67: 0 | E67: =(C67-(U67*9)-(S67*13))/($D$2-U67-S67) -> 9 | F67: =if(isna(VLOOKUP(B67,Checkin!A:B,2,false)),0,VLOOKUP(B67,Checkin!A:B,2,false)) -> 0 | G67: =if(OR($F67=1, $F67=2),VLOOKUP($B67,Courts!$B$2:$K$50,10,false),0) -> 0 | H67: =IF(OR(F67=3,F67=4),9,IF(F67=5,13,0)) -> 0 | I67: =if(OR($F67=1, $F67=2),VLOOKUP($B67,Courts!$B$2:$J$50,5,false),0) -> 0 | J67: =if(OR($F67=1, $F67=2),VLOOKUP($B67,Courts!$B$2:$J$50,6,false),0) -> 0 | K67: =if(OR($F67=1, $F67=2),VLOOKUP($B67,Courts!$B$2:$J$50,7,false),0) -> 0 | L67: =H67+I67+J67+K67 -> 0 | M67: =if(OR($F67=1, $F67=2),VLOOKUP($B67,Courts!$B$2:$J$50,9,false),0) -> 0 | N67: =C67+L67 -> 238 | O67: =D67+M67 -> 0 | P67: X | Q67: X | R67: N | S67: =if(H67=13,1,0)+VLOOKUP(B67,indirect($AB$2&"!B:T"),18,false) -> 1 | U67: =if(H67=9,1,0)+VLOOKUP(B67,indirect($AB$2&"!B:U"),20,false) -> 24 | V67: =VLOOKUP(B67,indirect($AB$2&"!B$5:w$70"),22,false)-A67 -> 0 | W67: =W66+1 -> 63
A68: =A67+1 -> 64 | B68: Joyce Zhu | C68: 228 | D68: 11 | E68: =(C68-(U68*9)-(S68*13))/($D$2-U68-S68) -> 8.625 | F68: =if(isna(VLOOKUP(B68,Checkin!A:B,2,false)),0,VLOOKUP(B68,Checkin!A:B,2,false)) -> 0 | G68: =if(OR($F68=1, $F68=2),VLOOKUP($B68,Courts!$B$2:$K$50,10,false),0) -> 0 | H68: =IF(OR(F68=3,F68=4),9,IF(F68=5,13,0)) -> 0 | I68: =if(OR($F68=1, $F68=2),VLOOKUP($B68,Courts!$B$2:$J$50,5,false),0) -> 0 | J68: =if(OR($F68=1, $F68=2),VLOOKUP($B68,Courts!$B$2:$J$50,6,false),0) -> 0 | K68: =if(OR($F68=1, $F68=2),VLOOKUP($B68,Courts!$B$2:$J$50,7,false),0) -> 0 | L68: =H68+I68+J68+K68 -> 0 | M68: =if(OR($F68=1, $F68=2),VLOOKUP($B68,Courts!$B$2:$J$50,9,false),0) -> 0 | N68: =C68+L68 -> 228 | O68: =D68+M68 -> 11 | P68: X | Q68: X | R68: X | S68: =if(H68=13,1,0)+VLOOKUP(B68,indirect($AB$2&"!B:T"),18,false) -> 0 | U68: =if(H68=9,1,0)+VLOOKUP(B68,indirect($AB$2&"!B:U"),20,false) -> 10 | V68: =VLOOKUP(B68,indirect($AB$2&"!B$5:w$70"),22,false)-A68 -> 0 | W68: =W67+1 -> 64
A69: =A68+1 -> 65 | B69: Jose Ortiz | C69: 225 | D69: 0 | E69: =(C69-(U69*9)-(S69*13))/($D$2-U69-S69) -> #DIV/0! | F69: =if(isna(VLOOKUP(B69,Checkin!A:B,2,false)),0,VLOOKUP(B69,Checkin!A:B,2,false)) -> 0 | G69: =if(OR($F69=1, $F69=2),VLOOKUP($B69,Courts!$B$2:$K$50,10,false),0) -> 0 | H69: =IF(OR(F69=3,F69=4),9,IF(F69=5,13,0)) -> 0 | I69: =if(OR($F69=1, $F69=2),VLOOKUP($B69,Courts!$B$2:$J$50,5,false),0) -> 0 | J69: =if(OR($F69=1, $F69=2),VLOOKUP($B69,Courts!$B$2:$J$50,6,false),0) -> 0 | K69: =if(OR($F69=1, $F69=2),VLOOKUP($B69,Courts!$B$2:$J$50,7,false),0) -> 0 | L69: =H69+I69+J69+K69 -> 0 | M69: =if(OR($F69=1, $F69=2),VLOOKUP($B69,Courts!$B$2:$J$50,9,false),0) -> 0 | N69: =C69+L69 -> 225 | O69: =D69+M69 -> 0 | P69: X | Q69: X | R69: N | S69: =if(H69=13,1,0)+VLOOKUP(B69,indirect($AB$2&"!B:T"),18,false) -> 0 | U69: =if(H69=9,1,0)+VLOOKUP(B69,indirect($AB$2&"!B:U"),20,false) -> 26 | V69: =VLOOKUP(B69,indirect($AB$2&"!B$5:w$70"),22,false)-A69 -> 0 | W69: =W68+1 -> 65
B72: =COUNTA(B5:B69) -> 65
P77: Renewed | R77: =COUNTIF(R5:R69,"X") -> 55
B78: Top Scores | C78: Games | D78: Sets | E78: Court # | P78: Not Renewing | R78: =countif(R5:R69,"N") -> 10
B79: =IFERROR(__xludf.DUMMYFUNCTION("QUERY(B5:M69,""Select B, L, M, G where L >= 18 order by L desc,M desc"",0)"),"#N/A") -> #N/A | P79: To Renew | R79: =countif(R5:R69,"") -> 0
P80: Total | R80: =sum(R77:R79) -> 65
P82: * Jimmy Awolesi paid for Jan-Dec 2025
B92: Top 10 Movements (UP) | C92: Positions Moved | D92: Position Last week | E92: Position This week | F92: Points this week | G92: Court | L92: Cross Check
B93: =IFERROR(__xludf.DUMMYFUNCTION("query(B5:V69,""select B, V order by V Desc Limit 10"")"),"Sandy Weyant") -> Sandy Weyant | C93: =IFERROR(__xludf.DUMMYFUNCTION("""COMPUTED_VALUE"""),7.0) -> 7 | D93: =VLOOKUP(B93,indirect($AB$2&"!B$5:w$70"),22, false) -> 45 | E93: =VLOOKUP(B93,B$5:W$69,22, false) -> 38 | F93: =VLOOKUP(B93,indirect($AB$2&"!B$5:U$70"),11, false) -> 18 | G93: =VLOOKUP(B93,indirect($AB$2&"!B$5:U$70"),6, false) -> 7 | L93: =if(D93-E93=C93,"ok","Error") -> ok
B94: =IFERROR(__xludf.DUMMYFUNCTION("""COMPUTED_VALUE"""),"Sean Chang") -> Sean Chang | C94: =IFERROR(__xludf.DUMMYFUNCTION("""COMPUTED_VALUE"""),6.0) -> 6 | D94: =VLOOKUP(B94,indirect($AB$2&"!B$5:w$70"),22, false) -> 27 | E94: =VLOOKUP(B94,B$5:W$69,22, false) -> 21 | F94: =VLOOKUP(B94,indirect($AB$2&"!B$5:U$70"),11, false) -> 18 | G94: =VLOOKUP(B94,indirect($AB$2&"!B$5:U$70"),6, false) -> 5 | L94: =if(D94-E94=C94,"ok","Error") -> ok
B95: =IFERROR(__xludf.DUMMYFUNCTION("""COMPUTED_VALUE"""),"Pulkit Mathur") -> Pulkit Mathur | C95: =IFERROR(__xludf.DUMMYFUNCTION("""COMPUTED_VALUE"""),5.0) -> 5 | D95: =VLOOKUP(B95,indirect($AB$2&"!B$5:w$70"),22, false) -> 9 | E95: =VLOOKUP(B95,B$5:W$69,22, false) -> 4 | F95: =VLOOKUP(B95,indirect($AB$2&"!B$5:U$70"),11, false) -> 20 | G95: =VLOOKUP(B95,indirect($AB$2&"!B$5:U$70"),6, false) -> 2 | L95: =if(D95-E95=C95,"ok","Error") -> ok
B96: =IFERROR(__xludf.DUMMYFUNCTION("""COMPUTED_VALUE"""),"James Phan") -> James Phan | C96: =IFERROR(__xludf.DUMMYFUNCTION("""COMPUTED_VALUE"""),3.0) -> 3 | D96: =VLOOKUP(B96,indirect($AB$2&"!B$5:w$70"),22, false) -> 13 | E96: =VLOOKUP(B96,B$5:W$69,22, false) -> 10 | F96: =VLOOKUP(B96,indirect($AB$2&"!B$5:U$70"),11, false) -> 13 | G96: =VLOOKUP(B96,indirect($AB$2&"!B$5:U$70"),6, false) -> 0 | L96: =if(D96-E96=C96,"ok","Error") -> ok
B97: =IFERROR(__xludf.DUMMYFUNCTION("""COMPUTED_VALUE"""),"Sanjaye Elayattu") -> Sanjaye Elayattu | C97: =IFERROR(__xludf.DUMMYFUNCTION("""COMPUTED_VALUE"""),3.0) -> 3 | D97: =VLOOKUP(B97,indirect($AB$2&"!B$5:w$70"),22, false) -> 26 | E97: =VLOOKUP(B97,B$5:W$69,22, false) -> 23 | F97: =VLOOKUP(B97,indirect($AB$2&"!B$5:U$70"),11, false) -> 13 | G97: =VLOOKUP(B97,indirect($AB$2&"!B$5:U$70"),6, false) -> 0 | L97: =if(D97-E97=C97,"ok","Error") -> ok
B98: =IFERROR(__xludf.DUMMYFUNCTION("""COMPUTED_VALUE"""),"Nicole Ni") -> Nicole Ni | C98: =IFERROR(__xludf.DUMMYFUNCTION("""COMPUTED_VALUE"""),3.0) -> 3 | D98: =VLOOKUP(B98,indirect($AB$2&"!B$5:w$70"),22, false) -> 46 | E98: =VLOOKUP(B98,B$5:W$69,22, false) -> 43 | F98: =VLOOKUP(B98,indirect($AB$2&"!B$5:U$70"),11, false) -> 13 | G98: =VLOOKUP(B98,indirect($AB$2&"!B$5:U$70"),6, false) -> 7 | L98: =if(D98-E98=C98,"ok","Error") -> ok
B99: =IFERROR(__xludf.DUMMYFUNCTION("""COMPUTED_VALUE"""),"Vinaya Kajla") -> Vinaya Kajla | C99: =IFERROR(__xludf.DUMMYFUNCTION("""COMPUTED_VALUE"""),3.0) -> 3 | D99: =VLOOKUP(B99,indirect($AB$2&"!B$5:w$70"),22, false) -> 55 | E99: =VLOOKUP(B99,B$5:W$69,22, false) -> 52 | F99: =VLOOKUP(B99,indirect($AB$2&"!B$5:U$70"),11, false) -> 11 | G99: =VLOOKUP(B99,indirect($AB$2&"!B$5:U$70"),6, false) -> 7 | L99: =if(D99-E99=C99,"ok","Error") -> ok
B100: =IFERROR(__xludf.DUMMYFUNCTION("""COMPUTED_VALUE"""),"Suleman Alidina") -> Suleman Alidina | C100: =IFERROR(__xludf.DUMMYFUNCTION("""COMPUTED_VALUE"""),2.0) -> 2 | D100: =VLOOKUP(B100,indirect($AB$2&"!B$5:w$70"),22, false) -> 8 | E100: =VLOOKUP(B100,B$5:W$69,22, false) -> 6 | F100: =VLOOKUP(B100,indirect($AB$2&"!B$5:U$70"),11, false) -> 16 | G100: =VLOOKUP(B100,indirect($AB$2&"!B$5:U$70"),6, false) -> 2 | L100: =if(D100-E100=C100,"ok","Error") -> ok
B101: =IFERROR(__xludf.DUMMYFUNCTION("""COMPUTED_VALUE"""),"Robert Chang") -> Robert Chang | C101: =IFERROR(__xludf.DUMMYFUNCTION("""COMPUTED_VALUE"""),2.0) -> 2 | D101: =VLOOKUP(B101,indirect($AB$2&"!B$5:w$70"),22, false) -> 17 | E101: =VLOOKUP(B101,B$5:W$69,22, false) -> 15 | F101: =VLOOKUP(B101,indirect($AB$2&"!B$5:U$70"),11, false) -> 18 | G101: =VLOOKUP(B101,indirect($AB$2&"!B$5:U$70"),6, false) -> 3 | L101: =if(D101-E101=C101,"ok","Error") -> ok
B102: =IFERROR(__xludf.DUMMYFUNCTION("""COMPUTED_VALUE"""),"Ramesh Bandaru") -> Ramesh Bandaru | C102: =IFERROR(__xludf.DUMMYFUNCTION("""COMPUTED_VALUE"""),2.0) -> 2 | D102: =VLOOKUP(B102,indirect($AB$2&"!B$5:w$70"),22, false) -> 30 | E102: =VLOOKUP(B102,B$5:W$69,22, false) -> 28 | F102: =VLOOKUP(B102,indirect($AB$2&"!B$5:U$70"),11, false) -> 13 | G102: =VLOOKUP(B102,indirect($AB$2&"!B$5:U$70"),6, false) -> 5 | L102: =if(D102-E102=C102,"ok","Error") -> ok
B105: Top 10 Movements (Down) | C105: Positions | D105: Position Last week | E105: Position This week | F105: Points this week | G105: Court | L105: Cross Check
...

Sheet Courts
A1: Court # | B1: Name of the Player | C1: Games Won | D1: Sets Won | E1: Check In | F1: Set 1 | G1: Set 2 | H1: Set 3 | I1: Total Games won | J1: Sets Won | K1: Court # | M1: Set 1 | N1: Set 2 | O1: Set 2 | Q1: Sets Validations | T1: Set 1 | U1: Set 2 | V1: Set 2
A2: 1 | B2: =IFERROR(__xludf.DUMMYFUNCTION("QUERY(Current!B5:F69,""Select B, C, D, F where F = 1 or F = 2 "",0)"),"#N/A") -> #N/A | I2: =sum(F2:H2) -> 0 | K2: =A2 -> 1 | M2: =if(COUNTIF(T2:T4,"Good")=2,"Good","Error") -> Error | N2: =if(COUNTIF(U2:U4,"Good")=2,"Good","Error") -> Error | O2: =if(COUNTIF(V2:V4,"Good")=2,"Good","Error") -> Error | Q2: =sum(J2:J5) -> 0 | R2: =if(Q2=0,"",if(Q2=6,"Good","ERROR")) | T2: =if(isna(VLOOKUP(F2,F3:F5,1,false)),"Error","Good") -> Error | U2: =if(isna(VLOOKUP(G2,G3:G5,1,false)),"Error","Good") -> Error | V2: =if(isna(VLOOKUP(H2,H3:H5,1,false)),"Error","Good") -> Error
A3: 1 | I3: =sum(F3:H3) -> 0 | K3: =A3 -> 1 | T3: =if(isna(VLOOKUP(F3,F4:F5,1,false)),"Error","Good") -> Error | U3: =if(isna(VLOOKUP(G3,G4:G5,1,false)),"Error","Good") -> Error | V3: =if(isna(VLOOKUP(H3,H4:H5,1,false)),"Error","Good") -> Error | AB3: Alejandro Mejia
A4: 1 | I4: =sum(F4:H4) -> 0 | K4: =A4 -> 1 | T4: =if(F4=F5,"Good") -> Good | U4: =if(G4=G5,"Good") -> Good | V4: =if(H4=H5,"Good") -> Good | W4: N | X4: Skip Court 3 | AB4: Jimmy Awolesi
A5: 1 | I5: =sum(F5:H5) -> 0 | K5: =A5 -> 1 | W5: Y | X5: Skip Court 4 | AB5: Tony Wong
A6: 2 | I6: =sum(F6:H6) -> 0 | K6: =A6 -> 2 | M6: =if(COUNTIF(T6:T8,"Good")=2,"Good","Error") -> Error | N6: =if(COUNTIF(U6:U8,"Good")=2,"Good","Error") -> Error | O6: =if(COUNTIF(V6:V8,"Good")=2,"Good","Error") -> Error | Q6: =sum(J6:J9) -> 0 | R6: =if(Q6=0,"",if(Q6=6,"Good","ERROR")) | T6: =if(isna(VLOOKUP(F6,F7:F9,1,false)),"Error","Good") -> Error | U6: =if(isna(VLOOKUP(G6,G7:G9,1,false)),"Error","Good") -> Error | V6: =if(isna(VLOOKUP(H6,H7:H9,1,false)),"Error","Good") -> Error | AB6: Vinaya Kajla
A7: 2 | I7: =sum(F7:H7) -> 0 | K7: =A7 -> 2 | T7: =if(isna(VLOOKUP(F7,F8:F9,1,false)),"Error","Good") -> Error | U7: =if(isna(VLOOKUP(G7,G8:G9,1,false)),"Error","Good") -> Error | V7: =if(isna(VLOOKUP(H7,H8:H9,1,false)),"Error","Good") -> Error
A8: 2 | I8: =sum(F8:H8) -> 0 | K8: =A8 -> 2 | T8: =if(F8=F9,"Good") -> Good | U8: =if(G8=G9,"Good") -> Good | V8: =if(H8=H9,"Good") -> Good
A9: 2 | I9: =sum(F9:H9) -> 0 | K9: =A9 -> 2
A10: =if(W4="Y",A9+3,A9+1) -> 3 | I10: =sum(F10:H10) -> 0 | K10: =A10 -> 3 | M10: =if(COUNTIF(T10:T12,"Good")=2,"Good","Error") -> Error | N10: =if(COUNTIF(U10:U12,"Good")=2,"Good","Error") -> Error | O10: =if(COUNTIF(V10:V12,"Good")=2,"Good","Error") -> Error | Q10: =sum(J10:J13) -> 0 | R10: =if(Q10=0,"",if(Q10=6,"Good","ERROR")) | T10: =if(isna(VLOOKUP(F10,F11:F13,1,false)),"Error","Good") -> Error | U10: =if(isna(VLOOKUP(G10,G11:G13,1,false)),"Error","Good") -> Error | V10: =if(isna(VLOOKUP(H10,H11:H13,1,false)),"Error","Good") -> Error
A11: =A10 -> 3 | I11: =sum(F11:H11) -> 0 | K11: =A11 -> 3 | T11: =if(isna(VLOOKUP(F11,F12:F13,1,false)),"Error","Good") -> Error | U11: =if(isna(VLOOKUP(G11,G12:G13,1,false)),"Error","Good") -> Error | V11: =if(isna(VLOOKUP(H11,H12:H13,1,false)),"Error","Good") -> Error | AB11: Suleman Alidina
A12: =A11 -> 3 | I12: =sum(F12:H12) -> 0 | K12: =A12 -> 3 | T12: =if(F12=F13,"Good") -> Good | U12: =if(G12=G13,"Good") -> Good | V12: =if(H12=H13,"Good") -> Good | AB12: Ash Nikravan
A13: =A12 -> 3 | I13: =sum(F13:H13) -> 0 | K13: =A13 -> 3 | AB13: Susanta Mishra
A14: =if(W5="Y",A13+2,A13+1) -> 5 | I14: =sum(F14:H14) -> 0 | K14: =A14 -> 5 | M14: =if(COUNTIF(T14:T16,"Good")=2,"Good","Error") -> Error | N14: =if(COUNTIF(U14:U16,"Good")=2,"Good","Error") -> Error | O14: =if(COUNTIF(V14:V16,"Good")=2,"Good","Error") -> Error | Q14: =sum(J14:J17) -> 0 | R14: =if(Q14=0,"",if(Q14=6,"Good","ERROR")) | T14: =if(isna(VLOOKUP(F14,F15:F17,1,false)),"Error","Good") -> Error | U14: =if(isna(VLOOKUP(G14,G15:G17,1,false)),"Error","Good") -> Error | V14: =if(isna(VLOOKUP(H14,H15:H17,1,false)),"Error","Good") -> Error | AB14: David Tam
A15: =A14 -> 5 | I15: =sum(F15:H15) -> 0 | K15: =A15 -> 5 | T15: =if(isna(VLOOKUP(F15,F16:F17,1,false)),"Error","Good") -> Error | U15: =if(isna(VLOOKUP(G15,G16:G17,1,false)),"Error","Good") -> Error | V15: =if(isna(VLOOKUP(H15,H16:H17,1,false)),"Error","Good") -> Error
A16: =A15 -> 5 | I16: =sum(F16:H16) -> 0 | K16: =A16 -> 5 | T16: =if(F16=F17,"Good") -> Good | U16: =if(G16=G17,"Good") -> Good | V16: =if(H16=H17,"Good") -> Good
A17: =A16 -> 5 | I17: =sum(F17:H17) -> 0 | K17: =A17 -> 5
A18: =A17+1 -> 6 | I18: =sum(F18:H18) -> 0 | K18: =A18 -> 6 | M18: =if(COUNTIF(T18:T20,"Good")=2,"Good","Error") -> Error | N18: =if(COUNTIF(U18:U20,"Good")=2,"Good","Error") -> Error | O18: =if(COUNTIF(V18:V20,"Good")=2,"Good","Error") -> Error | Q18: =sum(J18:J21) -> 0 | R18: =if(Q18=0,"",if(Q18=6,"Good","ERROR")) | T18: =if(isna(VLOOKUP(F18,F19:F21,1,false)),"Error","Good") -> Error | U18: =if(isna(VLOOKUP(G18,G19:G21,1,false)),"Error","Good") -> Error | V18: =if(isna(VLOOKUP(H18,H19:H21,1,false)),"Error","Good") -> Error | AB18: Pulkit Mathur
A19: =A18 -> 6 | I19: =sum(F19:H19) -> 0 | K19: =A19 -> 6 | T19: =if(isna(VLOOKUP(F19,F20:F21,1,false)),"Error","Good") -> Error | U19: =if(isna(VLOOKUP(G19,G20:G21,1,false)),"Error","Good") -> Error | V19: =if(isna(VLOOKUP(H19,H20:H21,1,false)),"Error","Good") -> Error | AB19: Kingsley Kuo
A20: =A19 -> 6 | I20: =sum(F20:H20) -> 0 | K20: =A20 -> 6 | T20: =if(F20=F21,"Good") -> Good | U20: =if(G20=G21,"Good") -> Good | V20: =if(H20=H21,"Good") -> Good | AB20: Scott Li
A21: =A20 -> 6 | I21: =sum(F21:H21) -> 0 | K21: =A21 -> 6 | AB21: Vamsi Lolla
A22: =A21+1 -> 7 | I22: =sum(F22:H22) -> 0 | K22: =A22 -> 7 | M22: =if(COUNTIF(T22:T24,"Good")=2,"Good","Error") -> Error | N22: =if(COUNTIF(U22:U24,"Good")=2,"Good","Error") -> Error | O22: =if(COUNTIF(V22:V24,"Good")=2,"Good","Error") -> Error | Q22: =sum(J22:J25) -> 0 | R22: =if(Q22=0,"",if(Q22=6,"Good","ERROR")) | T22: =if(isna(VLOOKUP(F22,F23:F25,1,false)),"Error","Good") -> Error | U22: =if(isna(VLOOKUP(G22,G23:G25,1,false)),"Error","Good") -> Error | V22: =if(isna(VLOOKUP(H22,H23:H25,1,false)),"Error","Good") -> Error
A23: =A22 -> 7 | I23: =sum(F23:H23) -> 0 | K23: =A23 -> 7 | T23: =if(isna(VLOOKUP(F23,F24:F25,1,false)),"Error","Good") -> Error | U23: =if(isna(VLOOKUP(G23,G24:G25,1,false)),"Error","Good") -> Error | V23: =if(isna(VLOOKUP(H23,H24:H25,1,false)),"Error","Good") -> Error
A24: =A23 -> 7 | I24: =sum(F24:H24) -> 0 | K24: =A24 -> 7 | T24: =if(F24=F25,"Good") -> Good | U24: =if(G24=G25,"Good") -> Good | V24: =if(H24=H25,"Good") -> Good | AB24: Rajasekar Ramasamy
A25: =A24 -> 7 | I25: =sum(F25:H25) -> 0 | K25: =A25 -> 7 | AB25: Anish Kumar
A26: =A25+1 -> 8 | I26: =sum(F26:H26) -> 0 | K26: =A26 -> 8 | M26: =if(COUNTIF(T26:T28,"Good")=2,"Good","Error") -> Error | N26: =if(COUNTIF(U26:U28,"Good")=2,"Good","Error") -> Error | O26: =if(COUNTIF(V26:V28,"Good")=2,"Good","Error") -> Error | Q26: =sum(J26:J29) -> 0 | R26: =if(Q26=0,"",if(Q26=6,"Good","ERROR")) | T26: =if(isna(VLOOKUP(F26,F27:F29,1,false)),"Error","Good") -> Error | U26: =if(isna(VLOOKUP(G26,G27:G29,1,false)),"Error","Good") -> Error | V26: =if(isna(VLOOKUP(H26,H27:H29,1,false)),"Error","Good") -> Error | AB26: Manuel Rivera
A27: =A26 -> 8 | I27: =sum(F27:H27) -> 0 | K27: =A27 -> 8 | T27: =if(isna(VLOOKUP(F27,F28:F29,1,false)),"Error","Good") -> Error | U27: =if(isna(VLOOKUP(G27,G28:G29,1,false)),"Error","Good") -> Error | V27: =if(isna(VLOOKUP(H27,H28:H29,1,false)),"Error","Good") -> Error | AB27: Ted Shen
A28: =A27 -> 8 | I28: =sum(F28:H28) -> 0 | K28: =A28 -> 8 | T28: =if(F28=F29,"Good") -> Good | U28: =if(G28=G29,"Good") -> Good | V28: =if(H28=H29,"Good") -> Good
A29: =A28 -> 8 | I29: =sum(F29:H29) -> 0 | K29: =A29 -> 8
A30: =A29+1 -> 9 | I30: =sum(F30:H30) -> 0 | K30: =A30 -> 9 | M30: =if(COUNTIF(T30:T32,"Good")=2,"Good","Error") -> Error | N30: =if(COUNTIF(U30:U32,"Good")=2,"Good","Error") -> Error | O30: =if(COUNTIF(V30:V32,"Good")=2,"Good","Error") -> Error | Q30: =sum(J30:J33) -> 0 | R30: =if(Q30=0,"",if(Q30=6,"Good","ERROR")) | T30: =if(isna(VLOOKUP(F30,F31:F33,1,false)),"Error","Good") -> Error | U30: =if(isna(VLOOKUP(G30,G31:G33,1,false)),"Error","Good") -> Error | V30: =if(isna(VLOOKUP(H30,H31:H33,1,false)),"Error","Good") -> Error
A31: =A30 -> 9 | I31: =sum(F31:H31) -> 0 | K31: =A31 -> 9 | T31: =if(isna(VLOOKUP(F31,F32:F33,1,false)),"Error","Good") -> Error | U31: =if(isna(VLOOKUP(G31,G32:G33,1,false)),"Error","Good") -> Error | V31: =if(isna(VLOOKUP(H31,H32:H33,1,false)),"Error","Good") -> Error
A32: =A31 -> 9 | I32: =sum(F32:H32) -> 0 | K32: =A32 -> 9 | T32: =if(F32=F33,"Good") -> Good | U32: =if(G32=G33,"Good") -> Good | V32: =if(H32=H33,"Good") -> Good
A33: =A32 -> 9 | I33: =sum(F33:H33) -> 0 | K33: =A33 -> 9 | AB33: Chinna Ponnaganti
A34: 99 | I34: =sum(F34:H34) -> 0 | K34: 99 | AB34: Mauricio Palacios
A35: 99 | I35: =sum(F35:H35) -> 0 | K35: 99 | AB35: Joyce Zhu
A36: 99 | I36: =sum(F36:H36) -> 0 | K36: 99 | AB36: Balaji Alahari
A37: 99 | I37: =sum(F37:H37) -> 0 | K37: 99
A38: 99 | I38: =sum(F38:H38) -> 0 | K38: 99
A39: 99 | I39: =sum(F39:H39) -> 0 | K39: 99
A40: 99 | I40: =sum(F40:H40) -> 0 | K40: 99
...

Sheet Checkin
A1: Name | B1: Check in | C1: Sit Outs | E1: Sl.No | F1: Playing | G1: Out | H1: Out-Can Play | I1: To Respond | J1: Sitouts | K1: Playing-Can Sit | L1: Previous sitouts | M1: Sit Outs
A2: =IFERROR(__xludf.DUMMYFUNCTION("IMPORTRANGE(""1uZFF2o7rrfB0YZtASdZnP52Ef50ZinvtOPb1Tbuq8J4"",""CheckIn!C1:D99"")"),"#REF!") -> #REF! | C2: =VLOOKUP(A2,Current!B:S,18,false) -> #REF! | E2: 1 | F2: =IFERROR(__xludf.DUMMYFUNCTION("QUERY(A2:B99, ""Select A where B = 1 order by A"")"),"#N/A") -> #N/A | G2: =IFERROR(__xludf.DUMMYFUNCTION("QUERY($A2:$B99, ""Select A where B = 3 order by A"")"),"#N/A") -> #N/A | H2: =IFERROR(__xludf.DUMMYFUNCTION("QUERY($A2:$B99, ""Select A where B = 4"")"),"#N/A") -> #N/A | I2: =IFERROR(__xludf.DUMMYFUNCTION("QUERY(Current!B5:F69, ""Select B where F = 0 order by B"")"),"Adrian Tay") -> Adrian Tay | J2: =IFERROR(__xludf.DUMMYFUNCTION("QUERY(A2:C99, ""Select A where B = 5 order by C"")"),"#N/A") -> #N/A | K2: =IFERROR(__xludf.DUMMYFUNCTION("QUERY($A2:$C99, ""Select A,C where B = 2 order by C"")"),"#N/A") -> #N/A | M2: =if(P19>0,1,"")
C3: =VLOOKUP(A3,Current!B:S,18,false) -> #N/A | E3: =E2+1 -> 2 | I3: =IFERROR(__xludf.DUMMYFUNCTION("""COMPUTED_VALUE"""),"Alejandro Mejia") -> Alejandro Mejia | M3: =if(AND(M2>0, counta($K$2:K3)<=$P$19),M2+1,"")
C4: =VLOOKUP(A4,Current!B:S,18,false) -> #N/A | E4: =E3+1 -> 3 | I4: =IFERROR(__xludf.DUMMYFUNCTION("""COMPUTED_VALUE"""),"Alex Hou") -> Alex Hou | M4: =if(AND(M3>0, counta($K$2:K4)<=$P$19),M3+1,"") | O4: Last update | P4: =now() -> 46311.709
C5: =VLOOKUP(A5,Current!B:S,18,false) -> #N/A | E5: =E4+1 -> 4 | I5: =IFERROR(__xludf.DUMMYFUNCTION("""COMPUTED_VALUE"""),"Amit Patel") -> Amit Patel | M5: =if(AND(M4>0, counta($K$2:K5)<=$P$19),M4+1,"")
C6: =VLOOKUP(A6,Current!B:S,18,false) -> #N/A | E6: =E5+1 -> 5 | I6: =IFERROR(__xludf.DUMMYFUNCTION("""COMPUTED_VALUE"""),"Andrew Wen") -> Andrew Wen | M6: =if(AND(M5>0, counta($K$2:K6)<=$P$19),M5+1,"") | O6: Playing | P6: =if(isna(F2),0,COUNTA(F$2:F$58)) -> 0
C7: =VLOOKUP(A7,Current!B:S,18,false) -> #N/A | E7: =E6+1 -> 6 | I7: =IFERROR(__xludf.DUMMYFUNCTION("""COMPUTED_VALUE"""),"Arun Mallikarjuna") -> Arun Mallikarjuna | M7: =if(AND(M6>0, counta($K$2:K7)<=$P$19),M6+1,"") | O7: Playing-Can Sit | P7: =if(isna(K2),0,COUNTA(K2:K99)) -> 0
C8: =VLOOKUP(A8,Current!B:S,18,false) -> #N/A | E8: =E7+1 -> 7 | I8: =IFERROR(__xludf.DUMMYFUNCTION("""COMPUTED_VALUE"""),"Balaji Alahari") -> Balaji Alahari | M8: =if(AND(M7>0, counta($K$2:K8)<=$P$19),M7+1,"") | O8: Out/Can Play | P8: =if(isna(H2),0,COUNTA(H$2:H$58)) -> 0
C9: =VLOOKUP(A9,Current!B:S,18,false) -> #N/A | E9: =E8+1 -> 8 | I9: =IFERROR(__xludf.DUMMYFUNCTION("""COMPUTED_VALUE"""),"Chinna Ponnaganti") -> Chinna Ponnaganti | M9: =if(AND(M8>0, counta($K$2:K9)<=$P$19),M8+1,"") | O9: Out | P9: =if(isna(G2),0,COUNTA(G$2:G$58)) -> 0
C10: =VLOOKUP(A10,Current!B:S,18,false) -> #N/A | E10: =E9+1 -> 9 | I10: =IFERROR(__xludf.DUMMYFUNCTION("""COMPUTED_VALUE"""),"Christopher Li") -> Christopher Li | M10: =if(AND(M9>0, counta($K$2:K10)<=$P$19),M9+1,"") | O10: Sitouts | P10: =if(isna(J2),0,COUNTA(J$2:J$29)) -> 0
C11: =VLOOKUP(A11,Current!B:S,18,false) -> #N/A | E11: =E10+1 -> 10 | I11: =IFERROR(__xludf.DUMMYFUNCTION("""COMPUTED_VALUE"""),"Cid Macaraeg") -> Cid Macaraeg | M11: =if(AND(M10>0, counta($K$2:K11)<=$P$19),M10+1,"") | O11: TBD | P11: =if(isna(I2),0,COUNTA(I$2:I$99)) -> 65
C12: =VLOOKUP(A12,Current!B:S,18,false) -> #N/A | E12: =E11+1 -> 11 | I12: =IFERROR(__xludf.DUMMYFUNCTION("""COMPUTED_VALUE"""),"Coco Yan") -> Coco Yan | M12: =if(AND(M11>0, counta($K$2:K12)<=$P$19),M11+1,"") | O12: Total | P12: =sum(P6:P11) -> 65
C13: =VLOOKUP(A13,Current!B:S,18,false) -> #N/A | E13: =E12+1 -> 12 | I13: =IFERROR(__xludf.DUMMYFUNCTION("""COMPUTED_VALUE"""),"David Shin") -> David Shin | M13: =if(AND(M12>0, counta($K$2:K13)<=$P$19),M12+1,"")
C14: =VLOOKUP(A14,Current!B:S,18,false) -> #N/A | E14: =E13+1 -> 13 | I14: =IFERROR(__xludf.DUMMYFUNCTION("""COMPUTED_VALUE"""),"Elayaraja Thangaraj ") -> Elayaraja Thangaraj | M14: =if(AND(M13>0, counta($K$2:K14)<=$P$19),M13+1,"") | O14: Playing | P14: =sum(P6:P7) -> 0 | Q14: Check out-can play
C15: =VLOOKUP(A15,Current!B:S,18,false) -> #N/A | E15: =E14+1 -> 14 | I15: =IFERROR(__xludf.DUMMYFUNCTION("""COMPUTED_VALUE"""),"Eric Pan") -> Eric Pan | M15: =if(AND(M14>0, counta($K$2:K15)<=$P$19),M14+1,"") | O15: Out | P15: =P9+P8 -> 0
C16: =VLOOKUP(A16,Current!B:S,18,false) -> #N/A | E16: =E15+1 -> 15 | I16: =IFERROR(__xludf.DUMMYFUNCTION("""COMPUTED_VALUE"""),"Eric Tan") -> Eric Tan | M16: =if(AND(M15>0, counta($K$2:K16)<=$P$19),M15+1,"") | O16: TBD | P16: =P11 -> 65
C17: =VLOOKUP(A17,Current!B:S,18,false) -> #N/A | E17: =E16+1 -> 16 | I17: =IFERROR(__xludf.DUMMYFUNCTION("""COMPUTED_VALUE"""),"Erik Hoeckmann") -> Erik Hoeckmann | M17: =if(AND(M16>0, counta($K$2:K17)<=$P$19),M16+1,"") | O17: Total | P17: =sum(P14:P16) -> 65
C18: =VLOOKUP(A18,Current!B:S,18,false) -> #N/A | E18: =E17+1 -> 17 | I18: =IFERROR(__xludf.DUMMYFUNCTION("""COMPUTED_VALUE"""),"Frank Moon") -> Frank Moon | M18: =if(AND(M17>0, counta($K$2:K18)<=$P$19),M17+1,"")
C19: =VLOOKUP(A19,Current!B:S,18,false) -> #N/A | E19: =E18+1 -> 18 | I19: =IFERROR(__xludf.DUMMYFUNCTION("""COMPUTED_VALUE"""),"Herman Au") -> Herman Au | M19: =if(AND(M18>0, counta($K$2:K19)<=$P$19),M18+1,"") | O19: Sitouts Needed | P19: =IF((P14-32) > 0,(P14-32),0) -> 0
C20: =VLOOKUP(A20,Current!B:S,18,false) -> #N/A | E20: =E19+1 -> 19 | I20: =IFERROR(__xludf.DUMMYFUNCTION("""COMPUTED_VALUE"""),"James Phan") -> James Phan | M20: =if(AND(M19>0, counta($K$2:K20)<=$P$19),M19+1,"")
C21: =VLOOKUP(A21,Current!B:S,18,false) -> #N/A | E21: =E20+1 -> 20 | I21: =IFERROR(__xludf.DUMMYFUNCTION("""COMPUTED_VALUE"""),"Jim Miao") -> Jim Miao | M21: =if(AND(M20>0, counta($K$2:K21)<=$P$19),M20+1,"") | O21: Vacations
C22: =VLOOKUP(A22,Current!B:S,18,false) -> #N/A | E22: =E21+1 -> 21 | I22: =IFERROR(__xludf.DUMMYFUNCTION("""COMPUTED_VALUE"""),"Jimmy Awolesi") -> Jimmy Awolesi | M22: =if(AND(M21>0, counta($K$2:K22)<=$P$19),M21+1,"") | O22: Peter Homsey | P22: 6464581349
C23: =VLOOKUP(A23,Current!B:S,18,false) -> #N/A | E23: =E22+1 -> 22 | I23: =IFERROR(__xludf.DUMMYFUNCTION("""COMPUTED_VALUE"""),"Joe Luzzi") -> Joe Luzzi | L23: =if(K23<>"",VLOOKUP(K23,Current!B:S,17,false),"") | O23: Jose Ortiz | P23: 6268263665
C24: =VLOOKUP(A24,Current!B:S,18,false) -> #N/A | E24: =E23+1 -> 23 | I24: =IFERROR(__xludf.DUMMYFUNCTION("""COMPUTED_VALUE"""),"Jonathan Phan") -> Jonathan Phan | O24: Tony Lin | P24: 9092638257
C25: =VLOOKUP(A25,Current!B:S,18,false) -> #N/A | E25: =E24+1 -> 24 | I25: =IFERROR(__xludf.DUMMYFUNCTION("""COMPUTED_VALUE"""),"Jose Ortiz") -> Jose Ortiz
C26: =VLOOKUP(A26,Current!B:S,18,false) -> #N/A | E26: =E25+1 -> 25 | I26: =IFERROR(__xludf.DUMMYFUNCTION("""COMPUTED_VALUE"""),"Joyce Zhu") -> Joyce Zhu
C27: =VLOOKUP(A27,Current!B:S,18,false) -> #N/A | E27: =E26+1 -> 26 | I27: =IFERROR(__xludf.DUMMYFUNCTION("""COMPUTED_VALUE"""),"Kumar Palakeel") -> Kumar Palakeel
C28: =VLOOKUP(A28,Current!B:S,18,false) -> #N/A | E28: =E27+1 -> 27 | I28: =IFERROR(__xludf.DUMMYFUNCTION("""COMPUTED_VALUE"""),"Lam Bui") -> Lam Bui
C29: =VLOOKUP(A29,Current!B:S,18,false) -> #N/A | E29: =E28+1 -> 28 | I29: =IFERROR(__xludf.DUMMYFUNCTION("""COMPUTED_VALUE"""),"Leigh-Anh Nguyen") -> Leigh-Anh Nguyen | O29: Injured/Recovering
C30: =VLOOKUP(A30,Current!B:S,18,false) -> #N/A | E30: =E29+1 -> 29 | I30: =IFERROR(__xludf.DUMMYFUNCTION("""COMPUTED_VALUE"""),"Lloyd Sagar") -> Lloyd Sagar
C31: =VLOOKUP(A31,Current!B:S,18,false) -> #N/A | E31: =E30+1 -> 30 | I31: =IFERROR(__xludf.DUMMYFUNCTION("""COMPUTED_VALUE"""),"Luis Hsu") -> Luis Hsu
C32: =VLOOKUP(A32,Current!B:S,18,false) -> #N/A | E32: =E31+1 -> 31 | I32: =IFERROR(__xludf.DUMMYFUNCTION("""COMPUTED_VALUE"""),"Manish Anand") -> Manish Anand
C33: =VLOOKUP(A33,Current!B:S,18,false) -> #N/A | E33: =E32+1 -> 32 | I33: =IFERROR(__xludf.DUMMYFUNCTION("""COMPUTED_VALUE"""),"Manuel Rivera") -> Manuel Rivera
C34: =VLOOKUP(A34,Current!B:S,18,false) -> #N/A | E34: =E33+1 -> 33 | I34: =IFERROR(__xludf.DUMMYFUNCTION("""COMPUTED_VALUE"""),"Matthew Huang") -> Matthew Huang
C35: =VLOOKUP(A35,Current!B:S,18,false) -> #N/A | E35: =E34+1 -> 34 | I35: =IFERROR(__xludf.DUMMYFUNCTION("""COMPUTED_VALUE"""),"Mauricio Palacios") -> Mauricio Palacios
C36: =VLOOKUP(A36,Current!B:S,18,false) -> #N/A | E36: =E35+1 -> 35 | I36: =IFERROR(__xludf.DUMMYFUNCTION("""COMPUTED_VALUE"""),"Naveen Raj") -> Naveen Raj
C37: =VLOOKUP(A37,Current!B:S,18,false) -> #N/A | E37: =E36+1 -> 36 | I37: =IFERROR(__xludf.DUMMYFUNCTION("""COMPUTED_VALUE"""),"Nicole Ni") -> Nicole Ni
C38: =VLOOKUP(A38,Current!B:S,18,false) -> #N/A | E38: =E37+1 -> 37 | I38: =IFERROR(__xludf.DUMMYFUNCTION("""COMPUTED_VALUE"""),"Nohely Mejia") -> Nohely Mejia
C39: =VLOOKUP(A39,Current!B:S,18,false) -> #N/A | E39: =E38+1 -> 38 | I39: =IFERROR(__xludf.DUMMYFUNCTION("""COMPUTED_VALUE"""),"Oscar Bonilla") -> Oscar Bonilla
C40: =VLOOKUP(A40,Current!B:S,18,false) -> #N/A | E40: =E39+1 -> 39 | I40: =IFERROR(__xludf.DUMMYFUNCTION("""COMPUTED_VALUE"""),"Pavan Akkimsetty") -> Pavan Akkimsetty
...

Sheet Waitlist
A1: =IFERROR(__xludf.DUMMYFUNCTION("IMPORTRANGE(""1vk67ABbS4TvdE0gnpv39mwReeTC8qhP2vyc266Yeuy8"",""Waitlist!A1:D99"")"),"#REF!") -> #REF!
G4: Here is the link to add new players to the waitlist.
G5: tinyurl.com/UTCWaitList

Sheet 122824
B1: Standings as of | C1: 45654
B2: Number of Weeks Played | D2: 26 | AB2: =text(C1-7,"mm/dd/yy") -> 12/21/24
C3: Beginning of week | F3: Current Week Scores | N3: End of week | Q3: Jul-Dec 2024 | R3: Jan-Jun 2025
A4: Ranking | B4: Name of Player | C4: Games Won | D4: Sets Won | E4: Games Won / Match | F4: Check IN | G4: Court # | H4: Set 0 | I4: Set 1 | J4: Set 2 | K4: Set 3 | L4: Games Won | M4: Sets Won | N4: Games Won | O4: Sets Won | P4: Waiver | Q4: Fee | R4: Fee | S4: Sit outs | T4: No Shows | U4: Absent | V4: Positions Gained/Lost | W4: Ranking
A5: 1 | B5: Adrian Tay | C5: 392 | D5: 47 | E5: =(C5-(U5*9)-(S5*13))/($D$2-U5-S5) -> 17.333333 | F5: 4 | G5: 0 | H5: 9 | I5: 0 | J5: 0 | K5: 0 | L5: 9 | M5: 0 | N5: =C5+L5 -> 401 | O5: =D5+M5 -> 47 | P5: X | Q5: X | R5: X | S5: =if(H5=13,1,0)+VLOOKUP(B5,indirect($AB$2&"!B:T"),18,false) -> 2 | U5: =if(H5=9,1,0)+VLOOKUP(B5,indirect($AB$2&"!B:U"),20,false) -> 6 | V5: =VLOOKUP(B5,indirect($AB$2&"!B$5:w$70"),22,false)-A5 -> 0 | W5: 1
A6: =A5+1 -> 2 | B6: David Shin | C6: 336 | D6: 28 | E6: =(C6-(U6*9)-(S6*13))/($D$2-U6-S6) -> 14 | F6: 1 | G6: 1 | H6: 0 | I6: 6 | J6: 5 | K6: 7 | L6: 18 | M6: 2 | N6: =C6+L6 -> 354 | O6: =D6+M6 -> 30 | P6: X | Q6: X | R6: X | S6: =if(H6=13,1,0)+VLOOKUP(B6,indirect($AB$2&"!B:T"),18,false) -> 3 | U6: =if(H6=9,1,0)+VLOOKUP(B6,indirect($AB$2&"!B:U"),20,false) -> 5 | V6: =VLOOKUP(B6,indirect($AB$2&"!B$5:w$70"),22,false)-A6 -> 1 | W6: =W5+1 -> 2
A7: =A6+1 -> 3 | B7: Tom Le | C7: 331 | D7: 32 | E7: =(C7-(U7*9)-(S7*13))/($D$2-U7-S7) -> 14.105263 | F7: 1 | G7: 1 | H7: 0 | I7: 6 | J7: 7 | K7: 6 | L7: 19 | M7: 2 | N7: =C7+L7 -> 350 | O7: =D7+M7 -> 34 | P7: X | Q7: X | R7: X | S7: =if(H7=13,1,0)+VLOOKUP(B7,indirect($AB$2&"!B:T"),18,false) -> 0 | U7: =if(H7=9,1,0)+VLOOKUP(B7,indirect($AB$2&"!B:U"),20,false) -> 7 | V7: =VLOOKUP(B7,indirect($AB$2&"!B$5:w$70"),22,false)-A7 -> 1 | W7: =W6+1 -> 3
A8: =A7+1 -> 4 | B8: Ted Shen | C8: 331 | D8: 30 | E8: =(C8-(U8*9)-(S8*13))/($D$2-U8-S8) -> 13.043478 | F8: 1 | G8: 1 | H8: 0 | I8: 0 | J8: 7 | K8: 7 | L8: 14 | M8: 2 | N8: =C8+L8 -> 345 | O8: =D8+M8 -> 32 | P8: X | Q8: X | R8: X | S8: =if(H8=13,1,0)+VLOOKUP(B8,indirect($AB$2&"!B:T"),18,false) -> 1 | U8: =if(H8=9,1,0)+VLOOKUP(B8,indirect($AB$2&"!B:U"),20,false) -> 2 | V8: =VLOOKUP(B8,indirect($AB$2&"!B$5:w$70"),22,false)-A8 -> 6 | W8: =W7+1 -> 4
A9: =A8+1 -> 5 | B9: Frank Moon | C9: 329 | D9: 31 | E9: =(C9-(U9*9)-(S9*13))/($D$2-U9-S9) -> 12.958333 | F9: 3 | G9: 0 | H9: 9 | I9: 0 | J9: 0 | K9: 0 | L9: 9 | M9: 0 | N9: =C9+L9 -> 338 | O9: =D9+M9 -> 31 | P9: X | Q9: X | R9: X | S9: =if(H9=13,1,0)+VLOOKUP(B9,indirect($AB$2&"!B:T"),18,false) -> 0 | U9: =if(H9=9,1,0)+VLOOKUP(B9,indirect($AB$2&"!B:U"),20,false) -> 2 | V9: =VLOOKUP(B9,indirect($AB$2&"!B$5:w$70"),22,false)-A9 -> 0 | W9: =W8+1 -> 5
A10: =A9+1 -> 6 | B10: Scott Li | C10: 329 | D10: 25 | E10: =(C10-(U10*9)-(S10*13))/($D$2-U10-S10) -> 13.55 | F10: 1 | G10: 1 | H10: 0 | I10: 0 | J10: 5 | K10: 6 | L10: 11 | M10: 0 | N10: =C10+L10 -> 340 | O10: =D10+M10 -> 25 | P10: X | Q10: X | R10: X | S10: =if(H10=13,1,0)+VLOOKUP(B10,indirect($AB$2&"!B:T"),18,false) -> 1 | U10: =if(H10=9,1,0)+VLOOKUP(B10,indirect($AB$2&"!B:U"),20,false) -> 5 | V10: =VLOOKUP(B10,indirect($AB$2&"!B$5:w$70"),22,false)-A10 -> 0 | W10: =W9+1 -> 6
A11: =A10+1 -> 7 | B11: Lam Bui | C11: 327 | D11: 27 | E11: =(C11-(U11*9)-(S11*13))/($D$2-U11-S11) -> 15.538462 | F11: 3 | G11: 0 | H11: 9 | I11: 0 | J11: 0 | K11: 0 | L11: 9 | M11: 0 | N11: =C11+L11 -> 336 | O11: =D11+M11 -> 27 | P11: X | Q11: X | R11: X | S11: =if(H11=13,1,0)+VLOOKUP(B11,indirect($AB$2&"!B:T"),18,false) -> 2 | U11: =if(H11=9,1,0)+VLOOKUP(B11,indirect($AB$2&"!B:U"),20,false) -> 11 | V11: =VLOOKUP(B11,indirect($AB$2&"!B$5:w$70"),22,false)-A11 -> -5 | W11: =W10+1 -> 7
A12: =A11+1 -> 8 | B12: Suleman Alidina | C12: 326 | D12: 31 | E12: =(C12-(U12*9)-(S12*13))/($D$2-U12-S12) -> 13.4 | F12: 1 | G12: 2 | H12: 0 | I12: 5 | J12: 6 | K12: 5 | L12: 16 | M12: 1 | N12: =C12+L12 -> 342 | O12: =D12+M12 -> 32 | P12: X | Q12: X | R12: X | S12: =if(H12=13,1,0)+VLOOKUP(B12,indirect($AB$2&"!B:T"),18,false) -> 1 | U12: =if(H12=9,1,0)+VLOOKUP(B12,indirect($AB$2&"!B:U"),20,false) -> 5 | V12: =VLOOKUP(B12,indirect($AB$2&"!B$5:w$70"),22,false)-A12 -> -1 | W12: =W11+1 -> 8
A13: =A12+1 -> 9 | B13: Pulkit Mathur | C13: 326 | D13: 29 | E13: =(C13-(U13*9)-(S13*13))/($D$2-U13-S13) -> 16 | F13: 1 | G13: 2 | H13: 0 | I13: 7 | J13: 6 | K13: 7 | L13: 20 | M13: 3 | N13: =C13+L13 -> 346 | O13: =D13+M13 -> 32 | P13: X | Q13: X | R13: X | S13: =if(H13=13,1,0)+VLOOKUP(B13,indirect($AB$2&"!B:T"),18,false) -> 2 | U13: =if(H13=9,1,0)+VLOOKUP(B13,indirect($AB$2&"!B:U"),20,false) -> 12 | V13: =VLOOKUP(B13,indirect($AB$2&"!B$5:w$70"),22,false)-A13 -> 4 | W13: =W12+1 -> 9
A14: =A13+1 -> 10 | B14: Alejandro Mejia | C14: 325 | D14: 34 | E14: =(C14-(U14*9)-(S14*13))/($D$2-U14-S14) -> 13.789474 | F14: 3 | G14: 0 | H14: 9 | I14: 0 | J14: 0 | K14: 0 | L14: 9 | M14: 0 | N14: =C14+L14 -> 334 | O14: =D14+M14 -> 34 | P14: X | Q14: X | R14: X | S14: =if(H14=13,1,0)+VLOOKUP(B14,indirect($AB$2&"!B:T"),18,false) -> 0 | U14: =if(H14=9,1,0)+VLOOKUP(B14,indirect($AB$2&"!B:U"),20,false) -> 7 | V14: =VLOOKUP(B14,indirect($AB$2&"!B$5:w$70"),22,false)-A14 -> -1 | W14: =W13+1 -> 10
A15: =A14+1 -> 11 | B15: Pavan Akkimsetty | C15: 324 | D15: 26 | E15: =(C15-(U15*9)-(S15*13))/($D$2-U15-S15) -> 14.625 | F15: 3 | G15: 0 | H15: 9 | I15: 0 | J15: 0 | K15: 0 | L15: 9 | M15: 0 | N15: =C15+L15 -> 333 | O15: =D15+M15 -> 26 | P15: X | Q15: X | R15: X | S15: =if(H15=13,1,0)+VLOOKUP(B15,indirect($AB$2&"!B:T"),18,false) -> 0 | U15: =if(H15=9,1,0)+VLOOKUP(B15,indirect($AB$2&"!B:U"),20,false) -> 10 | V15: =VLOOKUP(B15,indirect($AB$2&"!B$5:w$70"),22,false)-A15 -> 1 | W15: =W14+1 -> 11
A16: =A15+1 -> 12 | B16: Herman Au | C16: 323 | D16: 21 | E16: =(C16-(U16*9)-(S16*13))/($D$2-U16-S16) -> 12.666667 | F16: 2 | G16: 2 | H16: 0 | I16: 5 | J16: 0 | K16: 7 | L16: 12 | M16: 1 | N16: =C16+L16 -> 335 | O16: =D16+M16 -> 22 | P16: X | Q16: X | R16: X | S16: =if(H16=13,1,0)+VLOOKUP(B16,indirect($AB$2&"!B:T"),18,false) -> 3 | U16: =if(H16=9,1,0)+VLOOKUP(B16,indirect($AB$2&"!B:U"),20,false) -> 2 | V16: =VLOOKUP(B16,indirect($AB$2&"!B$5:w$70"),22,false)-A16 -> -1 | W16: =W15+1 -> 12
A17: =A16+1 -> 13 | B17: James Phan | C17: 322 | D17: 26 | E17: =(C17-(U17*9)-(S17*13))/($D$2-U17-S17) -> 16.272727 | F17: 5 | G17: 0 | H17: 13 | I17: 0 | J17: 0 | K17: 0 | L17: 13 | M17: 0 | N17: =C17+L17 -> 335 | O17: =D17+M17 -> 26 | P17: X | Q17: X | R17: X | S17: =if(H17=13,1,0)+VLOOKUP(B17,indirect($AB$2&"!B:T"),18,false) -> 2 | U17: =if(H17=9,1,0)+VLOOKUP(B17,indirect($AB$2&"!B:U"),20,false) -> 13 | V17: =VLOOKUP(B17,indirect($AB$2&"!B$5:w$70"),22,false)-A17 -> -5 | W17: =W16+1 -> 13
... A65: =A64+1 -> 61 | B65: Eric Pan | C65: 234 | D65: 3 | E65: =(C65-(U65*9)-(S65*13))/($D$2-U65-S65) -> 9 | F65: 3 | G65: 0 | H65: 9 | I65: 0 | J65: 0 | K65: 0 | L65: 9 | M65: 0 | N65: =C65+L65 -> 243 | O65: =D65+M65 -> 3 | P65: X | Q65: X | R65: X | S65: =if(H65=13,1,0)+VLOOKUP(B65,indirect($AB$2&"!B:T"),18,false) -> 0 | U65: =if(H65=9,1,0)+VLOOKUP(B65,indirect($AB$2&"!B:U"),20,false) -> 25 | V65: =VLOOKUP(B65,indirect($AB$2&"!B$5:w$70"),22,false)-A65 -> 0 | W65: =W64+1 -> 61
A66: =A65+1 -> 62 | B66: Peter Homsey | C66: 229 | D66: 0 | E66: =(C66-(U66*9)-(S66*13))/($D$2-U66-S66) -> 4.5 | F66: 3 | H66: 9 | L66: 9 | N66: =C66+L66 -> 238 | O66: =D66+M66 -> 0 | P66: X | Q66: X | R66: N | S66: =if(H66=13,1,0)+VLOOKUP(B66,indirect($AB$2&"!B:T"),18,false) -> 1 | U66: =if(H66=9,1,0)+VLOOKUP(B66,indirect($AB$2&"!B:U"),20,false) -> 23 | W66: =W65+1 -> 62
A67: =A66+1 -> 63 | B67: Amit Patel | C67: 229 | D67: 0 | E67: =(C67-(U67*9)-(S67*13))/($D$2-U67-S67) -> 0 | F67: 3 | G67: 0 | H67: 9 | I67: 0 | J67: 0 | K67: 0 | L67: 9 | M67: 0 | N67: =C67+L67 -> 238 | O67: =D67+M67 -> 0 | P67: X | Q67: X | R67: N | S67: =if(H67=13,1,0)+VLOOKUP(B67,indirect($AB$2&"!B:T"),18,false) -> 1 | U67: =if(H67=9,1,0)+VLOOKUP(B67,indirect($AB$2&"!B:U"),20,false) -> 24 | V67: =VLOOKUP(B67,indirect($AB$2&"!B$5:w$70"),22,false)-A67 -> 0 | W67: =W66+1 -> 63
A68: =A67+1 -> 64 | B68: Joyce Zhu | C68: 219 | D68: 11 | E68: =(C68-(U68*9)-(S68*13))/($D$2-U68-S68) -> 8.0625 | F68: 3 | G68: 0 | H68: 9 | I68: 0 | J68: 0 | K68: 0 | L68: 9 | M68: 0 | N68: =C68+L68 -> 228 | O68: =D68+M68 -> 11 | P68: X | Q68: X | R68: X | S68: =if(H68=13,1,0)+VLOOKUP(B68,indirect($AB$2&"!B:T"),18,false) -> 0 | U68: =if(H68=9,1,0)+VLOOKUP(B68,indirect($AB$2&"!B:U"),20,false) -> 10 | V68: =VLOOKUP(B68,indirect($AB$2&"!B$5:w$70"),22,false)-A68 -> 0 | W68: =W67+1 -> 64
A69: =A68+1 -> 65 | B69: Jose Ortiz | C69: 216 | D69: 0 | E69: =(C69-(U69*9)-(S69*13))/($D$2-U69-S69) -> #DIV/0! | F69: 3 | G69: 0 | H69: 9 | I69: 0 | J69: 0 | K69: 0 | L69: 9 | M69: 0 | N69: =C69+L69 -> 225 | O69: =D69+M69 -> 0 | P69: X | Q69: X | R69: N | S69: =if(H69=13,1,0)+VLOOKUP(B69,indirect($AB$2&"!B:T"),18,false) -> 0 | U69: =if(H69=9,1,0)+VLOOKUP(B69,indirect($AB$2&"!B:U"),20,false) -> 26 | V69: =VLOOKUP(B69,indirect($AB$2&"!B$5:w$70"),22,false)-A69 -> 0 | W69: =W68+1 -> 65
B72: =COUNTA(B5:B69) -> 65
P77: Renewed | R77: =COUNTIF(R5:R69,"X") -> 55
B78: Top Scores | C78: Games | D78: Sets | E78: Court # | P78: Not Renewing | R78: =countif(R5:R69,"N") -> 10
B79: =IFERROR(__xludf.DUMMYFUNCTION("QUERY(B5:M69,""Select B, L, M, G where L >= 18 order by L desc,M desc"",0)"),"Pulkit Mathur") -> Pulkit Mathur | C79: =IFERROR(__xludf.DUMMYFUNCTION("""COMPUTED_VALUE"""),20.0) -> 20 | D79: =IFERROR(__xludf.DUMMYFUNCTION("""COMPUTED_VALUE"""),3.0) -> 3 | E79: =IFERROR(__xludf.DUMMYFUNCTION("""COMPUTED_VALUE"""),2.0) -> 2 | P79: To Renew | R79: =countif(R5:R69,"") -> 0
B80: =IFERROR(__xludf.DUMMYFUNCTION("""COMPUTED_VALUE"""),"Tom Le") -> Tom Le | C80: =IFERROR(__xludf.DUMMYFUNCTION("""COMPUTED_VALUE"""),19.0) -> 19 | D80: =IFERROR(__xludf.DUMMYFUNCTION("""COMPUTED_VALUE"""),2.0) -> 2 | E80: =IFERROR(__xludf.DUMMYFUNCTION("""COMPUTED_VALUE"""),1.0) -> 1 | P80: Total | R80: =sum(R77:R79) -> 65
B81: =IFERROR(__xludf.DUMMYFUNCTION("""COMPUTED_VALUE"""),"Robert Chang") -> Robert Chang | C81: =IFERROR(__xludf.DUMMYFUNCTION("""COMPUTED_VALUE"""),18.0) -> 18 | D81: =IFERROR(__xludf.DUMMYFUNCTION("""COMPUTED_VALUE"""),3.0) -> 3 | E81: =IFERROR(__xludf.DUMMYFUNCTION("""COMPUTED_VALUE"""),3.0) -> 3
B82: =IFERROR(__xludf.DUMMYFUNCTION("""COMPUTED_VALUE"""),"Sean Chang") -> Sean Chang | C82: =IFERROR(__xludf.DUMMYFUNCTION("""COMPUTED_VALUE"""),18.0) -> 18 | D82: =IFERROR(__xludf.DUMMYFUNCTION("""COMPUTED_VALUE"""),3.0) -> 3 | E82: =IFERROR(__xludf.DUMMYFUNCTION("""COMPUTED_VALUE"""),5.0) -> 5 | P82: * Jimmy Awolesi paid for Jan-Dec 2025
B83: =IFERROR(__xludf.DUMMYFUNCTION("""COMPUTED_VALUE"""),"Wayne Liu") -> Wayne Liu | C83: =IFERROR(__xludf.DUMMYFUNCTION("""COMPUTED_VALUE"""),18.0) -> 18 | D83: =IFERROR(__xludf.DUMMYFUNCTION("""COMPUTED_VALUE"""),3.0) -> 3 | E83: =IFERROR(__xludf.DUMMYFUNCTION("""COMPUTED_VALUE"""),6.0) -> 6
B84: =IFERROR(__xludf.DUMMYFUNCTION("""COMPUTED_VALUE"""),"Sandy Weyant") -> Sandy Weyant | C84: =IFERROR(__xludf.DUMMYFUNCTION("""COMPUTED_VALUE"""),18.0) -> 18 | D84: =IFERROR(__xludf.DUMMYFUNCTION("""COMPUTED_VALUE"""),3.0) -> 3 | E84: =IFERROR(__xludf.DUMMYFUNCTION("""COMPUTED_VALUE"""),7.0) -> 7
B85: =IFERROR(__xludf.DUMMYFUNCTION("""COMPUTED_VALUE"""),"David Shin") -> David Shin | C85: =IFERROR(__xludf.DUMMYFUNCTION("""COMPUTED_VALUE"""),18.0) -> 18 | D85: =IFERROR(__xludf.DUMMYFUNCTION("""COMPUTED_VALUE"""),2.0) -> 2 | E85: =IFERROR(__xludf.DUMMYFUNCTION("""COMPUTED_VALUE"""),1.0) -> 1
B92: Top 10 Movements (UP) | C92: Positions Moved | D92: Position Last week | E92: Position This week | F92: Points this week | G92: Court | L92: Cross Check
B93: =IFERROR(__xludf.DUMMYFUNCTION("query(B5:V69,""select B, V order by V Desc Limit 10"")"),"Chinna Ponnaganti") -> Chinna Ponnaganti | C93: =IFERROR(__xludf.DUMMYFUNCTION("""COMPUTED_VALUE"""),7.0) -> 7 | D93: =VLOOKUP(B93,indirect($AB$2&"!B$5:w$70"),22, false) -> 28 | E93: =VLOOKUP(B93,B$5:W$69,22, false) -> 21 | F93: =VLOOKUP(B93,indirect($AB$2&"!B$5:U$70"),11, false) -> 19 | G93: =VLOOKUP(B93,indirect($AB$2&"!B$5:U$70"),6, false) -> 5 | L93: =if(D93-E93=C93,"ok","Error") -> ok
B94: =IFERROR(__xludf.DUMMYFUNCTION("""COMPUTED_VALUE"""),"Ted Shen") -> Ted Shen | C94: =IFERROR(__xludf.DUMMYFUNCTION("""COMPUTED_VALUE"""),6.0) -> 6 | D94: =VLOOKUP(B94,indirect($AB$2&"!B$5:w$70"),22, false) -> 10 | E94: =VLOOKUP(B94,B$5:W$69,22, false) -> 4 | F94: =VLOOKUP(B94,indirect($AB$2&"!B$5:U$70"),11, false) -> 19 | G94: =VLOOKUP(B94,indirect($AB$2&"!B$5:U$70"),6, false) -> 2 | L94: =if(D94-E94=C94,"ok","Error") -> ok
B95: =IFERROR(__xludf.DUMMYFUNCTION("""COMPUTED_VALUE"""),"Wayne Liu") -> Wayne Liu | C95: =IFERROR(__xludf.DUMMYFUNCTION("""COMPUTED_VALUE"""),5.0) -> 5 | D95: =VLOOKUP(B95,indirect($AB$2&"!B$5:w$70"),22, false) -> 39 | E95: =VLOOKUP(B95,B$5:W$69,22, false) -> 34 | F95: =VLOOKUP(B95,indirect($AB$2&"!B$5:U$70"),11, false) -> 17 | G95: =VLOOKUP(B95,indirect($AB$2&"!B$5:U$70"),6, false) -> 7 | L95: =if(D95-E95=C95,"ok","Error") -> ok
B96: =IFERROR(__xludf.DUMMYFUNCTION("""COMPUTED_VALUE"""),"Santosh Sundaresan ") -> Santosh Sundaresan | C96: =IFERROR(__xludf.DUMMYFUNCTION("""COMPUTED_VALUE"""),5.0) -> 5 | D96: =VLOOKUP(B96,indirect($AB$2&"!B$5:w$70"),22, false) -> 55 | E96: =VLOOKUP(B96,B$5:W$69,22, false) -> 50 | F96: =VLOOKUP(B96,indirect($AB$2&"!B$5:U$70"),11, false) -> 17 | G96: =VLOOKUP(B96,indirect($AB$2&"!B$5:U$70"),6, false) -> 8 | L96: =if(D96-E96=C96,"ok","Error") -> ok
B97: =IFERROR(__xludf.DUMMYFUNCTION("""COMPUTED_VALUE"""),"Pulkit Mathur") -> Pulkit Mathur | C97: =IFERROR(__xludf.DUMMYFUNCTION("""COMPUTED_VALUE"""),4.0) -> 4 | D97: =VLOOKUP(B97,indirect($AB$2&"!B$5:w$70"),22, false) -> 13 | E97: =VLOOKUP(B97,B$5:W$69,22, false) -> 9 | F97: =VLOOKUP(B97,indirect($AB$2&"!B$5:U$70"),11, false) -> 19 | G97: =VLOOKUP(B97,indirect($AB$2&"!B$5:U$70"),6, false) -> 3 | L97: =if(D97-E97=C97,"ok","Error") -> ok
B98: =IFERROR(__xludf.DUMMYFUNCTION("""COMPUTED_VALUE"""),"Robert Chang") -> Robert Chang | C98: =IFERROR(__xludf.DUMMYFUNCTION("""COMPUTED_VALUE"""),4.0) -> 4 | D98: =VLOOKUP(B98,indirect($AB$2&"!B$5:w$70"),22, false) -> 21 | E98: =VLOOKUP(B98,B$5:W$69,22, false) -> 17 | F98: =VLOOKUP(B98,indirect($AB$2&"!B$5:U$70"),11, false) -> 18 | G98: =VLOOKUP(B98,indirect($AB$2&"!B$5:U$70"),6, false) -> 4 | L98: =if(D98-E98=C98,"ok","Error") -> ok
B99: =IFERROR(__xludf.DUMMYFUNCTION("""COMPUTED_VALUE"""),"Jim Miao") -> Jim Miao | C99: =IFERROR(__xludf.DUMMYFUNCTION("""COMPUTED_VALUE"""),2.0) -> 2 | D99: =VLOOKUP(B99,indirect($AB$2&"!B$5:w$70"),22, false) -> 30 | E99: =VLOOKUP(B99,B$5:W$69,22, false) -> 28 | F99: =VLOOKUP(B99,indirect($AB$2&"!B$5:U$70"),11, false) -> 15 | G99: =VLOOKUP(B99,indirect($AB$2&"!B$5:U$70"),6, false) -> 5 | L99: =if(D99-E99=C99,"ok","Error") -> ok
...

Sheet 122124
B1: Standings as of | C1: 45647
B2: Number of Weeks Played | D2: 25 | AB2: =text(C1-7,"mm/dd/yy") -> 12/14/24
C3: Beginning of week | F3: Current Week Scores | N3: End of week | Q3: Jul-Dec 2024 | R3: Jan-Jun 2025
A4: Ranking | B4: Name of Player | C4: Games Won | D4: Sets Won | E4: Games Won / Match | F4: Check IN | G4: Court # | H4: Set 0 | I4: Set 1 | J4: Set 2 | K4: Set 3 | L4: Games Won | M4: Sets Won | N4: Games Won | O4: Sets Won | P4: Waiver | Q4: Fee | R4: Fee | S4: Sit outs | T4: No Shows | U4: Absent | V4: Positions Gained/Lost | W4: Ranking
A5: 1 | B5: Adrian Tay | C5: 372 | D5: 44 | E5: =(C5-(U5*9)-(S5*13))/($D$2-U5-S5) -> 16.722222 | F5: 1 | G5: 1 | H5: 0 | I5: 7 | J5: 6 | K5: 7 | L5: 20 | M5: 3 | N5: =C5+L5 -> 392 | O5: =D5+M5 -> 47 | P5: X | Q5: X | R5: X | S5: =if(H5=13,1,0)+VLOOKUP(B5,indirect($AB$2&"!B:T"),18,false) -> 2 | U5: =if(H5=9,1,0)+VLOOKUP(B5,indirect($AB$2&"!B:U"),20,false) -> 5 | V5: =VLOOKUP(B5,indirect($AB$2&"!B$5:w$70"),22,false)-A5 -> 0 | W5: 1
A6: =A5+1 -> 2 | B6: Lam Bui | C6: 318 | D6: 27 | E6: =(C6-(U6*9)-(S6*13))/($D$2-U6-S6) -> 15.538462 | F6: 3 | G6: 0 | H6: 9 | I6: 0 | J6: 0 | K6: 0 | L6: 9 | M6: 0 | N6: =C6+L6 -> 327 | O6: =D6+M6 -> 27 | P6: X | Q6: X | R6: X | S6: =if(H6=13,1,0)+VLOOKUP(B6,indirect($AB$2&"!B:T"),18,false) -> 2 | U6: =if(H6=9,1,0)+VLOOKUP(B6,indirect($AB$2&"!B:U"),20,false) -> 10 | V6: =VLOOKUP(B6,indirect($AB$2&"!B$5:w$70"),22,false)-A6 -> 1 | W6: =W5+1 -> 2
A7: =A6+1 -> 3 | B7: David Shin | C7: 318 | D7: 27 | E7: =(C7-(U7*9)-(S7*13))/($D$2-U7-S7) -> 13.764706 | F7: 2 | G7: 1 | H7: 0 | I7: 6 | J7: 6 | K7: 6 | L7: 18 | M7: 1 | N7: =C7+L7 -> 336 | O7: =D7+M7 -> 28 | P7: X | Q7: X | R7: X | S7: =if(H7=13,1,0)+VLOOKUP(B7,indirect($AB$2&"!B:T"),18,false) -> 3 | U7: =if(H7=9,1,0)+VLOOKUP(B7,indirect($AB$2&"!B:U"),20,false) -> 5 | V7: =VLOOKUP(B7,indirect($AB$2&"!B$5:w$70"),22,false)-A7 -> -1 | W7: =W6+1 -> 3
A8: =A7+1 -> 4 | B8: Tom Le | C8: 317 | D8: 31 | E8: =(C8-(U8*9)-(S8*13))/($D$2-U8-S8) -> 14.111111 | F8: 1 | G8: 1 | H8: 0 | I8: 7 | J8: 1 | K8: 6 | L8: 14 | M8: 1 | N8: =C8+L8 -> 331 | O8: =D8+M8 -> 32 | P8: X | Q8: X | R8: X | S8: =if(H8=13,1,0)+VLOOKUP(B8,indirect($AB$2&"!B:T"),18,false) -> 0 | U8: =if(H8=9,1,0)+VLOOKUP(B8,indirect($AB$2&"!B:U"),20,false) -> 7 | V8: =VLOOKUP(B8,indirect($AB$2&"!B$5:w$70"),22,false)-A8 -> 2 | W8: =W7+1 -> 4
A9: =A8+1 -> 5 | B9: Frank Moon | C9: 315 | D9: 30 | E9: =(C9-(U9*9)-(S9*13))/($D$2-U9-S9) -> 12.75 | F9: 1 | G9: 1 | H9: 0 | I9: 6 | J9: 1 | K9: 7 | L9: 14 | M9: 1 | N9: =C9+L9 -> 329 | O9: =D9+M9 -> 31 | P9: X | Q9: X | R9: X | S9: =if(H9=13,1,0)+VLOOKUP(B9,indirect($AB$2&"!B:T"),18,false) -> 0 | U9: =if(H9=9,1,0)+VLOOKUP(B9,indirect($AB$2&"!B:U"),20,false) -> 1 | V9: =VLOOKUP(B9,indirect($AB$2&"!B$5:w$70"),22,false)-A9 -> 2 | W9: =W8+1 -> 5
A10: =A9+1 -> 6 | B10: Scott Li | C10: 314 | D10: 24 | E10: =(C10-(U10*9)-(S10*13))/($D$2-U10-S10) -> 13.473684 | F10: 1 | G10: 2 | H10: 0 | I10: 6 | J10: 4 | K10: 5 | L10: 15 | M10: 1 | N10: =C10+L10 -> 329 | O10: =D10+M10 -> 25 | P10: X | Q10: X | R10: X | S10: =if(H10=13,1,0)+VLOOKUP(B10,indirect($AB$2&"!B:T"),18,false) -> 1 | U10: =if(H10=9,1,0)+VLOOKUP(B10,indirect($AB$2&"!B:U"),20,false) -> 5 | V10: =VLOOKUP(B10,indirect($AB$2&"!B$5:w$70"),22,false)-A10 -> 3 | W10: =W9+1 -> 6
A11: =A10+1 -> 7 | B11: Suleman Alidina | C11: 313 | D11: 30 | E11: =(C11-(U11*9)-(S11*13))/($D$2-U11-S11) -> 13.421053 | F11: 1 | G11: 2 | H11: 0 | I11: 2 | J11: 6 | K11: 5 | L11: 13 | M11: 1 | N11: =C11+L11 -> 326 | O11: =D11+M11 -> 31 | P11: X | Q11: X | R11: X | S11: =if(H11=13,1,0)+VLOOKUP(B11,indirect($AB$2&"!B:T"),18,false) -> 1 | U11: =if(H11=9,1,0)+VLOOKUP(B11,indirect($AB$2&"!B:U"),20,false) -> 5 | V11: =VLOOKUP(B11,indirect($AB$2&"!B$5:w$70"),22,false)-A11 -> -3 | W11: =W10+1 -> 7
