Workbook

Sheet Current
B1: Standings as of | C1: 46200
B2: Number of Weeks Played | D2: 25 | AC2: =text(C1,"mm/dd/yy") -> 06/27/26
C3: Beginning of week | F3: Current Week Scores | N3: End of week | Q3: Jan-Jun 2026 | R3: Jul-Dec 2026
A4: Ranking | B4: Name of Player | C4: Games Won | D4: Sets Won | E4: Games Won / Match | F4: Check IN | G4: Court # | H4: Set 0 | I4: Set 1 | J4: Set 2 | K4: Set 3 | L4: Games Won | M4: Sets Won | N4: Games Won | O4: Sets Won | P4: Waiver | Q4: Fee | R4: Fee | S4: Games Played | T4: Sit outs | U4: No Shows | V4: Absent | W4: Positions Gained/Lost | X4: Ranking | Y4: Perfect attendence | Z4: Check
A5: 1 | B5: Andrew Yao | C5: 381 | D5: 50 | E5: =if(S5>0,(C5-(V5*9)-(T5*13))/S5,0) -> 16.090909 | F5: =if(isna(VLOOKUP(B5,Checkin!A:B,2,false)),0,VLOOKUP(B5,Checkin!A:B,2,false)) -> 0 | G5: =if(OR($F5=1, $F5=2),VLOOKUP($B5,Courts!$B$2:$K$50,10,false),0) -> 0 | H5: =IF(OR(F5=3,F5=4),9,IF(F5=5,13,0)) -> 0 | I5: =if(OR($F5=1, $F5=2),VLOOKUP($B5,Courts!$B$2:$J$50,5,false),0) -> 0 | J5: =if(OR($F5=1, $F5=2),VLOOKUP($B5,Courts!$B$2:$J$50,6,false),0) -> 0 | K5: =if(OR($F5=1, $F5=2),VLOOKUP($B5,Courts!$B$2:$J$50,7,false),0) -> 0 | L5: =H5+I5+J5+K5 -> 0 | M5: =if(OR($F5=1, $F5=2),VLOOKUP($B5,Courts!$B$2:$J$50,9,false),0) -> 0 | N5: =C5+L5 -> 381 | O5: =D5+M5 -> 50 | P5: X | Q5: X | R5: X | S5: =vlookup(B5,indirect("'" & AC$2 & "'!B5:W79"),18,false)++if(text(C$1,"mm/dd/yy")=$AC$2,0,if(H5>0,0,1)) -> 22 | T5: =if(H5=13,1,0)+vlookup(B5,indirect("'" & AC$2 & "'!B5:W79"),19,false) -> 0 | V5: =vlookup(B5,indirect("'" & AC$2 & "'!B5:W79"),21,false)+if(text(C$1,"mm/dd/yy")=$AC$2,0,if(H5=9,1,0)) -> 3 | W5: =vlookup(B5,indirect("'" & AC$2 & "'!B5:x79"),23,false)-X5 -> 0 | X5: 1 | Y5: =if(S5=D$2,"Y","N") -> N | Z5: =if($D$2=sum(S5:V5),"","Error")
A6: =A5+1 -> 2 | B6: Pulkit Mathur | C6: 371 | D6: 42 | E6: =if(S6>0,(C6-(V6*9)-(T6*13))/S6,0) -> 15.952381 | F6: =if(isna(VLOOKUP(B6,Checkin!A:B,2,false)),0,VLOOKUP(B6,Checkin!A:B,2,false)) -> 0 | G6: =if(OR($F6=1, $F6=2),VLOOKUP($B6,Courts!$B$2:$K$50,10,false),0) -> 0 | H6: =IF(OR(F6=3,F6=4),9,IF(F6=5,13,0)) -> 0 | I6: =if(OR($F6=1, $F6=2),VLOOKUP($B6,Courts!$B$2:$J$50,5,false),0) -> 0 | J6: =if(OR($F6=1, $F6=2),VLOOKUP($B6,Courts!$B$2:$J$50,6,false),0) -> 0 | K6: =if(OR($F6=1, $F6=2),VLOOKUP($B6,Courts!$B$2:$J$50,7,false),0) -> 0 | L6: =H6+I6+J6+K6 -> 0 | M6: =if(OR($F6=1, $F6=2),VLOOKUP($B6,Courts!$B$2:$J$50,9,false),0) -> 0 | N6: =C6+L6 -> 371 | O6: =D6+M6 -> 42 | P6: X | Q6: X | R6: X | S6: =vlookup(B6,indirect("'" & AC$2 & "'!B5:W79"),18,false)++if(text(C$1,"mm/dd/yy")=$AC$2,0,if(H6>0,0,1)) -> 21 | T6: =if(H6=13,1,0)+vlookup(B6,indirect("'" & AC$2 & "'!B5:W79"),19,false) -> 0 | V6: =vlookup(B6,indirect("'" & AC$2 & "'!B5:W79"),21,false)+if(text(C$1,"mm/dd/yy")=$AC$2,0,if(H6=9,1,0)) -> 4 | W6: =vlookup(B6,indirect("'" & AC$2 & "'!B5:x79"),23,false)-X6 -> 0 | X6: =X5+1 -> 2 | Y6: =if(S6=D$2,"Y","N") -> N | Z6: =if($D$2=sum(S6:V6),"","Error")
A7: =A6+1 -> 3 | B7: Sandeep Kamalon | C7: 355 | D7: 36 | E7: =if(S7>0,(C7-(V7*9)-(T7*13))/S7,0) -> 14.909091 | F7: =if(isna(VLOOKUP(B7,Checkin!A:B,2,false)),0,VLOOKUP(B7,Checkin!A:B,2,false)) -> 0 | G7: =if(OR($F7=1, $F7=2),VLOOKUP($B7,Courts!$B$2:$K$50,10,false),0) -> 0 | H7: =IF(OR(F7=3,F7=4),9,IF(F7=5,13,0)) -> 0 | I7: =if(OR($F7=1, $F7=2),VLOOKUP($B7,Courts!$B$2:$J$50,5,false),0) -> 0 | J7: =if(OR($F7=1, $F7=2),VLOOKUP($B7,Courts!$B$2:$J$50,6,false),0) -> 0 | K7: =if(OR($F7=1, $F7=2),VLOOKUP($B7,Courts!$B$2:$J$50,7,false),0) -> 0 | L7: =H7+I7+J7+K7 -> 0 | M7: =if(OR($F7=1, $F7=2),VLOOKUP($B7,Courts!$B$2:$J$50,9,false),0) -> 0 | N7: =C7+L7 -> 355 | O7: =D7+M7 -> 36 | P7: X | Q7: X | R7: X | S7: =vlookup(B7,indirect("'" & AC$2 & "'!B5:W79"),18,false)++if(text(C$1,"mm/dd/yy")=$AC$2,0,if(H7>0,0,1)) -> 22 | T7: =if(H7=13,1,0)+vlookup(B7,indirect("'" & AC$2 & "'!B5:W79"),19,false) -> 0 | V7: =vlookup(B7,indirect("'" & AC$2 & "'!B5:W79"),21,false)+if(text(C$1,"mm/dd/yy")=$AC$2,0,if(H7=9,1,0)) -> 3 | W7: =vlookup(B7,indirect("'" & AC$2 & "'!B5:x79"),23,false)-X7 -> 0 | X7: =X6+1 -> 3 | Y7: =if(S7=D$2,"Y","N") -> N | Z7: =if($D$2=sum(S7:V7),"","Error")
A8: =A7+1 -> 4 | B8: Tom Le | C8: 336 | D8: 34 | E8: =if(S8>0,(C8-(V8*9)-(T8*13))/S8,0) -> 17.230769 | F8: =if(isna(VLOOKUP(B8,Checkin!A:B,2,false)),0,VLOOKUP(B8,Checkin!A:B,2,false)) -> 0 | G8: =if(OR($F8=1, $F8=2),VLOOKUP($B8,Courts!$B$2:$K$50,10,false),0) -> 0 | H8: =IF(OR(F8=3,F8=4),9,IF(F8=5,13,0)) -> 0 | I8: =if(OR($F8=1, $F8=2),VLOOKUP($B8,Courts!$B$2:$J$50,5,false),0) -> 0 | J8: =if(OR($F8=1, $F8=2),VLOOKUP($B8,Courts!$B$2:$J$50,6,false),0) -> 0 | K8: =if(OR($F8=1, $F8=2),VLOOKUP($B8,Courts!$B$2:$J$50,7,false),0) -> 0 | L8: =H8+I8+J8+K8 -> 0 | M8: =if(OR($F8=1, $F8=2),VLOOKUP($B8,Courts!$B$2:$J$50,9,false),0) -> 0 | N8: =C8+L8 -> 336 | O8: =D8+M8 -> 34 | P8: X | Q8: X | R8: X | S8: =vlookup(B8,indirect("'" & AC$2 & "'!B5:W79"),18,false)++if(text(C$1,"mm/dd/yy")=$AC$2,0,if(H8>0,0,1)) -> 13 | T8: =if(H8=13,1,0)+vlookup(B8,indirect("'" & AC$2 & "'!B5:W79"),19,false) -> 1 | V8: =vlookup(B8,indirect("'" & AC$2 & "'!B5:W79"),21,false)+if(text(C$1,"mm/dd/yy")=$AC$2,0,if(H8=9,1,0)) -> 11 | W8: =vlookup(B8,indirect("'" & AC$2 & "'!B5:x79"),23,false)-X8 -> 2 | X8: =X7+1 -> 4 | Y8: =if(S8=D$2,"Y","N") -> N | Z8: =if($D$2=sum(S8:V8),"","Error")
A9: =A8+1 -> 5 | B9: Suleman Alidina | C9: 334 | D9: 28 | E9: =if(S9>0,(C9-(V9*9)-(T9*13))/S9,0) -> 13.85 | F9: =if(isna(VLOOKUP(B9,Checkin!A:B,2,false)),0,VLOOKUP(B9,Checkin!A:B,2,false)) -> 0 | G9: =if(OR($F9=1, $F9=2),VLOOKUP($B9,Courts!$B$2:$K$50,10,false),0) -> 0 | H9: =IF(OR(F9=3,F9=4),9,IF(F9=5,13,0)) -> 0 | I9: =if(OR($F9=1, $F9=2),VLOOKUP($B9,Courts!$B$2:$J$50,5,false),0) -> 0 | J9: =if(OR($F9=1, $F9=2),VLOOKUP($B9,Courts!$B$2:$J$50,6,false),0) -> 0 | K9: =if(OR($F9=1, $F9=2),VLOOKUP($B9,Courts!$B$2:$J$50,7,false),0) -> 0 | L9: =H9+I9+J9+K9 -> 0 | M9: =if(OR($F9=1, $F9=2),VLOOKUP($B9,Courts!$B$2:$J$50,9,false),0) -> 0 | N9: =C9+L9 -> 334 | O9: =D9+M9 -> 28 | P9: X | Q9: X | R9: X | S9: =vlookup(B9,indirect("'" & AC$2 & "'!B5:W79"),18,false)++if(text(C$1,"mm/dd/yy")=$AC$2,0,if(H9>0,0,1)) -> 20 | T9: =if(H9=13,1,0)+vlookup(B9,indirect("'" & AC$2 & "'!B5:W79"),19,false) -> 3 | V9: =vlookup(B9,indirect("'" & AC$2 & "'!B5:W79"),21,false)+if(text(C$1,"mm/dd/yy")=$AC$2,0,if(H9=9,1,0)) -> 2 | W9: =vlookup(B9,indirect("'" & AC$2 & "'!B5:x79"),23,false)-X9 -> -1 | X9: =X8+1 -> 5 | Y9: =if(S9=D$2,"Y","N") -> N | Z9: =if($D$2=sum(S9:V9),"","Error")
A10: =A9+1 -> 6 | B10: Pavan Akkimsetty | C10: 330 | D10: 30 | E10: =if(S10>0,(C10-(V10*9)-(T10*13))/S10,0) -> 14.611111 | F10: =if(isna(VLOOKUP(B10,Checkin!A:B,2,false)),0,VLOOKUP(B10,Checkin!A:B,2,false)) -> 0 | G10: =if(OR($F10=1, $F10=2),VLOOKUP($B10,Courts!$B$2:$K$50,10,false),0) -> 0 | H10: =IF(OR(F10=3,F10=4),9,IF(F10=5,13,0)) -> 0 | I10: =if(OR($F10=1, $F10=2),VLOOKUP($B10,Courts!$B$2:$J$50,5,false),0) -> 0 | J10: =if(OR($F10=1, $F10=2),VLOOKUP($B10,Courts!$B$2:$J$50,6,false),0) -> 0 | K10: =if(OR($F10=1, $F10=2),VLOOKUP($B10,Courts!$B$2:$J$50,7,false),0) -> 0 | L10: =H10+I10+J10+K10 -> 0 | M10: =if(OR($F10=1, $F10=2),VLOOKUP($B10,Courts!$B$2:$J$50,9,false),0) -> 0 | N10: =C10+L10 -> 330 | O10: =D10+M10 -> 30 | P10: X | Q10: X | R10: X | S10: =vlookup(B10,indirect("'" & AC$2 & "'!B5:W79"),18,false)++if(text(C$1,"mm/dd/yy")=$AC$2,0,if(H10>0,0,1)) -> 18 | T10: =if(H10=13,1,0)+vlookup(B10,indirect("'" & AC$2 & "'!B5:W79"),19,false) -> 1 | V10: =vlookup(B10,indirect("'" & AC$2 & "'!B5:W79"),21,false)+if(text(C$1,"mm/dd/yy")=$AC$2,0,if(H10=9,1,0)) -> 6 | W10: =vlookup(B10,indirect("'" & AC$2 & "'!B5:x79"),23,false)-X10 -> -1 | X10: =X9+1 -> 6 | Y10: =if(S10=D$2,"Y","N") -> N | Z10: =if($D$2=sum(S10:V10),"","Error")
A11: =A10+1 -> 7 | B11: Darren Wong | C11: 326 | D11: 31 | E11: =if(S11>0,(C11-(V11*9)-(T11*13))/S11,0) -> 16.769231 | F11: =if(isna(VLOOKUP(B11,Checkin!A:B,2,false)),0,VLOOKUP(B11,Checkin!A:B,2,false)) -> 0 | G11: =if(OR($F11=1, $F11=2),VLOOKUP($B11,Courts!$B$2:$K$50,10,false),0) -> 0 | H11: =IF(OR(F11=3,F11=4),9,IF(F11=5,13,0)) -> 0 | I11: =if(OR($F11=1, $F11=2),VLOOKUP($B11,Courts!$B$2:$J$50,5,false),0) -> 0 | J11: =if(OR($F11=1, $F11=2),VLOOKUP($B11,Courts!$B$2:$J$50,6,false),0) -> 0 | K11: =if(OR($F11=1, $F11=2),VLOOKUP($B11,Courts!$B$2:$J$50,7,false),0) -> 0 | L11: =H11+I11+J11+K11 -> 0 | M11: =if(OR($F11=1, $F11=2),VLOOKUP($B11,Courts!$B$2:$J$50,9,false),0) -> 0 | N11: =C11+L11 -> 326 | O11: =D11+M11 -> 31 | P11: X | Q11: X | R11: X | S11: =vlookup(B11,indirect("'" & AC$2 & "'!B5:W79"),18,false)++if(text(C$1,"mm/dd/yy")=$AC$2,0,if(H11>0,0,1)) -> 13 | T11: =if(H11=13,1,0)+vlookup(B11,indirect("'" & AC$2 & "'!B5:W79"),19,false) -> 0 | V11: =vlookup(B11,indirect("'" & AC$2 & "'!B5:W79"),21,false)+if(text(C$1,"mm/dd/yy")=$AC$2,0,if(H11=9,1,0)) -> 12 | W11: =vlookup(B11,indirect("'" & AC$2 & "'!B5:x79"),23,false)-X11 -> 8 | X11: =X10+1 -> 7 | Y11: =if(S11=D$2,"Y","N") -> N | Z11: =if($D$2=sum(S11:V11),"","Error")
A12: =A11+1 -> 8 | B12: Matthew Huang | C12: 325 | D12: 30 | E12: =if(S12>0,(C12-(V12*9)-(T12*13))/S12,0) -> 15 | F12: =if(isna(VLOOKUP(B12,Checkin!A:B,2,false)),0,VLOOKUP(B12,Checkin!A:B,2,false)) -> 0 | G12: =if(OR($F12=1, $F12=2),VLOOKUP($B12,Courts!$B$2:$K$50,10,false),0) -> 0 | H12: =IF(OR(F12=3,F12=4),9,IF(F12=5,13,0)) -> 0 | I12: =if(OR($F12=1, $F12=2),VLOOKUP($B12,Courts!$B$2:$J$50,5,false),0) -> 0 | J12: =if(OR($F12=1, $F12=2),VLOOKUP($B12,Courts!$B$2:$J$50,6,false),0) -> 0 | K12: =if(OR($F12=1, $F12=2),VLOOKUP($B12,Courts!$B$2:$J$50,7,false),0) -> 0 | L12: =H12+I12+J12+K12 -> 0 | M12: =if(OR($F12=1, $F12=2),VLOOKUP($B12,Courts!$B$2:$J$50,9,false),0) -> 0 | N12: =C12+L12 -> 325 | O12: =D12+M12 -> 30 | P12: X | Q12: X | R12: X | S12: =vlookup(B12,indirect("'" & AC$2 & "'!B5:W79"),18,false)++if(text(C$1,"mm/dd/yy")=$AC$2,0,if(H12>0,0,1)) -> 16 | T12: =if(H12=13,1,0)+vlookup(B12,indirect("'" & AC$2 & "'!B5:W79"),19,false) -> 1 | V12: =vlookup(B12,indirect("'" & AC$2 & "'!B5:W79"),21,false)+if(text(C$1,"mm/dd/yy")=$AC$2,0,if(H12=9,1,0)) -> 8 | W12: =vlookup(B12,indirect("'" & AC$2 & "'!B5:x79"),23,false)-X12 -> 2 | X12: =X11+1 -> 8 | Y12: =if(S12=D$2,"Y","N") -> N | Z12: =if($D$2=sum(S12:V12),"","Error")
A13: =A12+1 -> 9 | B13: Ethan Gu | C13: 325 | D13: 25 | E13: =if(S13>0,(C13-(V13*9)-(T13*13))/S13,0) -> 14.263158 | F13: =if(isna(VLOOKUP(B13,Checkin!A:B,2,false)),0,VLOOKUP(B13,Checkin!A:B,2,false)) -> 0 | G13: =if(OR($F13=1, $F13=2),VLOOKUP($B13,Courts!$B$2:$K$50,10,false),0) -> 0 | H13: =IF(OR(F13=3,F13=4),9,IF(F13=5,13,0)) -> 0 | I13: =if(OR($F13=1, $F13=2),VLOOKUP($B13,Courts!$B$2:$J$50,5,false),0) -> 0 | J13: =if(OR($F13=1, $F13=2),VLOOKUP($B13,Courts!$B$2:$J$50,6,false),0) -> 0 | K13: =if(OR($F13=1, $F13=2),VLOOKUP($B13,Courts!$B$2:$J$50,7,false),0) -> 0 | L13: =H13+I13+J13+K13 -> 0 | M13: =if(OR($F13=1, $F13=2),VLOOKUP($B13,Courts!$B$2:$J$50,9,false),0) -> 0 | N13: =C13+L13 -> 325 | O13: =D13+M13 -> 25 | P13: X | Q13: X | R13: X | S13: =vlookup(B13,indirect("'" & AC$2 & "'!B5:W79"),18,false)++if(text(C$1,"mm/dd/yy")=$AC$2,0,if(H13>0,0,1)) -> 19 | T13: =if(H13=13,1,0)+vlookup(B13,indirect("'" & AC$2 & "'!B5:W79"),19,false) -> 0 | V13: =vlookup(B13,indirect("'" & AC$2 & "'!B5:W79"),21,false)+if(text(C$1,"mm/dd/yy")=$AC$2,0,if(H13=9,1,0)) -> 6 | W13: =vlookup(B13,indirect("'" & AC$2 & "'!B5:x79"),23,false)-X13 -> -1 | X13: =X12+1 -> 9 | Y13: =if(S13=D$2,"Y","N") -> N | Z13: =if($D$2=sum(S13:V13),"","Error")
A14: =A13+1 -> 10 | B14: Erik Hoeckmann | C14: 324 | D14: 29 | E14: =if(S14>0,(C14-(V14*9)-(T14*13))/S14,0) -> 13.75 | F14: =if(isna(VLOOKUP(B14,Checkin!A:B,2,false)),0,VLOOKUP(B14,Checkin!A:B,2,false)) -> 0 | G14: =if(OR($F14=1, $F14=2),VLOOKUP($B14,Courts!$B$2:$K$50,10,false),0) -> 0 | H14: =IF(OR(F14=3,F14=4),9,IF(F14=5,13,0)) -> 0 | I14: =if(OR($F14=1, $F14=2),VLOOKUP($B14,Courts!$B$2:$J$50,5,false),0) -> 0 | J14: =if(OR($F14=1, $F14=2),VLOOKUP($B14,Courts!$B$2:$J$50,6,false),0) -> 0 | K14: =if(OR($F14=1, $F14=2),VLOOKUP($B14,Courts!$B$2:$J$50,7,false),0) -> 0 | L14: =H14+I14+J14+K14 -> 0 | M14: =if(OR($F14=1, $F14=2),VLOOKUP($B14,Courts!$B$2:$J$50,9,false),0) -> 0 | N14: =C14+L14 -> 324 | O14: =D14+M14 -> 29 | P14: X | Q14: X | R14: X | S14: =vlookup(B14,indirect("'" & AC$2 & "'!B5:W79"),18,false)++if(text(C$1,"mm/dd/yy")=$AC$2,0,if(H14>0,0,1)) -> 20 | T14: =if(H14=13,1,0)+vlookup(B14,indirect("'" & AC$2 & "'!B5:W79"),19,false) -> 1 | V14: =vlookup(B14,indirect("'" & AC$2 & "'!B5:W79"),21,false)+if(text(C$1,"mm/dd/yy")=$AC$2,0,if(H14=9,1,0)) -> 4 | W14: =vlookup(B14,indirect("'" & AC$2 & "'!B5:x79"),23,false)-X14 -> -3 | X14: =X13+1 -> 10 | Y14: =if(S14=D$2,"Y","N") -> N | Z14: =if($D$2=sum(S14:V14),"","Error")
A15: =A14+1 -> 11 | B15: David Shin | C15: 323 | D15: 30 | E15: =if(S15>0,(C15-(V15*9)-(T15*13))/S15,0) -> 13.7 | F15: =if(isna(VLOOKUP(B15,Checkin!A:B,2,false)),0,VLOOKUP(B15,Checkin!A:B,2,false)) -> 0 | G15: =if(OR($F15=1, $F15=2),VLOOKUP($B15,Courts!$B$2:$K$50,10,false),0) -> 0 | H15: =IF(OR(F15=3,F15=4),9,IF(F15=5,13,0)) -> 0 | I15: =if(OR($F15=1, $F15=2),VLOOKUP($B15,Courts!$B$2:$J$50,5,false),0) -> 0 | J15: =if(OR($F15=1, $F15=2),VLOOKUP($B15,Courts!$B$2:$J$50,6,false),0) -> 0 | K15: =if(OR($F15=1, $F15=2),VLOOKUP($B15,Courts!$B$2:$J$50,7,false),0) -> 0 | L15: =H15+I15+J15+K15 -> 0 | M15: =if(OR($F15=1, $F15=2),VLOOKUP($B15,Courts!$B$2:$J$50,9,false),0) -> 0 | N15: =C15+L15 -> 323 | O15: =D15+M15 -> 30 | P15: X | Q15: X | R15: X | S15: =vlookup(B15,indirect("'" & AC$2 & "'!B5:W79"),18,false)++if(text(C$1,"mm/dd/yy")=$AC$2,0,if(H15>0,0,1)) -> 20 | T15: =if(H15=13,1,0)+vlookup(B15,indirect("'" & AC$2 & "'!B5:W79"),19,false) -> 1 | V15: =vlookup(B15,indirect("'" & AC$2 & "'!B5:W79"),21,false)+if(text(C$1,"mm/dd/yy")=$AC$2,0,if(H15=9,1,0)) -> 4 | W15: =vlookup(B15,indirect("'" & AC$2 & "'!B5:x79"),23,false)-X15 -> -2 | X15: =X14+1 -> 11 | Y15: =if(S15=D$2,"Y","N") -> N | Z15: =if($D$2=sum(S15:V15),"","Error")
A16: =A15+1 -> 12 | B16: Manish Anand | C16: 322 | D16: 29 | E16: =if(S16>0,(C16-(V16*9)-(T16*13))/S16,0) -> 14.388889 | F16: =if(isna(VLOOKUP(B16,Checkin!A:B,2,false)),0,VLOOKUP(B16,Checkin!A:B,2,false)) -> 0 | G16: =if(OR($F16=1, $F16=2),VLOOKUP($B16,Courts!$B$2:$K$50,10,false),0) -> 0 | H16: =IF(OR(F16=3,F16=4),9,IF(F16=5,13,0)) -> 0 | I16: =if(OR($F16=1, $F16=2),VLOOKUP($B16,Courts!$B$2:$J$50,5,false),0) -> 0 | J16: =if(OR($F16=1, $F16=2),VLOOKUP($B16,Courts!$B$2:$J$50,6,false),0) -> 0 | K16: =if(OR($F16=1, $F16=2),VLOOKUP($B16,Courts!$B$2:$J$50,7,false),0) -> 0 | L16: =H16+I16+J16+K16 -> 0 | M16: =if(OR($F16=1, $F16=2),VLOOKUP($B16,Courts!$B$2:$J$50,9,false),0) -> 0 | N16: =C16+L16 -> 322 | O16: =D16+M16 -> 29 | P16: X | Q16: X | R16: X | S16: =vlookup(B16,indirect("'" & AC$2 & "'!B5:W79"),18,false)++if(text(C$1,"mm/dd/yy")=$AC$2,0,if(H16>0,0,1)) -> 18 | T16: =if(H16=13,1,0)+vlookup(B16,indirect("'" & AC$2 & "'!B5:W79"),19,false) -> 0 | V16: =vlookup(B16,indirect("'" & AC$2 & "'!B5:W79"),21,false)+if(text(C$1,"mm/dd/yy")=$AC$2,0,if(H16=9,1,0)) -> 7 | W16: =vlookup(B16,indirect("'" & AC$2 & "'!B5:x79"),23,false)-X16 -> 0 | X16: =X15+1 -> 12 | Y16: =if(S16=D$2,"Y","N") -> N | Z16: =if($D$2=sum(S16:V16),"","Error")
A17: =A16+1 -> 13 | B17: Frank Moon | C17: 321 | D17: 35 | E17: =if(S17>0,(C17-(V17*9)-(T17*13))/S17,0) -> 13 | F17: =if(isna(VLOOKUP(B17,Checkin!A:B,2,false)),0,VLOOKUP(B17,Checkin!A:B,2,false)) -> 0 | G17: =if(OR($F17=1, $F17=2),VLOOKUP($B17,Courts!$B$2:$K$50,10,false),0) -> 0 | H17: =IF(OR(F17=3,F17=4),9,IF(F17=5,13,0)) -> 0 | I17: =if(OR($F17=1, $F17=2),VLOOKUP($B17,Courts!$B$2:$J$50,5,false),0) -> 0 | J17: =if(OR($F17=1, $F17=2),VLOOKUP($B17,Courts!$B$2:$J$50,6,false),0) -> 0 | K17: =if(OR($F17=1, $F17=2),VLOOKUP($B17,Courts!$B$2:$J$50,7,false),0) -> 0 | L17: =H17+I17+J17+K17 -> 0 | M17: =if(OR($F17=1, $F17=2),VLOOKUP($B17,Courts!$B$2:$J$50,9,false),0) -> 0 | N17: =C17+L17 -> 321 | O17: =D17+M17 -> 35 | P17: X | Q17: X | R17: X | S17: =vlookup(B17,indirect("'" & AC$2 & "'!B5:W79"),18,false)++if(text(C$1,"mm/dd/yy")=$AC$2,0,if(H17>0,0,1)) -> 24 | T17: =if(H17=13,1,0)+vlookup(B17,indirect("'" & AC$2 & "'!B5:W79"),19,false) -> 0 | V17: =vlookup(B17,indirect("'" & AC$2 & "'!B5:W79"),21,false)+if(text(C$1,"mm/dd/yy")=$AC$2,0,if(H17=9,1,0)) -> 1 | W17: =vlookup(B17,indirect("'" & AC$2 & "'!B5:x79"),23,false)-X17 -> -2 | X17: =X16+1 -> 13 | Y17: =if(S17=D$2,"Y","N") -> N | Z17: =if($D$2=sum(S17:V17),"","Error")
... A56: =A55+1 -> 52 | B56: Ramesh Bandaru | C56: 274 | D56: 18 | E56: =if(S56>0,(C56-(V56*9)-(T56*13))/S56,0) -> 13.454545 | F56: =if(isna(VLOOKUP(B56,Checkin!A:B,2,false)),0,VLOOKUP(B56,Checkin!A:B,2,false)) -> 0 | G56: =if(OR($F56=1, $F56=2),VLOOKUP($B56,Courts!$B$2:$K$50,10,false),0) -> 0 | H56: =IF(OR(F56=3,F56=4),9,IF(F56=5,13,0)) -> 0 | I56: =if(OR($F56=1, $F56=2),VLOOKUP($B56,Courts!$B$2:$J$50,5,false),0) -> 0 | J56: =if(OR($F56=1, $F56=2),VLOOKUP($B56,Courts!$B$2:$J$50,6,false),0) -> 0 | K56: =if(OR($F56=1, $F56=2),VLOOKUP($B56,Courts!$B$2:$J$50,7,false),0) -> 0 | L56: =H56+I56+J56+K56 -> 0 | M56: =if(OR($F56=1, $F56=2),VLOOKUP($B56,Courts!$B$2:$J$50,9,false),0) -> 0 | N56: =C56+L56 -> 274 | O56: =D56+M56 -> 18 | P56: X | Q56: X | R56: X | S56: =vlookup(B56,indirect("'" & AC$2 & "'!B5:W79"),18,false)++if(text(C$1,"mm/dd/yy")=$AC$2,0,if(H56>0,0,1)) -> 11 | T56: =if(H56=13,1,0)+vlookup(B56,indirect("'" & AC$2 & "'!B5:W79"),19,false) -> 0 | V56: =vlookup(B56,indirect("'" & AC$2 & "'!B5:W79"),21,false)+if(text(C$1,"mm/dd/yy")=$AC$2,0,if(H56=9,1,0)) -> 14 | W56: =vlookup(B56,indirect("'" & AC$2 & "'!B5:x79"),23,false)-X56 -> -1 | X56: =X55+1 -> 52 | Y56: =if(S56=D$2,"Y","N") -> N | Z56: =if($D$2=sum(S56:V56),"","Error")
A57: =A56+1 -> 53 | B57: Adrian Tay | C57: 269 | D57: 14 | E57: =if(S57>0,(C57-(V57*9)-(T57*13))/S57,0) -> 17.8 | F57: =if(isna(VLOOKUP(B57,Checkin!A:B,2,false)),0,VLOOKUP(B57,Checkin!A:B,2,false)) -> 0 | G57: =if(OR($F57=1, $F57=2),VLOOKUP($B57,Courts!$B$2:$K$50,10,false),0) -> 0 | H57: =IF(OR(F57=3,F57=4),9,IF(F57=5,13,0)) -> 0 | I57: =if(OR($F57=1, $F57=2),VLOOKUP($B57,Courts!$B$2:$J$50,5,false),0) -> 0 | J57: =if(OR($F57=1, $F57=2),VLOOKUP($B57,Courts!$B$2:$J$50,6,false),0) -> 0 | K57: =if(OR($F57=1, $F57=2),VLOOKUP($B57,Courts!$B$2:$J$50,7,false),0) -> 0 | L57: =H57+I57+J57+K57 -> 0 | M57: =if(OR($F57=1, $F57=2),VLOOKUP($B57,Courts!$B$2:$J$50,9,false),0) -> 0 | N57: =C57+L57 -> 269 | O57: =D57+M57 -> 14 | P57: X | Q57: X | S57: =vlookup(B57,indirect("'" & AC$2 & "'!B5:W79"),18,false)++if(text(C$1,"mm/dd/yy")=$AC$2,0,if(H57>0,0,1)) -> 5 | T57: =if(H57=13,1,0)+vlookup(B57,indirect("'" & AC$2 & "'!B5:W79"),19,false) -> 0 | V57: =vlookup(B57,indirect("'" & AC$2 & "'!B5:W79"),21,false)+if(text(C$1,"mm/dd/yy")=$AC$2,0,if(H57=9,1,0)) -> 20 | W57: =vlookup(B57,indirect("'" & AC$2 & "'!B5:x79"),23,false)-X57 -> 0 | X57: =X56+1 -> 53 | Y57: =if(S57=D$2,"Y","N") -> N | Z57: =if($D$2=sum(S57:V57),"","Error")
A58: =A57+1 -> 54 | B58: Andrew Wen | C58: 268 | D58: 12 | E58: =if(S58>0,(C58-(V58*9)-(T58*13))/S58,0) -> 14.833333 | F58: =if(isna(VLOOKUP(B58,Checkin!A:B,2,false)),0,VLOOKUP(B58,Checkin!A:B,2,false)) -> 0 | G58: =if(OR($F58=1, $F58=2),VLOOKUP($B58,Courts!$B$2:$K$50,10,false),0) -> 0 | H58: =IF(OR(F58=3,F58=4),9,IF(F58=5,13,0)) -> 0 | I58: =if(OR($F58=1, $F58=2),VLOOKUP($B58,Courts!$B$2:$J$50,5,false),0) -> 0 | J58: =if(OR($F58=1, $F58=2),VLOOKUP($B58,Courts!$B$2:$J$50,6,false),0) -> 0 | K58: =if(OR($F58=1, $F58=2),VLOOKUP($B58,Courts!$B$2:$J$50,7,false),0) -> 0 | L58: =H58+I58+J58+K58 -> 0 | M58: =if(OR($F58=1, $F58=2),VLOOKUP($B58,Courts!$B$2:$J$50,9,false),0) -> 0 | N58: =C58+L58 -> 268 | O58: =D58+M58 -> 12 | P58: X | Q58: X | R58: X | S58: =vlookup(B58,indirect("'" & AC$2 & "'!B5:W79"),18,false)++if(text(C$1,"mm/dd/yy")=$AC$2,0,if(H58>0,0,1)) -> 6 | T58: =if(H58=13,1,0)+vlookup(B58,indirect("'" & AC$2 & "'!B5:W79"),19,false) -> 2 | V58: =vlookup(B58,indirect("'" & AC$2 & "'!B5:W79"),21,false)+if(text(C$1,"mm/dd/yy")=$AC$2,0,if(H58=9,1,0)) -> 17 | W58: =vlookup(B58,indirect("'" & AC$2 & "'!B5:x79"),23,false)-X58 -> 1 | X58: =X57+1 -> 54 | Y58: =if(S58=D$2,"Y","N") -> N | Z58: =if($D$2=sum(S58:V58),"","Error")
A59: =A58+1 -> 55 | B59: Susanta Mishra | C59: 263 | D59: 12 | E59: =if(S59>0,(C59-(V59*9)-(T59*13))/S59,0) -> 18.5 | F59: =if(isna(VLOOKUP(B59,Checkin!A:B,2,false)),0,VLOOKUP(B59,Checkin!A:B,2,false)) -> 0 | G59: =if(OR($F59=1, $F59=2),VLOOKUP($B59,Courts!$B$2:$K$50,10,false),0) -> 0 | H59: =IF(OR(F59=3,F59=4),9,IF(F59=5,13,0)) -> 0 | I59: =if(OR($F59=1, $F59=2),VLOOKUP($B59,Courts!$B$2:$J$50,5,false),0) -> 0 | J59: =if(OR($F59=1, $F59=2),VLOOKUP($B59,Courts!$B$2:$J$50,6,false),0) -> 0 | K59: =if(OR($F59=1, $F59=2),VLOOKUP($B59,Courts!$B$2:$J$50,7,false),0) -> 0 | L59: =H59+I59+J59+K59 -> 0 | M59: =if(OR($F59=1, $F59=2),VLOOKUP($B59,Courts!$B$2:$J$50,9,false),0) -> 0 | N59: =C59+L59 -> 263 | O59: =D59+M59 -> 12 | P59: X | Q59: X | R59: X | S59: =vlookup(B59,indirect("'" & AC$2 & "'!B5:W79"),18,false)++if(text(C$1,"mm/dd/yy")=$AC$2,0,if(H59>0,0,1)) -> 4 | T59: =if(H59=13,1,0)+vlookup(B59,indirect("'" & AC$2 & "'!B5:W79"),19,false) -> 0 | V59: =vlookup(B59,indirect("'" & AC$2 & "'!B5:W79"),21,false)+if(text(C$1,"mm/dd/yy")=$AC$2,0,if(H59=9,1,0)) -> 21 | W59: =vlookup(B59,indirect("'" & AC$2 & "'!B5:x79"),23,false)-X59 -> -1 | X59: =X58+1 -> 55 | Y59: =if(S59=D$2,"Y","N") -> N | Z59: =if($D$2=sum(S59:V59),"","Error")
A60: =A59+1 -> 56 | B60: Troy Wong | C60: 257 | D60: 10 | E60: =if(S60>0,(C60-(V60*9)-(T60*13))/S60,0) -> 15.4 | F60: =if(isna(VLOOKUP(B60,Checkin!A:B,2,false)),0,VLOOKUP(B60,Checkin!A:B,2,false)) -> 0 | G60: =if(OR($F60=1, $F60=2),VLOOKUP($B60,Courts!$B$2:$K$50,10,false),0) -> 0 | H60: =IF(OR(F60=3,F60=4),9,IF(F60=5,13,0)) -> 0 | I60: =if(OR($F60=1, $F60=2),VLOOKUP($B60,Courts!$B$2:$J$50,5,false),0) -> 0 | J60: =if(OR($F60=1, $F60=2),VLOOKUP($B60,Courts!$B$2:$J$50,6,false),0) -> 0 | K60: =if(OR($F60=1, $F60=2),VLOOKUP($B60,Courts!$B$2:$J$50,7,false),0) -> 0 | L60: =H60+I60+J60+K60 -> 0 | M60: =if(OR($F60=1, $F60=2),VLOOKUP($B60,Courts!$B$2:$J$50,9,false),0) -> 0 | N60: =C60+L60 -> 257 | O60: =D60+M60 -> 10 | P60: X | Q60: X | R60: X | S60: =vlookup(B60,indirect("'" & AC$2 & "'!B5:W79"),18,false)++if(text(C$1,"mm/dd/yy")=$AC$2,0,if(H60>0,0,1)) -> 5 | T60: =if(H60=13,1,0)+vlookup(B60,indirect("'" & AC$2 & "'!B5:W79"),19,false) -> 0 | V60: =vlookup(B60,indirect("'" & AC$2 & "'!B5:W79"),21,false)+if(text(C$1,"mm/dd/yy")=$AC$2,0,if(H60=9,1,0)) -> 20 | W60: =vlookup(B60,indirect("'" & AC$2 & "'!B5:x79"),23,false)-X60 -> 0 | X60: =X59+1 -> 56 | Y60: =if(S60=D$2,"Y","N") -> N | Z60: =if($D$2=sum(S60:V60),"","Error")
A61: =A60+1 -> 57 | B61: Camille Jung | C61: 254 | D61: 12 | E61: =if(S61>0,(C61-(V61*9)-(T61*13))/S61,0) -> 10.3125 | F61: =if(isna(VLOOKUP(B61,Checkin!A:B,2,false)),0,VLOOKUP(B61,Checkin!A:B,2,false)) -> 0 | G61: =if(OR($F61=1, $F61=2),VLOOKUP($B61,Courts!$B$2:$K$50,10,false),0) -> 0 | H61: =IF(OR(F61=3,F61=4),9,IF(F61=5,13,0)) -> 0 | I61: =if(OR($F61=1, $F61=2),VLOOKUP($B61,Courts!$B$2:$J$50,5,false),0) -> 0 | J61: =if(OR($F61=1, $F61=2),VLOOKUP($B61,Courts!$B$2:$J$50,6,false),0) -> 0 | K61: =if(OR($F61=1, $F61=2),VLOOKUP($B61,Courts!$B$2:$J$50,7,false),0) -> 0 | L61: =H61+I61+J61+K61 -> 0 | M61: =if(OR($F61=1, $F61=2),VLOOKUP($B61,Courts!$B$2:$J$50,9,false),0) -> 0 | N61: =C61+L61 -> 254 | O61: =D61+M61 -> 12 | P61: X | Q61: X | R61: X | S61: =vlookup(B61,indirect("'" & AC$2 & "'!B5:W79"),18,false)++if(text(C$1,"mm/dd/yy")=$AC$2,0,if(H61>0,0,1)) -> 16 | T61: =if(H61=13,1,0)+vlookup(B61,indirect("'" & AC$2 & "'!B5:W79"),19,false) -> 2 | V61: =vlookup(B61,indirect("'" & AC$2 & "'!B5:W79"),21,false)+if(text(C$1,"mm/dd/yy")=$AC$2,0,if(H61=9,1,0)) -> 7 | W61: =vlookup(B61,indirect("'" & AC$2 & "'!B5:x79"),23,false)-X61 -> 1 | X61: =X60+1 -> 57 | Y61: =if(S61=D$2,"Y","N") -> N | Z61: =if($D$2=sum(S61:V61),"","Error")
A62: =A61+1 -> 58 | B62: Art Hui | C62: 254 | D62: 8 | E62: =if(S62>0,(C62-(V62*9)-(T62*13))/S62,0) -> 13.166667 | F62: =if(isna(VLOOKUP(B62,Checkin!A:B,2,false)),0,VLOOKUP(B62,Checkin!A:B,2,false)) -> 0 | G62: =if(OR($F62=1, $F62=2),VLOOKUP($B62,Courts!$B$2:$K$50,10,false),0) -> 0 | H62: =IF(OR(F62=3,F62=4),9,IF(F62=5,13,0)) -> 0 | I62: =if(OR($F62=1, $F62=2),VLOOKUP($B62,Courts!$B$2:$J$50,5,false),0) -> 0 | J62: =if(OR($F62=1, $F62=2),VLOOKUP($B62,Courts!$B$2:$J$50,6,false),0) -> 0 | K62: =if(OR($F62=1, $F62=2),VLOOKUP($B62,Courts!$B$2:$J$50,7,false),0) -> 0 | L62: =H62+I62+J62+K62 -> 0 | M62: =if(OR($F62=1, $F62=2),VLOOKUP($B62,Courts!$B$2:$J$50,9,false),0) -> 0 | N62: =C62+L62 -> 254 | O62: =D62+M62 -> 8 | P62: X | Q62: X | R62: X | S62: =vlookup(B62,indirect("'" & AC$2 & "'!B5:W79"),18,false)++if(text(C$1,"mm/dd/yy")=$AC$2,0,if(H62>0,0,1)) -> 6 | T62: =if(H62=13,1,0)+vlookup(B62,indirect("'" & AC$2 & "'!B5:W79"),19,false) -> 1 | V62: =vlookup(B62,indirect("'" & AC$2 & "'!B5:W79"),21,false)+if(text(C$1,"mm/dd/yy")=$AC$2,0,if(H62=9,1,0)) -> 18 | W62: =vlookup(B62,indirect("'" & AC$2 & "'!B5:x79"),23,false)-X62 -> -1 | X62: =X61+1 -> 58 | Y62: =if(S62=D$2,"Y","N") -> N | Z62: =if($D$2=sum(S62:V62),"","Error")
A63: =A62+1 -> 59 | B63: Ranjith Doraiswamy | C63: 251 | D63: 13 | E63: =if(S63>0,(C63-(V63*9)-(T63*13))/S63,0) -> 10.857143 | F63: =if(isna(VLOOKUP(B63,Checkin!A:B,2,false)),0,VLOOKUP(B63,Checkin!A:B,2,false)) -> 0 | G63: =if(OR($F63=1, $F63=2),VLOOKUP($B63,Courts!$B$2:$K$50,10,false),0) -> 0 | H63: =IF(OR(F63=3,F63=4),9,IF(F63=5,13,0)) -> 0 | I63: =if(OR($F63=1, $F63=2),VLOOKUP($B63,Courts!$B$2:$J$50,5,false),0) -> 0 | J63: =if(OR($F63=1, $F63=2),VLOOKUP($B63,Courts!$B$2:$J$50,6,false),0) -> 0 | K63: =if(OR($F63=1, $F63=2),VLOOKUP($B63,Courts!$B$2:$J$50,7,false),0) -> 0 | L63: =H63+I63+J63+K63 -> 0 | M63: =if(OR($F63=1, $F63=2),VLOOKUP($B63,Courts!$B$2:$J$50,9,false),0) -> 0 | N63: =C63+L63 -> 251 | O63: =D63+M63 -> 13 | P63: X | Q63: X | R63: X | S63: =vlookup(B63,indirect("'" & AC$2 & "'!B5:W79"),18,false)++if(text(C$1,"mm/dd/yy")=$AC$2,0,if(H63>0,0,1)) -> 14 | T63: =if(H63=13,1,0)+vlookup(B63,indirect("'" & AC$2 & "'!B5:W79"),19,false) -> 0 | V63: =vlookup(B63,indirect("'" & AC$2 & "'!B5:W79"),21,false)+if(text(C$1,"mm/dd/yy")=$AC$2,0,if(H63=9,1,0)) -> 11 | W63: =vlookup(B63,indirect("'" & AC$2 & "'!B5:x79"),23,false)-X63 -> 4 | X63: =X62+1 -> 59 | Y63: =if(S63=D$2,"Y","N") -> N | Z63: =if($D$2=sum(S63:V63),"","Error")
A64: =A63+1 -> 60 | B64: Vicki Martinet | C64: 250 | D64: 10 | E64: =if(S64>0,(C64-(V64*9)-(T64*13))/S64,0) -> 13.166667 | F64: =if(isna(VLOOKUP(B64,Checkin!A:B,2,false)),0,VLOOKUP(B64,Checkin!A:B,2,false)) -> 0 | G64: =if(OR($F64=1, $F64=2),VLOOKUP($B64,Courts!$B$2:$K$50,10,false),0) -> 0 | H64: =IF(OR(F64=3,F64=4),9,IF(F64=5,13,0)) -> 0 | I64: =if(OR($F64=1, $F64=2),VLOOKUP($B64,Courts!$B$2:$J$50,5,false),0) -> 0 | J64: =if(OR($F64=1, $F64=2),VLOOKUP($B64,Courts!$B$2:$J$50,6,false),0) -> 0 | K64: =if(OR($F64=1, $F64=2),VLOOKUP($B64,Courts!$B$2:$J$50,7,false),0) -> 0 | L64: =H64+I64+J64+K64 -> 0 | M64: =if(OR($F64=1, $F64=2),VLOOKUP($B64,Courts!$B$2:$J$50,9,false),0) -> 0 | N64: =C64+L64 -> 250 | O64: =D64+M64 -> 10 | P64: X | Q64: X | R64: X | S64: =vlookup(B64,indirect("'" & AC$2 & "'!B5:W79"),18,false)++if(text(C$1,"mm/dd/yy")=$AC$2,0,if(H64>0,0,1)) -> 6 | T64: =if(H64=13,1,0)+vlookup(B64,indirect("'" & AC$2 & "'!B5:W79"),19,false) -> 0 | V64: =vlookup(B64,indirect("'" & AC$2 & "'!B5:W79"),21,false)+if(text(C$1,"mm/dd/yy")=$AC$2,0,if(H64=9,1,0)) -> 19 | W64: =vlookup(B64,indirect("'" & AC$2 & "'!B5:x79"),23,false)-X64 -> -1 | X64: =X63+1 -> 60 | Y64: =if(S64=D$2,"Y","N") -> N | Z64: =if($D$2=sum(S64:V64),"","Error")
A65: =A64+1 -> 61 | B65: Jonathan Phan | C65: 245 | D65: 6 | E65: =if(S65>0,(C65-(V65*9)-(T65*13))/S65,0) -> 14.333333 | F65: =if(isna(VLOOKUP(B65,Checkin!A:B,2,false)),0,VLOOKUP(B65,Checkin!A:B,2,false)) -> 0 | G65: =if(OR($F65=1, $F65=2),VLOOKUP($B65,Courts!$B$2:$K$50,10,false),0) -> 0 | H65: =IF(OR(F65=3,F65=4),9,IF(F65=5,13,0)) -> 0 | I65: =if(OR($F65=1, $F65=2),VLOOKUP($B65,Courts!$B$2:$J$50,5,false),0) -> 0 | J65: =if(OR($F65=1, $F65=2),VLOOKUP($B65,Courts!$B$2:$J$50,6,false),0) -> 0 | K65: =if(OR($F65=1, $F65=2),VLOOKUP($B65,Courts!$B$2:$J$50,7,false),0) -> 0 | L65: =H65+I65+J65+K65 -> 0 | M65: =if(OR($F65=1, $F65=2),VLOOKUP($B65,Courts!$B$2:$J$50,9,false),0) -> 0 | N65: =C65+L65 -> 245 | O65: =D65+M65 -> 6 | P65: X | Q65: X | R65: X | S65: =vlookup(B65,indirect("'" & AC$2 & "'!B5:W79"),18,false)++if(text(C$1,"mm/dd/yy")=$AC$2,0,if(H65>0,0,1)) -> 3 | T65: =if(H65=13,1,0)+vlookup(B65,indirect("'" & AC$2 & "'!B5:W79"),19,false) -> 1 | V65: =vlookup(B65,indirect("'" & AC$2 & "'!B5:W79"),21,false)+if(text(C$1,"mm/dd/yy")=$AC$2,0,if(H65=9,1,0)) -> 21 | W65: =vlookup(B65,indirect("'" & AC$2 & "'!B5:x79"),23,false)-X65 -> -1 | X65: =X64+1 -> 61 | Y65: =if(S65=D$2,"Y","N") -> N | Z65: =if($D$2=sum(S65:V65),"","Error")
A66: =A65+1 -> 62 | B66: Joyce Zhu | C66: 245 | D66: 6 | E66: =if(S66>0,(C66-(V66*9)-(T66*13))/S66,0) -> 11.222222 | F66: =if(isna(VLOOKUP(B66,Checkin!A:B,2,false)),0,VLOOKUP(B66,Checkin!A:B,2,false)) -> 0 | G66: =if(OR($F66=1, $F66=2),VLOOKUP($B66,Courts!$B$2:$K$50,10,false),0) -> 0 | H66: =IF(OR(F66=3,F66=4),9,IF(F66=5,13,0)) -> 0 | I66: =if(OR($F66=1, $F66=2),VLOOKUP($B66,Courts!$B$2:$J$50,5,false),0) -> 0 | J66: =if(OR($F66=1, $F66=2),VLOOKUP($B66,Courts!$B$2:$J$50,6,false),0) -> 0 | K66: =if(OR($F66=1, $F66=2),VLOOKUP($B66,Courts!$B$2:$J$50,7,false),0) -> 0 | L66: =H66+I66+J66+K66 -> 0 | M66: =if(OR($F66=1, $F66=2),VLOOKUP($B66,Courts!$B$2:$J$50,9,false),0) -> 0 | N66: =C66+L66 -> 245 | O66: =D66+M66 -> 6 | P66: X | Q66: X | R66: X | S66: =vlookup(B66,indirect("'" & AC$2 & "'!B5:W79"),18,false)++if(text(C$1,"mm/dd/yy")=$AC$2,0,if(H66>0,0,1)) -> 9 | T66: =if(H66=13,1,0)+vlookup(B66,indirect("'" & AC$2 & "'!B5:W79"),19,false) -> 0 | V66: =vlookup(B66,indirect("'" & AC$2 & "'!B5:W79"),21,false)+if(text(C$1,"mm/dd/yy")=$AC$2,0,if(H66=9,1,0)) -> 16 | W66: =vlookup(B66,indirect("'" & AC$2 & "'!B5:x79"),23,false)-X66 -> -1 | X66: =X65+1 -> 62 | Y66: =if(S66=D$2,"Y","N") -> N | Z66: =if($D$2=sum(S66:V66),"","Error")
A67: =A66+1 -> 63 | B67: Santosh Sundaresan | C67: 244 | D67: 4 | E67: =if(S67>0,(C67-(V67*9)-(T67*13))/S67,0) -> 14.5 | F67: =if(isna(VLOOKUP(B67,Checkin!A:B,2,false)),0,VLOOKUP(B67,Checkin!A:B,2,false)) -> 0 | G67: =if(OR($F67=1, $F67=2),VLOOKUP($B67,Courts!$B$2:$K$50,10,false),0) -> 0 | H67: =IF(OR(F67=3,F67=4),9,IF(F67=5,13,0)) -> 0 | I67: =if(OR($F67=1, $F67=2),VLOOKUP($B67,Courts!$B$2:$J$50,5,false),0) -> 0 | J67: =if(OR($F67=1, $F67=2),VLOOKUP($B67,Courts!$B$2:$J$50,6,false),0) -> 0 | K67: =if(OR($F67=1, $F67=2),VLOOKUP($B67,Courts!$B$2:$J$50,7,false),0) -> 0 | L67: =H67+I67+J67+K67 -> 0 | M67: =if(OR($F67=1, $F67=2),VLOOKUP($B67,Courts!$B$2:$J$50,9,false),0) -> 0 | N67: =C67+L67 -> 244 | O67: =D67+M67 -> 4 | P67: X | Q67: X | R67: X | S67: =vlookup(B67,indirect("'" & AC$2 & "'!B5:W79"),18,false)++if(text(C$1,"mm/dd/yy")=$AC$2,0,if(H67>0,0,1)) -> 2 | T67: =if(H67=13,1,0)+vlookup(B67,indirect("'" & AC$2 & "'!B5:W79"),19,false) -> 2 | V67: =vlookup(B67,indirect("'" & AC$2 & "'!B5:W79"),21,false)+if(text(C$1,"mm/dd/yy")=$AC$2,0,if(H67=9,1,0)) -> 21 | W67: =vlookup(B67,indirect("'" & AC$2 & "'!B5:x79"),23,false)-X67 -> 3 | X67: =X66+1 -> 63 | Y67: =if(S67=D$2,"Y","N") -> N | Z67: =if($D$2=sum(S67:V67),"","Error")
A68: =A67+1 -> 64 | B68: Saravanan Veerapandian | C68: 243 | D68: 8 | E68: =if(S68>0,(C68-(V68*9)-(T68*13))/S68,0) -> 11.25 | F68: =if(isna(VLOOKUP(B68,Checkin!A:B,2,false)),0,VLOOKUP(B68,Checkin!A:B,2,false)) -> 0 | G68: =if(OR($F68=1, $F68=2),VLOOKUP($B68,Courts!$B$2:$K$50,10,false),0) -> 0 | H68: =IF(OR(F68=3,F68=4),9,IF(F68=5,13,0)) -> 0 | I68: =if(OR($F68=1, $F68=2),VLOOKUP($B68,Courts!$B$2:$J$50,5,false),0) -> 0 | J68: =if(OR($F68=1, $F68=2),VLOOKUP($B68,Courts!$B$2:$J$50,6,false),0) -> 0 | K68: =if(OR($F68=1, $F68=2),VLOOKUP($B68,Courts!$B$2:$J$50,7,false),0) -> 0 | L68: =H68+I68+J68+K68 -> 0 | M68: =if(OR($F68=1, $F68=2),VLOOKUP($B68,Courts!$B$2:$J$50,9,false),0) -> 0 | N68: =C68+L68 -> 243 | O68: =D68+M68 -> 8 | P68: X | Q68: X | R68: X | S68: =vlookup(B68,indirect("'" & AC$2 & "'!B5:W79"),18,false)++if(text(C$1,"mm/dd/yy")=$AC$2,0,if(H68>0,0,1)) -> 8 | T68: =if(H68=13,1,0)+vlookup(B68,indirect("'" & AC$2 & "'!B5:W79"),19,false) -> 0 | V68: =vlookup(B68,indirect("'" & AC$2 & "'!B5:W79"),21,false)+if(text(C$1,"mm/dd/yy")=$AC$2,0,if(H68=9,1,0)) -> 17 | W68: =vlookup(B68,indirect("'" & AC$2 & "'!B5:x79"),23,false)-X68 -> 3 | X68: =X67+1 -> 64 | Y68: =if(S68=D$2,"Y","N") -> N | Z68: =if($D$2=sum(S68:V68),"","Error")
A69: =A68+1 -> 65 | B69: Sandy Weyant | C69: 242 | D69: 12 | E69: =if(S69>0,(C69-(V69*9)-(T69*13))/S69,0) -> 10.888889 | F69: =if(isna(VLOOKUP(B69,Checkin!A:B,2,false)),0,VLOOKUP(B69,Checkin!A:B,2,false)) -> 0 | G69: =if(OR($F69=1, $F69=2),VLOOKUP($B69,Courts!$B$2:$K$50,10,false),0) -> 0 | H69: =IF(OR(F69=3,F69=4),9,IF(F69=5,13,0)) -> 0 | I69: =if(OR($F69=1, $F69=2),VLOOKUP($B69,Courts!$B$2:$J$50,5,false),0) -> 0 | J69: =if(OR($F69=1, $F69=2),VLOOKUP($B69,Courts!$B$2:$J$50,6,false),0) -> 0 | K69: =if(OR($F69=1, $F69=2),VLOOKUP($B69,Courts!$B$2:$J$50,7,false),0) -> 0 | L69: =H69+I69+J69+K69 -> 0 | M69: =if(OR($F69=1, $F69=2),VLOOKUP($B69,Courts!$B$2:$J$50,9,false),0) -> 0 | N69: =C69+L69 -> 242 | O69: =D69+M69 -> 12 | P69: X | Q69: X | R69: N | S69: =vlookup(B69,indirect("'" & AC$2 & "'!B5:W79"),18,false)++if(text(C$1,"mm/dd/yy")=$AC$2,0,if(H69>0,0,1)) -> 9 | T69: =if(H69=13,1,0)+vlookup(B69,indirect("'" & AC$2 & "'!B5:W79"),19,false) -> 0 | V69: =vlookup(B69,indirect("'" & AC$2 & "'!B5:W79"),21,false)+if(text(C$1,"mm/dd/yy")=$AC$2,0,if(H69=9,1,0)) -> 16 | W69: =vlookup(B69,indirect("'" & AC$2 & "'!B5:x79"),23,false)-X69 -> -3 | X69: =X68+1 -> 65 | Y69: =if(S69=D$2,"Y","N") -> N | Z69: =if($D$2=sum(S69:V69),"","Error")
... A74: =A73+1 -> 70 | B74: Balaji Alahari | C74: 235 | D74: 2 | E74: =if(S74>0,(C74-(V74*9)-(T74*13))/S74,0) -> 15 | F74: =if(isna(VLOOKUP(B74,Checkin!A:B,2,false)),0,VLOOKUP(B74,Checkin!A:B,2,false)) -> 0 | G74: =if(OR($F74=1, $F74=2),VLOOKUP($B74,Courts!$B$2:$K$50,10,false),0) -> 0 | H74: =IF(OR(F74=3,F74=4),9,IF(F74=5,13,0)) -> 0 | I74: =if(OR($F74=1, $F74=2),VLOOKUP($B74,Courts!$B$2:$J$50,5,false),0) -> 0 | J74: =if(OR($F74=1, $F74=2),VLOOKUP($B74,Courts!$B$2:$J$50,6,false),0) -> 0 | K74: =if(OR($F74=1, $F74=2),VLOOKUP($B74,Courts!$B$2:$J$50,7,false),0) -> 0 | L74: =H74+I74+J74+K74 -> 0 | M74: =if(OR($F74=1, $F74=2),VLOOKUP($B74,Courts!$B$2:$J$50,9,false),0) -> 0 | N74: =C74+L74 -> 235 | O74: =D74+M74 -> 2 | P74: X | Q74: X | R74: N | S74: =vlookup(B74,indirect("'" & AC$2 & "'!B5:W79"),18,false)++if(text(C$1,"mm/dd/yy")=$AC$2,0,if(H74>0,0,1)) -> 1 | T74: =if(H74=13,1,0)+vlookup(B74,indirect("'" & AC$2 & "'!B5:W79"),19,false) -> 1 | V74: =vlookup(B74,indirect("'" & AC$2 & "'!B5:W79"),21,false)+if(text(C$1,"mm/dd/yy")=$AC$2,0,if(H74=9,1,0)) -> 23 | W74: =vlookup(B74,indirect("'" & AC$2 & "'!B5:x79"),23,false)-X74 -> 0 | X74: =X73+1 -> 70 | Y74: =if(S74=D$2,"Y","N") -> N | Z74: =if($D$2=sum(S74:V74),"","Error")
A75: =A74+1 -> 71 | B75: Robert Chang | C75: 231 | D75: 1 | E75: =if(S75>0,(C75-(V75*9)-(T75*13))/S75,0) -> 15 | F75: =if(isna(VLOOKUP(B75,Checkin!A:B,2,false)),0,VLOOKUP(B75,Checkin!A:B,2,false)) -> 0 | G75: =if(OR($F75=1, $F75=2),VLOOKUP($B75,Courts!$B$2:$K$50,10,false),0) -> 0 | H75: =IF(OR(F75=3,F75=4),9,IF(F75=5,13,0)) -> 0 | I75: =if(OR($F75=1, $F75=2),VLOOKUP($B75,Courts!$B$2:$J$50,5,false),0) -> 0 | J75: =if(OR($F75=1, $F75=2),VLOOKUP($B75,Courts!$B$2:$J$50,6,false),0) -> 0 | K75: =if(OR($F75=1, $F75=2),VLOOKUP($B75,Courts!$B$2:$J$50,7,false),0) -> 0 | L75: =H75+I75+J75+K75 -> 0 | M75: =if(OR($F75=1, $F75=2),VLOOKUP($B75,Courts!$B$2:$J$50,9,false),0) -> 0 | N75: =C75+L75 -> 231 | O75: =D75+M75 -> 1 | P75: X | Q75: X | S75: =vlookup(B75,indirect("'" & AC$2 & "'!B5:W79"),18,false)++if(text(C$1,"mm/dd/yy")=$AC$2,0,if(H75>0,0,1)) -> 1 | T75: =if(H75=13,1,0)+vlookup(B75,indirect("'" & AC$2 & "'!B5:W79"),19,false) -> 0 | V75: =vlookup(B75,indirect("'" & AC$2 & "'!B5:W79"),21,false)+if(text(C$1,"mm/dd/yy")=$AC$2,0,if(H75=9,1,0)) -> 24 | W75: =vlookup(B75,indirect("'" & AC$2 & "'!B5:x79"),23,false)-X75 -> 0 | X75: =X74+1 -> 71 | Y75: =if(S75=D$2,"Y","N") -> N | Z75: =if($D$2=sum(S75:V75),"","Error")
A76: =A75+1 -> 72 | B76: Rajesh Dorairaj | C76: 230 | D76: 1 | E76: =if(S76>0,(C76-(V76*9)-(T76*13))/S76,0) -> 14 | F76: =if(isna(VLOOKUP(B76,Checkin!A:B,2,false)),0,VLOOKUP(B76,Checkin!A:B,2,false)) -> 0 | G76: =if(OR($F76=1, $F76=2),VLOOKUP($B76,Courts!$B$2:$K$50,10,false),0) -> 0 | H76: =IF(OR(F76=3,F76=4),9,IF(F76=5,13,0)) -> 0 | I76: =if(OR($F76=1, $F76=2),VLOOKUP($B76,Courts!$B$2:$J$50,5,false),0) -> 0 | J76: =if(OR($F76=1, $F76=2),VLOOKUP($B76,Courts!$B$2:$J$50,6,false),0) -> 0 | K76: =if(OR($F76=1, $F76=2),VLOOKUP($B76,Courts!$B$2:$J$50,7,false),0) -> 0 | L76: =H76+I76+J76+K76 -> 0 | M76: =if(OR($F76=1, $F76=2),VLOOKUP($B76,Courts!$B$2:$J$50,9,false),0) -> 0 | N76: =C76+L76 -> 230 | O76: =D76+M76 -> 1 | P76: X | Q76: X | R76: X | S76: =vlookup(B76,indirect("'" & AC$2 & "'!B5:W79"),18,false)++if(text(C$1,"mm/dd/yy")=$AC$2,0,if(H76>0,0,1)) -> 1 | T76: =if(H76=13,1,0)+vlookup(B76,indirect("'" & AC$2 & "'!B5:W79"),19,false) -> 0 | V76: =vlookup(B76,indirect("'" & AC$2 & "'!B5:W79"),21,false)+if(text(C$1,"mm/dd/yy")=$AC$2,0,if(H76=9,1,0)) -> 24 | W76: =vlookup(B76,indirect("'" & AC$2 & "'!B5:x79"),23,false)-X76 -> 0 | X76: =X75+1 -> 72 | Y76: =if(S76=D$2,"Y","N") -> N | Z76: =if($D$2=sum(S76:V76),"","Error")
A77: =A76+1 -> 73 | B77: Hubert J Sung | C77: 227 | D77: 1 | E77: =if(S77>0,(C77-(V77*9)-(T77*13))/S77,0) -> 11 | F77: =if(isna(VLOOKUP(B77,Checkin!A:B,2,false)),0,VLOOKUP(B77,Checkin!A:B,2,false)) -> 0 | G77: =if(OR($F77=1, $F77=2),VLOOKUP($B77,Courts!$B$2:$K$50,10,false),0) -> 0 | H77: =IF(OR(F77=3,F77=4),9,IF(F77=5,13,0)) -> 0 | I77: =if(OR($F77=1, $F77=2),VLOOKUP($B77,Courts!$B$2:$J$50,5,false),0) -> 0 | J77: =if(OR($F77=1, $F77=2),VLOOKUP($B77,Courts!$B$2:$J$50,6,false),0) -> 0 | K77: =if(OR($F77=1, $F77=2),VLOOKUP($B77,Courts!$B$2:$J$50,7,false),0) -> 0 | L77: =H77+I77+J77+K77 -> 0 | M77: =if(OR($F77=1, $F77=2),VLOOKUP($B77,Courts!$B$2:$J$50,9,false),0) -> 0 | N77: =C77+L77 -> 227 | O77: =D77+M77 -> 1 | P77: X | Q77: X | R77: N | S77: =vlookup(B77,indirect("'" & AC$2 & "'!B5:W79"),18,false)++if(text(C$1,"mm/dd/yy")=$AC$2,0,if(H77>0,0,1)) -> 1 | T77: =if(H77=13,1,0)+vlookup(B77,indirect("'" & AC$2 & "'!B5:W79"),19,false) -> 0 | V77: =vlookup(B77,indirect("'" & AC$2 & "'!B5:W79"),21,false)+if(text(C$1,"mm/dd/yy")=$AC$2,0,if(H77=9,1,0)) -> 24 | W77: =vlookup(B77,indirect("'" & AC$2 & "'!B5:x79"),23,false)-X77 -> 0 | X77: =X76+1 -> 73 | Y77: =if(S77=D$2,"Y","N") -> N | Z77: =if($D$2=sum(S77:V77),"","Error")
A78: =A77+1 -> 74 | B78: Barathi Sundaram | C78: 225 | D78: 0 | E78: =if(S78>0,(C78-(V78*9)-(T78*13))/S78,0) -> 9 | F78: =if(isna(VLOOKUP(B78,Checkin!A:B,2,false)),0,VLOOKUP(B78,Checkin!A:B,2,false)) -> 0 | G78: =if(OR($F78=1, $F78=2),VLOOKUP($B78,Courts!$B$2:$K$50,10,false),0) -> 0 | H78: =IF(OR(F78=3,F78=4),9,IF(F78=5,13,0)) -> 0 | I78: =if(OR($F78=1, $F78=2),VLOOKUP($B78,Courts!$B$2:$J$50,5,false),0) -> 0 | J78: =if(OR($F78=1, $F78=2),VLOOKUP($B78,Courts!$B$2:$J$50,6,false),0) -> 0 | K78: =if(OR($F78=1, $F78=2),VLOOKUP($B78,Courts!$B$2:$J$50,7,false),0) -> 0 | L78: =H78+I78+J78+K78 -> 0 | M78: =if(OR($F78=1, $F78=2),VLOOKUP($B78,Courts!$B$2:$J$50,9,false),0) -> 0 | N78: =C78+L78 -> 225 | O78: =D78+M78 -> 0 | P78: X | Q78: X | R78: N | S78: =vlookup(B78,indirect("'" & AC$2 & "'!B5:W79"),18,false)++if(text(C$1,"mm/dd/yy")=$AC$2,0,if(H78>0,0,1)) -> 1 | T78: =if(H78=13,1,0)+vlookup(B78,indirect("'" & AC$2 & "'!B5:W79"),19,false) -> 0 | V78: =vlookup(B78,indirect("'" & AC$2 & "'!B5:W79"),21,false)+if(text(C$1,"mm/dd/yy")=$AC$2,0,if(H78=9,1,0)) -> 24 | W78: =vlookup(B78,indirect("'" & AC$2 & "'!B5:x79"),23,false)-X78 -> 0 | X78: =X77+1 -> 74 | Y78: =if(S78=D$2,"Y","N") -> N | Z78: =if($D$2=sum(S78:V78),"","Error")
A79: =A78+1 -> 75 | B79: Leigh-Anh Nguyen | C79: 225 | D79: 0 | E79: =if(S79>0,(C79-(V79*9)-(T79*13))/S79,0) -> 0 | F79: =if(isna(VLOOKUP(B79,Checkin!A:B,2,false)),0,VLOOKUP(B79,Checkin!A:B,2,false)) -> 0 | G79: =if(OR($F79=1, $F79=2),VLOOKUP($B79,Courts!$B$2:$K$50,10,false),0) -> 0 | H79: =IF(OR(F79=3,F79=4),9,IF(F79=5,13,0)) -> 0 | I79: =if(OR($F79=1, $F79=2),VLOOKUP($B79,Courts!$B$2:$J$50,5,false),0) -> 0 | J79: =if(OR($F79=1, $F79=2),VLOOKUP($B79,Courts!$B$2:$J$50,6,false),0) -> 0 | K79: =if(OR($F79=1, $F79=2),VLOOKUP($B79,Courts!$B$2:$J$50,7,false),0) -> 0 | L79: =H79+I79+J79+K79 -> 0 | M79: =if(OR($F79=1, $F79=2),VLOOKUP($B79,Courts!$B$2:$J$50,9,false),0) -> 0 | N79: =C79+L79 -> 225 | O79: =D79+M79 -> 0 | P79: X | Q79: X | R79: N | S79: =vlookup(B79,indirect("'" & AC$2 & "'!B5:W79"),18,false)++if(text(C$1,"mm/dd/yy")=$AC$2,0,if(H79>0,0,1)) -> 0 | T79: =if(H79=13,1,0)+vlookup(B79,indirect("'" & AC$2 & "'!B5:W79"),19,false) -> 0 | V79: =vlookup(B79,indirect("'" & AC$2 & "'!B5:W79"),21,false)+if(text(C$1,"mm/dd/yy")=$AC$2,0,if(H79=9,1,0)) -> 25 | W79: =vlookup(B79,indirect("'" & AC$2 & "'!B5:x79"),23,false)-X79 -> 0 | X79: =X78+1 -> 75 | Y79: =if(S79=D$2,"Y","N") -> N | Z79: =if($D$2=sum(S79:V79),"","Error")
P83: Membership Renewals
P84: Renewed | R84: =countif(R5:R79,"X") -> 65 | S84: =R84/R87 -> 0.86666667
B85: For Publishing in the WhatsApp Group for the score updates on saturday | P85: Not Renewing | R85: =countif(R5:R79,"N") -> 8
...

Sheet Courts
A1: Court # | B1: Name of the Player | C1: Games Won | D1: Sets Won | E1: Check In | F1: Set 1 | G1: Set 2 | H1: Set 3 | I1: Total Games won | J1: Sets Won | K1: Court # | L1: Scores Entered by | M1: WHS | N1: Count of Player at WHS | O1: Suggestion for WHS | P1: Admin | Q1: No WHS | S1: Set 1 | T1: Set 2 | U1: Set 3 | V1: Sets Won | AA1: Court # | AQ1: court # | AR1: Admin | AS1: Players
A2: 1 | B2: =IFERROR(__xludf.DUMMYFUNCTION("QUERY(indirect(""'"" & ""Current"" & ""'!B5:F79""),""Select B, C, D, F where F = 1 or F = 2 "",0)"),"#N/A") -> #N/A | I2: =sum(F2:H2) -> 0 | J2: =if(sum(F2:F5)=0,0,if(max(F2:F5)=F2,1,0)+if(max(G2:G5)=G2,1,0)+if(max(H2:H5)=H2,1,0)) -> 0 | K2: =A2 -> 1 | O2: =sum(N2:N5) -> 0 | P2: =countif(Z$73:Z$79,B2) -> 0 | Q2: =sum(P2:P5) -> 0 | S2: =if(sum(F2:F5)=0,"",if(or(max(F2:F5)=6, max(F2:F5)=7),"G","E")) | T2: =if(sum(G2:G5)=0,"",if(or(max(G2:G5)=6, max(G2:G5)=7),"G","E")) | U2: =if(sum(H2:H5)=0,"",if(or(max(H2:H5)=6, max(H2:H5)=7),"G","E")) | V2: =if(sum(F2:F5)=0,0,if(max(F2:F5)=F2,1,0)+if(max(G2:G5)=G2,1,0)+if(max(H2:H5)=H2,1,0)) -> 0 | W2: Max=6/7 | AA2: =if(M2<>"","W" & vlookup(B2,B$122:E$133,4,false),"D" & vlookup(B2,B44:E75,4,false)) -> #N/A | AQ2: =K2 -> 1 | AR2: =P2 -> 0 | AS2: =counta(B2) -> 1
A3: 1 | I3: =sum(F3:H3) -> 0 | J3: =if(sum(F2:F5)=0,0,if(max(F2:F5)=F3,1,0)+if(max(G2:G5)=G3,1,0)+if(max(H2:H5)=H3,1,0)) -> 0 | K3: =A3 -> 1 | P3: =countif(Z$73:Z$79,B3) -> 0 | S3: =if(sum(F2:F5)=0,"",if(SUMPRODUCT(1/COUNTIF(F2:F5, F2:F5))=2,"G","E")) | T3: =if(sum(G2:G5)=0,"",if(SUMPRODUCT(1/COUNTIF(G2:G5, G2:G5))=2,"G","E")) | U3: =if(sum(H2:H5)=0,"",if(SUMPRODUCT(1/COUNTIF(H2:H5, H2:H5))=2,"G","E")) | V3: =if(sum(F2:F5)=0,0,if(max(F2:F5)=F3,1,0)+if(max(G2:G5)=G3,1,0)+if(max(H2:H5)=H3,1,0)) -> 0 | W3: two equal scores | AA3: =if(M3<>"","W" & vlookup(B3,B$122:E$133,4,false),"D" & vlookup(B3,B45:E76,4,false)) -> #N/A | AD3: Court # | AE3: Scores | AQ3: =K3 -> 1 | AR3: =P3 -> 0 | AS3: =counta(B3) -> 0
A4: 1 | I4: =sum(F4:H4) -> 0 | J4: =if(sum(F2:F5)=0,0,if(max(F2:F5)=F4,1,0)+if(max(G2:G5)=G4,1,0)+if(max(H2:H5)=H4,1,0)) -> 0 | K4: =A4 -> 1 | P4: =countif(Z$73:Z$79,B4) -> 0 | S4: =if(sum(F2:F5)=0,"",if(and(max(F2:F5)=7, min(F2:F5)=6),"G",if(max(F2:F5)-min(F2:F5)>=2,"G","E"))) | T4: =if(sum(G2:G5)=0,"",if(and(max(G2:G5)=7, min(G2:G5)=6),"G",if(max(G2:G5)-min(G2:G5)>=2,"G","E"))) | U4: =if(sum(H2:H5)=0,"",if(and(max(H2:H5)=7, min(H2:H5)=6),"G",if(max(H2:H5)-min(H2:H5)>=2,"G","E"))) | V4: =if(sum(F2:F5)=0,0,if(max(F2:F5)=F4,1,0)+if(max(G2:G5)=G4,1,0)+if(max(H2:H5)=H4,1,0)) -> 0 | W4: Diff of 2 or tie breaker | AA4: =if(M4<>"","W" & vlookup(B4,B$122:E$133,4,false),"D" & vlookup(B4,B46:E77,4,false)) -> #N/A | AD4: 1 | AE4: =IF(B2="", "X", IF(COUNTA(F2:H2)=0, "N", "Y")) -> #N/A | AQ4: =K4 -> 1 | AR4: =P4 -> 0 | AS4: =counta(B4) -> 0
A5: 1 | I5: =sum(F5:H5) -> 0 | J5: =if(sum(F2:F5)=0,0,if(max(F2:F5)=F5,1,0)+if(max(G2:G5)=G5,1,0)+if(max(H2:H5)=H5,1,0)) -> 0 | K5: =A5 -> 1 | P5: =countif(Z$73:Z$79,B5) -> 0 | S5: =IF(COUNTIF(S2:S4, "") = 3, "", IF(COUNTIF(S2:S4, "G") = 3, "G", "E")) | T5: =IF(COUNTIF(T2:T4, "") = 3, "", IF(COUNTIF(T2:T4, "G") = 3, "G", "E")) | U5: =IF(COUNTIF(U2:U4, "") = 3, "", IF(COUNTIF(U2:U4, "G") = 3, "G", "E")) | V5: =if(sum(F2:F5)=0,0,if(max(F2:F5)=F5,1,0)+if(max(G2:G5)=G5,1,0)+if(max(H2:H5)=H5,1,0)) -> 0 | W5: All Good | AA5: =if(M5<>"","W" & vlookup(B5,B$122:E$133,4,false),"D" & vlookup(B5,B47:E78,4,false)) -> #N/A | AD5: 2 | AE5: =IF(B6="", "X", IF(COUNTA(F6:H6)=0, "N", "Y")) -> X | AQ5: =K5 -> 1 | AR5: =P5 -> 0 | AS5: =counta(B5) -> 0
A6: 2 | I6: =sum(F6:H6) -> 0 | J6: =if(sum(F6:F9)=0,0,if(max(F6:F9)=F6,1,0)+if(max(G6:G9)=G6,1,0)+if(max(H6:H9)=H6,1,0)) -> 0 | K6: =A6 -> 2 | O6: =sum(N6:N9) -> 0 | P6: =countif(Z$73:Z$79,B6) -> 0 | Q6: =sum(P6:P9) -> 0 | S6: =if(sum(F6:F9)=0,"",if(or(max(F6:F9)=6, max(F6:F9)=7),"G","E")) | T6: =if(sum(G6:G9)=0,"",if(or(max(G6:G9)=6, max(G6:G9)=7),"G","E")) | U6: =if(sum(H6:H9)=0,"",if(or(max(H6:H9)=6, max(H6:H9)=7),"G","E")) | V6: =if(sum(F6:F9)=0,0,if(max(F6:F9)=F6,1,0)+if(max(G6:G9)=G6,1,0)+if(max(H6:H9)=H6,1,0)) -> 0 | W6: Max=6/7 | AA6: =if(M6<>"","W" & vlookup(B6,B$122:E$133,4,false),"D" & vlookup(B6,B48:E79,4,false)) -> #N/A | AD6: 3 | AE6: =IF(B10="", "X", IF(COUNTA(F10:H10)=0, "N", "Y")) -> X | AQ6: =K6 -> 2 | AR6: =P6 -> 0 | AS6: =counta(B6) -> 0
A7: 2 | I7: =sum(F7:H7) -> 0 | J7: =if(sum(F6:F9)=0,0,if(max(F6:F9)=F7,1,0)+if(max(G6:G9)=G7,1,0)+if(max(H6:H9)=H7,1,0)) -> 0 | K7: =A7 -> 2 | P7: =countif(Z$73:Z$79,B7) -> 0 | S7: =if(sum(F6:F9)=0,"",if(SUMPRODUCT(1/COUNTIF(F6:F9, F6:F9))=2,"G","E")) | T7: =if(sum(G6:G9)=0,"",if(SUMPRODUCT(1/COUNTIF(G6:G9, G6:G9))=2,"G","E")) | U7: =if(sum(H6:H9)=0,"",if(SUMPRODUCT(1/COUNTIF(H6:H9, H6:H9))=2,"G","E")) | V7: =if(sum(F6:F9)=0,0,if(max(F6:F9)=F7,1,0)+if(max(G6:G9)=G7,1,0)+if(max(H6:H9)=H7,1,0)) -> 0 | W7: two equal scores | AA7: =if(M7<>"","W" & vlookup(B7,B$122:E$133,4,false),"D" & vlookup(B7,B49:E80,4,false)) -> #N/A | AD7: 4 | AE7: =IF(B14="", "X", IF(COUNTA(F14:H14)=0, "N", "Y")) -> X | AQ7: =K7 -> 2 | AR7: =P7 -> 0 | AS7: =counta(B7) -> 0
A8: 2 | I8: =sum(F8:H8) -> 0 | J8: =if(sum(F6:F9)=0,0,if(max(F6:F9)=F8,1,0)+if(max(G6:G9)=G8,1,0)+if(max(H6:H9)=H8,1,0)) -> 0 | K8: =A8 -> 2 | P8: =countif(Z$73:Z$79,B8) -> 0 | S8: =if(sum(F6:F9)=0,"",if(and(max(F6:F9)=7, min(F6:F9)=6),"G",if(max(F6:F9)-min(F6:F9)>=2,"G","E"))) | T8: =if(sum(G6:G9)=0,"",if(and(max(G6:G9)=7, min(G6:G9)=6),"G",if(max(G6:G9)-min(G6:G9)>=2,"G","E"))) | U8: =if(sum(H6:H9)=0,"",if(and(max(H6:H9)=7, min(H6:H9)=6),"G",if(max(H6:H9)-min(H6:H9)>=2,"G","E"))) | V8: =if(sum(F6:F9)=0,0,if(max(F6:F9)=F8,1,0)+if(max(G6:G9)=G8,1,0)+if(max(H6:H9)=H8,1,0)) -> 0 | W8: Diff of 2 or tie breaker | AA8: =if(M8<>"","W" & vlookup(B8,B$122:E$133,4,false),"D" & vlookup(B8,B50:E81,4,false)) -> #N/A | AD8: 5 | AE8: =IF(B18="", "X", IF(COUNTA(F18:H18)=0, "N", "Y")) -> X | AQ8: =K8 -> 2 | AR8: =P8 -> 0 | AS8: =counta(B8) -> 0
A9: 2 | I9: =sum(F9:H9) -> 0 | J9: =if(sum(F6:F9)=0,0,if(max(F6:F9)=F9,1,0)+if(max(G6:G9)=G9,1,0)+if(max(H6:H9)=H9,1,0)) -> 0 | K9: =A9 -> 2 | P9: =countif(Z$73:Z$79,B9) -> 0 | S9: =IF(COUNTIF(S6:S8, "") = 3, "", IF(COUNTIF(S6:S8, "G") = 3, "G", "E")) | T9: =IF(COUNTIF(T6:T8, "") = 3, "", IF(COUNTIF(T6:T8, "G") = 3, "G", "E")) | U9: =IF(COUNTIF(U6:U8, "") = 3, "", IF(COUNTIF(U6:U8, "G") = 3, "G", "E")) | V9: =if(sum(F6:F9)=0,0,if(max(F6:F9)=F9,1,0)+if(max(G6:G9)=G9,1,0)+if(max(H6:H9)=H9,1,0)) -> 0 | AA9: =if(M9<>"","W" & vlookup(B9,B$122:E$133,4,false),"D" & vlookup(B9,B51:E82,4,false)) -> #N/A | AD9: 6 | AE9: =IF(B22="", "X", IF(COUNTA(F22:H22)=0, "N", "Y")) -> X | AQ9: =K9 -> 2 | AR9: =P9 -> 0 | AS9: =counta(B9) -> 0
A10: 3 | I10: =sum(F10:H10) -> 0 | J10: =if(sum(F10:F13)=0,0,if(max(F10:F13)=F10,1,0)+if(max(G10:G13)=G10,1,0)+if(max(H10:H13)=H10,1,0)) -> 0 | K10: =A10 -> 3 | O10: =sum(N10:N13) -> 0 | P10: =countif(Z$73:Z$79,B10) -> 0 | Q10: =sum(P10:P13) -> 0 | S10: =if(sum(F10:F13)=0,"",if(or(max(F10:F13)=6, max(F10:F13)=7),"G","E")) | T10: =if(sum(G10:G13)=0,"",if(or(max(G10:G13)=6, max(G10:G13)=7),"G","E")) | U10: =if(sum(H10:H13)=0,"",if(or(max(H10:H13)=6, max(H10:H13)=7),"G","E")) | V10: =if(sum(F10:F13)=0,0,if(max(F10:F13)=F10,1,0)+if(max(G10:G13)=G10,1,0)+if(max(H10:H13)=H10,1,0)) -> 0 | W10: Max=6/7 | AA10: =if(M10<>"","W" & vlookup(B10,B$122:E$133,4,false),"D" & vlookup(B10,B52:E83,4,false)) -> #N/A | AD10: 7 | AE10: =IF(B26="", "X", IF(COUNTA(F26:H26)=0, "N", "Y")) -> X | AQ10: =K10 -> 3 | AR10: =P10 -> 0 | AS10: =counta(B10) -> 0
A11: 3 | I11: =sum(F11:H11) -> 0 | J11: =if(sum(F10:F13)=0,0,if(max(F10:F13)=F11,1,0)+if(max(G10:G13)=G11,1,0)+if(max(H10:H13)=H11,1,0)) -> 0 | K11: =A11 -> 3 | P11: =countif(Z$73:Z$79,B11) -> 0 | S11: =if(sum(F10:F13)=0,"",if(SUMPRODUCT(1/COUNTIF(F10:F13, F10:F13))=2,"G","E")) | T11: =if(sum(G10:G13)=0,"",if(SUMPRODUCT(1/COUNTIF(G10:G13, G10:G13))=2,"G","E")) | U11: =if(sum(H10:H13)=0,"",if(SUMPRODUCT(1/COUNTIF(H10:H13, H10:H13))=2,"G","E")) | V11: =if(sum(F10:F13)=0,0,if(max(F10:F13)=F11,1,0)+if(max(G10:G13)=G11,1,0)+if(max(H10:H13)=H11,1,0)) -> 0 | W11: two equal scores | AA11: =if(M11<>"","W" & vlookup(B11,B$122:E$133,4,false),"D" & vlookup(B11,B53:E84,4,false)) -> #N/A | AD11: 8 | AE11: =IF(B30="", "X", IF(COUNTA(F30:H30)=0, "N", "Y")) -> X | AQ11: =K11 -> 3 | AR11: =P11 -> 0 | AS11: =counta(B11) -> 0
A12: 3 | I12: =sum(F12:H12) -> 0 | J12: =if(sum(F10:F13)=0,0,if(max(F10:F13)=F12,1,0)+if(max(G10:G13)=G12,1,0)+if(max(H10:H13)=H12,1,0)) -> 0 | K12: =A12 -> 3 | P12: =countif(Z$73:Z$79,B12) -> 0 | S12: =if(sum(F10:F13)=0,"",if(and(max(F10:F13)=7, min(F10:F13)=6),"G",if(max(F10:F13)-min(F10:F13)>=2,"G","E"))) | T12: =if(sum(G10:G13)=0,"",if(and(max(G10:G13)=7, min(G10:G13)=6),"G",if(max(G10:G13)-min(G10:G13)>=2,"G","E"))) | U12: =if(sum(H10:H13)=0,"",if(and(max(H10:H13)=7, min(H10:H13)=6),"G",if(max(H10:H13)-min(H10:H13)>=2,"G","E"))) | V12: =if(sum(F10:F13)=0,0,if(max(F10:F13)=F12,1,0)+if(max(G10:G13)=G12,1,0)+if(max(H10:H13)=H12,1,0)) -> 0 | W12: Diff of 2 or tie breaker | AA12: =if(M12<>"","W" & vlookup(B12,B$122:E$133,4,false),"D" & vlookup(B12,B54:E85,4,false)) -> #N/A | AQ12: =K12 -> 3 | AR12: =P12 -> 0 | AS12: =counta(B12) -> 0
A13: 3 | I13: =sum(F13:H13) -> 0 | J13: =if(sum(F10:F13)=0,0,if(max(F10:F13)=F13,1,0)+if(max(G10:G13)=G13,1,0)+if(max(H10:H13)=H13,1,0)) -> 0 | K13: =A13 -> 3 | P13: =countif(Z$73:Z$79,B13) -> 0 | S13: =IF(COUNTIF(S10:S12, "") = 3, "", IF(COUNTIF(S10:S12, "G") = 3, "G", "E")) | T13: =IF(COUNTIF(T10:T12, "") = 3, "", IF(COUNTIF(T10:T12, "G") = 3, "G", "E")) | U13: =IF(COUNTIF(U10:U12, "") = 3, "", IF(COUNTIF(U10:U12, "G") = 3, "G", "E")) | V13: =if(sum(F10:F13)=0,0,if(max(F10:F13)=F13,1,0)+if(max(G10:G13)=G13,1,0)+if(max(H10:H13)=H13,1,0)) -> 0 | AA13: =if(M13<>"","W" & vlookup(B13,B$122:E$133,4,false),"D" & vlookup(B13,B55:E86,4,false)) -> #N/A | AD13: Pending Scores | AE13: Status | AQ13: =K13 -> 3 | AR13: =P13 -> 0 | AS13: =counta(B13) -> 0
A14: 4 | I14: =sum(F14:H14) -> 0 | J14: =if(sum(F14:F17)=0,0,if(max(F14:F17)=F14,1,0)+if(max(G14:G17)=G14,1,0)+if(max(H14:H17)=H14,1,0)) -> 0 | K14: =A14 -> 4 | O14: =sum(N14:N17) -> 0 | P14: =countif(Z$73:Z$79,B14) -> 0 | Q14: =sum(P14:P17) -> 0 | S14: =if(sum(F14:F17)=0,"",if(or(max(F14:F17)=6, max(F14:F17)=7),"G","E")) | T14: =if(sum(G14:G17)=0,"",if(or(max(G14:G17)=6, max(G14:G17)=7),"G","E")) | U14: =if(sum(H14:H17)=0,"",if(or(max(H14:H17)=6, max(H14:H17)=7),"G","E")) | V14: =if(sum(F14:F17)=0,0,if(max(F14:F17)=F14,1,0)+if(max(G14:G17)=G14,1,0)+if(max(H14:H17)=H14,1,0)) -> 0 | W14: Max=6/7 | AA14: =if(M14<>"","W" & vlookup(B14,B$122:E$133,4,false),"D" & vlookup(B14,B56:E87,4,false)) -> #N/A | AQ14: =K14 -> 4 | AR14: =P14 -> 0 | AS14: =counta(B14) -> 0
A15: 4 | I15: =sum(F15:H15) -> 0 | J15: =if(sum(F14:F17)=0,0,if(max(F14:F17)=F15,1,0)+if(max(G14:G17)=G15,1,0)+if(max(H14:H17)=H15,1,0)) -> 0 | K15: =A15 -> 4 | P15: =countif(Z$73:Z$79,B15) -> 0 | S15: =if(sum(F14:F17)=0,"",if(SUMPRODUCT(1/COUNTIF(F14:F17, F14:F17))=2,"G","E")) | T15: =if(sum(G14:G17)=0,"",if(SUMPRODUCT(1/COUNTIF(G14:G17, G14:G17))=2,"G","E")) | U15: =if(sum(H14:H17)=0,"",if(SUMPRODUCT(1/COUNTIF(H14:H17, H14:H17))=2,"G","E")) | V15: =if(sum(F14:F17)=0,0,if(max(F14:F17)=F15,1,0)+if(max(G14:G17)=G15,1,0)+if(max(H14:H17)=H15,1,0)) -> 0 | W15: two equal scores | AA15: =if(M15<>"","W" & vlookup(B15,B$122:E$133,4,false),"D" & vlookup(B15,B57:E88,4,false)) -> #N/A | AD15: =IFERROR(__xludf.DUMMYFUNCTION("IFERROR(QUERY(AD4:AE11, ""SELECT AD WHERE AE = 'N'"", 0), """")"),"") | AE15: =IF(AND(COUNTIF(AE4:AE11, "N")=0, COUNTIF(AE4:AE11, "Y")>0), "Y", "N") -> N | AQ15: =K15 -> 4 | AR15: =P15 -> 0 | AS15: =counta(B15) -> 0
A16: 4 | I16: =sum(F16:H16) -> 0 | J16: =if(sum(F14:F17)=0,0,if(max(F14:F17)=F16,1,0)+if(max(G14:G17)=G16,1,0)+if(max(H14:H17)=H16,1,0)) -> 0 | K16: =A16 -> 4 | P16: =countif(Z$73:Z$79,B16) -> 0 | S16: =if(sum(F14:F17)=0,"",if(and(max(F14:F17)=7, min(F14:F17)=6),"G",if(max(F14:F17)-min(F14:F17)>=2,"G","E"))) | T16: =if(sum(G14:G17)=0,"",if(and(max(G14:G17)=7, min(G14:G17)=6),"G",if(max(G14:G17)-min(G14:G17)>=2,"G","E"))) | U16: =if(sum(H14:H17)=0,"",if(and(max(H14:H17)=7, min(H14:H17)=6),"G",if(max(H14:H17)-min(H14:H17)>=2,"G","E"))) | V16: =if(sum(F14:F17)=0,0,if(max(F14:F17)=F16,1,0)+if(max(G14:G17)=G16,1,0)+if(max(H14:H17)=H16,1,0)) -> 0 | W16: Diff of 2 or tie breaker | AA16: =if(M16<>"","W" & vlookup(B16,B$122:E$133,4,false),"D" & vlookup(B16,B58:E89,4,false)) -> #N/A | AQ16: =K16 -> 4 | AR16: =P16 -> 0 | AS16: =counta(B16) -> 0
A17: 4 | I17: =sum(F17:H17) -> 0 | J17: =if(sum(F14:F17)=0,0,if(max(F14:F17)=F17,1,0)+if(max(G14:G17)=G17,1,0)+if(max(H14:H17)=H17,1,0)) -> 0 | K17: =A17 -> 4 | P17: =countif(Z$73:Z$79,B17) -> 0 | S17: =IF(COUNTIF(S14:S16, "") = 3, "", IF(COUNTIF(S14:S16, "G") = 3, "G", "E")) | T17: =IF(COUNTIF(T14:T16, "") = 3, "", IF(COUNTIF(T14:T16, "G") = 3, "G", "E")) | U17: =IF(COUNTIF(U14:U16, "") = 3, "", IF(COUNTIF(U14:U16, "G") = 3, "G", "E")) | V17: =if(sum(F14:F17)=0,0,if(max(F14:F17)=F17,1,0)+if(max(G14:G17)=G17,1,0)+if(max(H14:H17)=H17,1,0)) -> 0 | AA17: =if(M17<>"","W" & vlookup(B17,B$122:E$133,4,false),"D" & vlookup(B17,B59:E90,4,false)) -> #N/A | AQ17: =K17 -> 4 | AR17: =P17 -> 0 | AS17: =counta(B17) -> 0
A18: 5 | I18: =sum(F18:H18) -> 0 | J18: =if(sum(F18:F21)=0,0,if(max(F18:F21)=F18,1,0)+if(max(G18:G21)=G18,1,0)+if(max(H18:H21)=H18,1,0)) -> 0 | K18: =A18 -> 5 | O18: =sum(N18:N21) -> 0 | P18: =countif(Z$73:Z$79,B18) -> 0 | Q18: =sum(P18:P21) -> 0 | S18: =if(sum(F18:F21)=0,"",if(or(max(F18:F21)=6, max(F18:F21)=7),"G","E")) | T18: =if(sum(G18:G21)=0,"",if(or(max(G18:G21)=6, max(G18:G21)=7),"G","E")) | U18: =if(sum(H18:H21)=0,"",if(or(max(H18:H21)=6, max(H18:H21)=7),"G","E")) | V18: =if(sum(F18:F21)=0,0,if(max(F18:F21)=F18,1,0)+if(max(G18:G21)=G18,1,0)+if(max(H18:H21)=H18,1,0)) -> 0 | W18: Max=6/7 | AA18: =if(M18<>"","W" & vlookup(B18,B$122:E$133,4,false),"D" & vlookup(B18,B60:E91,4,false)) -> #N/A | AQ18: =K18 -> 5 | AR18: =P18 -> 0 | AS18: =counta(B18) -> 0
A19: 5 | I19: =sum(F19:H19) -> 0 | J19: =if(sum(F18:F21)=0,0,if(max(F18:F21)=F19,1,0)+if(max(G18:G21)=G19,1,0)+if(max(H18:H21)=H19,1,0)) -> 0 | K19: =A19 -> 5 | P19: =countif(Z$73:Z$79,B19) -> 0 | S19: =if(sum(F18:F21)=0,"",if(SUMPRODUCT(1/COUNTIF(F18:F21, F18:F21))=2,"G","E")) | T19: =if(sum(G18:G21)=0,"",if(SUMPRODUCT(1/COUNTIF(G18:G21, G18:G21))=2,"G","E")) | U19: =if(sum(H18:H21)=0,"",if(SUMPRODUCT(1/COUNTIF(H18:H21, H18:H21))=2,"G","E")) | V19: =if(sum(F18:F21)=0,0,if(max(F18:F21)=F19,1,0)+if(max(G18:G21)=G19,1,0)+if(max(H18:H21)=H19,1,0)) -> 0 | W19: two equal scores | AA19: =if(M19<>"","W" & vlookup(B19,B$122:E$133,4,false),"D" & vlookup(B19,B61:E92,4,false)) -> #N/A | AQ19: =K19 -> 5 | AR19: =P19 -> 0 | AS19: =counta(B19) -> 0
A20: 5 | I20: =sum(F20:H20) -> 0 | J20: =if(sum(F18:F21)=0,0,if(max(F18:F21)=F20,1,0)+if(max(G18:G21)=G20,1,0)+if(max(H18:H21)=H20,1,0)) -> 0 | K20: =A20 -> 5 | P20: =countif(Z$73:Z$79,B20) -> 0 | S20: =if(sum(F18:F21)=0,"",if(and(max(F18:F21)=7, min(F18:F21)=6),"G",if(max(F18:F21)-min(F18:F21)>=2,"G","E"))) | T20: =if(sum(G18:G21)=0,"",if(and(max(G18:G21)=7, min(G18:G21)=6),"G",if(max(G18:G21)-min(G18:G21)>=2,"G","E"))) | U20: =if(sum(H18:H21)=0,"",if(and(max(H18:H21)=7, min(H18:H21)=6),"G",if(max(H18:H21)-min(H18:H21)>=2,"G","E"))) | V20: =if(sum(F18:F21)=0,0,if(max(F18:F21)=F20,1,0)+if(max(G18:G21)=G20,1,0)+if(max(H18:H21)=H20,1,0)) -> 0 | W20: Diff of 2 or tie breaker | AA20: =if(M20<>"","W" & vlookup(B20,B$122:E$133,4,false),"D" & vlookup(B20,B62:E93,4,false)) -> #N/A | AQ20: =K20 -> 5 | AR20: =P20 -> 0 | AS20: =counta(B20) -> 0
A21: 5 | I21: =sum(F21:H21) -> 0 | J21: =if(sum(F18:F21)=0,0,if(max(F18:F21)=F21,1,0)+if(max(G18:G21)=G21,1,0)+if(max(H18:H21)=H21,1,0)) -> 0 | K21: =A21 -> 5 | P21: =countif(Z$73:Z$79,B21) -> 0 | S21: =IF(COUNTIF(S18:S20, "") = 3, "", IF(COUNTIF(S18:S20, "G") = 3, "G", "E")) | T21: =IF(COUNTIF(T18:T20, "") = 3, "", IF(COUNTIF(T18:T20, "G") = 3, "G", "E")) | U21: =IF(COUNTIF(U18:U20, "") = 3, "", IF(COUNTIF(U18:U20, "G") = 3, "G", "E")) | V21: =if(sum(F18:F21)=0,0,if(max(F18:F21)=F21,1,0)+if(max(G18:G21)=G21,1,0)+if(max(H18:H21)=H21,1,0)) -> 0 | AA21: =if(M21<>"","W" & vlookup(B21,B$122:E$133,4,false),"D" & vlookup(B21,B63:E94,4,false)) -> #N/A | AQ21: =K21 -> 5 | AR21: =P21 -> 0 | AS21: =counta(B21) -> 0
A22: 6 | I22: =sum(F22:H22) -> 0 | J22: =if(sum(F22:F25)=0,0,if(max(F22:F25)=F22,1,0)+if(max(G22:G25)=G22,1,0)+if(max(H22:H25)=H22,1,0)) -> 0 | K22: =A22 -> 6 | O22: =sum(N22:N25) -> 0 | P22: =countif(Z$73:Z$79,B22) -> 0 | Q22: =sum(P22:P25) -> 0 | S22: =if(sum(F22:F25)=0,"",if(or(max(F22:F25)=6, max(F22:F25)=7),"G","E")) | T22: =if(sum(G22:G25)=0,"",if(or(max(G22:G25)=6, max(G22:G25)=7),"G","E")) | U22: =if(sum(H22:H25)=0,"",if(or(max(H22:H25)=6, max(H22:H25)=7),"G","E")) | V22: =if(sum(F22:F25)=0,0,if(max(F22:F25)=F22,1,0)+if(max(G22:G25)=G22,1,0)+if(max(H22:H25)=H22,1,0)) -> 0 | W22: Max=6/7 | AA22: =if(M22<>"","W" & vlookup(B22,B$122:E$133,4,false),"D" & vlookup(B22,B64:E95,4,false)) -> #N/A | AQ22: =K22 -> 6 | AR22: =P22 -> 0 | AS22: =counta(B22) -> 0
A23: 6 | I23: =sum(F23:H23) -> 0 | J23: =if(sum(F22:F25)=0,0,if(max(F22:F25)=F23,1,0)+if(max(G22:G25)=G23,1,0)+if(max(H22:H25)=H23,1,0)) -> 0 | K23: =A23 -> 6 | P23: =countif(Z$73:Z$79,B23) -> 0 | S23: =if(sum(F22:F25)=0,"",if(SUMPRODUCT(1/COUNTIF(F22:F25, F22:F25))=2,"G","E")) | T23: =if(sum(G22:G25)=0,"",if(SUMPRODUCT(1/COUNTIF(G22:G25, G22:G25))=2,"G","E")) | U23: =if(sum(H22:H25)=0,"",if(SUMPRODUCT(1/COUNTIF(H22:H25, H22:H25))=2,"G","E")) | V23: =if(sum(F22:F25)=0,0,if(max(F22:F25)=F23,1,0)+if(max(G22:G25)=G23,1,0)+if(max(H22:H25)=H23,1,0)) -> 0 | W23: two equal scores | AA23: =if(M23<>"","W" & vlookup(B23,B$122:E$133,4,false),"D" & vlookup(B23,B65:E96,4,false)) -> #N/A | AQ23: =K23 -> 6 | AR23: =P23 -> 0 | AS23: =counta(B23) -> 0
A24: 6 | I24: =sum(F24:H24) -> 0 | J24: =if(sum(F22:F25)=0,0,if(max(F22:F25)=F24,1,0)+if(max(G22:G25)=G24,1,0)+if(max(H22:H25)=H24,1,0)) -> 0 | K24: =A24 -> 6 | P24: =countif(Z$73:Z$79,B24) -> 0 | S24: =if(sum(F22:F25)=0,"",if(and(max(F22:F25)=7, min(F22:F25)=6),"G",if(max(F22:F25)-min(F22:F25)>=2,"G","E"))) | T24: =if(sum(G22:G25)=0,"",if(and(max(G22:G25)=7, min(G22:G25)=6),"G",if(max(G22:G25)-min(G22:G25)>=2,"G","E"))) | U24: =if(sum(H22:H25)=0,"",if(and(max(H22:H25)=7, min(H22:H25)=6),"G",if(max(H22:H25)-min(H22:H25)>=2,"G","E"))) | V24: =if(sum(F22:F25)=0,0,if(max(F22:F25)=F24,1,0)+if(max(G22:G25)=G24,1,0)+if(max(H22:H25)=H24,1,0)) -> 0 | W24: Diff of 2 or tie breaker | AA24: =if(M24<>"","W" & vlookup(B24,B$122:E$133,4,false),"D" & vlookup(B24,B66:E97,4,false)) -> #N/A | AQ24: =K24 -> 6 | AR24: =P24 -> 0 | AS24: =counta(B24) -> 0
