Workbook

Sheet Current
B1: Standings as of | C1: 45283
B2: Number of Weeks Played | D2: 24
C3: Beginning of week | G3: Current Week Scores | M3: End of week | P3: Jan-Jul 2024
A4: Ranking | B4: Name of Player | C4: Games Won | D4: Sets Won | E4: Check IN | F4: Court # | G4: Set 0 | H4: Set 1 | I4: Set 2 | J4: Set 3 | K4: Games Won | L4: Sets Won | M4: Games Won | N4: Sets Won | O4: Waiver | P4: Fee | Q4: Sit outs | R4: No Shows | S4: Absent
A5: 1 | B5: Peter Cheng | C5: 339 | D5: 36 | E5: =if(isna(VLOOKUP(B5,Checkin!A:B,2,false)),0,VLOOKUP(B5,Checkin!A:B,2,false)) -> 0 | F5: =if(OR($E5=1, $E5=2),VLOOKUP($B5,Courts!$B$2:$K$33,10,false),0) -> 0 | G5: =IF(OR(E5=3,E5=4),9,IF(E5=5,13,0)) -> 0 | H5: =if(OR($E5=1, $E5=2),VLOOKUP($B5,Courts!$B$2:$J$33,5,false),0) -> 0 | I5: =if(OR($E5=1, $E5=2),VLOOKUP($B5,Courts!$B$2:$J$33,6,false),0) -> 0 | J5: =if(OR($E5=1, $E5=2),VLOOKUP($B5,Courts!$B$2:$J$33,7,false),0) -> 0 | K5: =G5+H5+I5+J5 -> 0 | L5: =if(OR($E5=1, $E5=2),VLOOKUP($B5,Courts!$B$2:$J$33,9,false),0) -> 0 | M5: =C5+K5 -> 339 | N5: =D5+L5 -> 36 | O5: X | P5: X | Q5: =if(G5=13,1,0)+VLOOKUP(B5,'122323'!B:Q,16,false) -> 1 | S5: =if(G5=9,1,0)+VLOOKUP(B5,'122323'!B:S,18,false) -> 6
A6: =A5+1 -> 2 | B6: Adrian Tay | C6: 324 | D6: 31 | E6: =if(isna(VLOOKUP(B6,Checkin!A:B,2,false)),0,VLOOKUP(B6,Checkin!A:B,2,false)) -> 0 | F6: =if(OR($E6=1, $E6=2),VLOOKUP($B6,Courts!$B$2:$K$33,10,false),0) -> 0 | G6: =IF(OR(E6=3,E6=4),9,IF(E6=5,13,0)) -> 0 | H6: =if(OR($E6=1, $E6=2),VLOOKUP($B6,Courts!$B$2:$J$33,5,false),0) -> 0 | I6: =if(OR($E6=1, $E6=2),VLOOKUP($B6,Courts!$B$2:$J$33,6,false),0) -> 0 | J6: =if(OR($E6=1, $E6=2),VLOOKUP($B6,Courts!$B$2:$J$33,7,false),0) -> 0 | K6: =G6+H6+I6+J6 -> 0 | L6: =if(OR($E6=1, $E6=2),VLOOKUP($B6,Courts!$B$2:$J$33,9,false),0) -> 0 | M6: =C6+K6 -> 324 | N6: =D6+L6 -> 31 | O6: X | P6: X | Q6: =if(G6=13,1,0)+VLOOKUP(B6,'122323'!B:Q,16,false) -> 0 | S6: =if(G6=9,1,0)+VLOOKUP(B6,'122323'!B:S,18,false) -> 9
A7: =A6+1 -> 3 | B7: Robert Chang | C7: 324 | D7: 31 | E7: =if(isna(VLOOKUP(B7,Checkin!A:B,2,false)),0,VLOOKUP(B7,Checkin!A:B,2,false)) -> 0 | F7: =if(OR($E7=1, $E7=2),VLOOKUP($B7,Courts!$B$2:$K$33,10,false),0) -> 0 | G7: =IF(OR(E7=3,E7=4),9,IF(E7=5,13,0)) -> 0 | H7: =if(OR($E7=1, $E7=2),VLOOKUP($B7,Courts!$B$2:$J$33,5,false),0) -> 0 | I7: =if(OR($E7=1, $E7=2),VLOOKUP($B7,Courts!$B$2:$J$33,6,false),0) -> 0 | J7: =if(OR($E7=1, $E7=2),VLOOKUP($B7,Courts!$B$2:$J$33,7,false),0) -> 0 | K7: =G7+H7+I7+J7 -> 0 | L7: =if(OR($E7=1, $E7=2),VLOOKUP($B7,Courts!$B$2:$J$33,9,false),0) -> 0 | M7: =C7+K7 -> 324 | N7: =D7+L7 -> 31 | O7: X | P7: X | Q7: =if(G7=13,1,0)+VLOOKUP(B7,'122323'!B:Q,16,false) -> 0 | S7: =if(G7=9,1,0)+VLOOKUP(B7,'122323'!B:S,18,false) -> 10
A8: =A7+1 -> 4 | B8: Alejandro Mejia | C8: 314 | D8: 28 | E8: =if(isna(VLOOKUP(B8,Checkin!A:B,2,false)),0,VLOOKUP(B8,Checkin!A:B,2,false)) -> 0 | F8: =if(OR($E8=1, $E8=2),VLOOKUP($B8,Courts!$B$2:$K$33,10,false),0) -> 0 | G8: =IF(OR(E8=3,E8=4),9,IF(E8=5,13,0)) -> 0 | H8: =if(OR($E8=1, $E8=2),VLOOKUP($B8,Courts!$B$2:$J$33,5,false),0) -> 0 | I8: =if(OR($E8=1, $E8=2),VLOOKUP($B8,Courts!$B$2:$J$33,6,false),0) -> 0 | J8: =if(OR($E8=1, $E8=2),VLOOKUP($B8,Courts!$B$2:$J$33,7,false),0) -> 0 | K8: =G8+H8+I8+J8 -> 0 | L8: =if(OR($E8=1, $E8=2),VLOOKUP($B8,Courts!$B$2:$J$33,9,false),0) -> 0 | M8: =C8+K8 -> 314 | N8: =D8+L8 -> 28 | O8: X | P8: X | Q8: =if(G8=13,1,0)+VLOOKUP(B8,'122323'!B:Q,16,false) -> 1 | S8: =if(G8=9,1,0)+VLOOKUP(B8,'122323'!B:S,18,false) -> 4
A9: =A8+1 -> 5 | B9: Matthew Huang | C9: 309 | D9: 25 | E9: =if(isna(VLOOKUP(B9,Checkin!A:B,2,false)),0,VLOOKUP(B9,Checkin!A:B,2,false)) -> 0 | F9: =if(OR($E9=1, $E9=2),VLOOKUP($B9,Courts!$B$2:$K$33,10,false),0) -> 0 | G9: =IF(OR(E9=3,E9=4),9,IF(E9=5,13,0)) -> 0 | H9: =if(OR($E9=1, $E9=2),VLOOKUP($B9,Courts!$B$2:$J$33,5,false),0) -> 0 | I9: =if(OR($E9=1, $E9=2),VLOOKUP($B9,Courts!$B$2:$J$33,6,false),0) -> 0 | J9: =if(OR($E9=1, $E9=2),VLOOKUP($B9,Courts!$B$2:$J$33,7,false),0) -> 0 | K9: =G9+H9+I9+J9 -> 0 | L9: =if(OR($E9=1, $E9=2),VLOOKUP($B9,Courts!$B$2:$J$33,9,false),0) -> 0 | M9: =C9+K9 -> 309 | N9: =D9+L9 -> 25 | O9: X | P9: X | Q9: =if(G9=13,1,0)+VLOOKUP(B9,'122323'!B:Q,16,false) -> 0 | S9: =if(G9=9,1,0)+VLOOKUP(B9,'122323'!B:S,18,false) -> 10
A10: =A9+1 -> 6 | B10: Pulkit Mathur | C10: 308 | D10: 25 | E10: =if(isna(VLOOKUP(B10,Checkin!A:B,2,false)),0,VLOOKUP(B10,Checkin!A:B,2,false)) -> 0 | F10: =if(OR($E10=1, $E10=2),VLOOKUP($B10,Courts!$B$2:$K$33,10,false),0) -> 0 | G10: =IF(OR(E10=3,E10=4),9,IF(E10=5,13,0)) -> 0 | H10: =if(OR($E10=1, $E10=2),VLOOKUP($B10,Courts!$B$2:$J$33,5,false),0) -> 0 | I10: =if(OR($E10=1, $E10=2),VLOOKUP($B10,Courts!$B$2:$J$33,6,false),0) -> 0 | J10: =if(OR($E10=1, $E10=2),VLOOKUP($B10,Courts!$B$2:$J$33,7,false),0) -> 0 | K10: =G10+H10+I10+J10 -> 0 | L10: =if(OR($E10=1, $E10=2),VLOOKUP($B10,Courts!$B$2:$J$33,9,false),0) -> 0 | M10: =C10+K10 -> 308 | N10: =D10+L10 -> 25 | O10: X | P10: X | Q10: =if(G10=13,1,0)+VLOOKUP(B10,'122323'!B:Q,16,false) -> 0 | S10: =if(G10=9,1,0)+VLOOKUP(B10,'122323'!B:S,18,false) -> 9
A11: =A10+1 -> 7 | B11: Pavan Akkimsetty | C11: 305 | D11: 27 | E11: =if(isna(VLOOKUP(B11,Checkin!A:B,2,false)),0,VLOOKUP(B11,Checkin!A:B,2,false)) -> 0 | F11: =if(OR($E11=1, $E11=2),VLOOKUP($B11,Courts!$B$2:$K$33,10,false),0) -> 0 | G11: =IF(OR(E11=3,E11=4),9,IF(E11=5,13,0)) -> 0 | H11: =if(OR($E11=1, $E11=2),VLOOKUP($B11,Courts!$B$2:$J$33,5,false),0) -> 0 | I11: =if(OR($E11=1, $E11=2),VLOOKUP($B11,Courts!$B$2:$J$33,6,false),0) -> 0 | J11: =if(OR($E11=1, $E11=2),VLOOKUP($B11,Courts!$B$2:$J$33,7,false),0) -> 0 | K11: =G11+H11+I11+J11 -> 0 | L11: =if(OR($E11=1, $E11=2),VLOOKUP($B11,Courts!$B$2:$J$33,9,false),0) -> 0 | M11: =C11+K11 -> 305 | N11: =D11+L11 -> 27 | O11: X | P11: X | Q11: =if(G11=13,1,0)+VLOOKUP(B11,'122323'!B:Q,16,false) -> 0 | S11: =if(G11=9,1,0)+VLOOKUP(B11,'122323'!B:S,18,false) -> 2
A12: =A11+1 -> 8 | B12: Lam Bui | C12: 302 | D12: 26 | E12: =if(isna(VLOOKUP(B12,Checkin!A:B,2,false)),0,VLOOKUP(B12,Checkin!A:B,2,false)) -> 0 | F12: =if(OR($E12=1, $E12=2),VLOOKUP($B12,Courts!$B$2:$K$33,10,false),0) -> 0 | G12: =IF(OR(E12=3,E12=4),9,IF(E12=5,13,0)) -> 0 | H12: =if(OR($E12=1, $E12=2),VLOOKUP($B12,Courts!$B$2:$J$33,5,false),0) -> 0 | I12: =if(OR($E12=1, $E12=2),VLOOKUP($B12,Courts!$B$2:$J$33,6,false),0) -> 0 | J12: =if(OR($E12=1, $E12=2),VLOOKUP($B12,Courts!$B$2:$J$33,7,false),0) -> 0 | K12: =G12+H12+I12+J12 -> 0 | L12: =if(OR($E12=1, $E12=2),VLOOKUP($B12,Courts!$B$2:$J$33,9,false),0) -> 0 | M12: =C12+K12 -> 302 | N12: =D12+L12 -> 26 | O12: X | P12: X | Q12: =if(G12=13,1,0)+VLOOKUP(B12,'122323'!B:Q,16,false) -> 1 | S12: =if(G12=9,1,0)+VLOOKUP(B12,'122323'!B:S,18,false) -> 10
A13: =A12+1 -> 9 | B13: Joe Luzzi | C13: 301 | D13: 28 | E13: =if(isna(VLOOKUP(B13,Checkin!A:B,2,false)),0,VLOOKUP(B13,Checkin!A:B,2,false)) -> 0 | F13: =if(OR($E13=1, $E13=2),VLOOKUP($B13,Courts!$B$2:$K$33,10,false),0) -> 0 | G13: =IF(OR(E13=3,E13=4),9,IF(E13=5,13,0)) -> 0 | H13: =if(OR($E13=1, $E13=2),VLOOKUP($B13,Courts!$B$2:$J$33,5,false),0) -> 0 | I13: =if(OR($E13=1, $E13=2),VLOOKUP($B13,Courts!$B$2:$J$33,6,false),0) -> 0 | J13: =if(OR($E13=1, $E13=2),VLOOKUP($B13,Courts!$B$2:$J$33,7,false),0) -> 0 | K13: =G13+H13+I13+J13 -> 0 | L13: =if(OR($E13=1, $E13=2),VLOOKUP($B13,Courts!$B$2:$J$33,9,false),0) -> 0 | M13: =C13+K13 -> 301 | N13: =D13+L13 -> 28 | O13: X | P13: X | Q13: =if(G13=13,1,0)+VLOOKUP(B13,'122323'!B:Q,16,false) -> 0 | S13: =if(G13=9,1,0)+VLOOKUP(B13,'122323'!B:S,18,false) -> 6
A14: =A13+1 -> 10 | B14: Peter Homsey | C14: 301 | D14: 27 | E14: =if(isna(VLOOKUP(B14,Checkin!A:B,2,false)),0,VLOOKUP(B14,Checkin!A:B,2,false)) -> 0 | F14: =if(OR($E14=1, $E14=2),VLOOKUP($B14,Courts!$B$2:$K$33,10,false),0) -> 0 | G14: =IF(OR(E14=3,E14=4),9,IF(E14=5,13,0)) -> 0 | H14: =if(OR($E14=1, $E14=2),VLOOKUP($B14,Courts!$B$2:$J$33,5,false),0) -> 0 | I14: =if(OR($E14=1, $E14=2),VLOOKUP($B14,Courts!$B$2:$J$33,6,false),0) -> 0 | J14: =if(OR($E14=1, $E14=2),VLOOKUP($B14,Courts!$B$2:$J$33,7,false),0) -> 0 | K14: =G14+H14+I14+J14 -> 0 | L14: =if(OR($E14=1, $E14=2),VLOOKUP($B14,Courts!$B$2:$J$33,9,false),0) -> 0 | M14: =C14+K14 -> 301 | N14: =D14+L14 -> 27 | O14: X | P14: X | Q14: =if(G14=13,1,0)+VLOOKUP(B14,'122323'!B:Q,16,false) -> 0 | S14: =if(G14=9,1,0)+VLOOKUP(B14,'122323'!B:S,18,false) -> 8
A15: =A14+1 -> 11 | B15: Erik Hoeckmann | C15: 301 | D15: 24 | E15: =if(isna(VLOOKUP(B15,Checkin!A:B,2,false)),0,VLOOKUP(B15,Checkin!A:B,2,false)) -> 0 | F15: =if(OR($E15=1, $E15=2),VLOOKUP($B15,Courts!$B$2:$K$33,10,false),0) -> 0 | G15: =IF(OR(E15=3,E15=4),9,IF(E15=5,13,0)) -> 0 | H15: =if(OR($E15=1, $E15=2),VLOOKUP($B15,Courts!$B$2:$J$33,5,false),0) -> 0 | I15: =if(OR($E15=1, $E15=2),VLOOKUP($B15,Courts!$B$2:$J$33,6,false),0) -> 0 | J15: =if(OR($E15=1, $E15=2),VLOOKUP($B15,Courts!$B$2:$J$33,7,false),0) -> 0 | K15: =G15+H15+I15+J15 -> 0 | L15: =if(OR($E15=1, $E15=2),VLOOKUP($B15,Courts!$B$2:$J$33,9,false),0) -> 0 | M15: =C15+K15 -> 301 | N15: =D15+L15 -> 24 | O15: X | P15: X | Q15: =if(G15=13,1,0)+VLOOKUP(B15,'122323'!B:Q,16,false) -> 0 | S15: =if(G15=9,1,0)+VLOOKUP(B15,'122323'!B:S,18,false) -> 6
A16: =A15+1 -> 12 | B16: Ted Shen | C16: 297 | D16: 26 | E16: =if(isna(VLOOKUP(B16,Checkin!A:B,2,false)),0,VLOOKUP(B16,Checkin!A:B,2,false)) -> 0 | F16: =if(OR($E16=1, $E16=2),VLOOKUP($B16,Courts!$B$2:$K$33,10,false),0) -> 0 | G16: =IF(OR(E16=3,E16=4),9,IF(E16=5,13,0)) -> 0 | H16: =if(OR($E16=1, $E16=2),VLOOKUP($B16,Courts!$B$2:$J$33,5,false),0) -> 0 | I16: =if(OR($E16=1, $E16=2),VLOOKUP($B16,Courts!$B$2:$J$33,6,false),0) -> 0 | J16: =if(OR($E16=1, $E16=2),VLOOKUP($B16,Courts!$B$2:$J$33,7,false),0) -> 0 | K16: =G16+H16+I16+J16 -> 0 | L16: =if(OR($E16=1, $E16=2),VLOOKUP($B16,Courts!$B$2:$J$33,9,false),0) -> 0 | M16: =C16+K16 -> 297 | N16: =D16+L16 -> 26 | O16: X | P16: X | Q16: =if(G16=13,1,0)+VLOOKUP(B16,'122323'!B:Q,16,false) -> 0 | S16: =if(G16=9,1,0)+VLOOKUP(B16,'122323'!B:S,18,false) -> 8
A17: =A16+1 -> 13 | B17: Jonathan Phan | C17: 297 | D17: 22 | E17: =if(isna(VLOOKUP(B17,Checkin!A:B,2,false)),0,VLOOKUP(B17,Checkin!A:B,2,false)) -> 0 | F17: =if(OR($E17=1, $E17=2),VLOOKUP($B17,Courts!$B$2:$K$33,10,false),0) -> 0 | G17: =IF(OR(E17=3,E17=4),9,IF(E17=5,13,0)) -> 0 | H17: =if(OR($E17=1, $E17=2),VLOOKUP($B17,Courts!$B$2:$J$33,5,false),0) -> 0 | I17: =if(OR($E17=1, $E17=2),VLOOKUP($B17,Courts!$B$2:$J$33,6,false),0) -> 0 | J17: =if(OR($E17=1, $E17=2),VLOOKUP($B17,Courts!$B$2:$J$33,7,false),0) -> 0 | K17: =G17+H17+I17+J17 -> 0 | L17: =if(OR($E17=1, $E17=2),VLOOKUP($B17,Courts!$B$2:$J$33,9,false),0) -> 0 | M17: =C17+K17 -> 297 | N17: =D17+L17 -> 22 | O17: X | P17: X | Q17: =if(G17=13,1,0)+VLOOKUP(B17,'122323'!B:Q,16,false) -> 0 | S17: =if(G17=9,1,0)+VLOOKUP(B17,'122323'!B:S,18,false) -> 6
... A31: =A30+1 -> 27 | B31: Susanta Mishra | C31: 265 | D31: 17 | E31: =if(isna(VLOOKUP(B31,Checkin!A:B,2,false)),0,VLOOKUP(B31,Checkin!A:B,2,false)) -> 0 | F31: =if(OR($E31=1, $E31=2),VLOOKUP($B31,Courts!$B$2:$K$33,10,false),0) -> 0 | G31: =IF(OR(E31=3,E31=4),9,IF(E31=5,13,0)) -> 0 | H31: =if(OR($E31=1, $E31=2),VLOOKUP($B31,Courts!$B$2:$J$33,5,false),0) -> 0 | I31: =if(OR($E31=1, $E31=2),VLOOKUP($B31,Courts!$B$2:$J$33,6,false),0) -> 0 | J31: =if(OR($E31=1, $E31=2),VLOOKUP($B31,Courts!$B$2:$J$33,7,false),0) -> 0 | K31: =G31+H31+I31+J31 -> 0 | L31: =if(OR($E31=1, $E31=2),VLOOKUP($B31,Courts!$B$2:$J$33,9,false),0) -> 0 | M31: =C31+K31 -> 265 | N31: =D31+L31 -> 17 | O31: X | P31: X | Q31: =if(G31=13,1,0)+VLOOKUP(B31,'122323'!B:Q,16,false) -> 1 | S31: =if(G31=9,1,0)+VLOOKUP(B31,'122323'!B:S,18,false) -> 15
A32: =A31+1 -> 28 | B32: Eric Pan | C32: 260 | D32: 16 | E32: =if(isna(VLOOKUP(B32,Checkin!A:B,2,false)),0,VLOOKUP(B32,Checkin!A:B,2,false)) -> 0 | F32: =if(OR($V31=1, $V31=2),VLOOKUP($B32,Courts!$B$2:$K$33,10,false),0) -> 0 | G32: =IF(OR(E32=3,E32=4),9,IF(E32=5,13,0)) -> 0 | H32: =if(OR($V31=1, $V31=2),VLOOKUP($B32,Courts!$B$2:$J$33,5,false),0) -> 0 | I32: =if(OR($V31=1, $V31=2),VLOOKUP($B32,Courts!$B$2:$J$33,6,false),0) -> 0 | J32: =if(OR($V31=1, $V31=2),VLOOKUP($B32,Courts!$B$2:$J$33,7,false),0) -> 0 | K32: =G32+H32+I32+J32 -> 0 | L32: =if(OR($V31=1, $V31=2),VLOOKUP($B32,Courts!$B$2:$J$33,9,false),0) -> 0 | M32: =C32+K32 -> 260 | N32: =D32+L32 -> 16 | O32: X | P32: X | Q32: =if(G32=13,1,0)+VLOOKUP(B32,'122323'!B:Q,16,false) -> 1 | S32: =if(G32=9,1,0)+VLOOKUP(B32,'122323'!B:S,18,false) -> 15
A33: =A32+1 -> 29 | B33: Mauricio Palacios | C33: 259 | D33: 25 | E33: =if(isna(VLOOKUP(B33,Checkin!A:B,2,false)),0,VLOOKUP(B33,Checkin!A:B,2,false)) -> 0 | F33: =if(OR($E33=1, $E33=2),VLOOKUP($B33,Courts!$B$2:$K$33,10,false),0) -> 0 | G33: =IF(OR(E33=3,E33=4),9,IF(E33=5,13,0)) -> 0 | H33: =if(OR($E33=1, $E33=2),VLOOKUP($B33,Courts!$B$2:$J$33,5,false),0) -> 0 | I33: =if(OR($E33=1, $E33=2),VLOOKUP($B33,Courts!$B$2:$J$33,6,false),0) -> 0 | J33: =if(OR($E33=1, $E33=2),VLOOKUP($B33,Courts!$B$2:$J$33,7,false),0) -> 0 | K33: =G33+H33+I33+J33 -> 0 | L33: =if(OR($E33=1, $E33=2),VLOOKUP($B33,Courts!$B$2:$J$33,9,false),0) -> 0 | M33: =C33+K33 -> 259 | N33: =D33+L33 -> 25 | O33: X | P33: X | Q33: =if(G33=13,1,0)+VLOOKUP(B33,'122323'!B:Q,16,false) -> 0 | S33: =if(G33=9,1,0)+VLOOKUP(B33,'122323'!B:S,18,false) -> 4
A34: =A33+1 -> 30 | B34: Sanjaye Elayattu | C34: 259 | D34: 11 | E34: =if(isna(VLOOKUP(B34,Checkin!A:B,2,false)),0,VLOOKUP(B34,Checkin!A:B,2,false)) -> 0 | F34: =if(OR($E34=1, $E34=2),VLOOKUP($B34,Courts!$B$2:$K$33,10,false),0) -> 0 | G34: =IF(OR(E34=3,E34=4),9,IF(E34=5,13,0)) -> 0 | H34: =if(OR($E34=1, $E34=2),VLOOKUP($B34,Courts!$B$2:$J$33,5,false),0) -> 0 | I34: =if(OR($E34=1, $E34=2),VLOOKUP($B34,Courts!$B$2:$J$33,6,false),0) -> 0 | J34: =if(OR($E34=1, $E34=2),VLOOKUP($B34,Courts!$B$2:$J$33,7,false),0) -> 0 | K34: =G34+H34+I34+J34 -> 0 | L34: =if(OR($E34=1, $E34=2),VLOOKUP($B34,Courts!$B$2:$J$33,9,false),0) -> 0 | M34: =C34+K34 -> 259 | N34: =D34+L34 -> 11 | O34: X | P34: X | Q34: =if(G34=13,1,0)+VLOOKUP(B34,'122323'!B:Q,16,false) -> 0 | S34: =if(G34=9,1,0)+VLOOKUP(B34,'122323'!B:S,18,false) -> 17
A35: =A34+1 -> 31 | B35: Naveen Raj | C35: 258 | D35: 16 | E35: =if(isna(VLOOKUP(B35,Checkin!A:B,2,false)),0,VLOOKUP(B35,Checkin!A:B,2,false)) -> 0 | F35: =if(OR($E35=1, $E35=2),VLOOKUP($B35,Courts!$B$2:$K$33,10,false),0) -> 0 | G35: =IF(OR(E35=3,E35=4),9,IF(E35=5,13,0)) -> 0 | H35: =if(OR($E35=1, $E35=2),VLOOKUP($B35,Courts!$B$2:$J$33,5,false),0) -> 0 | I35: =if(OR($E35=1, $E35=2),VLOOKUP($B35,Courts!$B$2:$J$33,6,false),0) -> 0 | J35: =if(OR($E35=1, $E35=2),VLOOKUP($B35,Courts!$B$2:$J$33,7,false),0) -> 0 | K35: =G35+H35+I35+J35 -> 0 | L35: =if(OR($E35=1, $E35=2),VLOOKUP($B35,Courts!$B$2:$J$33,9,false),0) -> 0 | M35: =C35+K35 -> 258 | N35: =D35+L35 -> 16 | O35: X | P35: X | Q35: =if(G35=13,1,0)+VLOOKUP(B35,'122323'!B:Q,16,false) -> 0 | S35: =if(G35=9,1,0)+VLOOKUP(B35,'122323'!B:S,18,false) -> 7
A36: =A35+1 -> 32 | B36: Manuel Rivera | C36: 256 | D36: 17 | E36: =if(isna(VLOOKUP(B36,Checkin!A:B,2,false)),0,VLOOKUP(B36,Checkin!A:B,2,false)) -> 0 | F36: =if(OR($E36=1, $E36=2),VLOOKUP($B36,Courts!$B$2:$K$33,10,false),0) -> 0 | G36: =IF(OR(E36=3,E36=4),9,IF(E36=5,13,0)) -> 0 | H36: =if(OR($E36=1, $E36=2),VLOOKUP($B36,Courts!$B$2:$J$33,5,false),0) -> 0 | I36: =if(OR($E36=1, $E36=2),VLOOKUP($B36,Courts!$B$2:$J$33,6,false),0) -> 0 | J36: =if(OR($E36=1, $E36=2),VLOOKUP($B36,Courts!$B$2:$J$33,7,false),0) -> 0 | K36: =G36+H36+I36+J36 -> 0 | L36: =if(OR($E36=1, $E36=2),VLOOKUP($B36,Courts!$B$2:$J$33,9,false),0) -> 0 | M36: =C36+K36 -> 256 | N36: =D36+L36 -> 17 | O36: X | P36: X | Q36: =if(G36=13,1,0)+VLOOKUP(B36,'122323'!B:Q,16,false) -> 0 | S36: =if(G36=9,1,0)+VLOOKUP(B36,'122323'!B:S,18,false) -> 10
A37: =A36+1 -> 33 | B37: Rosie Bonilla | C37: 255 | D37: 14 | E37: =if(isna(VLOOKUP(B37,Checkin!A:B,2,false)),0,VLOOKUP(B37,Checkin!A:B,2,false)) -> 0 | F37: =if(OR($E37=1, $E37=2),VLOOKUP($B37,Courts!$B$2:$K$33,10,false),0) -> 0 | G37: =IF(OR(E37=3,E37=4),9,IF(E37=5,13,0)) -> 0 | H37: =if(OR($E37=1, $E37=2),VLOOKUP($B37,Courts!$B$2:$J$33,5,false),0) -> 0 | I37: =if(OR($E37=1, $E37=2),VLOOKUP($B37,Courts!$B$2:$J$33,6,false),0) -> 0 | J37: =if(OR($E37=1, $E37=2),VLOOKUP($B37,Courts!$B$2:$J$33,7,false),0) -> 0 | K37: =G37+H37+I37+J37 -> 0 | L37: =if(OR($E37=1, $E37=2),VLOOKUP($B37,Courts!$B$2:$J$33,9,false),0) -> 0 | M37: =C37+K37 -> 255 | N37: =D37+L37 -> 14 | O37: X | P37: X | Q37: =if(G37=13,1,0)+VLOOKUP(B37,'122323'!B:Q,16,false) -> 0 | S37: =if(G37=9,1,0)+VLOOKUP(B37,'122323'!B:S,18,false) -> 10
A38: =A37+1 -> 34 | B38: Sandy Weyant | C38: 252 | D38: 15 | E38: =if(isna(VLOOKUP(B38,Checkin!A:B,2,false)),0,VLOOKUP(B38,Checkin!A:B,2,false)) -> 0 | F38: =if(OR($E38=1, $E38=2),VLOOKUP($B38,Courts!$B$2:$K$33,10,false),0) -> 0 | G38: =IF(OR(E38=3,E38=4),9,IF(E38=5,13,0)) -> 0 | H38: =if(OR($E38=1, $E38=2),VLOOKUP($B38,Courts!$B$2:$J$33,5,false),0) -> 0 | I38: =if(OR($E38=1, $E38=2),VLOOKUP($B38,Courts!$B$2:$J$33,6,false),0) -> 0 | J38: =if(OR($E38=1, $E38=2),VLOOKUP($B38,Courts!$B$2:$J$33,7,false),0) -> 0 | K38: =G38+H38+I38+J38 -> 0 | L38: =if(OR($E38=1, $E38=2),VLOOKUP($B38,Courts!$B$2:$J$33,9,false),0) -> 0 | M38: =C38+K38 -> 252 | N38: =D38+L38 -> 15 | O38: X | P38: X | Q38: =if(G38=13,1,0)+VLOOKUP(B38,'122323'!B:Q,16,false) -> 0 | S38: =if(G38=9,1,0)+VLOOKUP(B38,'122323'!B:S,18,false) -> 7
A39: =A38+1 -> 35 | B39: Suleman Alidina | C39: 252 | D39: 13 | E39: =if(isna(VLOOKUP(B39,Checkin!A:B,2,false)),0,VLOOKUP(B39,Checkin!A:B,2,false)) -> 0 | F39: =if(OR($E39=1, $E39=2),VLOOKUP($B39,Courts!$B$2:$K$33,10,false),0) -> 0 | G39: =IF(OR(E39=3,E39=4),9,IF(E39=5,13,0)) -> 0 | H39: =if(OR($E39=1, $E39=2),VLOOKUP($B39,Courts!$B$2:$J$33,5,false),0) -> 0 | I39: =if(OR($E39=1, $E39=2),VLOOKUP($B39,Courts!$B$2:$J$33,6,false),0) -> 0 | J39: =if(OR($E39=1, $E39=2),VLOOKUP($B39,Courts!$B$2:$J$33,7,false),0) -> 0 | K39: =G39+H39+I39+J39 -> 0 | L39: =if(OR($E39=1, $E39=2),VLOOKUP($B39,Courts!$B$2:$J$33,9,false),0) -> 0 | M39: =C39+K39 -> 252 | N39: =D39+L39 -> 13 | O39: X | P39: X | Q39: =if(G39=13,1,0)+VLOOKUP(B39,'122323'!B:Q,16,false) -> 0 | S39: =if(G39=9,1,0)+VLOOKUP(B39,'122323'!B:S,18,false) -> 18
A40: =A39+1 -> 36 | B40: Troy Wong | C40: 252 | D40: 10 | E40: =if(isna(VLOOKUP(B40,Checkin!A:B,2,false)),0,VLOOKUP(B40,Checkin!A:B,2,false)) -> 0 | F40: =if(OR($E40=1, $E40=2),VLOOKUP($B40,Courts!$B$2:$K$33,10,false),0) -> 0 | G40: =IF(OR(E40=3,E40=4),9,IF(E40=5,13,0)) -> 0 | H40: =if(OR($E40=1, $E40=2),VLOOKUP($B40,Courts!$B$2:$J$33,5,false),0) -> 0 | I40: =if(OR($E40=1, $E40=2),VLOOKUP($B40,Courts!$B$2:$J$33,6,false),0) -> 0 | J40: =if(OR($E40=1, $E40=2),VLOOKUP($B40,Courts!$B$2:$J$33,7,false),0) -> 0 | K40: =G40+H40+I40+J40 -> 0 | L40: =if(OR($E40=1, $E40=2),VLOOKUP($B40,Courts!$B$2:$J$33,9,false),0) -> 0 | M40: =C40+K40 -> 252 | N40: =D40+L40 -> 10 | O40: X | P40: X | Q40: =if(G40=13,1,0)+VLOOKUP(B40,'122323'!B:Q,16,false) -> 0 | S40: =if(G40=9,1,0)+VLOOKUP(B40,'122323'!B:S,18,false) -> 19
A41: =A40+1 -> 37 | B41: Vamsi Lolla | C41: 251 | D41: 14 | E41: =if(isna(VLOOKUP(B41,Checkin!A:B,2,false)),0,VLOOKUP(B41,Checkin!A:B,2,false)) -> 0 | F41: =if(OR($E41=1, $E41=2),VLOOKUP($B41,Courts!$B$2:$K$33,10,false),0) -> 0 | G41: =IF(OR(E41=3,E41=4),9,IF(E41=5,13,0)) -> 0 | H41: =if(OR($E41=1, $E41=2),VLOOKUP($B41,Courts!$B$2:$J$33,5,false),0) -> 0 | I41: =if(OR($E41=1, $E41=2),VLOOKUP($B41,Courts!$B$2:$J$33,6,false),0) -> 0 | J41: =if(OR($E41=1, $E41=2),VLOOKUP($B41,Courts!$B$2:$J$33,7,false),0) -> 0 | K41: =G41+H41+I41+J41 -> 0 | L41: =if(OR($E41=1, $E41=2),VLOOKUP($B41,Courts!$B$2:$J$33,9,false),0) -> 0 | M41: =C41+K41 -> 251 | N41: =D41+L41 -> 14 | O41: X | P41: X | Q41: =if(G41=13,1,0)+VLOOKUP(B41,'122323'!B:Q,16,false) -> 1 | S41: =if(G41=9,1,0)+VLOOKUP(B41,'122323'!B:S,18,false) -> 11
A42: =A41+1 -> 38 | B42: Derek Fu | C42: 249 | D42: 10 | E42: =if(isna(VLOOKUP(B42,Checkin!A:B,2,false)),0,VLOOKUP(B42,Checkin!A:B,2,false)) -> 0 | F42: =if(OR($E42=1, $E42=2),VLOOKUP($B42,Courts!$B$2:$K$33,10,false),0) -> 0 | G42: =IF(OR(E42=3,E42=4),9,IF(E42=5,13,0)) -> 0 | H42: =if(OR($E42=1, $E42=2),VLOOKUP($B42,Courts!$B$2:$J$33,5,false),0) -> 0 | I42: =if(OR($E42=1, $E42=2),VLOOKUP($B42,Courts!$B$2:$J$33,6,false),0) -> 0 | J42: =if(OR($E42=1, $E42=2),VLOOKUP($B42,Courts!$B$2:$J$33,7,false),0) -> 0 | K42: =G42+H42+I42+J42 -> 0 | L42: =if(OR($E42=1, $E42=2),VLOOKUP($B42,Courts!$B$2:$J$33,9,false),0) -> 0 | M42: =C42+K42 -> 249 | N42: =D42+L42 -> 10 | O42: X | Q42: =if(G42=13,1,0)+VLOOKUP(B42,'122323'!B:Q,16,false) -> 0 | S42: =if(G42=9,1,0)+VLOOKUP(B42,'122323'!B:S,18,false) -> 20
A43: =A42+1 -> 39 | B43: Elayaraja Thangaraj | C43: 248 | D43: 21 | E43: =if(isna(VLOOKUP(B43,Checkin!A:B,2,false)),0,VLOOKUP(B43,Checkin!A:B,2,false)) -> 0 | F43: =if(OR($E43=1, $E43=2),VLOOKUP($B43,Courts!$B$2:$K$33,10,false),0) -> 0 | G43: =IF(OR(E43=3,E43=4),9,IF(E43=5,13,0)) -> 0 | H43: =if(OR($E43=1, $E43=2),VLOOKUP($B43,Courts!$B$2:$J$33,5,false),0) -> 0 | I43: =if(OR($E43=1, $E43=2),VLOOKUP($B43,Courts!$B$2:$J$33,6,false),0) -> 0 | J43: =if(OR($E43=1, $E43=2),VLOOKUP($B43,Courts!$B$2:$J$33,7,false),0) -> 0 | K43: =G43+H43+I43+J43 -> 0 | L43: =if(OR($E43=1, $E43=2),VLOOKUP($B43,Courts!$B$2:$J$33,9,false),0) -> 0 | M43: =C43+K43 -> 248 | N43: =D43+L43 -> 21 | O43: X | P43: X | Q43: =if(G43=13,1,0)+VLOOKUP(B43,'122323'!B:Q,16,false) -> 0 | S43: =if(G43=9,1,0)+VLOOKUP(B43,'122323'!B:S,18,false) -> 9
A44: =A43+1 -> 40 | B44: Andrew Chin | C44: 244 | D44: 9 | E44: =if(isna(VLOOKUP(B44,Checkin!A:B,2,false)),0,VLOOKUP(B44,Checkin!A:B,2,false)) -> 0 | F44: =if(OR($E44=1, $E44=2),VLOOKUP($B44,Courts!$B$2:$K$33,10,false),0) -> 0 | G44: =IF(OR(E44=3,E44=4),9,IF(E44=5,13,0)) -> 0 | H44: =if(OR($E44=1, $E44=2),VLOOKUP($B44,Courts!$B$2:$J$33,5,false),0) -> 0 | I44: =if(OR($E44=1, $E44=2),VLOOKUP($B44,Courts!$B$2:$J$33,6,false),0) -> 0 | J44: =if(OR($E44=1, $E44=2),VLOOKUP($B44,Courts!$B$2:$J$33,7,false),0) -> 0 | K44: =G44+H44+I44+J44 -> 0 | L44: =if(OR($E44=1, $E44=2),VLOOKUP($B44,Courts!$B$2:$J$33,9,false),0) -> 0 | M44: =C44+K44 -> 244 | N44: =D44+L44 -> 9 | O44: X | P44: X | Q44: =if(G44=13,1,0)+VLOOKUP(B44,'122323'!B:Q,16,false) -> 0 | S44: =if(G44=9,1,0)+VLOOKUP(B44,'122323'!B:S,18,false) -> 20
A45: =A44+1 -> 41 | B45: Vinot Kumar Nagappan | C45: 243 | D45: 13 | E45: =if(isna(VLOOKUP(B45,Checkin!A:B,2,false)),0,VLOOKUP(B45,Checkin!A:B,2,false)) -> 0 | F45: =if(OR($E45=1, $E45=2),VLOOKUP($B45,Courts!$B$2:$K$33,10,false),0) -> 0 | G45: =IF(OR(E45=3,E45=4),9,IF(E45=5,13,0)) -> 0 | H45: =if(OR($E45=1, $E45=2),VLOOKUP($B45,Courts!$B$2:$J$33,5,false),0) -> 0 | I45: =if(OR($E45=1, $E45=2),VLOOKUP($B45,Courts!$B$2:$J$33,6,false),0) -> 0 | J45: =if(OR($E45=1, $E45=2),VLOOKUP($B45,Courts!$B$2:$J$33,7,false),0) -> 0 | K45: =G45+H45+I45+J45 -> 0 | L45: =if(OR($E45=1, $E45=2),VLOOKUP($B45,Courts!$B$2:$J$33,9,false),0) -> 0 | M45: =C45+K45 -> 243 | N45: =D45+L45 -> 13 | O45: X | P45: X | Q45: =if(G45=13,1,0)+VLOOKUP(B45,'122323'!B:Q,16,false) -> 0 | S45: =if(G45=9,1,0)+VLOOKUP(B45,'122323'!B:S,18,false) -> 13
A46: =A45+1 -> 42 | B46: Paul Sanchez | C46: 243 | D46: 9 | E46: =if(isna(VLOOKUP(B46,Checkin!A:B,2,false)),0,VLOOKUP(B46,Checkin!A:B,2,false)) -> 0 | F46: =if(OR($E46=1, $E46=2),VLOOKUP($B46,Courts!$B$2:$K$33,10,false),0) -> 0 | G46: =IF(OR(E46=3,E46=4),9,IF(E46=5,13,0)) -> 0 | H46: =if(OR($E46=1, $E46=2),VLOOKUP($B46,Courts!$B$2:$J$33,5,false),0) -> 0 | I46: =if(OR($E46=1, $E46=2),VLOOKUP($B46,Courts!$B$2:$J$33,6,false),0) -> 0 | J46: =if(OR($E46=1, $E46=2),VLOOKUP($B46,Courts!$B$2:$J$33,7,false),0) -> 0 | K46: =G46+H46+I46+J46 -> 0 | L46: =if(OR($E46=1, $E46=2),VLOOKUP($B46,Courts!$B$2:$J$33,9,false),0) -> 0 | M46: =C46+K46 -> 243 | N46: =D46+L46 -> 9 | O46: X | Q46: =if(G46=13,1,0)+VLOOKUP(B46,'122323'!B:Q,16,false) -> 0 | S46: =if(G46=9,1,0)+VLOOKUP(B46,'122323'!B:S,18,false) -> 16
A47: =A46+1 -> 43 | B47: Jimmy Awolesi | C47: 238 | D47: 15 | E47: =if(isna(VLOOKUP(B47,Checkin!A:B,2,false)),0,VLOOKUP(B47,Checkin!A:B,2,false)) -> 0 | F47: =if(OR($E47=1, $E47=2),VLOOKUP($B47,Courts!$B$2:$K$33,10,false),0) -> 0 | G47: =IF(OR(E47=3,E47=4),9,IF(E47=5,13,0)) -> 0 | H47: =if(OR($E47=1, $E47=2),VLOOKUP($B47,Courts!$B$2:$J$33,5,false),0) -> 0 | I47: =if(OR($E47=1, $E47=2),VLOOKUP($B47,Courts!$B$2:$J$33,6,false),0) -> 0 | J47: =if(OR($E47=1, $E47=2),VLOOKUP($B47,Courts!$B$2:$J$33,7,false),0) -> 0 | K47: =G47+H47+I47+J47 -> 0 | L47: =if(OR($E47=1, $E47=2),VLOOKUP($B47,Courts!$B$2:$J$33,9,false),0) -> 0 | M47: =C47+K47 -> 238 | N47: =D47+L47 -> 15 | O47: X | P47: X | Q47: =if(G47=13,1,0)+VLOOKUP(B47,'122323'!B:Q,16,false) -> 0 | S47: =if(G47=9,1,0)+VLOOKUP(B47,'122323'!B:S,18,false) -> 10
A48: =A47+1 -> 44 | B48: Nohely Mejia | C48: 238 | D48: 12 | E48: =if(isna(VLOOKUP(B48,Checkin!A:B,2,false)),0,VLOOKUP(B48,Checkin!A:B,2,false)) -> 0 | F48: =if(OR($E48=1, $E48=2),VLOOKUP($B48,Courts!$B$2:$K$33,10,false),0) -> 0 | G48: =IF(OR(E48=3,E48=4),9,IF(E48=5,13,0)) -> 0 | H48: =if(OR($E48=1, $E48=2),VLOOKUP($B48,Courts!$B$2:$J$33,5,false),0) -> 0 | I48: =if(OR($E48=1, $E48=2),VLOOKUP($B48,Courts!$B$2:$J$33,6,false),0) -> 0 | J48: =if(OR($E48=1, $E48=2),VLOOKUP($B48,Courts!$B$2:$J$33,7,false),0) -> 0 | K48: =G48+H48+I48+J48 -> 0 | L48: =if(OR($E48=1, $E48=2),VLOOKUP($B48,Courts!$B$2:$J$33,9,false),0) -> 0 | M48: =C48+K48 -> 238 | N48: =D48+L48 -> 12 | O48: X | P48: X | Q48: =if(G48=13,1,0)+VLOOKUP(B48,'122323'!B:Q,16,false) -> 2 | S48: =if(G48=9,1,0)+VLOOKUP(B48,'122323'!B:S,18,false) -> 8
A49: =A48+1 -> 45 | B49: James Cole III | C49: 238 | D49: 8 | E49: =if(isna(VLOOKUP(B49,Checkin!A:B,2,false)),0,VLOOKUP(B49,Checkin!A:B,2,false)) -> 0 | F49: =if(OR($E49=1, $E49=2),VLOOKUP($B49,Courts!$B$2:$K$33,10,false),0) -> 0 | G49: =IF(OR(E49=3,E49=4),9,IF(E49=5,13,0)) -> 0 | H49: =if(OR($E49=1, $E49=2),VLOOKUP($B49,Courts!$B$2:$J$33,5,false),0) -> 0 | I49: =if(OR($E49=1, $E49=2),VLOOKUP($B49,Courts!$B$2:$J$33,6,false),0) -> 0 | J49: =if(OR($E49=1, $E49=2),VLOOKUP($B49,Courts!$B$2:$J$33,7,false),0) -> 0 | K49: =G49+H49+I49+J49 -> 0 | L49: =if(OR($E49=1, $E49=2),VLOOKUP($B49,Courts!$B$2:$J$33,9,false),0) -> 0 | M49: =C49+K49 -> 238 | N49: =D49+L49 -> 8 | O49: X | Q49: =if(G49=13,1,0)+VLOOKUP(B49,'122323'!B:Q,16,false) -> 0 | S49: =if(G49=9,1,0)+VLOOKUP(B49,'122323'!B:S,18,false) -> 18
A50: =A49+1 -> 46 | B50: Balaji Alahari | C50: 236 | D50: 7 | E50: =if(isna(VLOOKUP(B50,Checkin!A:B,2,false)),0,VLOOKUP(B50,Checkin!A:B,2,false)) -> 0 | F50: =if(OR($E50=1, $E50=2),VLOOKUP($B50,Courts!$B$2:$K$33,10,false),0) -> 0 | G50: =IF(OR(E50=3,E50=4),9,IF(E50=5,13,0)) -> 0 | H50: =if(OR($E50=1, $E50=2),VLOOKUP($B50,Courts!$B$2:$J$33,5,false),0) -> 0 | I50: =if(OR($E50=1, $E50=2),VLOOKUP($B50,Courts!$B$2:$J$33,6,false),0) -> 0 | J50: =if(OR($E50=1, $E50=2),VLOOKUP($B50,Courts!$B$2:$J$33,7,false),0) -> 0 | K50: =G50+H50+I50+J50 -> 0 | L50: =if(OR($E50=1, $E50=2),VLOOKUP($B50,Courts!$B$2:$J$33,9,false),0) -> 0 | M50: =C50+K50 -> 236 | N50: =D50+L50 -> 7 | O50: X | P50: X | Q50: =if(G50=13,1,0)+VLOOKUP(B50,'122323'!B:Q,16,false) -> 1 | S50: =if(G50=9,1,0)+VLOOKUP(B50,'122323'!B:S,18,false) -> 18
A51: =A50+1 -> 47 | B51: Kevin Wang | C51: 231 | D51: 16 | E51: =if(isna(VLOOKUP(B51,Checkin!A:B,2,false)),0,VLOOKUP(B51,Checkin!A:B,2,false)) -> 0 | F51: =if(OR($E51=1, $E51=2),VLOOKUP($B51,Courts!$B$2:$K$33,10,false),0) -> 0 | G51: =IF(OR(E51=3,E51=4),9,IF(E51=5,13,0)) -> 0 | H51: =if(OR($E51=1, $E51=2),VLOOKUP($B51,Courts!$B$2:$J$33,5,false),0) -> 0 | I51: =if(OR($E51=1, $E51=2),VLOOKUP($B51,Courts!$B$2:$J$33,6,false),0) -> 0 | J51: =if(OR($E51=1, $E51=2),VLOOKUP($B51,Courts!$B$2:$J$33,7,false),0) -> 0 | K51: =G51+H51+I51+J51 -> 0 | L51: =if(OR($E51=1, $E51=2),VLOOKUP($B51,Courts!$B$2:$J$33,9,false),0) -> 0 | M51: =C51+K51 -> 231 | N51: =D51+L51 -> 16 | O51: X | Q51: =if(G51=13,1,0)+VLOOKUP(B51,'122323'!B:Q,16,false) -> 0 | S51: =if(G51=9,1,0)+VLOOKUP(B51,'122323'!B:S,18,false) -> 9
A52: =A51+1 -> 48 | B52: Luis Hsu | C52: 231 | D52: 5 | E52: =if(isna(VLOOKUP(B52,Checkin!A:B,2,false)),0,VLOOKUP(B52,Checkin!A:B,2,false)) -> 0 | F52: =if(OR($E52=1, $E52=2),VLOOKUP($B52,Courts!$B$2:$K$33,10,false),0) -> 0 | G52: =IF(OR(E52=3,E52=4),9,IF(E52=5,13,0)) -> 0 | H52: =if(OR($E52=1, $E52=2),VLOOKUP($B52,Courts!$B$2:$J$33,5,false),0) -> 0 | I52: =if(OR($E52=1, $E52=2),VLOOKUP($B52,Courts!$B$2:$J$33,6,false),0) -> 0 | J52: =if(OR($E52=1, $E52=2),VLOOKUP($B52,Courts!$B$2:$J$33,7,false),0) -> 0 | K52: =G52+H52+I52+J52 -> 0 | L52: =if(OR($E52=1, $E52=2),VLOOKUP($B52,Courts!$B$2:$J$33,9,false),0) -> 0 | M52: =C52+K52 -> 231 | N52: =D52+L52 -> 5 | O52: X | P52: X | Q52: =if(G52=13,1,0)+VLOOKUP(B52,'122323'!B:Q,16,false) -> 0 | S52: =if(G52=9,1,0)+VLOOKUP(B52,'122323'!B:S,18,false) -> 21
A53: =A52+1 -> 49 | B53: Pan Lee | C53: 230 | D53: 5 | E53: =if(isna(VLOOKUP(B53,Checkin!A:B,2,false)),0,VLOOKUP(B53,Checkin!A:B,2,false)) -> 0 | F53: =if(OR($E53=1, $E53=2),VLOOKUP($B53,Courts!$B$2:$K$33,10,false),0) -> 0 | G53: =IF(OR(E53=3,E53=4),9,IF(E53=5,13,0)) -> 0 | H53: =if(OR($E53=1, $E53=2),VLOOKUP($B53,Courts!$B$2:$J$33,5,false),0) -> 0 | I53: =if(OR($E53=1, $E53=2),VLOOKUP($B53,Courts!$B$2:$J$33,6,false),0) -> 0 | J53: =if(OR($E53=1, $E53=2),VLOOKUP($B53,Courts!$B$2:$J$33,7,false),0) -> 0 | K53: =G53+H53+I53+J53 -> 0 | L53: =if(OR($E53=1, $E53=2),VLOOKUP($B53,Courts!$B$2:$J$33,9,false),0) -> 0 | M53: =C53+K53 -> 230 | N53: =D53+L53 -> 5 | O53: X | Q53: =if(G53=13,1,0)+VLOOKUP(B53,'122323'!B:Q,16,false) -> 0 | S53: =if(G53=9,1,0)+VLOOKUP(B53,'122323'!B:S,18,false) -> 22
...

Sheet Courts
A1: Court # | B1: Name of the Player | C1: Games Won | D1: Sets Won | E1: Check In | F1: Set 1 | G1: Set 2 | H1: Set 3 | I1: Total Games won | J1: Sets Won | K1: Court #
A2: 1 | B2: =IFERROR(__xludf.DUMMYFUNCTION("QUERY(Current!B5:E68,""Select B, C, D, E where E = 1 or E = 2 "",0)"),"#N/A") -> #N/A | I2: =sum(F2:H2) -> 0 | K2: =A2 -> 1
A3: 1 | I3: =sum(F3:H3) -> 0 | K3: =A3 -> 1
A4: 1 | I4: =sum(F4:H4) -> 0 | K4: =A4 -> 1
A5: 1 | I5: =sum(F5:H5) -> 0 | K5: =A5 -> 1
A6: 2 | I6: =sum(F6:H6) -> 0 | K6: =A6 -> 2
A7: 2 | I7: =sum(F7:H7) -> 0 | K7: =A7 -> 2
A8: 2 | I8: =sum(F8:H8) -> 0 | K8: =A8 -> 2
A9: 2 | I9: =sum(F9:H9) -> 0 | K9: =A9 -> 2
A10: =if(C38="Y",A9+3,A9+1) -> 3 | I10: =sum(F10:H10) -> 0 | K10: =A10 -> 3
A11: =A10 -> 3 | I11: =sum(F11:H11) -> 0 | K11: =A11 -> 3
A12: =A11 -> 3 | I12: =sum(F12:H12) -> 0 | K12: =A12 -> 3
A13: =A12 -> 3 | I13: =sum(F13:H13) -> 0 | K13: =A13 -> 3
A14: =if(C39="Y",A13+2,A13+1) -> 4 | I14: =sum(F14:H14) -> 0 | K14: =A14 -> 4
A15: =A14 -> 4 | I15: =sum(F15:H15) -> 0 | K15: =A15 -> 4
A16: =A15 -> 4 | I16: =sum(F16:H16) -> 0 | K16: =A16 -> 4
A17: =A16 -> 4 | I17: =sum(F17:H17) -> 0 | K17: =A17 -> 4
A18: =A17+1 -> 5 | I18: =sum(F18:H18) -> 0 | K18: =A18 -> 5
A19: =A18 -> 5 | I19: =sum(F19:H19) -> 0 | K19: =A19 -> 5
A20: =A19 -> 5 | I20: =sum(F20:H20) -> 0 | K20: =A20 -> 5
A21: =A20 -> 5 | I21: =sum(F21:H21) -> 0 | K21: =A21 -> 5
A22: =A21+1 -> 6 | I22: =sum(F22:H22) -> 0 | K22: =A22 -> 6
A23: =A22 -> 6 | I23: =sum(F23:H23) -> 0 | K23: =A23 -> 6
A24: =A23 -> 6 | I24: =sum(F24:H24) -> 0 | K24: =A24 -> 6
A25: =A24 -> 6 | I25: =sum(F25:H25) -> 0 | K25: =A25 -> 6
A26: =A25+1 -> 7 | I26: =sum(F26:H26) -> 0 | K26: =A26 -> 7
A27: =A26 -> 7 | I27: =sum(F27:H27) -> 0 | K27: =A27 -> 7
A28: =A27 -> 7 | I28: =sum(F28:H28) -> 0 | K28: =A28 -> 7
A29: =A28 -> 7 | I29: =sum(F29:H29) -> 0 | K29: =A29 -> 7
A30: =A29+1 -> 8 | I30: =sum(F30:H30) -> 0 | K30: =A30 -> 8
A31: =A30 -> 8 | I31: =sum(F31:H31) -> 0 | K31: =A31 -> 8
A32: =A31 -> 8 | I32: =sum(F32:H32) -> 0 | K32: =A32 -> 8
A33: =A32 -> 8 | I33: =sum(F33:H33) -> 0 | K33: =A33 -> 8
B38: skip court 3 | C38: N
B39: skip court 4 | C39: N

Sheet Checkin
A1: Name | B1: Check in | D1: Sl.No | E1: Options: 1 | F1: Options: 2 | G1: Options: 3 | H1: Option 4 | I1: To Respond | J1: Sitouts
A2: =IFERROR(__xludf.DUMMYFUNCTION("IMPORTRANGE(""1uZFF2o7rrfB0YZtASdZnP52Ef50ZinvtOPb1Tbuq8J4"",""CheckIn!C1:D99"")"),"#REF!") -> #REF! | D2: 1 | E2: =IFERROR(__xludf.DUMMYFUNCTION("QUERY(A2:B70, ""Select A where B = 1 order by A"")"),"#N/A") -> #N/A | F2: =IFERROR(__xludf.DUMMYFUNCTION("QUERY($A2:$B65, ""Select A where B = 2"")"),"#N/A") -> #N/A | G2: =IFERROR(__xludf.DUMMYFUNCTION("QUERY($A2:$B65, ""Select A where B = 3 order by A"")"),"#N/A") -> #N/A | H2: =IFERROR(__xludf.DUMMYFUNCTION("QUERY($A2:$B65, ""Select A where B = 4 order by A"")"),"#N/A") -> #N/A | I2: =IFERROR(__xludf.DUMMYFUNCTION("QUERY(Current!B5:E70, ""Select B where E = 0 order by B"")"),"Adrian Tay") -> Adrian Tay | J2: =IFERROR(__xludf.DUMMYFUNCTION("QUERY(Current!B5:E68, ""Select B where E = 5 order by B"")"),"#N/A") -> #N/A
D3: =D2+1 -> 2 | I3: =IFERROR(__xludf.DUMMYFUNCTION("""COMPUTED_VALUE"""),"Alejandro Mejia") -> Alejandro Mejia
D4: =D3+1 -> 3 | I4: =IFERROR(__xludf.DUMMYFUNCTION("""COMPUTED_VALUE"""),"Amit Patel") -> Amit Patel
D5: =D4+1 -> 4 | I5: =IFERROR(__xludf.DUMMYFUNCTION("""COMPUTED_VALUE"""),"Andrew Chin") -> Andrew Chin
D6: =D5+1 -> 5 | I6: =IFERROR(__xludf.DUMMYFUNCTION("""COMPUTED_VALUE"""),"Anish Kumar") -> Anish Kumar
D7: =D6+1 -> 6 | I7: =IFERROR(__xludf.DUMMYFUNCTION("""COMPUTED_VALUE"""),"Balaji Alahari") -> Balaji Alahari
D8: =D7+1 -> 7 | I8: =IFERROR(__xludf.DUMMYFUNCTION("""COMPUTED_VALUE"""),"Chinna Ponnaganti") -> Chinna Ponnaganti
D9: =D8+1 -> 8 | I9: =IFERROR(__xludf.DUMMYFUNCTION("""COMPUTED_VALUE"""),"Christopher Li") -> Christopher Li | M9: Playing | N9: =if(isna(E2),0,COUNTA(E$2:E$58)) -> 0
D10: =D9+1 -> 9 | I10: =IFERROR(__xludf.DUMMYFUNCTION("""COMPUTED_VALUE"""),"Coco Yan") -> Coco Yan | M10: Playing-Can Sit | N10: =if(isna(F2),0,COUNTA(F$2:F$58)) -> 0
D11: =D10+1 -> 10 | I11: =IFERROR(__xludf.DUMMYFUNCTION("""COMPUTED_VALUE"""),"David Shin") -> David Shin | M11: Out/Can Play | N11: =if(isna(H2),0,COUNTA(H$2:H$58)) -> 0
D12: =D11+1 -> 11 | I12: =IFERROR(__xludf.DUMMYFUNCTION("""COMPUTED_VALUE"""),"Derek Fu") -> Derek Fu | M12: Out | N12: =if(isna(G2),0,COUNTA(G$2:G$58)) -> 0
D13: =D12+1 -> 12 | I13: =IFERROR(__xludf.DUMMYFUNCTION("""COMPUTED_VALUE"""),"Elayaraja Thangaraj ") -> Elayaraja Thangaraj | M13: TBD | N13: =if(isna(I2),0,COUNTA(I$2:I$63)) -> 62
D14: =D13+1 -> 13 | I14: =IFERROR(__xludf.DUMMYFUNCTION("""COMPUTED_VALUE"""),"Eric Pan") -> Eric Pan | M14: Total | N14: =sum(N9:N13) -> 62
D15: =D14+1 -> 14 | I15: =IFERROR(__xludf.DUMMYFUNCTION("""COMPUTED_VALUE"""),"Erik Hoeckmann") -> Erik Hoeckmann
D16: =D15+1 -> 15 | I16: =IFERROR(__xludf.DUMMYFUNCTION("""COMPUTED_VALUE"""),"Fendi Purwadi") -> Fendi Purwadi | M16: Playing | N16: =sum(N9:N11) -> 0
D17: =D16+1 -> 16 | I17: =IFERROR(__xludf.DUMMYFUNCTION("""COMPUTED_VALUE"""),"James Cole III") -> James Cole III | M17: Out | N17: =if(isna(G2),0,COUNTA(G$2:G$58)) -> 0
D18: =D17+1 -> 17 | I18: =IFERROR(__xludf.DUMMYFUNCTION("""COMPUTED_VALUE"""),"Jason Kim ") -> Jason Kim | M18: TBD | N18: =N13 -> 62
D19: =D18+1 -> 18 | I19: =IFERROR(__xludf.DUMMYFUNCTION("""COMPUTED_VALUE"""),"Jimmy Awolesi") -> Jimmy Awolesi | M19: Total | N19: =sum(N15:N18) -> 62
D20: =D19+1 -> 19 | I20: =IFERROR(__xludf.DUMMYFUNCTION("""COMPUTED_VALUE"""),"Joe Luzzi") -> Joe Luzzi
D21: =D20+1 -> 20 | I21: =IFERROR(__xludf.DUMMYFUNCTION("""COMPUTED_VALUE"""),"Jonathan Phan") -> Jonathan Phan
D22: =D21+1 -> 21 | I22: =IFERROR(__xludf.DUMMYFUNCTION("""COMPUTED_VALUE"""),"Jose Ortiz") -> Jose Ortiz
D23: =D22+1 -> 22 | I23: =IFERROR(__xludf.DUMMYFUNCTION("""COMPUTED_VALUE"""),"Joyce Zhu") -> Joyce Zhu | M23: Vacations
D24: =D23+1 -> 23 | I24: =IFERROR(__xludf.DUMMYFUNCTION("""COMPUTED_VALUE"""),"Kevin Wang") -> Kevin Wang
D25: =D24+1 -> 24 | I25: =IFERROR(__xludf.DUMMYFUNCTION("""COMPUTED_VALUE"""),"Kingsley Kuo") -> Kingsley Kuo
D26: =D25+1 -> 25 | I26: =IFERROR(__xludf.DUMMYFUNCTION("""COMPUTED_VALUE"""),"Lam Bui") -> Lam Bui
D27: =D26+1 -> 26 | I27: =IFERROR(__xludf.DUMMYFUNCTION("""COMPUTED_VALUE"""),"Lauren Chang") -> Lauren Chang
D28: =D27+1 -> 27 | I28: =IFERROR(__xludf.DUMMYFUNCTION("""COMPUTED_VALUE"""),"Lloyd Sagar") -> Lloyd Sagar
D29: =D28+1 -> 28 | I29: =IFERROR(__xludf.DUMMYFUNCTION("""COMPUTED_VALUE"""),"Luis Hsu") -> Luis Hsu
D30: =D29+1 -> 29 | I30: =IFERROR(__xludf.DUMMYFUNCTION("""COMPUTED_VALUE"""),"Manish Anand") -> Manish Anand
D31: =D30+1 -> 30 | I31: =IFERROR(__xludf.DUMMYFUNCTION("""COMPUTED_VALUE"""),"Manuel Rivera") -> Manuel Rivera
D32: =D31+1 -> 31 | I32: =IFERROR(__xludf.DUMMYFUNCTION("""COMPUTED_VALUE"""),"Matthew Huang") -> Matthew Huang
D33: =D32+1 -> 32 | I33: =IFERROR(__xludf.DUMMYFUNCTION("""COMPUTED_VALUE"""),"Mauricio Palacios") -> Mauricio Palacios
D34: =D33+1 -> 33 | I34: =IFERROR(__xludf.DUMMYFUNCTION("""COMPUTED_VALUE"""),"Mihir Anand") -> Mihir Anand
D35: =D34+1 -> 34 | I35: =IFERROR(__xludf.DUMMYFUNCTION("""COMPUTED_VALUE"""),"Naveen Raj") -> Naveen Raj
D36: =D35+1 -> 35 | I36: =IFERROR(__xludf.DUMMYFUNCTION("""COMPUTED_VALUE"""),"Nohely Mejia") -> Nohely Mejia
D37: =D36+1 -> 36 | I37: =IFERROR(__xludf.DUMMYFUNCTION("""COMPUTED_VALUE"""),"Oscar Bonilla") -> Oscar Bonilla
D38: =D37+1 -> 37 | I38: =IFERROR(__xludf.DUMMYFUNCTION("""COMPUTED_VALUE"""),"Pan Lee") -> Pan Lee
D39: =D38+1 -> 38 | I39: =IFERROR(__xludf.DUMMYFUNCTION("""COMPUTED_VALUE"""),"Paul Sanchez") -> Paul Sanchez
D40: =D39+1 -> 39 | I40: =IFERROR(__xludf.DUMMYFUNCTION("""COMPUTED_VALUE"""),"Pavan Akkimsetty") -> Pavan Akkimsetty
...

Sheet 122323
B1: Standings as of | C1: 45283
B2: Number of Weeks Played | D2: 24
C3: Beginning of week | G3: Current Week Scores | M3: End of week | P3: Jan-Jul 2024
A4: Ranking | B4: Name of Player | C4: Games Won | D4: Sets Won | E4: Check IN | F4: Court # | G4: Set 0 | H4: Set 1 | I4: Set 2 | J4: Set 3 | K4: Games Won | L4: Sets Won | M4: Games Won | N4: Sets Won | O4: Waiver | P4: Fee | Q4: Sit outs | R4: No Shows | S4: Absent
A5: 1 | B5: Peter Cheng | C5: 321 | D5: 34 | E5: 1 | F5: 1 | G5: 0 | H5: 6 | I5: 6 | J5: 6 | K5: 18 | L5: 2 | M5: =C5+K5 -> 339 | N5: =D5+L5 -> 36 | O5: X | Q5: =if(G5=13,1,0)+VLOOKUP(B5,'121623'!B$5:Q$64,16,false) -> 1 | S5: =if(G5=9,1,0)+VLOOKUP(B5,'121623'!B:S,18,false) -> 6
A6: =A5+1 -> 2 | B6: Adrian Tay | C6: 315 | D6: 31 | E6: 3 | F6: 0 | G6: 9 | H6: 0 | I6: 0 | J6: 0 | K6: 9 | L6: 0 | M6: =C6+K6 -> 324 | N6: =D6+L6 -> 31 | O6: X | P6: X | Q6: =if(G6=13,1,0)+VLOOKUP(B6,'121623'!B$5:Q$64,16,false) -> 0 | S6: =if(G6=9,1,0)+VLOOKUP(B6,'121623'!B:S,18,false) -> 9
A7: =A6+1 -> 3 | B7: Robert Chang | C7: 307 | D7: 29 | E7: 2 | F7: 1 | G7: 0 | H7: 6 | I7: 4 | J7: 7 | K7: 17 | L7: 2 | M7: =C7+K7 -> 324 | N7: =D7+L7 -> 31 | O7: X | P7: X | Q7: =if(G7=13,1,0)+VLOOKUP(B7,'121623'!B$5:Q$64,16,false) -> 0 | S7: =if(G7=9,1,0)+VLOOKUP(B7,'121623'!B:S,18,false) -> 10
A8: =A7+1 -> 4 | B8: Pulkit Mathur | C8: 299 | D8: 25 | E8: 3 | F8: 0 | G8: 9 | H8: 0 | I8: 0 | J8: 0 | K8: 9 | L8: 0 | M8: =C8+K8 -> 308 | N8: =D8+L8 -> 25 | O8: X | P8: X | Q8: =if(G8=13,1,0)+VLOOKUP(B8,'121623'!B$5:Q$64,16,false) -> 0 | S8: =if(G8=9,1,0)+VLOOKUP(B8,'121623'!B:S,18,false) -> 9
A9: =A8+1 -> 5 | B9: Alejandro Mejia | C9: 297 | D9: 26 | E9: 1 | F9: 1 | G9: 0 | H9: 4 | I9: 6 | J9: 7 | K9: 17 | L9: 2 | M9: =C9+K9 -> 314 | N9: =D9+L9 -> 28 | O9: X | P9: X | Q9: =if(G9=13,1,0)+VLOOKUP(B9,'121623'!B$5:Q$64,16,false) -> 1 | S9: =if(G9=9,1,0)+VLOOKUP(B9,'121623'!B:S,18,false) -> 4
A10: =A9+1 -> 6 | B10: Matthew Huang | C10: 295 | D10: 25 | E10: 1 | F10: 1 | G10: 0 | H10: 4 | I10: 4 | J10: 6 | K10: 14 | L10: 0 | M10: =C10+K10 -> 309 | N10: =D10+L10 -> 25 | O10: X | P10: X | Q10: =if(G10=13,1,0)+VLOOKUP(B10,'121623'!B$5:Q$64,16,false) -> 0 | S10: =if(G10=9,1,0)+VLOOKUP(B10,'121623'!B:S,18,false) -> 10
A11: =A10+1 -> 7 | B11: Lam Bui | C11: 293 | D11: 26 | E11: 3 | F11: 0 | G11: 9 | H11: 0 | I11: 0 | J11: 0 | K11: 9 | L11: 0 | M11: =C11+K11 -> 302 | N11: =D11+L11 -> 26 | O11: X | P11: X | Q11: =if(G11=13,1,0)+VLOOKUP(B11,'121623'!B$5:Q$64,16,false) -> 1 | S11: =if(G11=9,1,0)+VLOOKUP(B11,'121623'!B:S,18,false) -> 10
A12: =A11+1 -> 8 | B12: Pavan Akkimsetty | C12: 291 | D12: 26 | E12: 1 | F12: 2 | G12: 0 | H12: 6 | I12: 4 | J12: 4 | K12: 14 | L12: 1 | M12: =C12+K12 -> 305 | N12: =D12+L12 -> 27 | O12: X | P12: X | Q12: =if(G12=13,1,0)+VLOOKUP(B12,'121623'!B$5:Q$64,16,false) -> 0 | S12: =if(G12=9,1,0)+VLOOKUP(B12,'121623'!B:S,18,false) -> 2
A13: =A12+1 -> 9 | B13: Erik Hoeckmann | C13: 290 | D13: 23 | E13: 1 | F13: 2 | G13: 0 | H13: 1 | I13: 4 | J13: 6 | K13: 11 | L13: 1 | M13: =C13+K13 -> 301 | N13: =D13+L13 -> 24 | O13: X | P13: X | Q13: =if(G13=13,1,0)+VLOOKUP(B13,'121623'!B$5:Q$64,16,false) -> 0 | S13: =if(G13=9,1,0)+VLOOKUP(B13,'121623'!B:S,18,false) -> 6
A14: =A13+1 -> 10 | B14: Peter Homsey | C14: 283 | D14: 24 | E14: 1 | F14: 2 | G14: 0 | H14: 6 | I14: 6 | J14: 6 | K14: 18 | L14: 3 | M14: =C14+K14 -> 301 | N14: =D14+L14 -> 27 | O14: X | P14: X | Q14: =if(G14=13,1,0)+VLOOKUP(B14,'121623'!B$5:Q$64,16,false) -> 0 | S14: =if(G14=9,1,0)+VLOOKUP(B14,'121623'!B:S,18,false) -> 8
A15: =A14+1 -> 11 | B15: Oscar Bonilla | C15: 283 | D15: 23 | E15: 3 | F15: 0 | G15: 9 | H15: 0 | I15: 0 | J15: 0 | K15: 9 | L15: 0 | M15: =C15+K15 -> 292 | N15: =D15+L15 -> 23 | O15: X | P15: X | Q15: =if(G15=13,1,0)+VLOOKUP(B15,'121623'!B$5:Q$64,16,false) -> 0 | S15: =if(G15=9,1,0)+VLOOKUP(B15,'121623'!B:S,18,false) -> 11
A16: =A15+1 -> 12 | B16: Chinna Ponnaganti | C16: 282 | D16: 26 | E16: 1 | F16: 2 | G16: 0 | H16: 1 | I16: 6 | J16: 4 | K16: 11 | L16: 1 | M16: =C16+K16 -> 293 | N16: =D16+L16 -> 27 | O16: X | P16: X | Q16: =if(G16=13,1,0)+VLOOKUP(B16,'121623'!B$5:Q$64,16,false) -> 1 | S16: =if(G16=9,1,0)+VLOOKUP(B16,'121623'!B:S,18,false) -> 5
A17: =A16+1 -> 13 | B17: Joe Luzzi | C17: 282 | D17: 26 | E17: 2 | F17: 3 | G17: 0 | H17: 6 | I17: 6 | J17: 7 | K17: 19 | L17: 2 | M17: =C17+K17 -> 301 | N17: =D17+L17 -> 28 | O17: X | P17: X | Q17: =if(G17=13,1,0)+VLOOKUP(B17,'121623'!B$5:Q$64,16,false) -> 0 | S17: =if(G17=9,1,0)+VLOOKUP(B17,'121623'!B:S,18,false) -> 6
... A39: =A38+1 -> 35 | B39: Mauricio Palacios | C39: 241 | D39: 22 | E39: 2 | F39: 6 | G39: 0 | H39: 6 | I39: 6 | J39: 6 | K39: 18 | L39: 3 | M39: =C39+K39 -> 259 | N39: =D39+L39 -> 25 | O39: X | P39: X | Q39: =if(G39=13,1,0)+VLOOKUP(B39,'121623'!B$5:Q$64,16,false) -> 0 | S39: =if(G39=9,1,0)+VLOOKUP(B39,'121623'!B:S,18,false) -> 4
A40: =A39+1 -> 36 | B40: Derek Fu | C40: 240 | D40: 10 | E40: 3 | F40: 0 | G40: 9 | H40: 0 | I40: 0 | J40: 0 | K40: 9 | L40: 0 | M40: =C40+K40 -> 249 | N40: =D40+L40 -> 10 | O40: X | Q40: =if(G40=13,1,0)+VLOOKUP(B40,'121623'!B$5:Q$64,16,false) -> 0 | S40: =if(G40=9,1,0)+VLOOKUP(B40,'121623'!B:S,18,false) -> 20
A41: =A40+1 -> 37 | B41: Sandy Weyant | C41: 238 | D41: 14 | E41: 1 | F41: 6 | G41: 0 | H41: 4 | I41: 6 | J41: 4 | K41: 14 | L41: 1 | M41: =C41+K41 -> 252 | N41: =D41+L41 -> 15 | O41: X | P41: X | Q41: =if(G41=13,1,0)+VLOOKUP(B41,'121623'!B$5:Q$64,16,false) -> 0 | S41: =if(G41=9,1,0)+VLOOKUP(B41,'121623'!B:S,18,false) -> 7
A42: =A41+1 -> 38 | B42: Vamsi Lolla | C42: 235 | D42: 12 | E42: 1 | F42: 7 | G42: 0 | H42: 4 | I42: 6 | J42: 6 | K42: 16 | L42: 2 | M42: =C42+K42 -> 251 | N42: =D42+L42 -> 14 | O42: X | P42: X | Q42: =if(G42=13,1,0)+VLOOKUP(B42,'121623'!B$5:Q$64,16,false) -> 1 | S42: =if(G42=9,1,0)+VLOOKUP(B42,'121623'!B:S,18,false) -> 11
A43: =A42+1 -> 39 | B43: Andrew Chin | C43: 235 | D43: 9 | E43: 3 | F43: 0 | G43: 9 | H43: 0 | I43: 0 | J43: 0 | K43: 9 | L43: 0 | M43: =C43+K43 -> 244 | N43: =D43+L43 -> 9 | O43: X | P43: X | Q43: =if(G43=13,1,0)+VLOOKUP(B43,'121623'!B$5:Q$64,16,false) -> 0 | S43: =if(G43=9,1,0)+VLOOKUP(B43,'121623'!B:S,18,false) -> 20
A44: =A43+1 -> 40 | B44: Elayaraja Thangaraj | C44: 234 | D44: 19 | E44: 1 | F44: 7 | G44: 0 | H44: 6 | I44: 6 | J44: 2 | K44: 14 | L44: 2 | M44: =C44+K44 -> 248 | N44: =D44+L44 -> 21 | O44: X | P44: X | Q44: =if(G44=13,1,0)+VLOOKUP(B44,'121623'!B$5:Q$64,16,false) -> 0 | S44: =if(G44=9,1,0)+VLOOKUP(B44,'121623'!B:S,18,false) -> 9
A45: =A44+1 -> 41 | B45: Paul Sanchez | C45: 234 | D45: 9 | E45: 3 | F45: 0 | G45: 9 | H45: 0 | I45: 0 | J45: 0 | K45: 9 | L45: 0 | M45: =C45+K45 -> 243 | N45: =D45+L45 -> 9 | O45: X | Q45: =if(G45=13,1,0)+VLOOKUP(B45,'121623'!B$5:Q$64,16,false) -> 0 | S45: =if(G45=9,1,0)+VLOOKUP(B45,'121623'!B:S,18,false) -> 16
A46: =A45+1 -> 42 | B46: Nohely Mejia | C46: 232 | D46: 12 | E46: 2 | F46: 7 | G46: 0 | H46: 4 | I46: 0 | J46: 2 | K46: 6 | L46: 0 | M46: =C46+K46 -> 238 | N46: =D46+L46 -> 12 | O46: X | P46: X | Q46: =if(G46=13,1,0)+VLOOKUP(B46,'121623'!B$5:Q$64,16,false) -> 2 | S46: =if(G46=9,1,0)+VLOOKUP(B46,'121623'!B:S,18,false) -> 8
A47: =A46+1 -> 43 | B47: Vinot Kumar Nagappan | C47: 231 | D47: 11 | E47: 1 | F47: 7 | G47: 0 | H47: 6 | I47: 0 | J47: 6 | K47: 12 | L47: 2 | M47: =C47+K47 -> 243 | N47: =D47+L47 -> 13 | O47: X | P47: X | Q47: =if(G47=13,1,0)+VLOOKUP(B47,'121623'!B$5:Q$64,16,false) -> 0 | S47: =if(G47=9,1,0)+VLOOKUP(B47,'121623'!B:S,18,false) -> 13
A48: =A47+1 -> 44 | B48: James Cole III | C48: 229 | D48: 8 | E48: 3 | F48: 0 | G48: 9 | H48: 0 | I48: 0 | J48: 0 | K48: 9 | L48: 0 | M48: =C48+K48 -> 238 | N48: =D48+L48 -> 8 | O48: X | Q48: =if(G48=13,1,0)+VLOOKUP(B48,'121623'!B$5:Q$64,16,false) -> 0 | S48: =if(G48=9,1,0)+VLOOKUP(B48,'121623'!B:S,18,false) -> 18
A49: =A48+1 -> 45 | B49: Jimmy Awolesi | C49: 225 | D49: 13 | E49: 1 | F49: 8 | G49: 0 | H49: 6 | I49: 1 | J49: 6 | K49: 13 | L49: 2 | M49: =C49+K49 -> 238 | N49: =D49+L49 -> 15 | O49: X | P49: X | Q49: =if(G49=13,1,0)+VLOOKUP(B49,'121623'!B$5:Q$64,16,false) -> 0 | S49: =if(G49=9,1,0)+VLOOKUP(B49,'121623'!B:S,18,false) -> 10
A50: =A49+1 -> 46 | B50: Balaji Alahari | C50: 222 | D50: 5 | E50: 1 | F50: 8 | G50: 0 | H50: 6 | I50: 6 | J50: 2 | K50: 14 | L50: 2 | M50: =C50+K50 -> 236 | N50: =D50+L50 -> 7 | O50: X | P50: X | Q50: =if(G50=13,1,0)+VLOOKUP(B50,'121623'!B$5:Q$64,16,false) -> 1 | S50: =if(G50=9,1,0)+VLOOKUP(B50,'121623'!B:S,18,false) -> 18
A51: =A50+1 -> 47 | B51: Luis Hsu | C51: 222 | D51: 5 | E51: 3 | F51: 0 | G51: 9 | H51: 0 | I51: 0 | J51: 0 | K51: 9 | L51: 0 | M51: =C51+K51 -> 231 | N51: =D51+L51 -> 5 | O51: X | P51: X | Q51: =if(G51=13,1,0)+VLOOKUP(B51,'121623'!B$5:Q$64,16,false) -> 0 | S51: =if(G51=9,1,0)+VLOOKUP(B51,'121623'!B:S,18,false) -> 21
A52: =A51+1 -> 48 | B52: Pan Lee | C52: 221 | D52: 5 | E52: 3 | F52: 0 | G52: 9 | H52: 0 | I52: 0 | J52: 0 | K52: 9 | L52: 0 | M52: =C52+K52 -> 230 | N52: =D52+L52 -> 5 | O52: X | Q52: =if(G52=13,1,0)+VLOOKUP(B52,'121623'!B$5:Q$64,16,false) -> 0 | S52: =if(G52=9,1,0)+VLOOKUP(B52,'121623'!B:S,18,false) -> 22
A53: =A52+1 -> 49 | B53: Lauren Chang | C53: 219 | D53: 4 | E53: 3 | F53: 0 | G53: 9 | H53: 0 | I53: 0 | J53: 0 | K53: 9 | L53: 0 | M53: =C53+K53 -> 228 | N53: =D53+L53 -> 4 | O53: X | Q53: =if(G53=13,1,0)+VLOOKUP(B53,'121623'!B$5:Q$64,16,false) -> 0 | S53: =if(G53=9,1,0)+VLOOKUP(B53,'121623'!B:S,18,false) -> 19
A54: =A53+1 -> 50 | B54: Santosh Sundaresan | C54: 217 | D54: 6 | E54: 3 | F54: 0 | G54: 9 | H54: 0 | I54: 0 | J54: 0 | K54: 9 | L54: 0 | M54: =C54+K54 -> 226 | N54: =D54+L54 -> 6 | O54: X | P54: X | Q54: =if(G54=13,1,0)+VLOOKUP(B54,'121623'!B$5:Q$64,16,false) -> 0 | S54: =if(G54=9,1,0)+VLOOKUP(B54,'121623'!B:S,18,false) -> 18
A55: =A54+1 -> 51 | B55: Kevin Wang | C55: 216 | D55: 14 | E55: 1 | F55: 8 | G55: 0 | H55: 3 | I55: 6 | J55: 6 | K55: 15 | L55: 2 | M55: =C55+K55 -> 231 | N55: =D55+L55 -> 16 | O55: X | Q55: =if(G55=13,1,0)+VLOOKUP(B55,'121623'!B$5:Q$64,16,false) -> 0 | S55: =if(G55=9,1,0)+VLOOKUP(B55,'121623'!B:S,18,false) -> 9
A56: =A55+1 -> 52 | B56: Vilas Janardhanan | C56: 216 | D56: 7 | E56: 3 | F56: 0 | G56: 9 | H56: 0 | I56: 0 | J56: 0 | K56: 9 | L56: 0 | M56: =C56+K56 -> 225 | N56: =D56+L56 -> 7 | O56: X | P56: X | Q56: =if(G56=13,1,0)+VLOOKUP(B56,'121623'!B$5:Q$64,16,false) -> 0 | S56: =if(G56=9,1,0)+VLOOKUP(B56,'121623'!B:S,18,false) -> 18
A57: =A56+1 -> 53 | B57: Piyorasa Li | C57: 216 | D57: 3 | E57: 3 | F57: 0 | G57: 9 | H57: 0 | I57: 0 | J57: 0 | K57: 9 | L57: 0 | M57: =C57+K57 -> 225 | N57: =D57+L57 -> 3 | O57: X | Q57: =if(G57=13,1,0)+VLOOKUP(B57,'121623'!B$5:Q$64,16,false) -> 0 | S57: =if(G57=9,1,0)+VLOOKUP(B57,'121623'!B:S,18,false) -> 19
A58: =A57+1 -> 54 | B58: Jason Kim | C58: 216 | D58: 3 | E58: 3 | F58: 0 | G58: 9 | H58: 0 | I58: 0 | J58: 0 | K58: 9 | L58: 0 | M58: =C58+K58 -> 225 | N58: =D58+L58 -> 3 | O58: X | Q58: =if(G58=13,1,0)+VLOOKUP(B58,'121623'!B$5:Q$64,16,false) -> 0 | S58: =if(G58=9,1,0)+VLOOKUP(B58,'121623'!B:S,18,false) -> 20
A59: =A58+1 -> 55 | B59: Amit Patel | C59: 214 | D59: 4 | E59: 3 | F59: 0 | G59: 9 | H59: 0 | I59: 0 | J59: 0 | K59: 9 | L59: 0 | M59: =C59+K59 -> 223 | N59: =D59+L59 -> 4 | O59: X | P59: X | Q59: =if(G59=13,1,0)+VLOOKUP(B59,'121623'!B$5:Q$64,16,false) -> 0 | S59: =if(G59=9,1,0)+VLOOKUP(B59,'121623'!B:S,18,false) -> 21
A60: =A59+1 -> 56 | B60: Coco Yan | C60: 211 | D60: 2 | E60: 3 | F60: 0 | G60: 9 | H60: 0 | I60: 0 | J60: 0 | K60: 9 | L60: 0 | M60: =C60+K60 -> 220 | N60: =D60+L60 -> 2 | O60: X | P60: X | Q60: =if(G60=13,1,0)+VLOOKUP(B60,'121623'!B$5:Q$64,16,false) -> 0 | S60: =if(G60=9,1,0)+VLOOKUP(B60,'121623'!B:S,18,false) -> 23
A61: =A60+1 -> 57 | B61: Thomas Zou | C61: 211 | D61: 2 | E61: 3 | F61: 0 | G61: 9 | K61: 9 | M61: =C61+K61 -> 220 | N61: =D61+L61 -> 2 | O61: X | Q61: =if(G61=13,1,0)+VLOOKUP(B61,'121623'!B$5:Q$64,16,false) -> 0 | S61: =if(G61=9,1,0)+VLOOKUP(B61,'121623'!B:S,18,false) -> 23
...

Sheet 121623
B1: Standings as of | C1: 45276
B2: Number of Weeks Played | D2: 23
C3: Beginning of week | G3: Current Week Scores | M3: End of week | P3: Jan-Jul 2024
A4: Ranking | B4: Name of Player | C4: Games Won | D4: Sets Won | E4: Check IN | F4: Court # | G4: Set 0 | H4: Set 1 | I4: Set 2 | J4: Set 3 | K4: Games Won | L4: Sets Won | M4: Games Won | N4: Sets Won | O4: Waiver | P4: Fee | Q4: Sit outs | R4: No Shows | S4: Absent
A5: 1 | B5: Peter Cheng | C5: 302 | D5: 32 | E5: 1 | F5: 1 | G5: 0 | H5: 7 | I5: 7 | J5: 5 | K5: 19 | L5: 2 | M5: =C5+K5 -> 321 | N5: =D5+L5 -> 34 | O5: X | Q5: =if(G5=13,1,0)+VLOOKUP(B5,'120923'!B:Q,16,false) -> 1 | S5: =if(G5=9,1,0)+VLOOKUP(B5,'120923'!B:S,18,false) -> 6
A6: =A5+1 -> 2 | B6: Adrian Tay | C6: 295 | D6: 29 | E6: 1 | F6: 1 | G6: 0 | H6: 7 | I6: 6 | J6: 7 | K6: 20 | L6: 2 | M6: =C6+K6 -> 315 | N6: =D6+L6 -> 31 | O6: X | Q6: =if(G6=13,1,0)+VLOOKUP(B6,'120923'!B:Q,16,false) -> 0 | S6: =if(G6=9,1,0)+VLOOKUP(B6,'120923'!B:S,18,false) -> 8
A7: =A6+1 -> 3 | B7: Robert Chang | C7: 288 | D7: 27 | E7: 2 | F7: 1 | G7: 0 | H7: 5 | I7: 7 | J7: 7 | K7: 19 | L7: 2 | M7: =C7+K7 -> 307 | N7: =D7+L7 -> 29 | O7: X | P7: X | Q7: =if(G7=13,1,0)+VLOOKUP(B7,'120923'!B:Q,16,false) -> 0 | S7: =if(G7=9,1,0)+VLOOKUP(B7,'120923'!B:S,18,false) -> 10
A8: =A7+1 -> 4 | B8: Pulkit Mathur | C8: 283 | D8: 25 | E8: 2 | F8: 1 | G8: 0 | H8: 5 | I8: 6 | J8: 5 | K8: 16 | L8: 0 | M8: =C8+K8 -> 299 | N8: =D8+L8 -> 25 | O8: X | P8: X | Q8: =if(G8=13,1,0)+VLOOKUP(B8,'120923'!B:Q,16,false) -> 0 | S8: =if(G8=9,1,0)+VLOOKUP(B8,'120923'!B:S,18,false) -> 8
A9: =A8+1 -> 5 | B9: Lam Bui | C9: 282 | D9: 25 | E9: 2 | F9: 2 | G9: 0 | H9: 6 | I9: 3 | J9: 2 | K9: 11 | L9: 1 | M9: =C9+K9 -> 293 | N9: =D9+L9 -> 26 | O9: X | P9: X | Q9: =if(G9=13,1,0)+VLOOKUP(B9,'120923'!B:Q,16,false) -> 1 | S9: =if(G9=9,1,0)+VLOOKUP(B9,'120923'!B:S,18,false) -> 9
A10: =A9+1 -> 6 | B10: Matthew Huang | C10: 282 | D10: 24 | E10: 1 | F10: 2 | G10: 0 | H10: 4 | I10: 3 | J10: 6 | K10: 13 | L10: 1 | M10: =C10+K10 -> 295 | N10: =D10+L10 -> 25 | O10: X | P10: X | Q10: =if(G10=13,1,0)+VLOOKUP(B10,'120923'!B:Q,16,false) -> 0 | S10: =if(G10=9,1,0)+VLOOKUP(B10,'120923'!B:S,18,false) -> 10
A11: =A10+1 -> 7 | B11: Pavan Akkimsetty | C11: 279 | D11: 25 | E11: 1 | F11: 2 | G11: 0 | H11: 4 | I11: 6 | J11: 2 | K11: 12 | L11: 1 | M11: =C11+K11 -> 291 | N11: =D11+L11 -> 26 | O11: X | P11: X | Q11: =if(G11=13,1,0)+VLOOKUP(B11,'120923'!B:Q,16,false) -> 0 | S11: =if(G11=9,1,0)+VLOOKUP(B11,'120923'!B:S,18,false) -> 2
A12: =A11+1 -> 8 | B12: Alejandro Mejia | C12: 279 | D12: 23 | E12: 1 | F12: 2 | G12: 0 | H12: 6 | I12: 6 | J12: 6 | K12: 18 | L12: 3 | M12: =C12+K12 -> 297 | N12: =D12+L12 -> 26 | O12: X | P12: X | Q12: =if(G12=13,1,0)+VLOOKUP(B12,'120923'!B:Q,16,false) -> 1 | S12: =if(G12=9,1,0)+VLOOKUP(B12,'120923'!B:S,18,false) -> 4
A13: =A12+1 -> 9 | B13: Erik Hoeckmann | C13: 271 | D13: 20 | E13: 1 | F13: 3 | G13: 0 | H13: 6 | I13: 7 | J13: 6 | K13: 19 | L13: 3 | M13: =C13+K13 -> 290 | N13: =D13+L13 -> 23 | O13: X | P13: X | Q13: =if(G13=13,1,0)+VLOOKUP(B13,'120923'!B:Q,16,false) -> 0 | S13: =if(G13=9,1,0)+VLOOKUP(B13,'120923'!B:S,18,false) -> 6
A14: =A13+1 -> 10 | B14: Lloyd Sagar | C14: 271 | D14: 19 | E14: 3 | F14: 0 | G14: 9 | H14: 0 | I14: 0 | J14: 0 | K14: 9 | L14: 0 | M14: =C14+K14 -> 280 | N14: =D14+L14 -> 19 | O14: X | P14: X | Q14: =if(G14=13,1,0)+VLOOKUP(B14,'120923'!B:Q,16,false) -> 0 | S14: =if(G14=9,1,0)+VLOOKUP(B14,'120923'!B:S,18,false) -> 6
A15: =A14+1 -> 11 | B15: Peter Homsey | C15: 269 | D15: 23 | E15: 1 | F15: 3 | G15: 0 | H15: 6 | I15: 6 | J15: 2 | K15: 14 | L15: 1 | M15: =C15+K15 -> 283 | N15: =D15+L15 -> 24 | O15: X | P15: X | Q15: =if(G15=13,1,0)+VLOOKUP(B15,'120923'!B:Q,16,false) -> 0 | S15: =if(G15=9,1,0)+VLOOKUP(B15,'120923'!B:S,18,false) -> 8
A16: =A15+1 -> 12 | B16: Jonathan Phan | C16: 269 | D16: 20 | E16: 3 | F16: 0 | G16: 9 | H16: 0 | I16: 0 | J16: 0 | K16: 9 | L16: 0 | M16: =C16+K16 -> 278 | N16: =D16+L16 -> 20 | O16: X | P16: X | Q16: =if(G16=13,1,0)+VLOOKUP(B16,'120923'!B:Q,16,false) -> 0 | S16: =if(G16=9,1,0)+VLOOKUP(B16,'120923'!B:S,18,false) -> 6
A17: =A16+1 -> 13 | B17: Oscar Bonilla | C17: 268 | D17: 22 | E17: 1 | F17: 3 | G17: 0 | H17: 3 | I17: 6 | J17: 6 | K17: 15 | L17: 1 | M17: =C17+K17 -> 283 | N17: =D17+L17 -> 23 | O17: X | Q17: =if(G17=13,1,0)+VLOOKUP(B17,'120923'!B:Q,16,false) -> 0 | S17: =if(G17=9,1,0)+VLOOKUP(B17,'120923'!B:S,18,false) -> 10
A18: =A17+1 -> 14 | B18: Ted Shen | C18: 267 | D18: 23 | E18: 1 | F18: 3 | G18: 0 | H18: 3 | I18: 7 | J18: 2 | K18: 12 | L18: 1 | M18: =C18+K18 -> 279 | N18: =D18+L18 -> 24 | O18: X | P18: X | Q18: =if(G18=13,1,0)+VLOOKUP(B18,'120923'!B:Q,16,false) -> 0 | S18: =if(G18=9,1,0)+VLOOKUP(B18,'120923'!B:S,18,false) -> 8
A19: =A18+1 -> 15 | B19: Chinna Ponnaganti | C19: 266 | D19: 24 | E19: 1 | F19: 4 | G19: 0 | H19: 7 | I19: 2 | J19: 7 | K19: 16 | L19: 2 | M19: =C19+K19 -> 282 | N19: =D19+L19 -> 26 | O19: X | P19: X | Q19: =if(G19=13,1,0)+VLOOKUP(B19,'120923'!B:Q,16,false) -> 1 | S19: =if(G19=9,1,0)+VLOOKUP(B19,'120923'!B:S,18,false) -> 5
A20: =A19+1 -> 16 | B20: Joe Luzzi | C20: 263 | D20: 24 | E20: 2 | F20: 4 | G20: 0 | H20: 7 | I20: 6 | J20: 6 | K20: 19 | L20: 2 | M20: =C20+K20 -> 282 | N20: =D20+L20 -> 26 | O20: X | P20: X | Q20: =if(G20=13,1,0)+VLOOKUP(B20,'120923'!B:Q,16,false) -> 0 | S20: =if(G20=9,1,0)+VLOOKUP(B20,'120923'!B:S,18,false) -> 6
A21: =A20+1 -> 17 | B21: Tony Wong | C21: 263 | D21: 18 | E21: 2 | F21: 4 | G21: 0 | H21: 5 | I21: 2 | J21: 6 | K21: 13 | L21: 0 | M21: =C21+K21 -> 276 | N21: =D21+L21 -> 18 | O21: X | Q21: =if(G21=13,1,0)+VLOOKUP(B21,'120923'!B:Q,16,false) -> 0 | S21: =if(G21=9,1,0)+VLOOKUP(B21,'120923'!B:S,18,false) -> 6
A22: =A21+1 -> 18 | B22: David Shin | C22: 262 | D22: 20 | E22: 1 | F22: 4 | G22: 0 | H22: 5 | I22: 6 | J22: 7 | K22: 18 | L22: 2 | M22: =C22+K22 -> 280 | N22: =D22+L22 -> 22 | O22: X | P22: X | Q22: =if(G22=13,1,0)+VLOOKUP(B22,'120923'!B:Q,16,false) -> 0 | S22: =if(G22=9,1,0)+VLOOKUP(B22,'120923'!B:S,18,false) -> 7
A23: =A22+1 -> 19 | B23: Kingsley Kuo | C23: 262 | D23: 18 | E23: 3 | F23: 0 | G23: 9 | H23: 0 | I23: 0 | J23: 0 | K23: 9 | L23: 0 | M23: =C23+K23 -> 271 | N23: =D23+L23 -> 18 | O23: X | Q23: =if(G23=13,1,0)+VLOOKUP(B23,'120923'!B:Q,16,false) -> 0 | S23: =if(G23=9,1,0)+VLOOKUP(B23,'120923'!B:S,18,false) -> 14
A24: =A23+1 -> 20 | B24: Trinath Goteti | C24: 255 | D24: 16 | E24: 2 | F24: 5 | G24: 0 | H24: 6 | I24: 4 | J24: 6 | K24: 16 | L24: 2 | M24: =C24+K24 -> 271 | N24: =D24+L24 -> 18 | O24: X | P24: X | Q24: =if(G24=13,1,0)+VLOOKUP(B24,'120923'!B:Q,16,false) -> 0 | S24: =if(G24=9,1,0)+VLOOKUP(B24,'120923'!B:S,18,false) -> 14
A25: =A24+1 -> 21 | B25: Sai Dilip Ponnaganti | C25: 255 | D25: 15 | E25: 1 | F25: 5 | G25: 0 | H25: 2 | I25: 6 | J25: 6 | K25: 14 | L25: 2 | M25: =C25+K25 -> 269 | N25: =D25+L25 -> 17 | O25: X | P25: X | Q25: =if(G25=13,1,0)+VLOOKUP(B25,'120923'!B:Q,16,false) -> 0 | S25: =if(G25=9,1,0)+VLOOKUP(B25,'120923'!B:S,18,false) -> 13
A26: =A25+1 -> 22 | B26: Sean Chang | C26: 255 | D26: 15 | E26: 1 | F26: 5 | G26: 0 | H26: 6 | I26: 6 | J26: 0 | K26: 12 | L26: 2 | M26: =C26+K26 -> 267 | N26: =D26+L26 -> 17 | O26: X | P26: X | Q26: =if(G26=13,1,0)+VLOOKUP(B26,'120923'!B:Q,16,false) -> 2 | S26: =if(G26=9,1,0)+VLOOKUP(B26,'120923'!B:S,18,false) -> 8
A27: =A26+1 -> 23 | B27: Anish Kumar | C27: 254 | D27: 17 | E27: 3 | F27: 0 | G27: 9 | H27: 0 | I27: 0 | J27: 0 | K27: 9 | L27: 0 | M27: =C27+K27 -> 263 | N27: =D27+L27 -> 17 | O27: X | P27: X | Q27: =if(G27=13,1,0)+VLOOKUP(B27,'120923'!B:Q,16,false) -> 0 | S27: =if(G27=9,1,0)+VLOOKUP(B27,'120923'!B:S,18,false) -> 13
A28: =A27+1 -> 24 | B28: Tom Le | C28: 254 | D28: 15 | E28: 3 | F28: 0 | G28: 9 | H28: 0 | I28: 0 | J28: 0 | K28: 9 | L28: 0 | M28: =C28+K28 -> 263 | N28: =D28+L28 -> 15 | O28: X | P28: X | Q28: =if(G28=13,1,0)+VLOOKUP(B28,'120923'!B:Q,16,false) -> 1 | S28: =if(G28=9,1,0)+VLOOKUP(B28,'120923'!B:S,18,false) -> 15
A29: =A28+1 -> 25 | B29: Christopher Li | C29: 251 | D29: 16 | E29: 3 | F29: 0 | G29: 9 | H29: 0 | I29: 0 | J29: 0 | K29: 9 | L29: 0 | M29: =C29+K29 -> 260 | N29: =D29+L29 -> 16 | O29: X | P29: X | Q29: =if(G29=13,1,0)+VLOOKUP(B29,'120923'!B:Q,16,false) -> 0 | S29: =if(G29=9,1,0)+VLOOKUP(B29,'120923'!B:S,18,false) -> 17
A30: =A29+1 -> 26 | B30: Rajasekar Ramasamy | C30: 249 | D30: 21 | E30: 3 | F30: 0 | G30: 9 | H30: 0 | I30: 0 | J30: 0 | K30: 9 | L30: 0 | M30: =C30+K30 -> 258 | N30: =D30+L30 -> 21 | O30: X | P30: X | Q30: =if(G30=13,1,0)+VLOOKUP(B30,'120923'!B:Q,16,false) -> 0 | S30: =if(G30=9,1,0)+VLOOKUP(B30,'120923'!B:S,18,false) -> 8
A31: =A30+1 -> 27 | B31: Eric Pan | C31: 242 | D31: 16 | E31: 3 | F31: 0 | G31: 9 | H31: 0 | I31: 0 | J31: 0 | K31: 9 | L31: 0 | M31: =C31+K31 -> 251 | N31: =D31+L31 -> 16 | O31: X | Q31: =if(G31=13,1,0)+VLOOKUP(B31,'120923'!B:Q,16,false) -> 1 | S31: =if(G31=9,1,0)+VLOOKUP(B31,'120923'!B:S,18,false) -> 14
A32: =A31+1 -> 28 | B32: Sanjaye Elayattu | C32: 241 | D32: 11 | E32: 3 | F32: 0 | G32: 9 | H32: 0 | I32: 0 | J32: 0 | K32: 9 | L32: 0 | M32: =C32+K32 -> 250 | N32: =D32+L32 -> 11 | O32: X | P32: X | Q32: =if(G32=13,1,0)+VLOOKUP(B32,'120923'!B:Q,16,false) -> 0 | S32: =if(G32=9,1,0)+VLOOKUP(B32,'120923'!B:S,18,false) -> 16
A33: =A32+1 -> 29 | B33: Naveen Raj | C33: 238 | D33: 15 | E33: 1 | F33: 5 | G33: 0 | H33: 2 | I33: 4 | J33: 0 | K33: 6 | L33: 0 | M33: =C33+K33 -> 244 | N33: =D33+L33 -> 15 | O33: X | P33: X | Q33: =if(G33=13,1,0)+VLOOKUP(B33,'120923'!B:Q,16,false) -> 0 | S33: =if(G33=9,1,0)+VLOOKUP(B33,'120923'!B:S,18,false) -> 7
A34: =A33+1 -> 30 | B34: Susanta Mishra | C34: 238 | D34: 13 | E34: 1 | F34: 6 | G34: 0 | H34: 6 | I34: 6 | J34: 6 | K34: 18 | L34: 3 | M34: =C34+K34 -> 256 | N34: =D34+L34 -> 16 | O34: X | P34: X | Q34: =if(G34=13,1,0)+VLOOKUP(B34,'120923'!B:Q,16,false) -> 1 | S34: =if(G34=9,1,0)+VLOOKUP(B34,'120923'!B:S,18,false) -> 15
A35: =A34+1 -> 31 | B35: Rosie Bonilla | C35: 237 | D35: 14 | E35: 3 | F35: 0 | G35: 9 | H35: 0 | I35: 0 | J35: 0 | K35: 9 | L35: 0 | M35: =C35+K35 -> 246 | N35: =D35+L35 -> 14 | O35: X | Q35: =if(G35=13,1,0)+VLOOKUP(B35,'120923'!B:Q,16,false) -> 0 | S35: =if(G35=9,1,0)+VLOOKUP(B35,'120923'!B:S,18,false) -> 9
A36: =A35+1 -> 32 | B36: Troy Wong | C36: 234 | D36: 10 | E36: 3 | F36: 0 | G36: 9 | H36: 0 | I36: 0 | J36: 0 | K36: 9 | L36: 0 | M36: =C36+K36 -> 243 | N36: =D36+L36 -> 10 | O36: X | P36: X | Q36: =if(G36=13,1,0)+VLOOKUP(B36,'120923'!B:Q,16,false) -> 0 | S36: =if(G36=9,1,0)+VLOOKUP(B36,'120923'!B:S,18,false) -> 18
A37: =A36+1 -> 33 | B37: Manuel Rivera | C37: 233 | D37: 16 | E37: 3 | F37: 0 | G37: 9 | H37: 0 | I37: 0 | J37: 0 | K37: 9 | L37: 0 | M37: =C37+K37 -> 242 | N37: =D37+L37 -> 16 | O37: X | P37: X | Q37: =if(G37=13,1,0)+VLOOKUP(B37,'120923'!B:Q,16,false) -> 0 | S37: =if(G37=9,1,0)+VLOOKUP(B37,'120923'!B:S,18,false) -> 10
A38: =A37+1 -> 34 | B38: Mauricio Palacios | C38: 232 | D38: 22 | E38: 3 | F38: 0 | G38: 9 | H38: 0 | I38: 0 | J38: 0 | K38: 9 | L38: 0 | M38: =C38+K38 -> 241 | N38: =D38+L38 -> 22 | O38: X | P38: X | Q38: =if(G38=13,1,0)+VLOOKUP(B38,'120923'!B:Q,16,false) -> 0 | S38: =if(G38=9,1,0)+VLOOKUP(B38,'120923'!B:S,18,false) -> 4
